{"date": "20240907-113149", "backend": "vllm", "model_id": "meta-llama/Meta-Llama-3-70B-Instruct", "tokenizer_id": "meta-llama/Meta-Llama-3-70B-Instruct", "best_of": 1, "use_beam_search": false, "num_prompts": 160, "request_rate": "inf", "duration": 8.509652566164732, "completed": 21, "total_input_tokens": 8272, "total_output_tokens": 0, "request_throughput": 2.4677858275316895, "input_throughput": 972.0725888258161, "output_throughput": 0.0, "mean_ttft_ms": 0.0, "median_ttft_ms": 0.0, "std_ttft_ms": 0.0, "p99_ttft_ms": 0.0, "mean_tpot_ms": 0.0, "median_tpot_ms": 0.0, "std_tpot_ms": 0.0, "p99_tpot_ms": 0.0, "mean_itl_ms": 0.0, "median_itl_ms": 0.0, "std_itl_ms": 0.0, "p99_itl_ms": 0.0, "mean_latency_ms": 722.9261999484152, "median_latency_ms": 0.0, "std_latency_ms": 2017.6813601714687, "p99_latency_ms": 8106.553943455217, "input_lens": [13, 25, 27, 10, 329, 29, 399, 328, 4, 205, 16, 372, 403, 9, 12, 770, 227, 8, 14, 390, 659, 59, 76, 744, 619, 279, 344, 9, 10, 45, 11, 4, 80, 768, 317, 40, 619, 8, 298, 16, 17, 696, 575, 11, 7, 281, 12, 147, 481, 770, 336, 6, 331, 9, 45, 222, 802, 481, 93, 641, 22, 15, 16, 77, 32, 689, 178, 9, 628, 480, 42, 336, 24, 515, 761, 112, 113, 348, 82, 467, 245, 11, 24, 343, 13, 387, 258, 32, 28, 225, 248, 35, 133, 98, 27, 23, 58, 363, 203, 140, 140, 230, 310, 521, 768, 317, 298, 336, 491, 19, 10, 59, 48, 20, 20, 54, 107, 53, 72, 18, 10, 768, 7, 933, 239, 277, 26, 35, 462, 386, 25, 23, 17, 20, 44, 661, 631, 349, 53, 71, 37, 10, 21, 37, 496, 8, 9, 353, 10, 595, 5, 49, 286, 305, 56, 43, 52, 310, 35, 7], "output_lens": [0, 0, 0, 0, 0, 0, 0, 0, 0, 0, 0, 0, 0, 0, 0, 0, 0, 0, 0, 0, 0, 0, 0, 0, 0, 0, 0, 0, 0, 0, 0, 0, 0, 0, 0, 0, 0, 0, 0, 0, 0, 0, 0, 0, 0, 0, 0, 0, 0, 0, 0, 0, 0, 0, 0, 0, 0, 0, 0, 0, 0, 0, 0, 0, 0, 0, 0, 0, 0, 0, 0, 0, 0, 0, 0, 0, 0, 0, 0, 0, 0, 0, 0, 0, 0, 0, 0, 0, 0, 0, 0, 0, 0, 0, 0, 0, 0, 0, 0, 0, 0, 0, 0, 0, 0, 0, 0, 0, 0, 0, 0, 0, 0, 0, 0, 0, 0, 0, 0, 0, 0, 0, 0, 0, 0, 0, 0, 0, 0, 0, 0, 0, 0, 0, 0, 0, 0, 0, 0, 0, 0, 0, 0, 0, 0, 0, 0, 0, 0, 0, 0, 0, 0, 0, 0, 0, 0, 0, 0, 0], "ttfts": [2.4918362721800804, 2.491578046232462, 2.491472192108631, 2.4913717210292816, 2.491075586527586, 2.9582157023251057, 0.0, 0.0, 2.95766144990921, 2.9575272649526596, 2.9574524611234665, 2.9574321396648884, 2.957111794501543, 2.95713322237134, 3.5843944400548935, 3.5840546749532223, 3.584077823907137, 4.137838426977396, 4.137527450919151, 0.0, 4.137029331177473, 4.137236759066582, 4.136919271200895, 4.138022638857365, 0.0, 0.0, 4.798778209835291, 4.798397149890661, 4.13714312389493, 4.798125110566616, 4.136742800474167, 4.797546569257975, 4.136374659836292, 4.796627074480057, 0.0, 4.797081429511309, 5.424891144037247, 5.4245977737009525, 0.0, 5.4253871999681, 5.42415438964963, 0.0, 0.0, 6.058109223842621, 6.057334139943123, 6.0572526678442955, 6.057596154510975, 6.057498160749674, 0.0, 6.057239629328251, 6.663511645048857, 6.663434240967035, 6.663349658250809, 7.199849031865597, 6.663780886679888, 7.1988715417683125, 6.663306348025799, 0.0, 0.0, 7.1979322880506516, 7.198509979993105, 7.198384426534176, 7.19844850897789, 0.0, 8.309450704604387, 7.830681622028351, 7.197522487491369, 7.830135978758335, 7.82990562543273, 0.0, 7.196999061852694, 0.0, 7.966561134904623, 7.966229625046253, 0.0, 7.966009013354778, 7.965918812900782, 0.0, 8.306568920612335, 0.0, 8.300207391381264, 8.30583717674017, 8.299902766942978, 0.0, 0.0, 0.0, 0.0, 0.0, 8.304040260612965, 0.0, 0.0, 0.0, 0.0, 0.0, 0.0, 0.0, 0.0, 0.0, 0.0, 0.0, 0.0, 0.0, 0.0, 0.0, 0.0, 0.0, 0.0, 0.0, 0.0, 1.8913581110537052, 0.0, 1.8912336379289627, 0.0, 0.0, 0.0, 0.0, 1.8900117762386799, 1.8902916423976421, 1.8903395719826221, 1.8896984905004501, 1.889591220766306, 2.465310625731945, 1.888874627649784, 1.8891577571630478, 0.0, 0.0, 0.0, 2.46417798101902, 0.0, 2.463962186127901, 0.0, 2.4636591002345085, 2.463582318276167, 2.4635277576744556, 2.4628787264227867, 0.0, 0.0, 0.0, 0.0, 0.0, 0.0, 0.0, 0.0, 0.0, 0.0, 0.0, 0.0, 0.0, 0.0, 0.0, 0.0, 0.0, 0.0, 0.0, 0.0, 0.0, 0.0, 0.0, 0.0, 0.0], "itls": [[], [], [], [], [], [], [], [], [], [], [], [], [], [], [], [], [], [], [], [], [], [], [], [], [], [], [], [], [], [], [], [], [], [], [], [], [], [], [], [], [], [], [], [], [], [], [], [], [], [], [], [], [], [], [], [], [], [], [], [], [], [], [], [], [], [], [], [], [], [], [], [], [], [], [], [], [], [], [], [], [], [], [], [], [], [], [], [], [], [], [], [], [], [], [], [], [], [], [], [], [], [], [], [], [], [], [], [], [], [], [], [], [], [], [], [], [], [], [], [], [], [], [], [], [], [], [], [], [], [], [], [], [], [], [], [], [], [], [], [], [], [], [], [], [], [], [], [], [], [], [], [], [], [], [], [], [], [], [], []], "generated_texts": ["", "", "", "", "", "", "", "", "", "", "", "", "", "", "", "", "", "", "", "", "", "", "", "", "", "", "", "", "", "", "", "", "", "", "", "", "", "", "", "", "", "", "", "", "", "", "", "", "", "", "", "", "", "", "", "", "", "", "", "", "", "", "", "", "", "", "", "", "", "", "", "", "", "", "", "", "", "", "", "", "", "", "", "", "", "", "", "", "", "", "", "", "", "", "", "", "", "", "", "", "", "", "", "", "", "", "", "", "", "", "", "", "", "", "", "", "", "", "", "", "", "", "", "", "", "", "", "", "", "", "", "", "", "", "", "", "", "", "", "", "", "", "", "", "", "", "", "", "", "", "", "", "", "", "", "", "", "", "", ""], "errors": ["Traceback (most recent call last):\n  File \"/usr/local/lib/python3.10/dist-packages/aiohttp/client_proto.py\", line 94, in connection_lost\n    uncompleted = self._parser.feed_eof()\n  File \"aiohttp/_http_parser.pyx\", line 513, in aiohttp._http_parser.HttpParser.feed_eof\naiohttp.http_exceptions.TransferEncodingError: 400, message:\n  Not enough data for satisfy transfer length header.\n\nThe above exception was the direct cause of the following exception:\n\nTraceback (most recent call last):\n  File \"/vllm-workspace/backend_request_func.py\", line 261, in async_request_openai_completions\n    async for chunk_bytes in response.content:\n  File \"/usr/local/lib/python3.10/dist-packages/aiohttp/streams.py\", line 50, in __anext__\n    rv = await self.read_func()\n  File \"/usr/local/lib/python3.10/dist-packages/aiohttp/streams.py\", line 317, in readline\n    return await self.readuntil()\n  File \"/usr/local/lib/python3.10/dist-packages/aiohttp/streams.py\", line 351, in readuntil\n    await self._wait(\"readuntil\")\n  File \"/usr/local/lib/python3.10/dist-packages/aiohttp/streams.py\", line 312, in _wait\n    await waiter\naiohttp.client_exceptions.ClientPayloadError: Response payload is not completed: <TransferEncodingError: 400, message='Not enough data for satisfy transfer length header.'>\n", "Traceback (most recent call last):\n  File \"/usr/local/lib/python3.10/dist-packages/aiohttp/client_proto.py\", line 94, in connection_lost\n    uncompleted = self._parser.feed_eof()\n  File \"aiohttp/_http_parser.pyx\", line 513, in aiohttp._http_parser.HttpParser.feed_eof\naiohttp.http_exceptions.TransferEncodingError: 400, message:\n  Not enough data for satisfy transfer length header.\n\nThe above exception was the direct cause of the following exception:\n\nTraceback (most recent call last):\n  File \"/vllm-workspace/backend_request_func.py\", line 261, in async_request_openai_completions\n    async for chunk_bytes in response.content:\n  File \"/usr/local/lib/python3.10/dist-packages/aiohttp/streams.py\", line 50, in __anext__\n    rv = await self.read_func()\n  File \"/usr/local/lib/python3.10/dist-packages/aiohttp/streams.py\", line 317, in readline\n    return await self.readuntil()\n  File \"/usr/local/lib/python3.10/dist-packages/aiohttp/streams.py\", line 351, in readuntil\n    await self._wait(\"readuntil\")\n  File \"/usr/local/lib/python3.10/dist-packages/aiohttp/streams.py\", line 312, in _wait\n    await waiter\naiohttp.client_exceptions.ClientPayloadError: Response payload is not completed: <TransferEncodingError: 400, message='Not enough data for satisfy transfer length header.'>\n", "Traceback (most recent call last):\n  File \"/usr/local/lib/python3.10/dist-packages/aiohttp/client_proto.py\", line 94, in connection_lost\n    uncompleted = self._parser.feed_eof()\n  File \"aiohttp/_http_parser.pyx\", line 513, in aiohttp._http_parser.HttpParser.feed_eof\naiohttp.http_exceptions.TransferEncodingError: 400, message:\n  Not enough data for satisfy transfer length header.\n\nThe above exception was the direct cause of the following exception:\n\nTraceback (most recent call last):\n  File \"/vllm-workspace/backend_request_func.py\", line 261, in async_request_openai_completions\n    async for chunk_bytes in response.content:\n  File \"/usr/local/lib/python3.10/dist-packages/aiohttp/streams.py\", line 50, in __anext__\n    rv = await self.read_func()\n  File \"/usr/local/lib/python3.10/dist-packages/aiohttp/streams.py\", line 317, in readline\n    return await self.readuntil()\n  File \"/usr/local/lib/python3.10/dist-packages/aiohttp/streams.py\", line 351, in readuntil\n    await self._wait(\"readuntil\")\n  File \"/usr/local/lib/python3.10/dist-packages/aiohttp/streams.py\", line 312, in _wait\n    await waiter\naiohttp.client_exceptions.ClientPayloadError: Response payload is not completed: <TransferEncodingError: 400, message='Not enough data for satisfy transfer length header.'>\n", "Traceback (most recent call last):\n  File \"/usr/local/lib/python3.10/dist-packages/aiohttp/client_proto.py\", line 94, in connection_lost\n    uncompleted = self._parser.feed_eof()\n  File \"aiohttp/_http_parser.pyx\", line 513, in aiohttp._http_parser.HttpParser.feed_eof\naiohttp.http_exceptions.TransferEncodingError: 400, message:\n  Not enough data for satisfy transfer length header.\n\nThe above exception was the direct cause of the following exception:\n\nTraceback (most recent call last):\n  File \"/vllm-workspace/backend_request_func.py\", line 261, in async_request_openai_completions\n    async for chunk_bytes in response.content:\n  File \"/usr/local/lib/python3.10/dist-packages/aiohttp/streams.py\", line 50, in __anext__\n    rv = await self.read_func()\n  File \"/usr/local/lib/python3.10/dist-packages/aiohttp/streams.py\", line 317, in readline\n    return await self.readuntil()\n  File \"/usr/local/lib/python3.10/dist-packages/aiohttp/streams.py\", line 351, in readuntil\n    await self._wait(\"readuntil\")\n  File \"/usr/local/lib/python3.10/dist-packages/aiohttp/streams.py\", line 312, in _wait\n    await waiter\naiohttp.client_exceptions.ClientPayloadError: Response payload is not completed: <TransferEncodingError: 400, message='Not enough data for satisfy transfer length header.'>\n", "Traceback (most recent call last):\n  File \"/usr/local/lib/python3.10/dist-packages/aiohttp/client_proto.py\", line 94, in connection_lost\n    uncompleted = self._parser.feed_eof()\n  File \"aiohttp/_http_parser.pyx\", line 513, in aiohttp._http_parser.HttpParser.feed_eof\naiohttp.http_exceptions.TransferEncodingError: 400, message:\n  Not enough data for satisfy transfer length header.\n\nThe above exception was the direct cause of the following exception:\n\nTraceback (most recent call last):\n  File \"/vllm-workspace/backend_request_func.py\", line 261, in async_request_openai_completions\n    async for chunk_bytes in response.content:\n  File \"/usr/local/lib/python3.10/dist-packages/aiohttp/streams.py\", line 50, in __anext__\n    rv = await self.read_func()\n  File \"/usr/local/lib/python3.10/dist-packages/aiohttp/streams.py\", line 317, in readline\n    return await self.readuntil()\n  File \"/usr/local/lib/python3.10/dist-packages/aiohttp/streams.py\", line 351, in readuntil\n    await self._wait(\"readuntil\")\n  File \"/usr/local/lib/python3.10/dist-packages/aiohttp/streams.py\", line 312, in _wait\n    await waiter\naiohttp.client_exceptions.ClientPayloadError: Response payload is not completed: <TransferEncodingError: 400, message='Not enough data for satisfy transfer length header.'>\n", "Traceback (most recent call last):\n  File \"/usr/local/lib/python3.10/dist-packages/aiohttp/client_proto.py\", line 94, in connection_lost\n    uncompleted = self._parser.feed_eof()\n  File \"aiohttp/_http_parser.pyx\", line 513, in aiohttp._http_parser.HttpParser.feed_eof\naiohttp.http_exceptions.TransferEncodingError: 400, message:\n  Not enough data for satisfy transfer length header.\n\nThe above exception was the direct cause of the following exception:\n\nTraceback (most recent call last):\n  File \"/vllm-workspace/backend_request_func.py\", line 261, in async_request_openai_completions\n    async for chunk_bytes in response.content:\n  File \"/usr/local/lib/python3.10/dist-packages/aiohttp/streams.py\", line 50, in __anext__\n    rv = await self.read_func()\n  File \"/usr/local/lib/python3.10/dist-packages/aiohttp/streams.py\", line 317, in readline\n    return await self.readuntil()\n  File \"/usr/local/lib/python3.10/dist-packages/aiohttp/streams.py\", line 351, in readuntil\n    await self._wait(\"readuntil\")\n  File \"/usr/local/lib/python3.10/dist-packages/aiohttp/streams.py\", line 312, in _wait\n    await waiter\naiohttp.client_exceptions.ClientPayloadError: Response payload is not completed: <TransferEncodingError: 400, message='Not enough data for satisfy transfer length header.'>\n", "", "", "Traceback (most recent call last):\n  File \"/usr/local/lib/python3.10/dist-packages/aiohttp/client_proto.py\", line 94, in connection_lost\n    uncompleted = self._parser.feed_eof()\n  File \"aiohttp/_http_parser.pyx\", line 513, in aiohttp._http_parser.HttpParser.feed_eof\naiohttp.http_exceptions.TransferEncodingError: 400, message:\n  Not enough data for satisfy transfer length header.\n\nThe above exception was the direct cause of the following exception:\n\nTraceback (most recent call last):\n  File \"/vllm-workspace/backend_request_func.py\", line 261, in async_request_openai_completions\n    async for chunk_bytes in response.content:\n  File \"/usr/local/lib/python3.10/dist-packages/aiohttp/streams.py\", line 50, in __anext__\n    rv = await self.read_func()\n  File \"/usr/local/lib/python3.10/dist-packages/aiohttp/streams.py\", line 317, in readline\n    return await self.readuntil()\n  File \"/usr/local/lib/python3.10/dist-packages/aiohttp/streams.py\", line 351, in readuntil\n    await self._wait(\"readuntil\")\n  File \"/usr/local/lib/python3.10/dist-packages/aiohttp/streams.py\", line 312, in _wait\n    await waiter\naiohttp.client_exceptions.ClientPayloadError: Response payload is not completed: <TransferEncodingError: 400, message='Not enough data for satisfy transfer length header.'>\n", "Traceback (most recent call last):\n  File \"/usr/local/lib/python3.10/dist-packages/aiohttp/client_proto.py\", line 94, in connection_lost\n    uncompleted = self._parser.feed_eof()\n  File \"aiohttp/_http_parser.pyx\", line 513, in aiohttp._http_parser.HttpParser.feed_eof\naiohttp.http_exceptions.TransferEncodingError: 400, message:\n  Not enough data for satisfy transfer length header.\n\nThe above exception was the direct cause of the following exception:\n\nTraceback (most recent call last):\n  File \"/vllm-workspace/backend_request_func.py\", line 261, in async_request_openai_completions\n    async for chunk_bytes in response.content:\n  File \"/usr/local/lib/python3.10/dist-packages/aiohttp/streams.py\", line 50, in __anext__\n    rv = await self.read_func()\n  File \"/usr/local/lib/python3.10/dist-packages/aiohttp/streams.py\", line 317, in readline\n    return await self.readuntil()\n  File \"/usr/local/lib/python3.10/dist-packages/aiohttp/streams.py\", line 351, in readuntil\n    await self._wait(\"readuntil\")\n  File \"/usr/local/lib/python3.10/dist-packages/aiohttp/streams.py\", line 312, in _wait\n    await waiter\naiohttp.client_exceptions.ClientPayloadError: Response payload is not completed: <TransferEncodingError: 400, message='Not enough data for satisfy transfer length header.'>\n", "Traceback (most recent call last):\n  File \"/usr/local/lib/python3.10/dist-packages/aiohttp/client_proto.py\", line 94, in connection_lost\n    uncompleted = self._parser.feed_eof()\n  File \"aiohttp/_http_parser.pyx\", line 513, in aiohttp._http_parser.HttpParser.feed_eof\naiohttp.http_exceptions.TransferEncodingError: 400, message:\n  Not enough data for satisfy transfer length header.\n\nThe above exception was the direct cause of the following exception:\n\nTraceback (most recent call last):\n  File \"/vllm-workspace/backend_request_func.py\", line 261, in async_request_openai_completions\n    async for chunk_bytes in response.content:\n  File \"/usr/local/lib/python3.10/dist-packages/aiohttp/streams.py\", line 50, in __anext__\n    rv = await self.read_func()\n  File \"/usr/local/lib/python3.10/dist-packages/aiohttp/streams.py\", line 317, in readline\n    return await self.readuntil()\n  File \"/usr/local/lib/python3.10/dist-packages/aiohttp/streams.py\", line 351, in readuntil\n    await self._wait(\"readuntil\")\n  File \"/usr/local/lib/python3.10/dist-packages/aiohttp/streams.py\", line 312, in _wait\n    await waiter\naiohttp.client_exceptions.ClientPayloadError: Response payload is not completed: <TransferEncodingError: 400, message='Not enough data for satisfy transfer length header.'>\n", "Traceback (most recent call last):\n  File \"/usr/local/lib/python3.10/dist-packages/aiohttp/client_proto.py\", line 94, in connection_lost\n    uncompleted = self._parser.feed_eof()\n  File \"aiohttp/_http_parser.pyx\", line 513, in aiohttp._http_parser.HttpParser.feed_eof\naiohttp.http_exceptions.TransferEncodingError: 400, message:\n  Not enough data for satisfy transfer length header.\n\nThe above exception was the direct cause of the following exception:\n\nTraceback (most recent call last):\n  File \"/vllm-workspace/backend_request_func.py\", line 261, in async_request_openai_completions\n    async for chunk_bytes in response.content:\n  File \"/usr/local/lib/python3.10/dist-packages/aiohttp/streams.py\", line 50, in __anext__\n    rv = await self.read_func()\n  File \"/usr/local/lib/python3.10/dist-packages/aiohttp/streams.py\", line 317, in readline\n    return await self.readuntil()\n  File \"/usr/local/lib/python3.10/dist-packages/aiohttp/streams.py\", line 351, in readuntil\n    await self._wait(\"readuntil\")\n  File \"/usr/local/lib/python3.10/dist-packages/aiohttp/streams.py\", line 312, in _wait\n    await waiter\naiohttp.client_exceptions.ClientPayloadError: Response payload is not completed: <TransferEncodingError: 400, message='Not enough data for satisfy transfer length header.'>\n", "Traceback (most recent call last):\n  File \"/usr/local/lib/python3.10/dist-packages/aiohttp/client_proto.py\", line 94, in connection_lost\n    uncompleted = self._parser.feed_eof()\n  File \"aiohttp/_http_parser.pyx\", line 513, in aiohttp._http_parser.HttpParser.feed_eof\naiohttp.http_exceptions.TransferEncodingError: 400, message:\n  Not enough data for satisfy transfer length header.\n\nThe above exception was the direct cause of the following exception:\n\nTraceback (most recent call last):\n  File \"/vllm-workspace/backend_request_func.py\", line 261, in async_request_openai_completions\n    async for chunk_bytes in response.content:\n  File \"/usr/local/lib/python3.10/dist-packages/aiohttp/streams.py\", line 50, in __anext__\n    rv = await self.read_func()\n  File \"/usr/local/lib/python3.10/dist-packages/aiohttp/streams.py\", line 317, in readline\n    return await self.readuntil()\n  File \"/usr/local/lib/python3.10/dist-packages/aiohttp/streams.py\", line 351, in readuntil\n    await self._wait(\"readuntil\")\n  File \"/usr/local/lib/python3.10/dist-packages/aiohttp/streams.py\", line 312, in _wait\n    await waiter\naiohttp.client_exceptions.ClientPayloadError: Response payload is not completed: <TransferEncodingError: 400, message='Not enough data for satisfy transfer length header.'>\n", "Traceback (most recent call last):\n  File \"/usr/local/lib/python3.10/dist-packages/aiohttp/client_proto.py\", line 94, in connection_lost\n    uncompleted = self._parser.feed_eof()\n  File \"aiohttp/_http_parser.pyx\", line 513, in aiohttp._http_parser.HttpParser.feed_eof\naiohttp.http_exceptions.TransferEncodingError: 400, message:\n  Not enough data for satisfy transfer length header.\n\nThe above exception was the direct cause of the following exception:\n\nTraceback (most recent call last):\n  File \"/vllm-workspace/backend_request_func.py\", line 261, in async_request_openai_completions\n    async for chunk_bytes in response.content:\n  File \"/usr/local/lib/python3.10/dist-packages/aiohttp/streams.py\", line 50, in __anext__\n    rv = await self.read_func()\n  File \"/usr/local/lib/python3.10/dist-packages/aiohttp/streams.py\", line 317, in readline\n    return await self.readuntil()\n  File \"/usr/local/lib/python3.10/dist-packages/aiohttp/streams.py\", line 351, in readuntil\n    await self._wait(\"readuntil\")\n  File \"/usr/local/lib/python3.10/dist-packages/aiohttp/streams.py\", line 312, in _wait\n    await waiter\naiohttp.client_exceptions.ClientPayloadError: Response payload is not completed: <TransferEncodingError: 400, message='Not enough data for satisfy transfer length header.'>\n", "Traceback (most recent call last):\n  File \"/usr/local/lib/python3.10/dist-packages/aiohttp/client_proto.py\", line 94, in connection_lost\n    uncompleted = self._parser.feed_eof()\n  File \"aiohttp/_http_parser.pyx\", line 513, in aiohttp._http_parser.HttpParser.feed_eof\naiohttp.http_exceptions.TransferEncodingError: 400, message:\n  Not enough data for satisfy transfer length header.\n\nThe above exception was the direct cause of the following exception:\n\nTraceback (most recent call last):\n  File \"/vllm-workspace/backend_request_func.py\", line 261, in async_request_openai_completions\n    async for chunk_bytes in response.content:\n  File \"/usr/local/lib/python3.10/dist-packages/aiohttp/streams.py\", line 50, in __anext__\n    rv = await self.read_func()\n  File \"/usr/local/lib/python3.10/dist-packages/aiohttp/streams.py\", line 317, in readline\n    return await self.readuntil()\n  File \"/usr/local/lib/python3.10/dist-packages/aiohttp/streams.py\", line 351, in readuntil\n    await self._wait(\"readuntil\")\n  File \"/usr/local/lib/python3.10/dist-packages/aiohttp/streams.py\", line 312, in _wait\n    await waiter\naiohttp.client_exceptions.ClientPayloadError: Response payload is not completed: <TransferEncodingError: 400, message='Not enough data for satisfy transfer length header.'>\n", "Traceback (most recent call last):\n  File \"/usr/local/lib/python3.10/dist-packages/aiohttp/client_proto.py\", line 94, in connection_lost\n    uncompleted = self._parser.feed_eof()\n  File \"aiohttp/_http_parser.pyx\", line 513, in aiohttp._http_parser.HttpParser.feed_eof\naiohttp.http_exceptions.TransferEncodingError: 400, message:\n  Not enough data for satisfy transfer length header.\n\nThe above exception was the direct cause of the following exception:\n\nTraceback (most recent call last):\n  File \"/vllm-workspace/backend_request_func.py\", line 261, in async_request_openai_completions\n    async for chunk_bytes in response.content:\n  File \"/usr/local/lib/python3.10/dist-packages/aiohttp/streams.py\", line 50, in __anext__\n    rv = await self.read_func()\n  File \"/usr/local/lib/python3.10/dist-packages/aiohttp/streams.py\", line 317, in readline\n    return await self.readuntil()\n  File \"/usr/local/lib/python3.10/dist-packages/aiohttp/streams.py\", line 351, in readuntil\n    await self._wait(\"readuntil\")\n  File \"/usr/local/lib/python3.10/dist-packages/aiohttp/streams.py\", line 312, in _wait\n    await waiter\naiohttp.client_exceptions.ClientPayloadError: Response payload is not completed: <TransferEncodingError: 400, message='Not enough data for satisfy transfer length header.'>\n", "Traceback (most recent call last):\n  File \"/usr/local/lib/python3.10/dist-packages/aiohttp/client_proto.py\", line 94, in connection_lost\n    uncompleted = self._parser.feed_eof()\n  File \"aiohttp/_http_parser.pyx\", line 513, in aiohttp._http_parser.HttpParser.feed_eof\naiohttp.http_exceptions.TransferEncodingError: 400, message:\n  Not enough data for satisfy transfer length header.\n\nThe above exception was the direct cause of the following exception:\n\nTraceback (most recent call last):\n  File \"/vllm-workspace/backend_request_func.py\", line 261, in async_request_openai_completions\n    async for chunk_bytes in response.content:\n  File \"/usr/local/lib/python3.10/dist-packages/aiohttp/streams.py\", line 50, in __anext__\n    rv = await self.read_func()\n  File \"/usr/local/lib/python3.10/dist-packages/aiohttp/streams.py\", line 317, in readline\n    return await self.readuntil()\n  File \"/usr/local/lib/python3.10/dist-packages/aiohttp/streams.py\", line 351, in readuntil\n    await self._wait(\"readuntil\")\n  File \"/usr/local/lib/python3.10/dist-packages/aiohttp/streams.py\", line 312, in _wait\n    await waiter\naiohttp.client_exceptions.ClientPayloadError: Response payload is not completed: <TransferEncodingError: 400, message='Not enough data for satisfy transfer length header.'>\n", "Traceback (most recent call last):\n  File \"/usr/local/lib/python3.10/dist-packages/aiohttp/client_proto.py\", line 94, in connection_lost\n    uncompleted = self._parser.feed_eof()\n  File \"aiohttp/_http_parser.pyx\", line 513, in aiohttp._http_parser.HttpParser.feed_eof\naiohttp.http_exceptions.TransferEncodingError: 400, message:\n  Not enough data for satisfy transfer length header.\n\nThe above exception was the direct cause of the following exception:\n\nTraceback (most recent call last):\n  File \"/vllm-workspace/backend_request_func.py\", line 261, in async_request_openai_completions\n    async for chunk_bytes in response.content:\n  File \"/usr/local/lib/python3.10/dist-packages/aiohttp/streams.py\", line 50, in __anext__\n    rv = await self.read_func()\n  File \"/usr/local/lib/python3.10/dist-packages/aiohttp/streams.py\", line 317, in readline\n    return await self.readuntil()\n  File \"/usr/local/lib/python3.10/dist-packages/aiohttp/streams.py\", line 351, in readuntil\n    await self._wait(\"readuntil\")\n  File \"/usr/local/lib/python3.10/dist-packages/aiohttp/streams.py\", line 312, in _wait\n    await waiter\naiohttp.client_exceptions.ClientPayloadError: Response payload is not completed: <TransferEncodingError: 400, message='Not enough data for satisfy transfer length header.'>\n", "Traceback (most recent call last):\n  File \"/usr/local/lib/python3.10/dist-packages/aiohttp/client_proto.py\", line 94, in connection_lost\n    uncompleted = self._parser.feed_eof()\n  File \"aiohttp/_http_parser.pyx\", line 513, in aiohttp._http_parser.HttpParser.feed_eof\naiohttp.http_exceptions.TransferEncodingError: 400, message:\n  Not enough data for satisfy transfer length header.\n\nThe above exception was the direct cause of the following exception:\n\nTraceback (most recent call last):\n  File \"/vllm-workspace/backend_request_func.py\", line 261, in async_request_openai_completions\n    async for chunk_bytes in response.content:\n  File \"/usr/local/lib/python3.10/dist-packages/aiohttp/streams.py\", line 50, in __anext__\n    rv = await self.read_func()\n  File \"/usr/local/lib/python3.10/dist-packages/aiohttp/streams.py\", line 317, in readline\n    return await self.readuntil()\n  File \"/usr/local/lib/python3.10/dist-packages/aiohttp/streams.py\", line 351, in readuntil\n    await self._wait(\"readuntil\")\n  File \"/usr/local/lib/python3.10/dist-packages/aiohttp/streams.py\", line 312, in _wait\n    await waiter\naiohttp.client_exceptions.ClientPayloadError: Response payload is not completed: <TransferEncodingError: 400, message='Not enough data for satisfy transfer length header.'>\n", "", "Traceback (most recent call last):\n  File \"/usr/local/lib/python3.10/dist-packages/aiohttp/client_proto.py\", line 94, in connection_lost\n    uncompleted = self._parser.feed_eof()\n  File \"aiohttp/_http_parser.pyx\", line 513, in aiohttp._http_parser.HttpParser.feed_eof\naiohttp.http_exceptions.TransferEncodingError: 400, message:\n  Not enough data for satisfy transfer length header.\n\nThe above exception was the direct cause of the following exception:\n\nTraceback (most recent call last):\n  File \"/vllm-workspace/backend_request_func.py\", line 261, in async_request_openai_completions\n    async for chunk_bytes in response.content:\n  File \"/usr/local/lib/python3.10/dist-packages/aiohttp/streams.py\", line 50, in __anext__\n    rv = await self.read_func()\n  File \"/usr/local/lib/python3.10/dist-packages/aiohttp/streams.py\", line 317, in readline\n    return await self.readuntil()\n  File \"/usr/local/lib/python3.10/dist-packages/aiohttp/streams.py\", line 351, in readuntil\n    await self._wait(\"readuntil\")\n  File \"/usr/local/lib/python3.10/dist-packages/aiohttp/streams.py\", line 312, in _wait\n    await waiter\naiohttp.client_exceptions.ClientPayloadError: Response payload is not completed: <TransferEncodingError: 400, message='Not enough data for satisfy transfer length header.'>\n", "Traceback (most recent call last):\n  File \"/usr/local/lib/python3.10/dist-packages/aiohttp/client_proto.py\", line 94, in connection_lost\n    uncompleted = self._parser.feed_eof()\n  File \"aiohttp/_http_parser.pyx\", line 513, in aiohttp._http_parser.HttpParser.feed_eof\naiohttp.http_exceptions.TransferEncodingError: 400, message:\n  Not enough data for satisfy transfer length header.\n\nThe above exception was the direct cause of the following exception:\n\nTraceback (most recent call last):\n  File \"/vllm-workspace/backend_request_func.py\", line 261, in async_request_openai_completions\n    async for chunk_bytes in response.content:\n  File \"/usr/local/lib/python3.10/dist-packages/aiohttp/streams.py\", line 50, in __anext__\n    rv = await self.read_func()\n  File \"/usr/local/lib/python3.10/dist-packages/aiohttp/streams.py\", line 317, in readline\n    return await self.readuntil()\n  File \"/usr/local/lib/python3.10/dist-packages/aiohttp/streams.py\", line 351, in readuntil\n    await self._wait(\"readuntil\")\n  File \"/usr/local/lib/python3.10/dist-packages/aiohttp/streams.py\", line 312, in _wait\n    await waiter\naiohttp.client_exceptions.ClientPayloadError: Response payload is not completed: <TransferEncodingError: 400, message='Not enough data for satisfy transfer length header.'>\n", "Traceback (most recent call last):\n  File \"/usr/local/lib/python3.10/dist-packages/aiohttp/client_proto.py\", line 94, in connection_lost\n    uncompleted = self._parser.feed_eof()\n  File \"aiohttp/_http_parser.pyx\", line 513, in aiohttp._http_parser.HttpParser.feed_eof\naiohttp.http_exceptions.TransferEncodingError: 400, message:\n  Not enough data for satisfy transfer length header.\n\nThe above exception was the direct cause of the following exception:\n\nTraceback (most recent call last):\n  File \"/vllm-workspace/backend_request_func.py\", line 261, in async_request_openai_completions\n    async for chunk_bytes in response.content:\n  File \"/usr/local/lib/python3.10/dist-packages/aiohttp/streams.py\", line 50, in __anext__\n    rv = await self.read_func()\n  File \"/usr/local/lib/python3.10/dist-packages/aiohttp/streams.py\", line 317, in readline\n    return await self.readuntil()\n  File \"/usr/local/lib/python3.10/dist-packages/aiohttp/streams.py\", line 351, in readuntil\n    await self._wait(\"readuntil\")\n  File \"/usr/local/lib/python3.10/dist-packages/aiohttp/streams.py\", line 312, in _wait\n    await waiter\naiohttp.client_exceptions.ClientPayloadError: Response payload is not completed: <TransferEncodingError: 400, message='Not enough data for satisfy transfer length header.'>\n", "Traceback (most recent call last):\n  File \"/usr/local/lib/python3.10/dist-packages/aiohttp/client_proto.py\", line 94, in connection_lost\n    uncompleted = self._parser.feed_eof()\n  File \"aiohttp/_http_parser.pyx\", line 513, in aiohttp._http_parser.HttpParser.feed_eof\naiohttp.http_exceptions.TransferEncodingError: 400, message:\n  Not enough data for satisfy transfer length header.\n\nThe above exception was the direct cause of the following exception:\n\nTraceback (most recent call last):\n  File \"/vllm-workspace/backend_request_func.py\", line 261, in async_request_openai_completions\n    async for chunk_bytes in response.content:\n  File \"/usr/local/lib/python3.10/dist-packages/aiohttp/streams.py\", line 50, in __anext__\n    rv = await self.read_func()\n  File \"/usr/local/lib/python3.10/dist-packages/aiohttp/streams.py\", line 317, in readline\n    return await self.readuntil()\n  File \"/usr/local/lib/python3.10/dist-packages/aiohttp/streams.py\", line 351, in readuntil\n    await self._wait(\"readuntil\")\n  File \"/usr/local/lib/python3.10/dist-packages/aiohttp/streams.py\", line 312, in _wait\n    await waiter\naiohttp.client_exceptions.ClientPayloadError: Response payload is not completed: <TransferEncodingError: 400, message='Not enough data for satisfy transfer length header.'>\n", "", "", "Traceback (most recent call last):\n  File \"/usr/local/lib/python3.10/dist-packages/aiohttp/client_proto.py\", line 94, in connection_lost\n    uncompleted = self._parser.feed_eof()\n  File \"aiohttp/_http_parser.pyx\", line 513, in aiohttp._http_parser.HttpParser.feed_eof\naiohttp.http_exceptions.TransferEncodingError: 400, message:\n  Not enough data for satisfy transfer length header.\n\nThe above exception was the direct cause of the following exception:\n\nTraceback (most recent call last):\n  File \"/vllm-workspace/backend_request_func.py\", line 261, in async_request_openai_completions\n    async for chunk_bytes in response.content:\n  File \"/usr/local/lib/python3.10/dist-packages/aiohttp/streams.py\", line 50, in __anext__\n    rv = await self.read_func()\n  File \"/usr/local/lib/python3.10/dist-packages/aiohttp/streams.py\", line 317, in readline\n    return await self.readuntil()\n  File \"/usr/local/lib/python3.10/dist-packages/aiohttp/streams.py\", line 351, in readuntil\n    await self._wait(\"readuntil\")\n  File \"/usr/local/lib/python3.10/dist-packages/aiohttp/streams.py\", line 312, in _wait\n    await waiter\naiohttp.client_exceptions.ClientPayloadError: Response payload is not completed: <TransferEncodingError: 400, message='Not enough data for satisfy transfer length header.'>\n", "Traceback (most recent call last):\n  File \"/usr/local/lib/python3.10/dist-packages/aiohttp/client_proto.py\", line 94, in connection_lost\n    uncompleted = self._parser.feed_eof()\n  File \"aiohttp/_http_parser.pyx\", line 513, in aiohttp._http_parser.HttpParser.feed_eof\naiohttp.http_exceptions.TransferEncodingError: 400, message:\n  Not enough data for satisfy transfer length header.\n\nThe above exception was the direct cause of the following exception:\n\nTraceback (most recent call last):\n  File \"/vllm-workspace/backend_request_func.py\", line 261, in async_request_openai_completions\n    async for chunk_bytes in response.content:\n  File \"/usr/local/lib/python3.10/dist-packages/aiohttp/streams.py\", line 50, in __anext__\n    rv = await self.read_func()\n  File \"/usr/local/lib/python3.10/dist-packages/aiohttp/streams.py\", line 317, in readline\n    return await self.readuntil()\n  File \"/usr/local/lib/python3.10/dist-packages/aiohttp/streams.py\", line 351, in readuntil\n    await self._wait(\"readuntil\")\n  File \"/usr/local/lib/python3.10/dist-packages/aiohttp/streams.py\", line 312, in _wait\n    await waiter\naiohttp.client_exceptions.ClientPayloadError: Response payload is not completed: <TransferEncodingError: 400, message='Not enough data for satisfy transfer length header.'>\n", "Traceback (most recent call last):\n  File \"/usr/local/lib/python3.10/dist-packages/aiohttp/client_proto.py\", line 94, in connection_lost\n    uncompleted = self._parser.feed_eof()\n  File \"aiohttp/_http_parser.pyx\", line 513, in aiohttp._http_parser.HttpParser.feed_eof\naiohttp.http_exceptions.TransferEncodingError: 400, message:\n  Not enough data for satisfy transfer length header.\n\nThe above exception was the direct cause of the following exception:\n\nTraceback (most recent call last):\n  File \"/vllm-workspace/backend_request_func.py\", line 261, in async_request_openai_completions\n    async for chunk_bytes in response.content:\n  File \"/usr/local/lib/python3.10/dist-packages/aiohttp/streams.py\", line 50, in __anext__\n    rv = await self.read_func()\n  File \"/usr/local/lib/python3.10/dist-packages/aiohttp/streams.py\", line 317, in readline\n    return await self.readuntil()\n  File \"/usr/local/lib/python3.10/dist-packages/aiohttp/streams.py\", line 351, in readuntil\n    await self._wait(\"readuntil\")\n  File \"/usr/local/lib/python3.10/dist-packages/aiohttp/streams.py\", line 312, in _wait\n    await waiter\naiohttp.client_exceptions.ClientPayloadError: Response payload is not completed: <TransferEncodingError: 400, message='Not enough data for satisfy transfer length header.'>\n", "Traceback (most recent call last):\n  File \"/usr/local/lib/python3.10/dist-packages/aiohttp/client_proto.py\", line 94, in connection_lost\n    uncompleted = self._parser.feed_eof()\n  File \"aiohttp/_http_parser.pyx\", line 513, in aiohttp._http_parser.HttpParser.feed_eof\naiohttp.http_exceptions.TransferEncodingError: 400, message:\n  Not enough data for satisfy transfer length header.\n\nThe above exception was the direct cause of the following exception:\n\nTraceback (most recent call last):\n  File \"/vllm-workspace/backend_request_func.py\", line 261, in async_request_openai_completions\n    async for chunk_bytes in response.content:\n  File \"/usr/local/lib/python3.10/dist-packages/aiohttp/streams.py\", line 50, in __anext__\n    rv = await self.read_func()\n  File \"/usr/local/lib/python3.10/dist-packages/aiohttp/streams.py\", line 317, in readline\n    return await self.readuntil()\n  File \"/usr/local/lib/python3.10/dist-packages/aiohttp/streams.py\", line 351, in readuntil\n    await self._wait(\"readuntil\")\n  File \"/usr/local/lib/python3.10/dist-packages/aiohttp/streams.py\", line 312, in _wait\n    await waiter\naiohttp.client_exceptions.ClientPayloadError: Response payload is not completed: <TransferEncodingError: 400, message='Not enough data for satisfy transfer length header.'>\n", "Traceback (most recent call last):\n  File \"/usr/local/lib/python3.10/dist-packages/aiohttp/client_proto.py\", line 94, in connection_lost\n    uncompleted = self._parser.feed_eof()\n  File \"aiohttp/_http_parser.pyx\", line 513, in aiohttp._http_parser.HttpParser.feed_eof\naiohttp.http_exceptions.TransferEncodingError: 400, message:\n  Not enough data for satisfy transfer length header.\n\nThe above exception was the direct cause of the following exception:\n\nTraceback (most recent call last):\n  File \"/vllm-workspace/backend_request_func.py\", line 261, in async_request_openai_completions\n    async for chunk_bytes in response.content:\n  File \"/usr/local/lib/python3.10/dist-packages/aiohttp/streams.py\", line 50, in __anext__\n    rv = await self.read_func()\n  File \"/usr/local/lib/python3.10/dist-packages/aiohttp/streams.py\", line 317, in readline\n    return await self.readuntil()\n  File \"/usr/local/lib/python3.10/dist-packages/aiohttp/streams.py\", line 351, in readuntil\n    await self._wait(\"readuntil\")\n  File \"/usr/local/lib/python3.10/dist-packages/aiohttp/streams.py\", line 312, in _wait\n    await waiter\naiohttp.client_exceptions.ClientPayloadError: Response payload is not completed: <TransferEncodingError: 400, message='Not enough data for satisfy transfer length header.'>\n", "Traceback (most recent call last):\n  File \"/usr/local/lib/python3.10/dist-packages/aiohttp/client_proto.py\", line 94, in connection_lost\n    uncompleted = self._parser.feed_eof()\n  File \"aiohttp/_http_parser.pyx\", line 513, in aiohttp._http_parser.HttpParser.feed_eof\naiohttp.http_exceptions.TransferEncodingError: 400, message:\n  Not enough data for satisfy transfer length header.\n\nThe above exception was the direct cause of the following exception:\n\nTraceback (most recent call last):\n  File \"/vllm-workspace/backend_request_func.py\", line 261, in async_request_openai_completions\n    async for chunk_bytes in response.content:\n  File \"/usr/local/lib/python3.10/dist-packages/aiohttp/streams.py\", line 50, in __anext__\n    rv = await self.read_func()\n  File \"/usr/local/lib/python3.10/dist-packages/aiohttp/streams.py\", line 317, in readline\n    return await self.readuntil()\n  File \"/usr/local/lib/python3.10/dist-packages/aiohttp/streams.py\", line 351, in readuntil\n    await self._wait(\"readuntil\")\n  File \"/usr/local/lib/python3.10/dist-packages/aiohttp/streams.py\", line 312, in _wait\n    await waiter\naiohttp.client_exceptions.ClientPayloadError: Response payload is not completed: <TransferEncodingError: 400, message='Not enough data for satisfy transfer length header.'>\n", "Traceback (most recent call last):\n  File \"/usr/local/lib/python3.10/dist-packages/aiohttp/client_proto.py\", line 94, in connection_lost\n    uncompleted = self._parser.feed_eof()\n  File \"aiohttp/_http_parser.pyx\", line 513, in aiohttp._http_parser.HttpParser.feed_eof\naiohttp.http_exceptions.TransferEncodingError: 400, message:\n  Not enough data for satisfy transfer length header.\n\nThe above exception was the direct cause of the following exception:\n\nTraceback (most recent call last):\n  File \"/vllm-workspace/backend_request_func.py\", line 261, in async_request_openai_completions\n    async for chunk_bytes in response.content:\n  File \"/usr/local/lib/python3.10/dist-packages/aiohttp/streams.py\", line 50, in __anext__\n    rv = await self.read_func()\n  File \"/usr/local/lib/python3.10/dist-packages/aiohttp/streams.py\", line 317, in readline\n    return await self.readuntil()\n  File \"/usr/local/lib/python3.10/dist-packages/aiohttp/streams.py\", line 351, in readuntil\n    await self._wait(\"readuntil\")\n  File \"/usr/local/lib/python3.10/dist-packages/aiohttp/streams.py\", line 312, in _wait\n    await waiter\naiohttp.client_exceptions.ClientPayloadError: Response payload is not completed: <TransferEncodingError: 400, message='Not enough data for satisfy transfer length header.'>\n", "Traceback (most recent call last):\n  File \"/usr/local/lib/python3.10/dist-packages/aiohttp/client_proto.py\", line 94, in connection_lost\n    uncompleted = self._parser.feed_eof()\n  File \"aiohttp/_http_parser.pyx\", line 513, in aiohttp._http_parser.HttpParser.feed_eof\naiohttp.http_exceptions.TransferEncodingError: 400, message:\n  Not enough data for satisfy transfer length header.\n\nThe above exception was the direct cause of the following exception:\n\nTraceback (most recent call last):\n  File \"/vllm-workspace/backend_request_func.py\", line 261, in async_request_openai_completions\n    async for chunk_bytes in response.content:\n  File \"/usr/local/lib/python3.10/dist-packages/aiohttp/streams.py\", line 50, in __anext__\n    rv = await self.read_func()\n  File \"/usr/local/lib/python3.10/dist-packages/aiohttp/streams.py\", line 317, in readline\n    return await self.readuntil()\n  File \"/usr/local/lib/python3.10/dist-packages/aiohttp/streams.py\", line 351, in readuntil\n    await self._wait(\"readuntil\")\n  File \"/usr/local/lib/python3.10/dist-packages/aiohttp/streams.py\", line 312, in _wait\n    await waiter\naiohttp.client_exceptions.ClientPayloadError: Response payload is not completed: <TransferEncodingError: 400, message='Not enough data for satisfy transfer length header.'>\n", "", "Traceback (most recent call last):\n  File \"/usr/local/lib/python3.10/dist-packages/aiohttp/client_proto.py\", line 94, in connection_lost\n    uncompleted = self._parser.feed_eof()\n  File \"aiohttp/_http_parser.pyx\", line 513, in aiohttp._http_parser.HttpParser.feed_eof\naiohttp.http_exceptions.TransferEncodingError: 400, message:\n  Not enough data for satisfy transfer length header.\n\nThe above exception was the direct cause of the following exception:\n\nTraceback (most recent call last):\n  File \"/vllm-workspace/backend_request_func.py\", line 261, in async_request_openai_completions\n    async for chunk_bytes in response.content:\n  File \"/usr/local/lib/python3.10/dist-packages/aiohttp/streams.py\", line 50, in __anext__\n    rv = await self.read_func()\n  File \"/usr/local/lib/python3.10/dist-packages/aiohttp/streams.py\", line 317, in readline\n    return await self.readuntil()\n  File \"/usr/local/lib/python3.10/dist-packages/aiohttp/streams.py\", line 351, in readuntil\n    await self._wait(\"readuntil\")\n  File \"/usr/local/lib/python3.10/dist-packages/aiohttp/streams.py\", line 312, in _wait\n    await waiter\naiohttp.client_exceptions.ClientPayloadError: Response payload is not completed: <TransferEncodingError: 400, message='Not enough data for satisfy transfer length header.'>\n", "Traceback (most recent call last):\n  File \"/usr/local/lib/python3.10/dist-packages/aiohttp/client_proto.py\", line 94, in connection_lost\n    uncompleted = self._parser.feed_eof()\n  File \"aiohttp/_http_parser.pyx\", line 513, in aiohttp._http_parser.HttpParser.feed_eof\naiohttp.http_exceptions.TransferEncodingError: 400, message:\n  Not enough data for satisfy transfer length header.\n\nThe above exception was the direct cause of the following exception:\n\nTraceback (most recent call last):\n  File \"/vllm-workspace/backend_request_func.py\", line 261, in async_request_openai_completions\n    async for chunk_bytes in response.content:\n  File \"/usr/local/lib/python3.10/dist-packages/aiohttp/streams.py\", line 50, in __anext__\n    rv = await self.read_func()\n  File \"/usr/local/lib/python3.10/dist-packages/aiohttp/streams.py\", line 317, in readline\n    return await self.readuntil()\n  File \"/usr/local/lib/python3.10/dist-packages/aiohttp/streams.py\", line 351, in readuntil\n    await self._wait(\"readuntil\")\n  File \"/usr/local/lib/python3.10/dist-packages/aiohttp/streams.py\", line 312, in _wait\n    await waiter\naiohttp.client_exceptions.ClientPayloadError: Response payload is not completed: <TransferEncodingError: 400, message='Not enough data for satisfy transfer length header.'>\n", "Traceback (most recent call last):\n  File \"/usr/local/lib/python3.10/dist-packages/aiohttp/client_proto.py\", line 94, in connection_lost\n    uncompleted = self._parser.feed_eof()\n  File \"aiohttp/_http_parser.pyx\", line 513, in aiohttp._http_parser.HttpParser.feed_eof\naiohttp.http_exceptions.TransferEncodingError: 400, message:\n  Not enough data for satisfy transfer length header.\n\nThe above exception was the direct cause of the following exception:\n\nTraceback (most recent call last):\n  File \"/vllm-workspace/backend_request_func.py\", line 261, in async_request_openai_completions\n    async for chunk_bytes in response.content:\n  File \"/usr/local/lib/python3.10/dist-packages/aiohttp/streams.py\", line 50, in __anext__\n    rv = await self.read_func()\n  File \"/usr/local/lib/python3.10/dist-packages/aiohttp/streams.py\", line 317, in readline\n    return await self.readuntil()\n  File \"/usr/local/lib/python3.10/dist-packages/aiohttp/streams.py\", line 351, in readuntil\n    await self._wait(\"readuntil\")\n  File \"/usr/local/lib/python3.10/dist-packages/aiohttp/streams.py\", line 312, in _wait\n    await waiter\naiohttp.client_exceptions.ClientPayloadError: Response payload is not completed: <TransferEncodingError: 400, message='Not enough data for satisfy transfer length header.'>\n", "", "Traceback (most recent call last):\n  File \"/usr/local/lib/python3.10/dist-packages/aiohttp/client_proto.py\", line 94, in connection_lost\n    uncompleted = self._parser.feed_eof()\n  File \"aiohttp/_http_parser.pyx\", line 513, in aiohttp._http_parser.HttpParser.feed_eof\naiohttp.http_exceptions.TransferEncodingError: 400, message:\n  Not enough data for satisfy transfer length header.\n\nThe above exception was the direct cause of the following exception:\n\nTraceback (most recent call last):\n  File \"/vllm-workspace/backend_request_func.py\", line 261, in async_request_openai_completions\n    async for chunk_bytes in response.content:\n  File \"/usr/local/lib/python3.10/dist-packages/aiohttp/streams.py\", line 50, in __anext__\n    rv = await self.read_func()\n  File \"/usr/local/lib/python3.10/dist-packages/aiohttp/streams.py\", line 317, in readline\n    return await self.readuntil()\n  File \"/usr/local/lib/python3.10/dist-packages/aiohttp/streams.py\", line 351, in readuntil\n    await self._wait(\"readuntil\")\n  File \"/usr/local/lib/python3.10/dist-packages/aiohttp/streams.py\", line 312, in _wait\n    await waiter\naiohttp.client_exceptions.ClientPayloadError: Response payload is not completed: <TransferEncodingError: 400, message='Not enough data for satisfy transfer length header.'>\n", "Traceback (most recent call last):\n  File \"/usr/local/lib/python3.10/dist-packages/aiohttp/client_proto.py\", line 94, in connection_lost\n    uncompleted = self._parser.feed_eof()\n  File \"aiohttp/_http_parser.pyx\", line 513, in aiohttp._http_parser.HttpParser.feed_eof\naiohttp.http_exceptions.TransferEncodingError: 400, message:\n  Not enough data for satisfy transfer length header.\n\nThe above exception was the direct cause of the following exception:\n\nTraceback (most recent call last):\n  File \"/vllm-workspace/backend_request_func.py\", line 261, in async_request_openai_completions\n    async for chunk_bytes in response.content:\n  File \"/usr/local/lib/python3.10/dist-packages/aiohttp/streams.py\", line 50, in __anext__\n    rv = await self.read_func()\n  File \"/usr/local/lib/python3.10/dist-packages/aiohttp/streams.py\", line 317, in readline\n    return await self.readuntil()\n  File \"/usr/local/lib/python3.10/dist-packages/aiohttp/streams.py\", line 351, in readuntil\n    await self._wait(\"readuntil\")\n  File \"/usr/local/lib/python3.10/dist-packages/aiohttp/streams.py\", line 312, in _wait\n    await waiter\naiohttp.client_exceptions.ClientPayloadError: Response payload is not completed: <TransferEncodingError: 400, message='Not enough data for satisfy transfer length header.'>\n", "", "", "Traceback (most recent call last):\n  File \"/usr/local/lib/python3.10/dist-packages/aiohttp/client_proto.py\", line 94, in connection_lost\n    uncompleted = self._parser.feed_eof()\n  File \"aiohttp/_http_parser.pyx\", line 513, in aiohttp._http_parser.HttpParser.feed_eof\naiohttp.http_exceptions.TransferEncodingError: 400, message:\n  Not enough data for satisfy transfer length header.\n\nThe above exception was the direct cause of the following exception:\n\nTraceback (most recent call last):\n  File \"/vllm-workspace/backend_request_func.py\", line 261, in async_request_openai_completions\n    async for chunk_bytes in response.content:\n  File \"/usr/local/lib/python3.10/dist-packages/aiohttp/streams.py\", line 50, in __anext__\n    rv = await self.read_func()\n  File \"/usr/local/lib/python3.10/dist-packages/aiohttp/streams.py\", line 317, in readline\n    return await self.readuntil()\n  File \"/usr/local/lib/python3.10/dist-packages/aiohttp/streams.py\", line 351, in readuntil\n    await self._wait(\"readuntil\")\n  File \"/usr/local/lib/python3.10/dist-packages/aiohttp/streams.py\", line 312, in _wait\n    await waiter\naiohttp.client_exceptions.ClientPayloadError: Response payload is not completed: <TransferEncodingError: 400, message='Not enough data for satisfy transfer length header.'>\n", "Traceback (most recent call last):\n  File \"/usr/local/lib/python3.10/dist-packages/aiohttp/client_proto.py\", line 94, in connection_lost\n    uncompleted = self._parser.feed_eof()\n  File \"aiohttp/_http_parser.pyx\", line 513, in aiohttp._http_parser.HttpParser.feed_eof\naiohttp.http_exceptions.TransferEncodingError: 400, message:\n  Not enough data for satisfy transfer length header.\n\nThe above exception was the direct cause of the following exception:\n\nTraceback (most recent call last):\n  File \"/vllm-workspace/backend_request_func.py\", line 261, in async_request_openai_completions\n    async for chunk_bytes in response.content:\n  File \"/usr/local/lib/python3.10/dist-packages/aiohttp/streams.py\", line 50, in __anext__\n    rv = await self.read_func()\n  File \"/usr/local/lib/python3.10/dist-packages/aiohttp/streams.py\", line 317, in readline\n    return await self.readuntil()\n  File \"/usr/local/lib/python3.10/dist-packages/aiohttp/streams.py\", line 351, in readuntil\n    await self._wait(\"readuntil\")\n  File \"/usr/local/lib/python3.10/dist-packages/aiohttp/streams.py\", line 312, in _wait\n    await waiter\naiohttp.client_exceptions.ClientPayloadError: Response payload is not completed: <TransferEncodingError: 400, message='Not enough data for satisfy transfer length header.'>\n", "Traceback (most recent call last):\n  File \"/usr/local/lib/python3.10/dist-packages/aiohttp/client_proto.py\", line 94, in connection_lost\n    uncompleted = self._parser.feed_eof()\n  File \"aiohttp/_http_parser.pyx\", line 513, in aiohttp._http_parser.HttpParser.feed_eof\naiohttp.http_exceptions.TransferEncodingError: 400, message:\n  Not enough data for satisfy transfer length header.\n\nThe above exception was the direct cause of the following exception:\n\nTraceback (most recent call last):\n  File \"/vllm-workspace/backend_request_func.py\", line 261, in async_request_openai_completions\n    async for chunk_bytes in response.content:\n  File \"/usr/local/lib/python3.10/dist-packages/aiohttp/streams.py\", line 50, in __anext__\n    rv = await self.read_func()\n  File \"/usr/local/lib/python3.10/dist-packages/aiohttp/streams.py\", line 317, in readline\n    return await self.readuntil()\n  File \"/usr/local/lib/python3.10/dist-packages/aiohttp/streams.py\", line 351, in readuntil\n    await self._wait(\"readuntil\")\n  File \"/usr/local/lib/python3.10/dist-packages/aiohttp/streams.py\", line 312, in _wait\n    await waiter\naiohttp.client_exceptions.ClientPayloadError: Response payload is not completed: <TransferEncodingError: 400, message='Not enough data for satisfy transfer length header.'>\n", "Traceback (most recent call last):\n  File \"/usr/local/lib/python3.10/dist-packages/aiohttp/client_proto.py\", line 94, in connection_lost\n    uncompleted = self._parser.feed_eof()\n  File \"aiohttp/_http_parser.pyx\", line 513, in aiohttp._http_parser.HttpParser.feed_eof\naiohttp.http_exceptions.TransferEncodingError: 400, message:\n  Not enough data for satisfy transfer length header.\n\nThe above exception was the direct cause of the following exception:\n\nTraceback (most recent call last):\n  File \"/vllm-workspace/backend_request_func.py\", line 261, in async_request_openai_completions\n    async for chunk_bytes in response.content:\n  File \"/usr/local/lib/python3.10/dist-packages/aiohttp/streams.py\", line 50, in __anext__\n    rv = await self.read_func()\n  File \"/usr/local/lib/python3.10/dist-packages/aiohttp/streams.py\", line 317, in readline\n    return await self.readuntil()\n  File \"/usr/local/lib/python3.10/dist-packages/aiohttp/streams.py\", line 351, in readuntil\n    await self._wait(\"readuntil\")\n  File \"/usr/local/lib/python3.10/dist-packages/aiohttp/streams.py\", line 312, in _wait\n    await waiter\naiohttp.client_exceptions.ClientPayloadError: Response payload is not completed: <TransferEncodingError: 400, message='Not enough data for satisfy transfer length header.'>\n", "Traceback (most recent call last):\n  File \"/usr/local/lib/python3.10/dist-packages/aiohttp/client_proto.py\", line 94, in connection_lost\n    uncompleted = self._parser.feed_eof()\n  File \"aiohttp/_http_parser.pyx\", line 513, in aiohttp._http_parser.HttpParser.feed_eof\naiohttp.http_exceptions.TransferEncodingError: 400, message:\n  Not enough data for satisfy transfer length header.\n\nThe above exception was the direct cause of the following exception:\n\nTraceback (most recent call last):\n  File \"/vllm-workspace/backend_request_func.py\", line 261, in async_request_openai_completions\n    async for chunk_bytes in response.content:\n  File \"/usr/local/lib/python3.10/dist-packages/aiohttp/streams.py\", line 50, in __anext__\n    rv = await self.read_func()\n  File \"/usr/local/lib/python3.10/dist-packages/aiohttp/streams.py\", line 317, in readline\n    return await self.readuntil()\n  File \"/usr/local/lib/python3.10/dist-packages/aiohttp/streams.py\", line 351, in readuntil\n    await self._wait(\"readuntil\")\n  File \"/usr/local/lib/python3.10/dist-packages/aiohttp/streams.py\", line 312, in _wait\n    await waiter\naiohttp.client_exceptions.ClientPayloadError: Response payload is not completed: <TransferEncodingError: 400, message='Not enough data for satisfy transfer length header.'>\n", "", "Traceback (most recent call last):\n  File \"/usr/local/lib/python3.10/dist-packages/aiohttp/client_proto.py\", line 94, in connection_lost\n    uncompleted = self._parser.feed_eof()\n  File \"aiohttp/_http_parser.pyx\", line 513, in aiohttp._http_parser.HttpParser.feed_eof\naiohttp.http_exceptions.TransferEncodingError: 400, message:\n  Not enough data for satisfy transfer length header.\n\nThe above exception was the direct cause of the following exception:\n\nTraceback (most recent call last):\n  File \"/vllm-workspace/backend_request_func.py\", line 261, in async_request_openai_completions\n    async for chunk_bytes in response.content:\n  File \"/usr/local/lib/python3.10/dist-packages/aiohttp/streams.py\", line 50, in __anext__\n    rv = await self.read_func()\n  File \"/usr/local/lib/python3.10/dist-packages/aiohttp/streams.py\", line 317, in readline\n    return await self.readuntil()\n  File \"/usr/local/lib/python3.10/dist-packages/aiohttp/streams.py\", line 351, in readuntil\n    await self._wait(\"readuntil\")\n  File \"/usr/local/lib/python3.10/dist-packages/aiohttp/streams.py\", line 312, in _wait\n    await waiter\naiohttp.client_exceptions.ClientPayloadError: Response payload is not completed: <TransferEncodingError: 400, message='Not enough data for satisfy transfer length header.'>\n", "Traceback (most recent call last):\n  File \"/usr/local/lib/python3.10/dist-packages/aiohttp/client_proto.py\", line 94, in connection_lost\n    uncompleted = self._parser.feed_eof()\n  File \"aiohttp/_http_parser.pyx\", line 513, in aiohttp._http_parser.HttpParser.feed_eof\naiohttp.http_exceptions.TransferEncodingError: 400, message:\n  Not enough data for satisfy transfer length header.\n\nThe above exception was the direct cause of the following exception:\n\nTraceback (most recent call last):\n  File \"/vllm-workspace/backend_request_func.py\", line 261, in async_request_openai_completions\n    async for chunk_bytes in response.content:\n  File \"/usr/local/lib/python3.10/dist-packages/aiohttp/streams.py\", line 50, in __anext__\n    rv = await self.read_func()\n  File \"/usr/local/lib/python3.10/dist-packages/aiohttp/streams.py\", line 317, in readline\n    return await self.readuntil()\n  File \"/usr/local/lib/python3.10/dist-packages/aiohttp/streams.py\", line 351, in readuntil\n    await self._wait(\"readuntil\")\n  File \"/usr/local/lib/python3.10/dist-packages/aiohttp/streams.py\", line 312, in _wait\n    await waiter\naiohttp.client_exceptions.ClientPayloadError: Response payload is not completed: <TransferEncodingError: 400, message='Not enough data for satisfy transfer length header.'>\n", "Traceback (most recent call last):\n  File \"/usr/local/lib/python3.10/dist-packages/aiohttp/client_proto.py\", line 94, in connection_lost\n    uncompleted = self._parser.feed_eof()\n  File \"aiohttp/_http_parser.pyx\", line 513, in aiohttp._http_parser.HttpParser.feed_eof\naiohttp.http_exceptions.TransferEncodingError: 400, message:\n  Not enough data for satisfy transfer length header.\n\nThe above exception was the direct cause of the following exception:\n\nTraceback (most recent call last):\n  File \"/vllm-workspace/backend_request_func.py\", line 261, in async_request_openai_completions\n    async for chunk_bytes in response.content:\n  File \"/usr/local/lib/python3.10/dist-packages/aiohttp/streams.py\", line 50, in __anext__\n    rv = await self.read_func()\n  File \"/usr/local/lib/python3.10/dist-packages/aiohttp/streams.py\", line 317, in readline\n    return await self.readuntil()\n  File \"/usr/local/lib/python3.10/dist-packages/aiohttp/streams.py\", line 351, in readuntil\n    await self._wait(\"readuntil\")\n  File \"/usr/local/lib/python3.10/dist-packages/aiohttp/streams.py\", line 312, in _wait\n    await waiter\naiohttp.client_exceptions.ClientPayloadError: Response payload is not completed: <TransferEncodingError: 400, message='Not enough data for satisfy transfer length header.'>\n", "Traceback (most recent call last):\n  File \"/usr/local/lib/python3.10/dist-packages/aiohttp/client_proto.py\", line 94, in connection_lost\n    uncompleted = self._parser.feed_eof()\n  File \"aiohttp/_http_parser.pyx\", line 513, in aiohttp._http_parser.HttpParser.feed_eof\naiohttp.http_exceptions.TransferEncodingError: 400, message:\n  Not enough data for satisfy transfer length header.\n\nThe above exception was the direct cause of the following exception:\n\nTraceback (most recent call last):\n  File \"/vllm-workspace/backend_request_func.py\", line 261, in async_request_openai_completions\n    async for chunk_bytes in response.content:\n  File \"/usr/local/lib/python3.10/dist-packages/aiohttp/streams.py\", line 50, in __anext__\n    rv = await self.read_func()\n  File \"/usr/local/lib/python3.10/dist-packages/aiohttp/streams.py\", line 317, in readline\n    return await self.readuntil()\n  File \"/usr/local/lib/python3.10/dist-packages/aiohttp/streams.py\", line 351, in readuntil\n    await self._wait(\"readuntil\")\n  File \"/usr/local/lib/python3.10/dist-packages/aiohttp/streams.py\", line 312, in _wait\n    await waiter\naiohttp.client_exceptions.ClientPayloadError: Response payload is not completed: <TransferEncodingError: 400, message='Not enough data for satisfy transfer length header.'>\n", "Traceback (most recent call last):\n  File \"/usr/local/lib/python3.10/dist-packages/aiohttp/client_proto.py\", line 94, in connection_lost\n    uncompleted = self._parser.feed_eof()\n  File \"aiohttp/_http_parser.pyx\", line 513, in aiohttp._http_parser.HttpParser.feed_eof\naiohttp.http_exceptions.TransferEncodingError: 400, message:\n  Not enough data for satisfy transfer length header.\n\nThe above exception was the direct cause of the following exception:\n\nTraceback (most recent call last):\n  File \"/vllm-workspace/backend_request_func.py\", line 261, in async_request_openai_completions\n    async for chunk_bytes in response.content:\n  File \"/usr/local/lib/python3.10/dist-packages/aiohttp/streams.py\", line 50, in __anext__\n    rv = await self.read_func()\n  File \"/usr/local/lib/python3.10/dist-packages/aiohttp/streams.py\", line 317, in readline\n    return await self.readuntil()\n  File \"/usr/local/lib/python3.10/dist-packages/aiohttp/streams.py\", line 351, in readuntil\n    await self._wait(\"readuntil\")\n  File \"/usr/local/lib/python3.10/dist-packages/aiohttp/streams.py\", line 312, in _wait\n    await waiter\naiohttp.client_exceptions.ClientPayloadError: Response payload is not completed: <TransferEncodingError: 400, message='Not enough data for satisfy transfer length header.'>\n", "Traceback (most recent call last):\n  File \"/usr/local/lib/python3.10/dist-packages/aiohttp/client_proto.py\", line 94, in connection_lost\n    uncompleted = self._parser.feed_eof()\n  File \"aiohttp/_http_parser.pyx\", line 513, in aiohttp._http_parser.HttpParser.feed_eof\naiohttp.http_exceptions.TransferEncodingError: 400, message:\n  Not enough data for satisfy transfer length header.\n\nThe above exception was the direct cause of the following exception:\n\nTraceback (most recent call last):\n  File \"/vllm-workspace/backend_request_func.py\", line 261, in async_request_openai_completions\n    async for chunk_bytes in response.content:\n  File \"/usr/local/lib/python3.10/dist-packages/aiohttp/streams.py\", line 50, in __anext__\n    rv = await self.read_func()\n  File \"/usr/local/lib/python3.10/dist-packages/aiohttp/streams.py\", line 317, in readline\n    return await self.readuntil()\n  File \"/usr/local/lib/python3.10/dist-packages/aiohttp/streams.py\", line 351, in readuntil\n    await self._wait(\"readuntil\")\n  File \"/usr/local/lib/python3.10/dist-packages/aiohttp/streams.py\", line 312, in _wait\n    await waiter\naiohttp.client_exceptions.ClientPayloadError: Response payload is not completed: <TransferEncodingError: 400, message='Not enough data for satisfy transfer length header.'>\n", "Traceback (most recent call last):\n  File \"/usr/local/lib/python3.10/dist-packages/aiohttp/client_proto.py\", line 94, in connection_lost\n    uncompleted = self._parser.feed_eof()\n  File \"aiohttp/_http_parser.pyx\", line 513, in aiohttp._http_parser.HttpParser.feed_eof\naiohttp.http_exceptions.TransferEncodingError: 400, message:\n  Not enough data for satisfy transfer length header.\n\nThe above exception was the direct cause of the following exception:\n\nTraceback (most recent call last):\n  File \"/vllm-workspace/backend_request_func.py\", line 261, in async_request_openai_completions\n    async for chunk_bytes in response.content:\n  File \"/usr/local/lib/python3.10/dist-packages/aiohttp/streams.py\", line 50, in __anext__\n    rv = await self.read_func()\n  File \"/usr/local/lib/python3.10/dist-packages/aiohttp/streams.py\", line 317, in readline\n    return await self.readuntil()\n  File \"/usr/local/lib/python3.10/dist-packages/aiohttp/streams.py\", line 351, in readuntil\n    await self._wait(\"readuntil\")\n  File \"/usr/local/lib/python3.10/dist-packages/aiohttp/streams.py\", line 312, in _wait\n    await waiter\naiohttp.client_exceptions.ClientPayloadError: Response payload is not completed: <TransferEncodingError: 400, message='Not enough data for satisfy transfer length header.'>\n", "Traceback (most recent call last):\n  File \"/usr/local/lib/python3.10/dist-packages/aiohttp/client_proto.py\", line 94, in connection_lost\n    uncompleted = self._parser.feed_eof()\n  File \"aiohttp/_http_parser.pyx\", line 513, in aiohttp._http_parser.HttpParser.feed_eof\naiohttp.http_exceptions.TransferEncodingError: 400, message:\n  Not enough data for satisfy transfer length header.\n\nThe above exception was the direct cause of the following exception:\n\nTraceback (most recent call last):\n  File \"/vllm-workspace/backend_request_func.py\", line 261, in async_request_openai_completions\n    async for chunk_bytes in response.content:\n  File \"/usr/local/lib/python3.10/dist-packages/aiohttp/streams.py\", line 50, in __anext__\n    rv = await self.read_func()\n  File \"/usr/local/lib/python3.10/dist-packages/aiohttp/streams.py\", line 317, in readline\n    return await self.readuntil()\n  File \"/usr/local/lib/python3.10/dist-packages/aiohttp/streams.py\", line 351, in readuntil\n    await self._wait(\"readuntil\")\n  File \"/usr/local/lib/python3.10/dist-packages/aiohttp/streams.py\", line 312, in _wait\n    await waiter\naiohttp.client_exceptions.ClientPayloadError: Response payload is not completed: <TransferEncodingError: 400, message='Not enough data for satisfy transfer length header.'>\n", "", "", "Traceback (most recent call last):\n  File \"/usr/local/lib/python3.10/dist-packages/aiohttp/client_proto.py\", line 94, in connection_lost\n    uncompleted = self._parser.feed_eof()\n  File \"aiohttp/_http_parser.pyx\", line 513, in aiohttp._http_parser.HttpParser.feed_eof\naiohttp.http_exceptions.TransferEncodingError: 400, message:\n  Not enough data for satisfy transfer length header.\n\nThe above exception was the direct cause of the following exception:\n\nTraceback (most recent call last):\n  File \"/vllm-workspace/backend_request_func.py\", line 261, in async_request_openai_completions\n    async for chunk_bytes in response.content:\n  File \"/usr/local/lib/python3.10/dist-packages/aiohttp/streams.py\", line 50, in __anext__\n    rv = await self.read_func()\n  File \"/usr/local/lib/python3.10/dist-packages/aiohttp/streams.py\", line 317, in readline\n    return await self.readuntil()\n  File \"/usr/local/lib/python3.10/dist-packages/aiohttp/streams.py\", line 351, in readuntil\n    await self._wait(\"readuntil\")\n  File \"/usr/local/lib/python3.10/dist-packages/aiohttp/streams.py\", line 312, in _wait\n    await waiter\naiohttp.client_exceptions.ClientPayloadError: Response payload is not completed: <TransferEncodingError: 400, message='Not enough data for satisfy transfer length header.'>\n", "Traceback (most recent call last):\n  File \"/usr/local/lib/python3.10/dist-packages/aiohttp/client_proto.py\", line 94, in connection_lost\n    uncompleted = self._parser.feed_eof()\n  File \"aiohttp/_http_parser.pyx\", line 513, in aiohttp._http_parser.HttpParser.feed_eof\naiohttp.http_exceptions.TransferEncodingError: 400, message:\n  Not enough data for satisfy transfer length header.\n\nThe above exception was the direct cause of the following exception:\n\nTraceback (most recent call last):\n  File \"/vllm-workspace/backend_request_func.py\", line 261, in async_request_openai_completions\n    async for chunk_bytes in response.content:\n  File \"/usr/local/lib/python3.10/dist-packages/aiohttp/streams.py\", line 50, in __anext__\n    rv = await self.read_func()\n  File \"/usr/local/lib/python3.10/dist-packages/aiohttp/streams.py\", line 317, in readline\n    return await self.readuntil()\n  File \"/usr/local/lib/python3.10/dist-packages/aiohttp/streams.py\", line 351, in readuntil\n    await self._wait(\"readuntil\")\n  File \"/usr/local/lib/python3.10/dist-packages/aiohttp/streams.py\", line 312, in _wait\n    await waiter\naiohttp.client_exceptions.ClientPayloadError: Response payload is not completed: <TransferEncodingError: 400, message='Not enough data for satisfy transfer length header.'>\n", "Traceback (most recent call last):\n  File \"/usr/local/lib/python3.10/dist-packages/aiohttp/client_proto.py\", line 94, in connection_lost\n    uncompleted = self._parser.feed_eof()\n  File \"aiohttp/_http_parser.pyx\", line 513, in aiohttp._http_parser.HttpParser.feed_eof\naiohttp.http_exceptions.TransferEncodingError: 400, message:\n  Not enough data for satisfy transfer length header.\n\nThe above exception was the direct cause of the following exception:\n\nTraceback (most recent call last):\n  File \"/vllm-workspace/backend_request_func.py\", line 261, in async_request_openai_completions\n    async for chunk_bytes in response.content:\n  File \"/usr/local/lib/python3.10/dist-packages/aiohttp/streams.py\", line 50, in __anext__\n    rv = await self.read_func()\n  File \"/usr/local/lib/python3.10/dist-packages/aiohttp/streams.py\", line 317, in readline\n    return await self.readuntil()\n  File \"/usr/local/lib/python3.10/dist-packages/aiohttp/streams.py\", line 351, in readuntil\n    await self._wait(\"readuntil\")\n  File \"/usr/local/lib/python3.10/dist-packages/aiohttp/streams.py\", line 312, in _wait\n    await waiter\naiohttp.client_exceptions.ClientPayloadError: Response payload is not completed: <TransferEncodingError: 400, message='Not enough data for satisfy transfer length header.'>\n", "Traceback (most recent call last):\n  File \"/usr/local/lib/python3.10/dist-packages/aiohttp/client_proto.py\", line 94, in connection_lost\n    uncompleted = self._parser.feed_eof()\n  File \"aiohttp/_http_parser.pyx\", line 513, in aiohttp._http_parser.HttpParser.feed_eof\naiohttp.http_exceptions.TransferEncodingError: 400, message:\n  Not enough data for satisfy transfer length header.\n\nThe above exception was the direct cause of the following exception:\n\nTraceback (most recent call last):\n  File \"/vllm-workspace/backend_request_func.py\", line 261, in async_request_openai_completions\n    async for chunk_bytes in response.content:\n  File \"/usr/local/lib/python3.10/dist-packages/aiohttp/streams.py\", line 50, in __anext__\n    rv = await self.read_func()\n  File \"/usr/local/lib/python3.10/dist-packages/aiohttp/streams.py\", line 317, in readline\n    return await self.readuntil()\n  File \"/usr/local/lib/python3.10/dist-packages/aiohttp/streams.py\", line 351, in readuntil\n    await self._wait(\"readuntil\")\n  File \"/usr/local/lib/python3.10/dist-packages/aiohttp/streams.py\", line 312, in _wait\n    await waiter\naiohttp.client_exceptions.ClientPayloadError: Response payload is not completed: <TransferEncodingError: 400, message='Not enough data for satisfy transfer length header.'>\n", "", "Traceback (most recent call last):\n  File \"/usr/local/lib/python3.10/dist-packages/aiohttp/client_proto.py\", line 94, in connection_lost\n    uncompleted = self._parser.feed_eof()\n  File \"aiohttp/_http_parser.pyx\", line 513, in aiohttp._http_parser.HttpParser.feed_eof\naiohttp.http_exceptions.TransferEncodingError: 400, message:\n  Not enough data for satisfy transfer length header.\n\nThe above exception was the direct cause of the following exception:\n\nTraceback (most recent call last):\n  File \"/vllm-workspace/backend_request_func.py\", line 261, in async_request_openai_completions\n    async for chunk_bytes in response.content:\n  File \"/usr/local/lib/python3.10/dist-packages/aiohttp/streams.py\", line 50, in __anext__\n    rv = await self.read_func()\n  File \"/usr/local/lib/python3.10/dist-packages/aiohttp/streams.py\", line 317, in readline\n    return await self.readuntil()\n  File \"/usr/local/lib/python3.10/dist-packages/aiohttp/streams.py\", line 351, in readuntil\n    await self._wait(\"readuntil\")\n  File \"/usr/local/lib/python3.10/dist-packages/aiohttp/streams.py\", line 312, in _wait\n    await waiter\naiohttp.client_exceptions.ClientPayloadError: Response payload is not completed: <TransferEncodingError: 400, message='Not enough data for satisfy transfer length header.'>\n", "Traceback (most recent call last):\n  File \"/usr/local/lib/python3.10/dist-packages/aiohttp/client_proto.py\", line 94, in connection_lost\n    uncompleted = self._parser.feed_eof()\n  File \"aiohttp/_http_parser.pyx\", line 513, in aiohttp._http_parser.HttpParser.feed_eof\naiohttp.http_exceptions.TransferEncodingError: 400, message:\n  Not enough data for satisfy transfer length header.\n\nThe above exception was the direct cause of the following exception:\n\nTraceback (most recent call last):\n  File \"/vllm-workspace/backend_request_func.py\", line 261, in async_request_openai_completions\n    async for chunk_bytes in response.content:\n  File \"/usr/local/lib/python3.10/dist-packages/aiohttp/streams.py\", line 50, in __anext__\n    rv = await self.read_func()\n  File \"/usr/local/lib/python3.10/dist-packages/aiohttp/streams.py\", line 317, in readline\n    return await self.readuntil()\n  File \"/usr/local/lib/python3.10/dist-packages/aiohttp/streams.py\", line 351, in readuntil\n    await self._wait(\"readuntil\")\n  File \"/usr/local/lib/python3.10/dist-packages/aiohttp/streams.py\", line 312, in _wait\n    await waiter\naiohttp.client_exceptions.ClientPayloadError: Response payload is not completed: <TransferEncodingError: 400, message='Not enough data for satisfy transfer length header.'>\n", "Traceback (most recent call last):\n  File \"/usr/local/lib/python3.10/dist-packages/aiohttp/client_proto.py\", line 94, in connection_lost\n    uncompleted = self._parser.feed_eof()\n  File \"aiohttp/_http_parser.pyx\", line 513, in aiohttp._http_parser.HttpParser.feed_eof\naiohttp.http_exceptions.TransferEncodingError: 400, message:\n  Not enough data for satisfy transfer length header.\n\nThe above exception was the direct cause of the following exception:\n\nTraceback (most recent call last):\n  File \"/vllm-workspace/backend_request_func.py\", line 261, in async_request_openai_completions\n    async for chunk_bytes in response.content:\n  File \"/usr/local/lib/python3.10/dist-packages/aiohttp/streams.py\", line 50, in __anext__\n    rv = await self.read_func()\n  File \"/usr/local/lib/python3.10/dist-packages/aiohttp/streams.py\", line 317, in readline\n    return await self.readuntil()\n  File \"/usr/local/lib/python3.10/dist-packages/aiohttp/streams.py\", line 351, in readuntil\n    await self._wait(\"readuntil\")\n  File \"/usr/local/lib/python3.10/dist-packages/aiohttp/streams.py\", line 312, in _wait\n    await waiter\naiohttp.client_exceptions.ClientPayloadError: Response payload is not completed: <TransferEncodingError: 400, message='Not enough data for satisfy transfer length header.'>\n", "Traceback (most recent call last):\n  File \"/usr/local/lib/python3.10/dist-packages/aiohttp/client_proto.py\", line 94, in connection_lost\n    uncompleted = self._parser.feed_eof()\n  File \"aiohttp/_http_parser.pyx\", line 513, in aiohttp._http_parser.HttpParser.feed_eof\naiohttp.http_exceptions.TransferEncodingError: 400, message:\n  Not enough data for satisfy transfer length header.\n\nThe above exception was the direct cause of the following exception:\n\nTraceback (most recent call last):\n  File \"/vllm-workspace/backend_request_func.py\", line 261, in async_request_openai_completions\n    async for chunk_bytes in response.content:\n  File \"/usr/local/lib/python3.10/dist-packages/aiohttp/streams.py\", line 50, in __anext__\n    rv = await self.read_func()\n  File \"/usr/local/lib/python3.10/dist-packages/aiohttp/streams.py\", line 317, in readline\n    return await self.readuntil()\n  File \"/usr/local/lib/python3.10/dist-packages/aiohttp/streams.py\", line 351, in readuntil\n    await self._wait(\"readuntil\")\n  File \"/usr/local/lib/python3.10/dist-packages/aiohttp/streams.py\", line 312, in _wait\n    await waiter\naiohttp.client_exceptions.ClientPayloadError: Response payload is not completed: <TransferEncodingError: 400, message='Not enough data for satisfy transfer length header.'>\n", "Traceback (most recent call last):\n  File \"/usr/local/lib/python3.10/dist-packages/aiohttp/client_proto.py\", line 94, in connection_lost\n    uncompleted = self._parser.feed_eof()\n  File \"aiohttp/_http_parser.pyx\", line 513, in aiohttp._http_parser.HttpParser.feed_eof\naiohttp.http_exceptions.TransferEncodingError: 400, message:\n  Not enough data for satisfy transfer length header.\n\nThe above exception was the direct cause of the following exception:\n\nTraceback (most recent call last):\n  File \"/vllm-workspace/backend_request_func.py\", line 261, in async_request_openai_completions\n    async for chunk_bytes in response.content:\n  File \"/usr/local/lib/python3.10/dist-packages/aiohttp/streams.py\", line 50, in __anext__\n    rv = await self.read_func()\n  File \"/usr/local/lib/python3.10/dist-packages/aiohttp/streams.py\", line 317, in readline\n    return await self.readuntil()\n  File \"/usr/local/lib/python3.10/dist-packages/aiohttp/streams.py\", line 351, in readuntil\n    await self._wait(\"readuntil\")\n  File \"/usr/local/lib/python3.10/dist-packages/aiohttp/streams.py\", line 312, in _wait\n    await waiter\naiohttp.client_exceptions.ClientPayloadError: Response payload is not completed: <TransferEncodingError: 400, message='Not enough data for satisfy transfer length header.'>\n", "", "Traceback (most recent call last):\n  File \"/usr/local/lib/python3.10/dist-packages/aiohttp/client_proto.py\", line 94, in connection_lost\n    uncompleted = self._parser.feed_eof()\n  File \"aiohttp/_http_parser.pyx\", line 513, in aiohttp._http_parser.HttpParser.feed_eof\naiohttp.http_exceptions.TransferEncodingError: 400, message:\n  Not enough data for satisfy transfer length header.\n\nThe above exception was the direct cause of the following exception:\n\nTraceback (most recent call last):\n  File \"/vllm-workspace/backend_request_func.py\", line 261, in async_request_openai_completions\n    async for chunk_bytes in response.content:\n  File \"/usr/local/lib/python3.10/dist-packages/aiohttp/streams.py\", line 50, in __anext__\n    rv = await self.read_func()\n  File \"/usr/local/lib/python3.10/dist-packages/aiohttp/streams.py\", line 317, in readline\n    return await self.readuntil()\n  File \"/usr/local/lib/python3.10/dist-packages/aiohttp/streams.py\", line 351, in readuntil\n    await self._wait(\"readuntil\")\n  File \"/usr/local/lib/python3.10/dist-packages/aiohttp/streams.py\", line 312, in _wait\n    await waiter\naiohttp.client_exceptions.ClientPayloadError: Response payload is not completed: <TransferEncodingError: 400, message='Not enough data for satisfy transfer length header.'>\n", "", "Traceback (most recent call last):\n  File \"/usr/local/lib/python3.10/dist-packages/aiohttp/client_proto.py\", line 94, in connection_lost\n    uncompleted = self._parser.feed_eof()\n  File \"aiohttp/_http_parser.pyx\", line 513, in aiohttp._http_parser.HttpParser.feed_eof\naiohttp.http_exceptions.TransferEncodingError: 400, message:\n  Not enough data for satisfy transfer length header.\n\nThe above exception was the direct cause of the following exception:\n\nTraceback (most recent call last):\n  File \"/vllm-workspace/backend_request_func.py\", line 261, in async_request_openai_completions\n    async for chunk_bytes in response.content:\n  File \"/usr/local/lib/python3.10/dist-packages/aiohttp/streams.py\", line 50, in __anext__\n    rv = await self.read_func()\n  File \"/usr/local/lib/python3.10/dist-packages/aiohttp/streams.py\", line 317, in readline\n    return await self.readuntil()\n  File \"/usr/local/lib/python3.10/dist-packages/aiohttp/streams.py\", line 351, in readuntil\n    await self._wait(\"readuntil\")\n  File \"/usr/local/lib/python3.10/dist-packages/aiohttp/streams.py\", line 312, in _wait\n    await waiter\naiohttp.client_exceptions.ClientPayloadError: Response payload is not completed: <TransferEncodingError: 400, message='Not enough data for satisfy transfer length header.'>\n", "Traceback (most recent call last):\n  File \"/usr/local/lib/python3.10/dist-packages/aiohttp/client_proto.py\", line 94, in connection_lost\n    uncompleted = self._parser.feed_eof()\n  File \"aiohttp/_http_parser.pyx\", line 513, in aiohttp._http_parser.HttpParser.feed_eof\naiohttp.http_exceptions.TransferEncodingError: 400, message:\n  Not enough data for satisfy transfer length header.\n\nThe above exception was the direct cause of the following exception:\n\nTraceback (most recent call last):\n  File \"/vllm-workspace/backend_request_func.py\", line 261, in async_request_openai_completions\n    async for chunk_bytes in response.content:\n  File \"/usr/local/lib/python3.10/dist-packages/aiohttp/streams.py\", line 50, in __anext__\n    rv = await self.read_func()\n  File \"/usr/local/lib/python3.10/dist-packages/aiohttp/streams.py\", line 317, in readline\n    return await self.readuntil()\n  File \"/usr/local/lib/python3.10/dist-packages/aiohttp/streams.py\", line 351, in readuntil\n    await self._wait(\"readuntil\")\n  File \"/usr/local/lib/python3.10/dist-packages/aiohttp/streams.py\", line 312, in _wait\n    await waiter\naiohttp.client_exceptions.ClientPayloadError: Response payload is not completed: <TransferEncodingError: 400, message='Not enough data for satisfy transfer length header.'>\n", "", "Traceback (most recent call last):\n  File \"/usr/local/lib/python3.10/dist-packages/aiohttp/client_proto.py\", line 94, in connection_lost\n    uncompleted = self._parser.feed_eof()\n  File \"aiohttp/_http_parser.pyx\", line 513, in aiohttp._http_parser.HttpParser.feed_eof\naiohttp.http_exceptions.TransferEncodingError: 400, message:\n  Not enough data for satisfy transfer length header.\n\nThe above exception was the direct cause of the following exception:\n\nTraceback (most recent call last):\n  File \"/vllm-workspace/backend_request_func.py\", line 261, in async_request_openai_completions\n    async for chunk_bytes in response.content:\n  File \"/usr/local/lib/python3.10/dist-packages/aiohttp/streams.py\", line 50, in __anext__\n    rv = await self.read_func()\n  File \"/usr/local/lib/python3.10/dist-packages/aiohttp/streams.py\", line 317, in readline\n    return await self.readuntil()\n  File \"/usr/local/lib/python3.10/dist-packages/aiohttp/streams.py\", line 351, in readuntil\n    await self._wait(\"readuntil\")\n  File \"/usr/local/lib/python3.10/dist-packages/aiohttp/streams.py\", line 312, in _wait\n    await waiter\naiohttp.client_exceptions.ClientPayloadError: Response payload is not completed: <TransferEncodingError: 400, message='Not enough data for satisfy transfer length header.'>\n", "Traceback (most recent call last):\n  File \"/usr/local/lib/python3.10/dist-packages/aiohttp/client_proto.py\", line 94, in connection_lost\n    uncompleted = self._parser.feed_eof()\n  File \"aiohttp/_http_parser.pyx\", line 513, in aiohttp._http_parser.HttpParser.feed_eof\naiohttp.http_exceptions.TransferEncodingError: 400, message:\n  Not enough data for satisfy transfer length header.\n\nThe above exception was the direct cause of the following exception:\n\nTraceback (most recent call last):\n  File \"/vllm-workspace/backend_request_func.py\", line 261, in async_request_openai_completions\n    async for chunk_bytes in response.content:\n  File \"/usr/local/lib/python3.10/dist-packages/aiohttp/streams.py\", line 50, in __anext__\n    rv = await self.read_func()\n  File \"/usr/local/lib/python3.10/dist-packages/aiohttp/streams.py\", line 317, in readline\n    return await self.readuntil()\n  File \"/usr/local/lib/python3.10/dist-packages/aiohttp/streams.py\", line 351, in readuntil\n    await self._wait(\"readuntil\")\n  File \"/usr/local/lib/python3.10/dist-packages/aiohttp/streams.py\", line 312, in _wait\n    await waiter\naiohttp.client_exceptions.ClientPayloadError: Response payload is not completed: <TransferEncodingError: 400, message='Not enough data for satisfy transfer length header.'>\n", "Traceback (most recent call last):\n  File \"/usr/local/lib/python3.10/dist-packages/aiohttp/client_proto.py\", line 94, in connection_lost\n    uncompleted = self._parser.feed_eof()\n  File \"aiohttp/_http_parser.pyx\", line 513, in aiohttp._http_parser.HttpParser.feed_eof\naiohttp.http_exceptions.TransferEncodingError: 400, message:\n  Not enough data for satisfy transfer length header.\n\nThe above exception was the direct cause of the following exception:\n\nTraceback (most recent call last):\n  File \"/vllm-workspace/backend_request_func.py\", line 261, in async_request_openai_completions\n    async for chunk_bytes in response.content:\n  File \"/usr/local/lib/python3.10/dist-packages/aiohttp/streams.py\", line 50, in __anext__\n    rv = await self.read_func()\n  File \"/usr/local/lib/python3.10/dist-packages/aiohttp/streams.py\", line 317, in readline\n    return await self.readuntil()\n  File \"/usr/local/lib/python3.10/dist-packages/aiohttp/streams.py\", line 351, in readuntil\n    await self._wait(\"readuntil\")\n  File \"/usr/local/lib/python3.10/dist-packages/aiohttp/streams.py\", line 312, in _wait\n    await waiter\naiohttp.client_exceptions.ClientPayloadError: Response payload is not completed: <TransferEncodingError: 400, message='Not enough data for satisfy transfer length header.'>\n", "Traceback (most recent call last):\n  File \"/usr/local/lib/python3.10/dist-packages/aiohttp/client_proto.py\", line 94, in connection_lost\n    uncompleted = self._parser.feed_eof()\n  File \"aiohttp/_http_parser.pyx\", line 513, in aiohttp._http_parser.HttpParser.feed_eof\naiohttp.http_exceptions.TransferEncodingError: 400, message:\n  Not enough data for satisfy transfer length header.\n\nThe above exception was the direct cause of the following exception:\n\nTraceback (most recent call last):\n  File \"/vllm-workspace/backend_request_func.py\", line 261, in async_request_openai_completions\n    async for chunk_bytes in response.content:\n  File \"/usr/local/lib/python3.10/dist-packages/aiohttp/streams.py\", line 50, in __anext__\n    rv = await self.read_func()\n  File \"/usr/local/lib/python3.10/dist-packages/aiohttp/streams.py\", line 317, in readline\n    return await self.readuntil()\n  File \"/usr/local/lib/python3.10/dist-packages/aiohttp/streams.py\", line 351, in readuntil\n    await self._wait(\"readuntil\")\n  File \"/usr/local/lib/python3.10/dist-packages/aiohttp/streams.py\", line 312, in _wait\n    await waiter\naiohttp.client_exceptions.ClientPayloadError: Response payload is not completed: <TransferEncodingError: 400, message='Not enough data for satisfy transfer length header.'>\n", "", "Traceback (most recent call last):\n  File \"/usr/local/lib/python3.10/dist-packages/aiohttp/client_proto.py\", line 94, in connection_lost\n    uncompleted = self._parser.feed_eof()\n  File \"aiohttp/_http_parser.pyx\", line 513, in aiohttp._http_parser.HttpParser.feed_eof\naiohttp.http_exceptions.TransferEncodingError: 400, message:\n  Not enough data for satisfy transfer length header.\n\nThe above exception was the direct cause of the following exception:\n\nTraceback (most recent call last):\n  File \"/vllm-workspace/backend_request_func.py\", line 261, in async_request_openai_completions\n    async for chunk_bytes in response.content:\n  File \"/usr/local/lib/python3.10/dist-packages/aiohttp/streams.py\", line 50, in __anext__\n    rv = await self.read_func()\n  File \"/usr/local/lib/python3.10/dist-packages/aiohttp/streams.py\", line 317, in readline\n    return await self.readuntil()\n  File \"/usr/local/lib/python3.10/dist-packages/aiohttp/streams.py\", line 351, in readuntil\n    await self._wait(\"readuntil\")\n  File \"/usr/local/lib/python3.10/dist-packages/aiohttp/streams.py\", line 312, in _wait\n    await waiter\naiohttp.client_exceptions.ClientPayloadError: Response payload is not completed: <TransferEncodingError: 400, message='Not enough data for satisfy transfer length header.'>\n", "Traceback (most recent call last):\n  File \"/usr/local/lib/python3.10/dist-packages/aiohttp/client_proto.py\", line 94, in connection_lost\n    uncompleted = self._parser.feed_eof()\n  File \"aiohttp/_http_parser.pyx\", line 513, in aiohttp._http_parser.HttpParser.feed_eof\naiohttp.http_exceptions.TransferEncodingError: 400, message:\n  Not enough data for satisfy transfer length header.\n\nThe above exception was the direct cause of the following exception:\n\nTraceback (most recent call last):\n  File \"/vllm-workspace/backend_request_func.py\", line 261, in async_request_openai_completions\n    async for chunk_bytes in response.content:\n  File \"/usr/local/lib/python3.10/dist-packages/aiohttp/streams.py\", line 50, in __anext__\n    rv = await self.read_func()\n  File \"/usr/local/lib/python3.10/dist-packages/aiohttp/streams.py\", line 317, in readline\n    return await self.readuntil()\n  File \"/usr/local/lib/python3.10/dist-packages/aiohttp/streams.py\", line 351, in readuntil\n    await self._wait(\"readuntil\")\n  File \"/usr/local/lib/python3.10/dist-packages/aiohttp/streams.py\", line 312, in _wait\n    await waiter\naiohttp.client_exceptions.ClientPayloadError: Response payload is not completed: <TransferEncodingError: 400, message='Not enough data for satisfy transfer length header.'>\n", "Traceback (most recent call last):\n  File \"/usr/local/lib/python3.10/dist-packages/aiohttp/client_proto.py\", line 94, in connection_lost\n    uncompleted = self._parser.feed_eof()\n  File \"aiohttp/_http_parser.pyx\", line 513, in aiohttp._http_parser.HttpParser.feed_eof\naiohttp.http_exceptions.TransferEncodingError: 400, message:\n  Not enough data for satisfy transfer length header.\n\nThe above exception was the direct cause of the following exception:\n\nTraceback (most recent call last):\n  File \"/vllm-workspace/backend_request_func.py\", line 261, in async_request_openai_completions\n    async for chunk_bytes in response.content:\n  File \"/usr/local/lib/python3.10/dist-packages/aiohttp/streams.py\", line 50, in __anext__\n    rv = await self.read_func()\n  File \"/usr/local/lib/python3.10/dist-packages/aiohttp/streams.py\", line 317, in readline\n    return await self.readuntil()\n  File \"/usr/local/lib/python3.10/dist-packages/aiohttp/streams.py\", line 351, in readuntil\n    await self._wait(\"readuntil\")\n  File \"/usr/local/lib/python3.10/dist-packages/aiohttp/streams.py\", line 312, in _wait\n    await waiter\naiohttp.client_exceptions.ClientPayloadError: Response payload is not completed: <TransferEncodingError: 400, message='Not enough data for satisfy transfer length header.'>\n", "", "Traceback (most recent call last):\n  File \"/usr/local/lib/python3.10/dist-packages/aiohttp/client_proto.py\", line 94, in connection_lost\n    uncompleted = self._parser.feed_eof()\n  File \"aiohttp/_http_parser.pyx\", line 513, in aiohttp._http_parser.HttpParser.feed_eof\naiohttp.http_exceptions.TransferEncodingError: 400, message:\n  Not enough data for satisfy transfer length header.\n\nThe above exception was the direct cause of the following exception:\n\nTraceback (most recent call last):\n  File \"/vllm-workspace/backend_request_func.py\", line 261, in async_request_openai_completions\n    async for chunk_bytes in response.content:\n  File \"/usr/local/lib/python3.10/dist-packages/aiohttp/streams.py\", line 50, in __anext__\n    rv = await self.read_func()\n  File \"/usr/local/lib/python3.10/dist-packages/aiohttp/streams.py\", line 317, in readline\n    return await self.readuntil()\n  File \"/usr/local/lib/python3.10/dist-packages/aiohttp/streams.py\", line 351, in readuntil\n    await self._wait(\"readuntil\")\n  File \"/usr/local/lib/python3.10/dist-packages/aiohttp/streams.py\", line 312, in _wait\n    await waiter\naiohttp.client_exceptions.ClientPayloadError: Response payload is not completed: <TransferEncodingError: 400, message='Not enough data for satisfy transfer length header.'>\n", "Traceback (most recent call last):\n  File \"/usr/local/lib/python3.10/dist-packages/aiohttp/client_proto.py\", line 94, in connection_lost\n    uncompleted = self._parser.feed_eof()\n  File \"aiohttp/_http_parser.pyx\", line 513, in aiohttp._http_parser.HttpParser.feed_eof\naiohttp.http_exceptions.TransferEncodingError: 400, message:\n  Not enough data for satisfy transfer length header.\n\nThe above exception was the direct cause of the following exception:\n\nTraceback (most recent call last):\n  File \"/vllm-workspace/backend_request_func.py\", line 261, in async_request_openai_completions\n    async for chunk_bytes in response.content:\n  File \"/usr/local/lib/python3.10/dist-packages/aiohttp/streams.py\", line 50, in __anext__\n    rv = await self.read_func()\n  File \"/usr/local/lib/python3.10/dist-packages/aiohttp/streams.py\", line 317, in readline\n    return await self.readuntil()\n  File \"/usr/local/lib/python3.10/dist-packages/aiohttp/streams.py\", line 351, in readuntil\n    await self._wait(\"readuntil\")\n  File \"/usr/local/lib/python3.10/dist-packages/aiohttp/streams.py\", line 312, in _wait\n    await waiter\naiohttp.client_exceptions.ClientPayloadError: Response payload is not completed: <TransferEncodingError: 400, message='Not enough data for satisfy transfer length header.'>\n", "Traceback (most recent call last):\n  File \"/usr/local/lib/python3.10/dist-packages/aiohttp/client_proto.py\", line 94, in connection_lost\n    uncompleted = self._parser.feed_eof()\n  File \"aiohttp/_http_parser.pyx\", line 513, in aiohttp._http_parser.HttpParser.feed_eof\naiohttp.http_exceptions.TransferEncodingError: 400, message:\n  Not enough data for satisfy transfer length header.\n\nThe above exception was the direct cause of the following exception:\n\nTraceback (most recent call last):\n  File \"/vllm-workspace/backend_request_func.py\", line 261, in async_request_openai_completions\n    async for chunk_bytes in response.content:\n  File \"/usr/local/lib/python3.10/dist-packages/aiohttp/streams.py\", line 50, in __anext__\n    rv = await self.read_func()\n  File \"/usr/local/lib/python3.10/dist-packages/aiohttp/streams.py\", line 317, in readline\n    return await self.readuntil()\n  File \"/usr/local/lib/python3.10/dist-packages/aiohttp/streams.py\", line 351, in readuntil\n    await self._wait(\"readuntil\")\n  File \"/usr/local/lib/python3.10/dist-packages/aiohttp/streams.py\", line 312, in _wait\n    await waiter\naiohttp.client_exceptions.ClientPayloadError: Response payload is not completed: <TransferEncodingError: 400, message='Not enough data for satisfy transfer length header.'>\n", "Traceback (most recent call last):\n  File \"/usr/local/lib/python3.10/dist-packages/aiohttp/client_proto.py\", line 94, in connection_lost\n    uncompleted = self._parser.feed_eof()\n  File \"aiohttp/_http_parser.pyx\", line 513, in aiohttp._http_parser.HttpParser.feed_eof\naiohttp.http_exceptions.TransferEncodingError: 400, message:\n  Not enough data for satisfy transfer length header.\n\nThe above exception was the direct cause of the following exception:\n\nTraceback (most recent call last):\n  File \"/vllm-workspace/backend_request_func.py\", line 261, in async_request_openai_completions\n    async for chunk_bytes in response.content:\n  File \"/usr/local/lib/python3.10/dist-packages/aiohttp/streams.py\", line 50, in __anext__\n    rv = await self.read_func()\n  File \"/usr/local/lib/python3.10/dist-packages/aiohttp/streams.py\", line 317, in readline\n    return await self.readuntil()\n  File \"/usr/local/lib/python3.10/dist-packages/aiohttp/streams.py\", line 351, in readuntil\n    await self._wait(\"readuntil\")\n  File \"/usr/local/lib/python3.10/dist-packages/aiohttp/streams.py\", line 312, in _wait\n    await waiter\naiohttp.client_exceptions.ClientPayloadError: Response payload is not completed: <TransferEncodingError: 400, message='Not enough data for satisfy transfer length header.'>\n", "Traceback (most recent call last):\n  File \"/usr/local/lib/python3.10/dist-packages/aiohttp/client_proto.py\", line 94, in connection_lost\n    uncompleted = self._parser.feed_eof()\n  File \"aiohttp/_http_parser.pyx\", line 513, in aiohttp._http_parser.HttpParser.feed_eof\naiohttp.http_exceptions.TransferEncodingError: 400, message:\n  Not enough data for satisfy transfer length header.\n\nThe above exception was the direct cause of the following exception:\n\nTraceback (most recent call last):\n  File \"/vllm-workspace/backend_request_func.py\", line 261, in async_request_openai_completions\n    async for chunk_bytes in response.content:\n  File \"/usr/local/lib/python3.10/dist-packages/aiohttp/streams.py\", line 50, in __anext__\n    rv = await self.read_func()\n  File \"/usr/local/lib/python3.10/dist-packages/aiohttp/streams.py\", line 317, in readline\n    return await self.readuntil()\n  File \"/usr/local/lib/python3.10/dist-packages/aiohttp/streams.py\", line 351, in readuntil\n    await self._wait(\"readuntil\")\n  File \"/usr/local/lib/python3.10/dist-packages/aiohttp/streams.py\", line 312, in _wait\n    await waiter\naiohttp.client_exceptions.ClientPayloadError: Response payload is not completed: <TransferEncodingError: 400, message='Not enough data for satisfy transfer length header.'>\n", "Traceback (most recent call last):\n  File \"/usr/local/lib/python3.10/dist-packages/aiohttp/client_proto.py\", line 94, in connection_lost\n    uncompleted = self._parser.feed_eof()\n  File \"aiohttp/_http_parser.pyx\", line 513, in aiohttp._http_parser.HttpParser.feed_eof\naiohttp.http_exceptions.TransferEncodingError: 400, message:\n  Not enough data for satisfy transfer length header.\n\nThe above exception was the direct cause of the following exception:\n\nTraceback (most recent call last):\n  File \"/vllm-workspace/backend_request_func.py\", line 261, in async_request_openai_completions\n    async for chunk_bytes in response.content:\n  File \"/usr/local/lib/python3.10/dist-packages/aiohttp/streams.py\", line 50, in __anext__\n    rv = await self.read_func()\n  File \"/usr/local/lib/python3.10/dist-packages/aiohttp/streams.py\", line 317, in readline\n    return await self.readuntil()\n  File \"/usr/local/lib/python3.10/dist-packages/aiohttp/streams.py\", line 351, in readuntil\n    await self._wait(\"readuntil\")\n  File \"/usr/local/lib/python3.10/dist-packages/aiohttp/streams.py\", line 312, in _wait\n    await waiter\naiohttp.client_exceptions.ClientPayloadError: Response payload is not completed: <TransferEncodingError: 400, message='Not enough data for satisfy transfer length header.'>\n", "Traceback (most recent call last):\n  File \"/usr/local/lib/python3.10/dist-packages/aiohttp/client_proto.py\", line 94, in connection_lost\n    uncompleted = self._parser.feed_eof()\n  File \"aiohttp/_http_parser.pyx\", line 513, in aiohttp._http_parser.HttpParser.feed_eof\naiohttp.http_exceptions.TransferEncodingError: 400, message:\n  Not enough data for satisfy transfer length header.\n\nThe above exception was the direct cause of the following exception:\n\nTraceback (most recent call last):\n  File \"/vllm-workspace/backend_request_func.py\", line 261, in async_request_openai_completions\n    async for chunk_bytes in response.content:\n  File \"/usr/local/lib/python3.10/dist-packages/aiohttp/streams.py\", line 50, in __anext__\n    rv = await self.read_func()\n  File \"/usr/local/lib/python3.10/dist-packages/aiohttp/streams.py\", line 317, in readline\n    return await self.readuntil()\n  File \"/usr/local/lib/python3.10/dist-packages/aiohttp/streams.py\", line 351, in readuntil\n    await self._wait(\"readuntil\")\n  File \"/usr/local/lib/python3.10/dist-packages/aiohttp/streams.py\", line 312, in _wait\n    await waiter\naiohttp.client_exceptions.ClientPayloadError: Response payload is not completed: <TransferEncodingError: 400, message='Not enough data for satisfy transfer length header.'>\n", "Traceback (most recent call last):\n  File \"/usr/local/lib/python3.10/dist-packages/aiohttp/client_proto.py\", line 94, in connection_lost\n    uncompleted = self._parser.feed_eof()\n  File \"aiohttp/_http_parser.pyx\", line 513, in aiohttp._http_parser.HttpParser.feed_eof\naiohttp.http_exceptions.TransferEncodingError: 400, message:\n  Not enough data for satisfy transfer length header.\n\nThe above exception was the direct cause of the following exception:\n\nTraceback (most recent call last):\n  File \"/vllm-workspace/backend_request_func.py\", line 261, in async_request_openai_completions\n    async for chunk_bytes in response.content:\n  File \"/usr/local/lib/python3.10/dist-packages/aiohttp/streams.py\", line 50, in __anext__\n    rv = await self.read_func()\n  File \"/usr/local/lib/python3.10/dist-packages/aiohttp/streams.py\", line 317, in readline\n    return await self.readuntil()\n  File \"/usr/local/lib/python3.10/dist-packages/aiohttp/streams.py\", line 351, in readuntil\n    await self._wait(\"readuntil\")\n  File \"/usr/local/lib/python3.10/dist-packages/aiohttp/streams.py\", line 312, in _wait\n    await waiter\naiohttp.client_exceptions.ClientPayloadError: Response payload is not completed: <TransferEncodingError: 400, message='Not enough data for satisfy transfer length header.'>\n", "Traceback (most recent call last):\n  File \"/usr/local/lib/python3.10/dist-packages/aiohttp/client_proto.py\", line 94, in connection_lost\n    uncompleted = self._parser.feed_eof()\n  File \"aiohttp/_http_parser.pyx\", line 513, in aiohttp._http_parser.HttpParser.feed_eof\naiohttp.http_exceptions.TransferEncodingError: 400, message:\n  Not enough data for satisfy transfer length header.\n\nThe above exception was the direct cause of the following exception:\n\nTraceback (most recent call last):\n  File \"/vllm-workspace/backend_request_func.py\", line 261, in async_request_openai_completions\n    async for chunk_bytes in response.content:\n  File \"/usr/local/lib/python3.10/dist-packages/aiohttp/streams.py\", line 50, in __anext__\n    rv = await self.read_func()\n  File \"/usr/local/lib/python3.10/dist-packages/aiohttp/streams.py\", line 317, in readline\n    return await self.readuntil()\n  File \"/usr/local/lib/python3.10/dist-packages/aiohttp/streams.py\", line 351, in readuntil\n    await self._wait(\"readuntil\")\n  File \"/usr/local/lib/python3.10/dist-packages/aiohttp/streams.py\", line 312, in _wait\n    await waiter\naiohttp.client_exceptions.ClientPayloadError: Response payload is not completed: <TransferEncodingError: 400, message='Not enough data for satisfy transfer length header.'>\n", "Traceback (most recent call last):\n  File \"/usr/local/lib/python3.10/dist-packages/aiohttp/client_proto.py\", line 94, in connection_lost\n    uncompleted = self._parser.feed_eof()\n  File \"aiohttp/_http_parser.pyx\", line 513, in aiohttp._http_parser.HttpParser.feed_eof\naiohttp.http_exceptions.TransferEncodingError: 400, message:\n  Not enough data for satisfy transfer length header.\n\nThe above exception was the direct cause of the following exception:\n\nTraceback (most recent call last):\n  File \"/vllm-workspace/backend_request_func.py\", line 261, in async_request_openai_completions\n    async for chunk_bytes in response.content:\n  File \"/usr/local/lib/python3.10/dist-packages/aiohttp/streams.py\", line 50, in __anext__\n    rv = await self.read_func()\n  File \"/usr/local/lib/python3.10/dist-packages/aiohttp/streams.py\", line 317, in readline\n    return await self.readuntil()\n  File \"/usr/local/lib/python3.10/dist-packages/aiohttp/streams.py\", line 351, in readuntil\n    await self._wait(\"readuntil\")\n  File \"/usr/local/lib/python3.10/dist-packages/aiohttp/streams.py\", line 312, in _wait\n    await waiter\naiohttp.client_exceptions.ClientPayloadError: Response payload is not completed: <TransferEncodingError: 400, message='Not enough data for satisfy transfer length header.'>\n", "Traceback (most recent call last):\n  File \"/usr/local/lib/python3.10/dist-packages/aiohttp/client_proto.py\", line 94, in connection_lost\n    uncompleted = self._parser.feed_eof()\n  File \"aiohttp/_http_parser.pyx\", line 513, in aiohttp._http_parser.HttpParser.feed_eof\naiohttp.http_exceptions.TransferEncodingError: 400, message:\n  Not enough data for satisfy transfer length header.\n\nThe above exception was the direct cause of the following exception:\n\nTraceback (most recent call last):\n  File \"/vllm-workspace/backend_request_func.py\", line 261, in async_request_openai_completions\n    async for chunk_bytes in response.content:\n  File \"/usr/local/lib/python3.10/dist-packages/aiohttp/streams.py\", line 50, in __anext__\n    rv = await self.read_func()\n  File \"/usr/local/lib/python3.10/dist-packages/aiohttp/streams.py\", line 317, in readline\n    return await self.readuntil()\n  File \"/usr/local/lib/python3.10/dist-packages/aiohttp/streams.py\", line 351, in readuntil\n    await self._wait(\"readuntil\")\n  File \"/usr/local/lib/python3.10/dist-packages/aiohttp/streams.py\", line 312, in _wait\n    await waiter\naiohttp.client_exceptions.ClientPayloadError: Response payload is not completed: <TransferEncodingError: 400, message='Not enough data for satisfy transfer length header.'>\n", "Traceback (most recent call last):\n  File \"/usr/local/lib/python3.10/dist-packages/aiohttp/client_proto.py\", line 94, in connection_lost\n    uncompleted = self._parser.feed_eof()\n  File \"aiohttp/_http_parser.pyx\", line 513, in aiohttp._http_parser.HttpParser.feed_eof\naiohttp.http_exceptions.TransferEncodingError: 400, message:\n  Not enough data for satisfy transfer length header.\n\nThe above exception was the direct cause of the following exception:\n\nTraceback (most recent call last):\n  File \"/vllm-workspace/backend_request_func.py\", line 261, in async_request_openai_completions\n    async for chunk_bytes in response.content:\n  File \"/usr/local/lib/python3.10/dist-packages/aiohttp/streams.py\", line 50, in __anext__\n    rv = await self.read_func()\n  File \"/usr/local/lib/python3.10/dist-packages/aiohttp/streams.py\", line 317, in readline\n    return await self.readuntil()\n  File \"/usr/local/lib/python3.10/dist-packages/aiohttp/streams.py\", line 351, in readuntil\n    await self._wait(\"readuntil\")\n  File \"/usr/local/lib/python3.10/dist-packages/aiohttp/streams.py\", line 312, in _wait\n    await waiter\naiohttp.client_exceptions.ClientPayloadError: Response payload is not completed: <TransferEncodingError: 400, message='Not enough data for satisfy transfer length header.'>\n", "Traceback (most recent call last):\n  File \"/usr/local/lib/python3.10/dist-packages/aiohttp/client_proto.py\", line 94, in connection_lost\n    uncompleted = self._parser.feed_eof()\n  File \"aiohttp/_http_parser.pyx\", line 513, in aiohttp._http_parser.HttpParser.feed_eof\naiohttp.http_exceptions.TransferEncodingError: 400, message:\n  Not enough data for satisfy transfer length header.\n\nThe above exception was the direct cause of the following exception:\n\nTraceback (most recent call last):\n  File \"/vllm-workspace/backend_request_func.py\", line 261, in async_request_openai_completions\n    async for chunk_bytes in response.content:\n  File \"/usr/local/lib/python3.10/dist-packages/aiohttp/streams.py\", line 50, in __anext__\n    rv = await self.read_func()\n  File \"/usr/local/lib/python3.10/dist-packages/aiohttp/streams.py\", line 317, in readline\n    return await self.readuntil()\n  File \"/usr/local/lib/python3.10/dist-packages/aiohttp/streams.py\", line 351, in readuntil\n    await self._wait(\"readuntil\")\n  File \"/usr/local/lib/python3.10/dist-packages/aiohttp/streams.py\", line 312, in _wait\n    await waiter\naiohttp.client_exceptions.ClientPayloadError: Response payload is not completed: <TransferEncodingError: 400, message='Not enough data for satisfy transfer length header.'>\n", "Traceback (most recent call last):\n  File \"/usr/local/lib/python3.10/dist-packages/aiohttp/client_proto.py\", line 94, in connection_lost\n    uncompleted = self._parser.feed_eof()\n  File \"aiohttp/_http_parser.pyx\", line 513, in aiohttp._http_parser.HttpParser.feed_eof\naiohttp.http_exceptions.TransferEncodingError: 400, message:\n  Not enough data for satisfy transfer length header.\n\nThe above exception was the direct cause of the following exception:\n\nTraceback (most recent call last):\n  File \"/vllm-workspace/backend_request_func.py\", line 261, in async_request_openai_completions\n    async for chunk_bytes in response.content:\n  File \"/usr/local/lib/python3.10/dist-packages/aiohttp/streams.py\", line 50, in __anext__\n    rv = await self.read_func()\n  File \"/usr/local/lib/python3.10/dist-packages/aiohttp/streams.py\", line 317, in readline\n    return await self.readuntil()\n  File \"/usr/local/lib/python3.10/dist-packages/aiohttp/streams.py\", line 351, in readuntil\n    await self._wait(\"readuntil\")\n  File \"/usr/local/lib/python3.10/dist-packages/aiohttp/streams.py\", line 312, in _wait\n    await waiter\naiohttp.client_exceptions.ClientPayloadError: Response payload is not completed: <TransferEncodingError: 400, message='Not enough data for satisfy transfer length header.'>\n", "Traceback (most recent call last):\n  File \"/usr/local/lib/python3.10/dist-packages/aiohttp/client_proto.py\", line 94, in connection_lost\n    uncompleted = self._parser.feed_eof()\n  File \"aiohttp/_http_parser.pyx\", line 513, in aiohttp._http_parser.HttpParser.feed_eof\naiohttp.http_exceptions.TransferEncodingError: 400, message:\n  Not enough data for satisfy transfer length header.\n\nThe above exception was the direct cause of the following exception:\n\nTraceback (most recent call last):\n  File \"/vllm-workspace/backend_request_func.py\", line 261, in async_request_openai_completions\n    async for chunk_bytes in response.content:\n  File \"/usr/local/lib/python3.10/dist-packages/aiohttp/streams.py\", line 50, in __anext__\n    rv = await self.read_func()\n  File \"/usr/local/lib/python3.10/dist-packages/aiohttp/streams.py\", line 317, in readline\n    return await self.readuntil()\n  File \"/usr/local/lib/python3.10/dist-packages/aiohttp/streams.py\", line 351, in readuntil\n    await self._wait(\"readuntil\")\n  File \"/usr/local/lib/python3.10/dist-packages/aiohttp/streams.py\", line 312, in _wait\n    await waiter\naiohttp.client_exceptions.ClientPayloadError: Response payload is not completed: <TransferEncodingError: 400, message='Not enough data for satisfy transfer length header.'>\n", "Traceback (most recent call last):\n  File \"/usr/local/lib/python3.10/dist-packages/aiohttp/client_proto.py\", line 94, in connection_lost\n    uncompleted = self._parser.feed_eof()\n  File \"aiohttp/_http_parser.pyx\", line 513, in aiohttp._http_parser.HttpParser.feed_eof\naiohttp.http_exceptions.TransferEncodingError: 400, message:\n  Not enough data for satisfy transfer length header.\n\nThe above exception was the direct cause of the following exception:\n\nTraceback (most recent call last):\n  File \"/vllm-workspace/backend_request_func.py\", line 261, in async_request_openai_completions\n    async for chunk_bytes in response.content:\n  File \"/usr/local/lib/python3.10/dist-packages/aiohttp/streams.py\", line 50, in __anext__\n    rv = await self.read_func()\n  File \"/usr/local/lib/python3.10/dist-packages/aiohttp/streams.py\", line 317, in readline\n    return await self.readuntil()\n  File \"/usr/local/lib/python3.10/dist-packages/aiohttp/streams.py\", line 351, in readuntil\n    await self._wait(\"readuntil\")\n  File \"/usr/local/lib/python3.10/dist-packages/aiohttp/streams.py\", line 312, in _wait\n    await waiter\naiohttp.client_exceptions.ClientPayloadError: Response payload is not completed: <TransferEncodingError: 400, message='Not enough data for satisfy transfer length header.'>\n", "Traceback (most recent call last):\n  File \"/usr/local/lib/python3.10/dist-packages/aiohttp/client_proto.py\", line 94, in connection_lost\n    uncompleted = self._parser.feed_eof()\n  File \"aiohttp/_http_parser.pyx\", line 513, in aiohttp._http_parser.HttpParser.feed_eof\naiohttp.http_exceptions.TransferEncodingError: 400, message:\n  Not enough data for satisfy transfer length header.\n\nThe above exception was the direct cause of the following exception:\n\nTraceback (most recent call last):\n  File \"/vllm-workspace/backend_request_func.py\", line 261, in async_request_openai_completions\n    async for chunk_bytes in response.content:\n  File \"/usr/local/lib/python3.10/dist-packages/aiohttp/streams.py\", line 50, in __anext__\n    rv = await self.read_func()\n  File \"/usr/local/lib/python3.10/dist-packages/aiohttp/streams.py\", line 317, in readline\n    return await self.readuntil()\n  File \"/usr/local/lib/python3.10/dist-packages/aiohttp/streams.py\", line 351, in readuntil\n    await self._wait(\"readuntil\")\n  File \"/usr/local/lib/python3.10/dist-packages/aiohttp/streams.py\", line 312, in _wait\n    await waiter\naiohttp.client_exceptions.ClientPayloadError: Response payload is not completed: <TransferEncodingError: 400, message='Not enough data for satisfy transfer length header.'>\n", "Traceback (most recent call last):\n  File \"/usr/local/lib/python3.10/dist-packages/aiohttp/client_proto.py\", line 94, in connection_lost\n    uncompleted = self._parser.feed_eof()\n  File \"aiohttp/_http_parser.pyx\", line 513, in aiohttp._http_parser.HttpParser.feed_eof\naiohttp.http_exceptions.TransferEncodingError: 400, message:\n  Not enough data for satisfy transfer length header.\n\nThe above exception was the direct cause of the following exception:\n\nTraceback (most recent call last):\n  File \"/vllm-workspace/backend_request_func.py\", line 261, in async_request_openai_completions\n    async for chunk_bytes in response.content:\n  File \"/usr/local/lib/python3.10/dist-packages/aiohttp/streams.py\", line 50, in __anext__\n    rv = await self.read_func()\n  File \"/usr/local/lib/python3.10/dist-packages/aiohttp/streams.py\", line 317, in readline\n    return await self.readuntil()\n  File \"/usr/local/lib/python3.10/dist-packages/aiohttp/streams.py\", line 351, in readuntil\n    await self._wait(\"readuntil\")\n  File \"/usr/local/lib/python3.10/dist-packages/aiohttp/streams.py\", line 312, in _wait\n    await waiter\naiohttp.client_exceptions.ClientPayloadError: Response payload is not completed: <TransferEncodingError: 400, message='Not enough data for satisfy transfer length header.'>\n", "Traceback (most recent call last):\n  File \"/usr/local/lib/python3.10/dist-packages/aiohttp/client_proto.py\", line 94, in connection_lost\n    uncompleted = self._parser.feed_eof()\n  File \"aiohttp/_http_parser.pyx\", line 513, in aiohttp._http_parser.HttpParser.feed_eof\naiohttp.http_exceptions.TransferEncodingError: 400, message:\n  Not enough data for satisfy transfer length header.\n\nThe above exception was the direct cause of the following exception:\n\nTraceback (most recent call last):\n  File \"/vllm-workspace/backend_request_func.py\", line 261, in async_request_openai_completions\n    async for chunk_bytes in response.content:\n  File \"/usr/local/lib/python3.10/dist-packages/aiohttp/streams.py\", line 50, in __anext__\n    rv = await self.read_func()\n  File \"/usr/local/lib/python3.10/dist-packages/aiohttp/streams.py\", line 317, in readline\n    return await self.readuntil()\n  File \"/usr/local/lib/python3.10/dist-packages/aiohttp/streams.py\", line 351, in readuntil\n    await self._wait(\"readuntil\")\n  File \"/usr/local/lib/python3.10/dist-packages/aiohttp/streams.py\", line 312, in _wait\n    await waiter\naiohttp.client_exceptions.ClientPayloadError: Response payload is not completed: <TransferEncodingError: 400, message='Not enough data for satisfy transfer length header.'>\n", "Traceback (most recent call last):\n  File \"/usr/local/lib/python3.10/dist-packages/aiohttp/client_proto.py\", line 94, in connection_lost\n    uncompleted = self._parser.feed_eof()\n  File \"aiohttp/_http_parser.pyx\", line 513, in aiohttp._http_parser.HttpParser.feed_eof\naiohttp.http_exceptions.TransferEncodingError: 400, message:\n  Not enough data for satisfy transfer length header.\n\nThe above exception was the direct cause of the following exception:\n\nTraceback (most recent call last):\n  File \"/vllm-workspace/backend_request_func.py\", line 261, in async_request_openai_completions\n    async for chunk_bytes in response.content:\n  File \"/usr/local/lib/python3.10/dist-packages/aiohttp/streams.py\", line 50, in __anext__\n    rv = await self.read_func()\n  File \"/usr/local/lib/python3.10/dist-packages/aiohttp/streams.py\", line 317, in readline\n    return await self.readuntil()\n  File \"/usr/local/lib/python3.10/dist-packages/aiohttp/streams.py\", line 351, in readuntil\n    await self._wait(\"readuntil\")\n  File \"/usr/local/lib/python3.10/dist-packages/aiohttp/streams.py\", line 312, in _wait\n    await waiter\naiohttp.client_exceptions.ClientPayloadError: Response payload is not completed: <TransferEncodingError: 400, message='Not enough data for satisfy transfer length header.'>\n", "Traceback (most recent call last):\n  File \"/usr/local/lib/python3.10/dist-packages/aiohttp/client_proto.py\", line 94, in connection_lost\n    uncompleted = self._parser.feed_eof()\n  File \"aiohttp/_http_parser.pyx\", line 513, in aiohttp._http_parser.HttpParser.feed_eof\naiohttp.http_exceptions.TransferEncodingError: 400, message:\n  Not enough data for satisfy transfer length header.\n\nThe above exception was the direct cause of the following exception:\n\nTraceback (most recent call last):\n  File \"/vllm-workspace/backend_request_func.py\", line 261, in async_request_openai_completions\n    async for chunk_bytes in response.content:\n  File \"/usr/local/lib/python3.10/dist-packages/aiohttp/streams.py\", line 50, in __anext__\n    rv = await self.read_func()\n  File \"/usr/local/lib/python3.10/dist-packages/aiohttp/streams.py\", line 317, in readline\n    return await self.readuntil()\n  File \"/usr/local/lib/python3.10/dist-packages/aiohttp/streams.py\", line 351, in readuntil\n    await self._wait(\"readuntil\")\n  File \"/usr/local/lib/python3.10/dist-packages/aiohttp/streams.py\", line 312, in _wait\n    await waiter\naiohttp.client_exceptions.ClientPayloadError: Response payload is not completed: <TransferEncodingError: 400, message='Not enough data for satisfy transfer length header.'>\n", "Traceback (most recent call last):\n  File \"/usr/local/lib/python3.10/dist-packages/aiohttp/client_proto.py\", line 94, in connection_lost\n    uncompleted = self._parser.feed_eof()\n  File \"aiohttp/_http_parser.pyx\", line 513, in aiohttp._http_parser.HttpParser.feed_eof\naiohttp.http_exceptions.TransferEncodingError: 400, message:\n  Not enough data for satisfy transfer length header.\n\nThe above exception was the direct cause of the following exception:\n\nTraceback (most recent call last):\n  File \"/vllm-workspace/backend_request_func.py\", line 261, in async_request_openai_completions\n    async for chunk_bytes in response.content:\n  File \"/usr/local/lib/python3.10/dist-packages/aiohttp/streams.py\", line 50, in __anext__\n    rv = await self.read_func()\n  File \"/usr/local/lib/python3.10/dist-packages/aiohttp/streams.py\", line 317, in readline\n    return await self.readuntil()\n  File \"/usr/local/lib/python3.10/dist-packages/aiohttp/streams.py\", line 351, in readuntil\n    await self._wait(\"readuntil\")\n  File \"/usr/local/lib/python3.10/dist-packages/aiohttp/streams.py\", line 312, in _wait\n    await waiter\naiohttp.client_exceptions.ClientPayloadError: Response payload is not completed: <TransferEncodingError: 400, message='Not enough data for satisfy transfer length header.'>\n", "Traceback (most recent call last):\n  File \"/usr/local/lib/python3.10/dist-packages/aiohttp/client_proto.py\", line 94, in connection_lost\n    uncompleted = self._parser.feed_eof()\n  File \"aiohttp/_http_parser.pyx\", line 513, in aiohttp._http_parser.HttpParser.feed_eof\naiohttp.http_exceptions.TransferEncodingError: 400, message:\n  Not enough data for satisfy transfer length header.\n\nThe above exception was the direct cause of the following exception:\n\nTraceback (most recent call last):\n  File \"/vllm-workspace/backend_request_func.py\", line 261, in async_request_openai_completions\n    async for chunk_bytes in response.content:\n  File \"/usr/local/lib/python3.10/dist-packages/aiohttp/streams.py\", line 50, in __anext__\n    rv = await self.read_func()\n  File \"/usr/local/lib/python3.10/dist-packages/aiohttp/streams.py\", line 317, in readline\n    return await self.readuntil()\n  File \"/usr/local/lib/python3.10/dist-packages/aiohttp/streams.py\", line 351, in readuntil\n    await self._wait(\"readuntil\")\n  File \"/usr/local/lib/python3.10/dist-packages/aiohttp/streams.py\", line 312, in _wait\n    await waiter\naiohttp.client_exceptions.ClientPayloadError: Response payload is not completed: <TransferEncodingError: 400, message='Not enough data for satisfy transfer length header.'>\n", "", "Traceback (most recent call last):\n  File \"/usr/local/lib/python3.10/dist-packages/aiohttp/client_proto.py\", line 94, in connection_lost\n    uncompleted = self._parser.feed_eof()\n  File \"aiohttp/_http_parser.pyx\", line 513, in aiohttp._http_parser.HttpParser.feed_eof\naiohttp.http_exceptions.TransferEncodingError: 400, message:\n  Not enough data for satisfy transfer length header.\n\nThe above exception was the direct cause of the following exception:\n\nTraceback (most recent call last):\n  File \"/vllm-workspace/backend_request_func.py\", line 261, in async_request_openai_completions\n    async for chunk_bytes in response.content:\n  File \"/usr/local/lib/python3.10/dist-packages/aiohttp/streams.py\", line 50, in __anext__\n    rv = await self.read_func()\n  File \"/usr/local/lib/python3.10/dist-packages/aiohttp/streams.py\", line 317, in readline\n    return await self.readuntil()\n  File \"/usr/local/lib/python3.10/dist-packages/aiohttp/streams.py\", line 351, in readuntil\n    await self._wait(\"readuntil\")\n  File \"/usr/local/lib/python3.10/dist-packages/aiohttp/streams.py\", line 312, in _wait\n    await waiter\naiohttp.client_exceptions.ClientPayloadError: Response payload is not completed: <TransferEncodingError: 400, message='Not enough data for satisfy transfer length header.'>\n", "Traceback (most recent call last):\n  File \"/usr/local/lib/python3.10/dist-packages/aiohttp/client_proto.py\", line 94, in connection_lost\n    uncompleted = self._parser.feed_eof()\n  File \"aiohttp/_http_parser.pyx\", line 513, in aiohttp._http_parser.HttpParser.feed_eof\naiohttp.http_exceptions.TransferEncodingError: 400, message:\n  Not enough data for satisfy transfer length header.\n\nThe above exception was the direct cause of the following exception:\n\nTraceback (most recent call last):\n  File \"/vllm-workspace/backend_request_func.py\", line 261, in async_request_openai_completions\n    async for chunk_bytes in response.content:\n  File \"/usr/local/lib/python3.10/dist-packages/aiohttp/streams.py\", line 50, in __anext__\n    rv = await self.read_func()\n  File \"/usr/local/lib/python3.10/dist-packages/aiohttp/streams.py\", line 317, in readline\n    return await self.readuntil()\n  File \"/usr/local/lib/python3.10/dist-packages/aiohttp/streams.py\", line 351, in readuntil\n    await self._wait(\"readuntil\")\n  File \"/usr/local/lib/python3.10/dist-packages/aiohttp/streams.py\", line 312, in _wait\n    await waiter\naiohttp.client_exceptions.ClientPayloadError: Response payload is not completed: <TransferEncodingError: 400, message='Not enough data for satisfy transfer length header.'>\n", "Traceback (most recent call last):\n  File \"/usr/local/lib/python3.10/dist-packages/aiohttp/client_proto.py\", line 94, in connection_lost\n    uncompleted = self._parser.feed_eof()\n  File \"aiohttp/_http_parser.pyx\", line 513, in aiohttp._http_parser.HttpParser.feed_eof\naiohttp.http_exceptions.TransferEncodingError: 400, message:\n  Not enough data for satisfy transfer length header.\n\nThe above exception was the direct cause of the following exception:\n\nTraceback (most recent call last):\n  File \"/vllm-workspace/backend_request_func.py\", line 261, in async_request_openai_completions\n    async for chunk_bytes in response.content:\n  File \"/usr/local/lib/python3.10/dist-packages/aiohttp/streams.py\", line 50, in __anext__\n    rv = await self.read_func()\n  File \"/usr/local/lib/python3.10/dist-packages/aiohttp/streams.py\", line 317, in readline\n    return await self.readuntil()\n  File \"/usr/local/lib/python3.10/dist-packages/aiohttp/streams.py\", line 351, in readuntil\n    await self._wait(\"readuntil\")\n  File \"/usr/local/lib/python3.10/dist-packages/aiohttp/streams.py\", line 312, in _wait\n    await waiter\naiohttp.client_exceptions.ClientPayloadError: Response payload is not completed: <TransferEncodingError: 400, message='Not enough data for satisfy transfer length header.'>\n", "Traceback (most recent call last):\n  File \"/usr/local/lib/python3.10/dist-packages/aiohttp/client_proto.py\", line 94, in connection_lost\n    uncompleted = self._parser.feed_eof()\n  File \"aiohttp/_http_parser.pyx\", line 513, in aiohttp._http_parser.HttpParser.feed_eof\naiohttp.http_exceptions.TransferEncodingError: 400, message:\n  Not enough data for satisfy transfer length header.\n\nThe above exception was the direct cause of the following exception:\n\nTraceback (most recent call last):\n  File \"/vllm-workspace/backend_request_func.py\", line 261, in async_request_openai_completions\n    async for chunk_bytes in response.content:\n  File \"/usr/local/lib/python3.10/dist-packages/aiohttp/streams.py\", line 50, in __anext__\n    rv = await self.read_func()\n  File \"/usr/local/lib/python3.10/dist-packages/aiohttp/streams.py\", line 317, in readline\n    return await self.readuntil()\n  File \"/usr/local/lib/python3.10/dist-packages/aiohttp/streams.py\", line 351, in readuntil\n    await self._wait(\"readuntil\")\n  File \"/usr/local/lib/python3.10/dist-packages/aiohttp/streams.py\", line 312, in _wait\n    await waiter\naiohttp.client_exceptions.ClientPayloadError: Response payload is not completed: <TransferEncodingError: 400, message='Not enough data for satisfy transfer length header.'>\n", "Traceback (most recent call last):\n  File \"/usr/local/lib/python3.10/dist-packages/aiohttp/client_proto.py\", line 94, in connection_lost\n    uncompleted = self._parser.feed_eof()\n  File \"aiohttp/_http_parser.pyx\", line 513, in aiohttp._http_parser.HttpParser.feed_eof\naiohttp.http_exceptions.TransferEncodingError: 400, message:\n  Not enough data for satisfy transfer length header.\n\nThe above exception was the direct cause of the following exception:\n\nTraceback (most recent call last):\n  File \"/vllm-workspace/backend_request_func.py\", line 261, in async_request_openai_completions\n    async for chunk_bytes in response.content:\n  File \"/usr/local/lib/python3.10/dist-packages/aiohttp/streams.py\", line 50, in __anext__\n    rv = await self.read_func()\n  File \"/usr/local/lib/python3.10/dist-packages/aiohttp/streams.py\", line 317, in readline\n    return await self.readuntil()\n  File \"/usr/local/lib/python3.10/dist-packages/aiohttp/streams.py\", line 351, in readuntil\n    await self._wait(\"readuntil\")\n  File \"/usr/local/lib/python3.10/dist-packages/aiohttp/streams.py\", line 312, in _wait\n    await waiter\naiohttp.client_exceptions.ClientPayloadError: Response payload is not completed: <TransferEncodingError: 400, message='Not enough data for satisfy transfer length header.'>\n", "Traceback (most recent call last):\n  File \"/usr/local/lib/python3.10/dist-packages/aiohttp/client_proto.py\", line 94, in connection_lost\n    uncompleted = self._parser.feed_eof()\n  File \"aiohttp/_http_parser.pyx\", line 513, in aiohttp._http_parser.HttpParser.feed_eof\naiohttp.http_exceptions.TransferEncodingError: 400, message:\n  Not enough data for satisfy transfer length header.\n\nThe above exception was the direct cause of the following exception:\n\nTraceback (most recent call last):\n  File \"/vllm-workspace/backend_request_func.py\", line 261, in async_request_openai_completions\n    async for chunk_bytes in response.content:\n  File \"/usr/local/lib/python3.10/dist-packages/aiohttp/streams.py\", line 50, in __anext__\n    rv = await self.read_func()\n  File \"/usr/local/lib/python3.10/dist-packages/aiohttp/streams.py\", line 317, in readline\n    return await self.readuntil()\n  File \"/usr/local/lib/python3.10/dist-packages/aiohttp/streams.py\", line 351, in readuntil\n    await self._wait(\"readuntil\")\n  File \"/usr/local/lib/python3.10/dist-packages/aiohttp/streams.py\", line 312, in _wait\n    await waiter\naiohttp.client_exceptions.ClientPayloadError: Response payload is not completed: <TransferEncodingError: 400, message='Not enough data for satisfy transfer length header.'>\n", "Traceback (most recent call last):\n  File \"/usr/local/lib/python3.10/dist-packages/aiohttp/client_proto.py\", line 94, in connection_lost\n    uncompleted = self._parser.feed_eof()\n  File \"aiohttp/_http_parser.pyx\", line 513, in aiohttp._http_parser.HttpParser.feed_eof\naiohttp.http_exceptions.TransferEncodingError: 400, message:\n  Not enough data for satisfy transfer length header.\n\nThe above exception was the direct cause of the following exception:\n\nTraceback (most recent call last):\n  File \"/vllm-workspace/backend_request_func.py\", line 261, in async_request_openai_completions\n    async for chunk_bytes in response.content:\n  File \"/usr/local/lib/python3.10/dist-packages/aiohttp/streams.py\", line 50, in __anext__\n    rv = await self.read_func()\n  File \"/usr/local/lib/python3.10/dist-packages/aiohttp/streams.py\", line 317, in readline\n    return await self.readuntil()\n  File \"/usr/local/lib/python3.10/dist-packages/aiohttp/streams.py\", line 351, in readuntil\n    await self._wait(\"readuntil\")\n  File \"/usr/local/lib/python3.10/dist-packages/aiohttp/streams.py\", line 312, in _wait\n    await waiter\naiohttp.client_exceptions.ClientPayloadError: Response payload is not completed: <TransferEncodingError: 400, message='Not enough data for satisfy transfer length header.'>\n", "Traceback (most recent call last):\n  File \"/usr/local/lib/python3.10/dist-packages/aiohttp/client_proto.py\", line 94, in connection_lost\n    uncompleted = self._parser.feed_eof()\n  File \"aiohttp/_http_parser.pyx\", line 513, in aiohttp._http_parser.HttpParser.feed_eof\naiohttp.http_exceptions.TransferEncodingError: 400, message:\n  Not enough data for satisfy transfer length header.\n\nThe above exception was the direct cause of the following exception:\n\nTraceback (most recent call last):\n  File \"/vllm-workspace/backend_request_func.py\", line 261, in async_request_openai_completions\n    async for chunk_bytes in response.content:\n  File \"/usr/local/lib/python3.10/dist-packages/aiohttp/streams.py\", line 50, in __anext__\n    rv = await self.read_func()\n  File \"/usr/local/lib/python3.10/dist-packages/aiohttp/streams.py\", line 317, in readline\n    return await self.readuntil()\n  File \"/usr/local/lib/python3.10/dist-packages/aiohttp/streams.py\", line 351, in readuntil\n    await self._wait(\"readuntil\")\n  File \"/usr/local/lib/python3.10/dist-packages/aiohttp/streams.py\", line 312, in _wait\n    await waiter\naiohttp.client_exceptions.ClientPayloadError: Response payload is not completed: <TransferEncodingError: 400, message='Not enough data for satisfy transfer length header.'>\n", "Traceback (most recent call last):\n  File \"/usr/local/lib/python3.10/dist-packages/aiohttp/client_proto.py\", line 94, in connection_lost\n    uncompleted = self._parser.feed_eof()\n  File \"aiohttp/_http_parser.pyx\", line 513, in aiohttp._http_parser.HttpParser.feed_eof\naiohttp.http_exceptions.TransferEncodingError: 400, message:\n  Not enough data for satisfy transfer length header.\n\nThe above exception was the direct cause of the following exception:\n\nTraceback (most recent call last):\n  File \"/vllm-workspace/backend_request_func.py\", line 261, in async_request_openai_completions\n    async for chunk_bytes in response.content:\n  File \"/usr/local/lib/python3.10/dist-packages/aiohttp/streams.py\", line 50, in __anext__\n    rv = await self.read_func()\n  File \"/usr/local/lib/python3.10/dist-packages/aiohttp/streams.py\", line 317, in readline\n    return await self.readuntil()\n  File \"/usr/local/lib/python3.10/dist-packages/aiohttp/streams.py\", line 351, in readuntil\n    await self._wait(\"readuntil\")\n  File \"/usr/local/lib/python3.10/dist-packages/aiohttp/streams.py\", line 312, in _wait\n    await waiter\naiohttp.client_exceptions.ClientPayloadError: Response payload is not completed: <TransferEncodingError: 400, message='Not enough data for satisfy transfer length header.'>\n", "Traceback (most recent call last):\n  File \"/usr/local/lib/python3.10/dist-packages/aiohttp/client_proto.py\", line 94, in connection_lost\n    uncompleted = self._parser.feed_eof()\n  File \"aiohttp/_http_parser.pyx\", line 513, in aiohttp._http_parser.HttpParser.feed_eof\naiohttp.http_exceptions.TransferEncodingError: 400, message:\n  Not enough data for satisfy transfer length header.\n\nThe above exception was the direct cause of the following exception:\n\nTraceback (most recent call last):\n  File \"/vllm-workspace/backend_request_func.py\", line 261, in async_request_openai_completions\n    async for chunk_bytes in response.content:\n  File \"/usr/local/lib/python3.10/dist-packages/aiohttp/streams.py\", line 50, in __anext__\n    rv = await self.read_func()\n  File \"/usr/local/lib/python3.10/dist-packages/aiohttp/streams.py\", line 317, in readline\n    return await self.readuntil()\n  File \"/usr/local/lib/python3.10/dist-packages/aiohttp/streams.py\", line 351, in readuntil\n    await self._wait(\"readuntil\")\n  File \"/usr/local/lib/python3.10/dist-packages/aiohttp/streams.py\", line 312, in _wait\n    await waiter\naiohttp.client_exceptions.ClientPayloadError: Response payload is not completed: <TransferEncodingError: 400, message='Not enough data for satisfy transfer length header.'>\n", "Traceback (most recent call last):\n  File \"/usr/local/lib/python3.10/dist-packages/aiohttp/client_proto.py\", line 94, in connection_lost\n    uncompleted = self._parser.feed_eof()\n  File \"aiohttp/_http_parser.pyx\", line 513, in aiohttp._http_parser.HttpParser.feed_eof\naiohttp.http_exceptions.TransferEncodingError: 400, message:\n  Not enough data for satisfy transfer length header.\n\nThe above exception was the direct cause of the following exception:\n\nTraceback (most recent call last):\n  File \"/vllm-workspace/backend_request_func.py\", line 261, in async_request_openai_completions\n    async for chunk_bytes in response.content:\n  File \"/usr/local/lib/python3.10/dist-packages/aiohttp/streams.py\", line 50, in __anext__\n    rv = await self.read_func()\n  File \"/usr/local/lib/python3.10/dist-packages/aiohttp/streams.py\", line 317, in readline\n    return await self.readuntil()\n  File \"/usr/local/lib/python3.10/dist-packages/aiohttp/streams.py\", line 351, in readuntil\n    await self._wait(\"readuntil\")\n  File \"/usr/local/lib/python3.10/dist-packages/aiohttp/streams.py\", line 312, in _wait\n    await waiter\naiohttp.client_exceptions.ClientPayloadError: Response payload is not completed: <TransferEncodingError: 400, message='Not enough data for satisfy transfer length header.'>\n", "Traceback (most recent call last):\n  File \"/usr/local/lib/python3.10/dist-packages/aiohttp/client_proto.py\", line 94, in connection_lost\n    uncompleted = self._parser.feed_eof()\n  File \"aiohttp/_http_parser.pyx\", line 513, in aiohttp._http_parser.HttpParser.feed_eof\naiohttp.http_exceptions.TransferEncodingError: 400, message:\n  Not enough data for satisfy transfer length header.\n\nThe above exception was the direct cause of the following exception:\n\nTraceback (most recent call last):\n  File \"/vllm-workspace/backend_request_func.py\", line 261, in async_request_openai_completions\n    async for chunk_bytes in response.content:\n  File \"/usr/local/lib/python3.10/dist-packages/aiohttp/streams.py\", line 50, in __anext__\n    rv = await self.read_func()\n  File \"/usr/local/lib/python3.10/dist-packages/aiohttp/streams.py\", line 317, in readline\n    return await self.readuntil()\n  File \"/usr/local/lib/python3.10/dist-packages/aiohttp/streams.py\", line 351, in readuntil\n    await self._wait(\"readuntil\")\n  File \"/usr/local/lib/python3.10/dist-packages/aiohttp/streams.py\", line 312, in _wait\n    await waiter\naiohttp.client_exceptions.ClientPayloadError: Response payload is not completed: <TransferEncodingError: 400, message='Not enough data for satisfy transfer length header.'>\n", "Traceback (most recent call last):\n  File \"/usr/local/lib/python3.10/dist-packages/aiohttp/client_proto.py\", line 94, in connection_lost\n    uncompleted = self._parser.feed_eof()\n  File \"aiohttp/_http_parser.pyx\", line 513, in aiohttp._http_parser.HttpParser.feed_eof\naiohttp.http_exceptions.TransferEncodingError: 400, message:\n  Not enough data for satisfy transfer length header.\n\nThe above exception was the direct cause of the following exception:\n\nTraceback (most recent call last):\n  File \"/vllm-workspace/backend_request_func.py\", line 261, in async_request_openai_completions\n    async for chunk_bytes in response.content:\n  File \"/usr/local/lib/python3.10/dist-packages/aiohttp/streams.py\", line 50, in __anext__\n    rv = await self.read_func()\n  File \"/usr/local/lib/python3.10/dist-packages/aiohttp/streams.py\", line 317, in readline\n    return await self.readuntil()\n  File \"/usr/local/lib/python3.10/dist-packages/aiohttp/streams.py\", line 351, in readuntil\n    await self._wait(\"readuntil\")\n  File \"/usr/local/lib/python3.10/dist-packages/aiohttp/streams.py\", line 312, in _wait\n    await waiter\naiohttp.client_exceptions.ClientPayloadError: Response payload is not completed: <TransferEncodingError: 400, message='Not enough data for satisfy transfer length header.'>\n", "Traceback (most recent call last):\n  File \"/usr/local/lib/python3.10/dist-packages/aiohttp/client_proto.py\", line 94, in connection_lost\n    uncompleted = self._parser.feed_eof()\n  File \"aiohttp/_http_parser.pyx\", line 513, in aiohttp._http_parser.HttpParser.feed_eof\naiohttp.http_exceptions.TransferEncodingError: 400, message:\n  Not enough data for satisfy transfer length header.\n\nThe above exception was the direct cause of the following exception:\n\nTraceback (most recent call last):\n  File \"/vllm-workspace/backend_request_func.py\", line 261, in async_request_openai_completions\n    async for chunk_bytes in response.content:\n  File \"/usr/local/lib/python3.10/dist-packages/aiohttp/streams.py\", line 50, in __anext__\n    rv = await self.read_func()\n  File \"/usr/local/lib/python3.10/dist-packages/aiohttp/streams.py\", line 317, in readline\n    return await self.readuntil()\n  File \"/usr/local/lib/python3.10/dist-packages/aiohttp/streams.py\", line 351, in readuntil\n    await self._wait(\"readuntil\")\n  File \"/usr/local/lib/python3.10/dist-packages/aiohttp/streams.py\", line 312, in _wait\n    await waiter\naiohttp.client_exceptions.ClientPayloadError: Response payload is not completed: <TransferEncodingError: 400, message='Not enough data for satisfy transfer length header.'>\n", "Traceback (most recent call last):\n  File \"/usr/local/lib/python3.10/dist-packages/aiohttp/client_proto.py\", line 94, in connection_lost\n    uncompleted = self._parser.feed_eof()\n  File \"aiohttp/_http_parser.pyx\", line 513, in aiohttp._http_parser.HttpParser.feed_eof\naiohttp.http_exceptions.TransferEncodingError: 400, message:\n  Not enough data for satisfy transfer length header.\n\nThe above exception was the direct cause of the following exception:\n\nTraceback (most recent call last):\n  File \"/vllm-workspace/backend_request_func.py\", line 261, in async_request_openai_completions\n    async for chunk_bytes in response.content:\n  File \"/usr/local/lib/python3.10/dist-packages/aiohttp/streams.py\", line 50, in __anext__\n    rv = await self.read_func()\n  File \"/usr/local/lib/python3.10/dist-packages/aiohttp/streams.py\", line 317, in readline\n    return await self.readuntil()\n  File \"/usr/local/lib/python3.10/dist-packages/aiohttp/streams.py\", line 351, in readuntil\n    await self._wait(\"readuntil\")\n  File \"/usr/local/lib/python3.10/dist-packages/aiohttp/streams.py\", line 312, in _wait\n    await waiter\naiohttp.client_exceptions.ClientPayloadError: Response payload is not completed: <TransferEncodingError: 400, message='Not enough data for satisfy transfer length header.'>\n", "Traceback (most recent call last):\n  File \"/usr/local/lib/python3.10/dist-packages/aiohttp/client_proto.py\", line 94, in connection_lost\n    uncompleted = self._parser.feed_eof()\n  File \"aiohttp/_http_parser.pyx\", line 513, in aiohttp._http_parser.HttpParser.feed_eof\naiohttp.http_exceptions.TransferEncodingError: 400, message:\n  Not enough data for satisfy transfer length header.\n\nThe above exception was the direct cause of the following exception:\n\nTraceback (most recent call last):\n  File \"/vllm-workspace/backend_request_func.py\", line 261, in async_request_openai_completions\n    async for chunk_bytes in response.content:\n  File \"/usr/local/lib/python3.10/dist-packages/aiohttp/streams.py\", line 50, in __anext__\n    rv = await self.read_func()\n  File \"/usr/local/lib/python3.10/dist-packages/aiohttp/streams.py\", line 317, in readline\n    return await self.readuntil()\n  File \"/usr/local/lib/python3.10/dist-packages/aiohttp/streams.py\", line 351, in readuntil\n    await self._wait(\"readuntil\")\n  File \"/usr/local/lib/python3.10/dist-packages/aiohttp/streams.py\", line 312, in _wait\n    await waiter\naiohttp.client_exceptions.ClientPayloadError: Response payload is not completed: <TransferEncodingError: 400, message='Not enough data for satisfy transfer length header.'>\n", "", "", "Traceback (most recent call last):\n  File \"/usr/local/lib/python3.10/dist-packages/aiohttp/client_proto.py\", line 94, in connection_lost\n    uncompleted = self._parser.feed_eof()\n  File \"aiohttp/_http_parser.pyx\", line 513, in aiohttp._http_parser.HttpParser.feed_eof\naiohttp.http_exceptions.TransferEncodingError: 400, message:\n  Not enough data for satisfy transfer length header.\n\nThe above exception was the direct cause of the following exception:\n\nTraceback (most recent call last):\n  File \"/vllm-workspace/backend_request_func.py\", line 261, in async_request_openai_completions\n    async for chunk_bytes in response.content:\n  File \"/usr/local/lib/python3.10/dist-packages/aiohttp/streams.py\", line 50, in __anext__\n    rv = await self.read_func()\n  File \"/usr/local/lib/python3.10/dist-packages/aiohttp/streams.py\", line 317, in readline\n    return await self.readuntil()\n  File \"/usr/local/lib/python3.10/dist-packages/aiohttp/streams.py\", line 351, in readuntil\n    await self._wait(\"readuntil\")\n  File \"/usr/local/lib/python3.10/dist-packages/aiohttp/streams.py\", line 312, in _wait\n    await waiter\naiohttp.client_exceptions.ClientPayloadError: Response payload is not completed: <TransferEncodingError: 400, message='Not enough data for satisfy transfer length header.'>\n", "Traceback (most recent call last):\n  File \"/usr/local/lib/python3.10/dist-packages/aiohttp/client_proto.py\", line 94, in connection_lost\n    uncompleted = self._parser.feed_eof()\n  File \"aiohttp/_http_parser.pyx\", line 513, in aiohttp._http_parser.HttpParser.feed_eof\naiohttp.http_exceptions.TransferEncodingError: 400, message:\n  Not enough data for satisfy transfer length header.\n\nThe above exception was the direct cause of the following exception:\n\nTraceback (most recent call last):\n  File \"/vllm-workspace/backend_request_func.py\", line 261, in async_request_openai_completions\n    async for chunk_bytes in response.content:\n  File \"/usr/local/lib/python3.10/dist-packages/aiohttp/streams.py\", line 50, in __anext__\n    rv = await self.read_func()\n  File \"/usr/local/lib/python3.10/dist-packages/aiohttp/streams.py\", line 317, in readline\n    return await self.readuntil()\n  File \"/usr/local/lib/python3.10/dist-packages/aiohttp/streams.py\", line 351, in readuntil\n    await self._wait(\"readuntil\")\n  File \"/usr/local/lib/python3.10/dist-packages/aiohttp/streams.py\", line 312, in _wait\n    await waiter\naiohttp.client_exceptions.ClientPayloadError: Response payload is not completed: <TransferEncodingError: 400, message='Not enough data for satisfy transfer length header.'>\n", "Traceback (most recent call last):\n  File \"/usr/local/lib/python3.10/dist-packages/aiohttp/client_proto.py\", line 94, in connection_lost\n    uncompleted = self._parser.feed_eof()\n  File \"aiohttp/_http_parser.pyx\", line 513, in aiohttp._http_parser.HttpParser.feed_eof\naiohttp.http_exceptions.TransferEncodingError: 400, message:\n  Not enough data for satisfy transfer length header.\n\nThe above exception was the direct cause of the following exception:\n\nTraceback (most recent call last):\n  File \"/vllm-workspace/backend_request_func.py\", line 261, in async_request_openai_completions\n    async for chunk_bytes in response.content:\n  File \"/usr/local/lib/python3.10/dist-packages/aiohttp/streams.py\", line 50, in __anext__\n    rv = await self.read_func()\n  File \"/usr/local/lib/python3.10/dist-packages/aiohttp/streams.py\", line 317, in readline\n    return await self.readuntil()\n  File \"/usr/local/lib/python3.10/dist-packages/aiohttp/streams.py\", line 351, in readuntil\n    await self._wait(\"readuntil\")\n  File \"/usr/local/lib/python3.10/dist-packages/aiohttp/streams.py\", line 312, in _wait\n    await waiter\naiohttp.client_exceptions.ClientPayloadError: Response payload is not completed: <TransferEncodingError: 400, message='Not enough data for satisfy transfer length header.'>\n", "Traceback (most recent call last):\n  File \"/usr/local/lib/python3.10/dist-packages/aiohttp/client_proto.py\", line 94, in connection_lost\n    uncompleted = self._parser.feed_eof()\n  File \"aiohttp/_http_parser.pyx\", line 513, in aiohttp._http_parser.HttpParser.feed_eof\naiohttp.http_exceptions.TransferEncodingError: 400, message:\n  Not enough data for satisfy transfer length header.\n\nThe above exception was the direct cause of the following exception:\n\nTraceback (most recent call last):\n  File \"/vllm-workspace/backend_request_func.py\", line 261, in async_request_openai_completions\n    async for chunk_bytes in response.content:\n  File \"/usr/local/lib/python3.10/dist-packages/aiohttp/streams.py\", line 50, in __anext__\n    rv = await self.read_func()\n  File \"/usr/local/lib/python3.10/dist-packages/aiohttp/streams.py\", line 317, in readline\n    return await self.readuntil()\n  File \"/usr/local/lib/python3.10/dist-packages/aiohttp/streams.py\", line 351, in readuntil\n    await self._wait(\"readuntil\")\n  File \"/usr/local/lib/python3.10/dist-packages/aiohttp/streams.py\", line 312, in _wait\n    await waiter\naiohttp.client_exceptions.ClientPayloadError: Response payload is not completed: <TransferEncodingError: 400, message='Not enough data for satisfy transfer length header.'>\n", "Traceback (most recent call last):\n  File \"/usr/local/lib/python3.10/dist-packages/aiohttp/client_proto.py\", line 94, in connection_lost\n    uncompleted = self._parser.feed_eof()\n  File \"aiohttp/_http_parser.pyx\", line 513, in aiohttp._http_parser.HttpParser.feed_eof\naiohttp.http_exceptions.TransferEncodingError: 400, message:\n  Not enough data for satisfy transfer length header.\n\nThe above exception was the direct cause of the following exception:\n\nTraceback (most recent call last):\n  File \"/vllm-workspace/backend_request_func.py\", line 261, in async_request_openai_completions\n    async for chunk_bytes in response.content:\n  File \"/usr/local/lib/python3.10/dist-packages/aiohttp/streams.py\", line 50, in __anext__\n    rv = await self.read_func()\n  File \"/usr/local/lib/python3.10/dist-packages/aiohttp/streams.py\", line 317, in readline\n    return await self.readuntil()\n  File \"/usr/local/lib/python3.10/dist-packages/aiohttp/streams.py\", line 351, in readuntil\n    await self._wait(\"readuntil\")\n  File \"/usr/local/lib/python3.10/dist-packages/aiohttp/streams.py\", line 312, in _wait\n    await waiter\naiohttp.client_exceptions.ClientPayloadError: Response payload is not completed: <TransferEncodingError: 400, message='Not enough data for satisfy transfer length header.'>\n", "Traceback (most recent call last):\n  File \"/usr/local/lib/python3.10/dist-packages/aiohttp/client_proto.py\", line 94, in connection_lost\n    uncompleted = self._parser.feed_eof()\n  File \"aiohttp/_http_parser.pyx\", line 513, in aiohttp._http_parser.HttpParser.feed_eof\naiohttp.http_exceptions.TransferEncodingError: 400, message:\n  Not enough data for satisfy transfer length header.\n\nThe above exception was the direct cause of the following exception:\n\nTraceback (most recent call last):\n  File \"/vllm-workspace/backend_request_func.py\", line 261, in async_request_openai_completions\n    async for chunk_bytes in response.content:\n  File \"/usr/local/lib/python3.10/dist-packages/aiohttp/streams.py\", line 50, in __anext__\n    rv = await self.read_func()\n  File \"/usr/local/lib/python3.10/dist-packages/aiohttp/streams.py\", line 317, in readline\n    return await self.readuntil()\n  File \"/usr/local/lib/python3.10/dist-packages/aiohttp/streams.py\", line 351, in readuntil\n    await self._wait(\"readuntil\")\n  File \"/usr/local/lib/python3.10/dist-packages/aiohttp/streams.py\", line 312, in _wait\n    await waiter\naiohttp.client_exceptions.ClientPayloadError: Response payload is not completed: <TransferEncodingError: 400, message='Not enough data for satisfy transfer length header.'>\n", "Traceback (most recent call last):\n  File \"/usr/local/lib/python3.10/dist-packages/aiohttp/client_proto.py\", line 94, in connection_lost\n    uncompleted = self._parser.feed_eof()\n  File \"aiohttp/_http_parser.pyx\", line 513, in aiohttp._http_parser.HttpParser.feed_eof\naiohttp.http_exceptions.TransferEncodingError: 400, message:\n  Not enough data for satisfy transfer length header.\n\nThe above exception was the direct cause of the following exception:\n\nTraceback (most recent call last):\n  File \"/vllm-workspace/backend_request_func.py\", line 261, in async_request_openai_completions\n    async for chunk_bytes in response.content:\n  File \"/usr/local/lib/python3.10/dist-packages/aiohttp/streams.py\", line 50, in __anext__\n    rv = await self.read_func()\n  File \"/usr/local/lib/python3.10/dist-packages/aiohttp/streams.py\", line 317, in readline\n    return await self.readuntil()\n  File \"/usr/local/lib/python3.10/dist-packages/aiohttp/streams.py\", line 351, in readuntil\n    await self._wait(\"readuntil\")\n  File \"/usr/local/lib/python3.10/dist-packages/aiohttp/streams.py\", line 312, in _wait\n    await waiter\naiohttp.client_exceptions.ClientPayloadError: Response payload is not completed: <TransferEncodingError: 400, message='Not enough data for satisfy transfer length header.'>\n", "Traceback (most recent call last):\n  File \"/usr/local/lib/python3.10/dist-packages/aiohttp/client_proto.py\", line 94, in connection_lost\n    uncompleted = self._parser.feed_eof()\n  File \"aiohttp/_http_parser.pyx\", line 513, in aiohttp._http_parser.HttpParser.feed_eof\naiohttp.http_exceptions.TransferEncodingError: 400, message:\n  Not enough data for satisfy transfer length header.\n\nThe above exception was the direct cause of the following exception:\n\nTraceback (most recent call last):\n  File \"/vllm-workspace/backend_request_func.py\", line 261, in async_request_openai_completions\n    async for chunk_bytes in response.content:\n  File \"/usr/local/lib/python3.10/dist-packages/aiohttp/streams.py\", line 50, in __anext__\n    rv = await self.read_func()\n  File \"/usr/local/lib/python3.10/dist-packages/aiohttp/streams.py\", line 317, in readline\n    return await self.readuntil()\n  File \"/usr/local/lib/python3.10/dist-packages/aiohttp/streams.py\", line 351, in readuntil\n    await self._wait(\"readuntil\")\n  File \"/usr/local/lib/python3.10/dist-packages/aiohttp/streams.py\", line 312, in _wait\n    await waiter\naiohttp.client_exceptions.ClientPayloadError: Response payload is not completed: <TransferEncodingError: 400, message='Not enough data for satisfy transfer length header.'>\n", "Traceback (most recent call last):\n  File \"/usr/local/lib/python3.10/dist-packages/aiohttp/client_proto.py\", line 94, in connection_lost\n    uncompleted = self._parser.feed_eof()\n  File \"aiohttp/_http_parser.pyx\", line 513, in aiohttp._http_parser.HttpParser.feed_eof\naiohttp.http_exceptions.TransferEncodingError: 400, message:\n  Not enough data for satisfy transfer length header.\n\nThe above exception was the direct cause of the following exception:\n\nTraceback (most recent call last):\n  File \"/vllm-workspace/backend_request_func.py\", line 261, in async_request_openai_completions\n    async for chunk_bytes in response.content:\n  File \"/usr/local/lib/python3.10/dist-packages/aiohttp/streams.py\", line 50, in __anext__\n    rv = await self.read_func()\n  File \"/usr/local/lib/python3.10/dist-packages/aiohttp/streams.py\", line 317, in readline\n    return await self.readuntil()\n  File \"/usr/local/lib/python3.10/dist-packages/aiohttp/streams.py\", line 351, in readuntil\n    await self._wait(\"readuntil\")\n  File \"/usr/local/lib/python3.10/dist-packages/aiohttp/streams.py\", line 312, in _wait\n    await waiter\naiohttp.client_exceptions.ClientPayloadError: Response payload is not completed: <TransferEncodingError: 400, message='Not enough data for satisfy transfer length header.'>\n", "Traceback (most recent call last):\n  File \"/usr/local/lib/python3.10/dist-packages/aiohttp/client_proto.py\", line 94, in connection_lost\n    uncompleted = self._parser.feed_eof()\n  File \"aiohttp/_http_parser.pyx\", line 513, in aiohttp._http_parser.HttpParser.feed_eof\naiohttp.http_exceptions.TransferEncodingError: 400, message:\n  Not enough data for satisfy transfer length header.\n\nThe above exception was the direct cause of the following exception:\n\nTraceback (most recent call last):\n  File \"/vllm-workspace/backend_request_func.py\", line 261, in async_request_openai_completions\n    async for chunk_bytes in response.content:\n  File \"/usr/local/lib/python3.10/dist-packages/aiohttp/streams.py\", line 50, in __anext__\n    rv = await self.read_func()\n  File \"/usr/local/lib/python3.10/dist-packages/aiohttp/streams.py\", line 317, in readline\n    return await self.readuntil()\n  File \"/usr/local/lib/python3.10/dist-packages/aiohttp/streams.py\", line 351, in readuntil\n    await self._wait(\"readuntil\")\n  File \"/usr/local/lib/python3.10/dist-packages/aiohttp/streams.py\", line 312, in _wait\n    await waiter\naiohttp.client_exceptions.ClientPayloadError: Response payload is not completed: <TransferEncodingError: 400, message='Not enough data for satisfy transfer length header.'>\n", "Traceback (most recent call last):\n  File \"/usr/local/lib/python3.10/dist-packages/aiohttp/client_proto.py\", line 94, in connection_lost\n    uncompleted = self._parser.feed_eof()\n  File \"aiohttp/_http_parser.pyx\", line 513, in aiohttp._http_parser.HttpParser.feed_eof\naiohttp.http_exceptions.TransferEncodingError: 400, message:\n  Not enough data for satisfy transfer length header.\n\nThe above exception was the direct cause of the following exception:\n\nTraceback (most recent call last):\n  File \"/vllm-workspace/backend_request_func.py\", line 261, in async_request_openai_completions\n    async for chunk_bytes in response.content:\n  File \"/usr/local/lib/python3.10/dist-packages/aiohttp/streams.py\", line 50, in __anext__\n    rv = await self.read_func()\n  File \"/usr/local/lib/python3.10/dist-packages/aiohttp/streams.py\", line 317, in readline\n    return await self.readuntil()\n  File \"/usr/local/lib/python3.10/dist-packages/aiohttp/streams.py\", line 351, in readuntil\n    await self._wait(\"readuntil\")\n  File \"/usr/local/lib/python3.10/dist-packages/aiohttp/streams.py\", line 312, in _wait\n    await waiter\naiohttp.client_exceptions.ClientPayloadError: Response payload is not completed: <TransferEncodingError: 400, message='Not enough data for satisfy transfer length header.'>\n", "Traceback (most recent call last):\n  File \"/usr/local/lib/python3.10/dist-packages/aiohttp/client_proto.py\", line 94, in connection_lost\n    uncompleted = self._parser.feed_eof()\n  File \"aiohttp/_http_parser.pyx\", line 513, in aiohttp._http_parser.HttpParser.feed_eof\naiohttp.http_exceptions.TransferEncodingError: 400, message:\n  Not enough data for satisfy transfer length header.\n\nThe above exception was the direct cause of the following exception:\n\nTraceback (most recent call last):\n  File \"/vllm-workspace/backend_request_func.py\", line 261, in async_request_openai_completions\n    async for chunk_bytes in response.content:\n  File \"/usr/local/lib/python3.10/dist-packages/aiohttp/streams.py\", line 50, in __anext__\n    rv = await self.read_func()\n  File \"/usr/local/lib/python3.10/dist-packages/aiohttp/streams.py\", line 317, in readline\n    return await self.readuntil()\n  File \"/usr/local/lib/python3.10/dist-packages/aiohttp/streams.py\", line 351, in readuntil\n    await self._wait(\"readuntil\")\n  File \"/usr/local/lib/python3.10/dist-packages/aiohttp/streams.py\", line 312, in _wait\n    await waiter\naiohttp.client_exceptions.ClientPayloadError: Response payload is not completed: <TransferEncodingError: 400, message='Not enough data for satisfy transfer length header.'>\n", "Traceback (most recent call last):\n  File \"/usr/local/lib/python3.10/dist-packages/aiohttp/client_proto.py\", line 94, in connection_lost\n    uncompleted = self._parser.feed_eof()\n  File \"aiohttp/_http_parser.pyx\", line 513, in aiohttp._http_parser.HttpParser.feed_eof\naiohttp.http_exceptions.TransferEncodingError: 400, message:\n  Not enough data for satisfy transfer length header.\n\nThe above exception was the direct cause of the following exception:\n\nTraceback (most recent call last):\n  File \"/vllm-workspace/backend_request_func.py\", line 261, in async_request_openai_completions\n    async for chunk_bytes in response.content:\n  File \"/usr/local/lib/python3.10/dist-packages/aiohttp/streams.py\", line 50, in __anext__\n    rv = await self.read_func()\n  File \"/usr/local/lib/python3.10/dist-packages/aiohttp/streams.py\", line 317, in readline\n    return await self.readuntil()\n  File \"/usr/local/lib/python3.10/dist-packages/aiohttp/streams.py\", line 351, in readuntil\n    await self._wait(\"readuntil\")\n  File \"/usr/local/lib/python3.10/dist-packages/aiohttp/streams.py\", line 312, in _wait\n    await waiter\naiohttp.client_exceptions.ClientPayloadError: Response payload is not completed: <TransferEncodingError: 400, message='Not enough data for satisfy transfer length header.'>\n", "Traceback (most recent call last):\n  File \"/usr/local/lib/python3.10/dist-packages/aiohttp/client_proto.py\", line 94, in connection_lost\n    uncompleted = self._parser.feed_eof()\n  File \"aiohttp/_http_parser.pyx\", line 513, in aiohttp._http_parser.HttpParser.feed_eof\naiohttp.http_exceptions.TransferEncodingError: 400, message:\n  Not enough data for satisfy transfer length header.\n\nThe above exception was the direct cause of the following exception:\n\nTraceback (most recent call last):\n  File \"/vllm-workspace/backend_request_func.py\", line 261, in async_request_openai_completions\n    async for chunk_bytes in response.content:\n  File \"/usr/local/lib/python3.10/dist-packages/aiohttp/streams.py\", line 50, in __anext__\n    rv = await self.read_func()\n  File \"/usr/local/lib/python3.10/dist-packages/aiohttp/streams.py\", line 317, in readline\n    return await self.readuntil()\n  File \"/usr/local/lib/python3.10/dist-packages/aiohttp/streams.py\", line 351, in readuntil\n    await self._wait(\"readuntil\")\n  File \"/usr/local/lib/python3.10/dist-packages/aiohttp/streams.py\", line 312, in _wait\n    await waiter\naiohttp.client_exceptions.ClientPayloadError: Response payload is not completed: <TransferEncodingError: 400, message='Not enough data for satisfy transfer length header.'>\n", "Traceback (most recent call last):\n  File \"/usr/local/lib/python3.10/dist-packages/aiohttp/client_proto.py\", line 94, in connection_lost\n    uncompleted = self._parser.feed_eof()\n  File \"aiohttp/_http_parser.pyx\", line 513, in aiohttp._http_parser.HttpParser.feed_eof\naiohttp.http_exceptions.TransferEncodingError: 400, message:\n  Not enough data for satisfy transfer length header.\n\nThe above exception was the direct cause of the following exception:\n\nTraceback (most recent call last):\n  File \"/vllm-workspace/backend_request_func.py\", line 261, in async_request_openai_completions\n    async for chunk_bytes in response.content:\n  File \"/usr/local/lib/python3.10/dist-packages/aiohttp/streams.py\", line 50, in __anext__\n    rv = await self.read_func()\n  File \"/usr/local/lib/python3.10/dist-packages/aiohttp/streams.py\", line 317, in readline\n    return await self.readuntil()\n  File \"/usr/local/lib/python3.10/dist-packages/aiohttp/streams.py\", line 351, in readuntil\n    await self._wait(\"readuntil\")\n  File \"/usr/local/lib/python3.10/dist-packages/aiohttp/streams.py\", line 312, in _wait\n    await waiter\naiohttp.client_exceptions.ClientPayloadError: Response payload is not completed: <TransferEncodingError: 400, message='Not enough data for satisfy transfer length header.'>\n", "Traceback (most recent call last):\n  File \"/usr/local/lib/python3.10/dist-packages/aiohttp/client_proto.py\", line 94, in connection_lost\n    uncompleted = self._parser.feed_eof()\n  File \"aiohttp/_http_parser.pyx\", line 513, in aiohttp._http_parser.HttpParser.feed_eof\naiohttp.http_exceptions.TransferEncodingError: 400, message:\n  Not enough data for satisfy transfer length header.\n\nThe above exception was the direct cause of the following exception:\n\nTraceback (most recent call last):\n  File \"/vllm-workspace/backend_request_func.py\", line 261, in async_request_openai_completions\n    async for chunk_bytes in response.content:\n  File \"/usr/local/lib/python3.10/dist-packages/aiohttp/streams.py\", line 50, in __anext__\n    rv = await self.read_func()\n  File \"/usr/local/lib/python3.10/dist-packages/aiohttp/streams.py\", line 317, in readline\n    return await self.readuntil()\n  File \"/usr/local/lib/python3.10/dist-packages/aiohttp/streams.py\", line 351, in readuntil\n    await self._wait(\"readuntil\")\n  File \"/usr/local/lib/python3.10/dist-packages/aiohttp/streams.py\", line 312, in _wait\n    await waiter\naiohttp.client_exceptions.ClientPayloadError: Response payload is not completed: <TransferEncodingError: 400, message='Not enough data for satisfy transfer length header.'>\n", "Traceback (most recent call last):\n  File \"/usr/local/lib/python3.10/dist-packages/aiohttp/client_proto.py\", line 94, in connection_lost\n    uncompleted = self._parser.feed_eof()\n  File \"aiohttp/_http_parser.pyx\", line 513, in aiohttp._http_parser.HttpParser.feed_eof\naiohttp.http_exceptions.TransferEncodingError: 400, message:\n  Not enough data for satisfy transfer length header.\n\nThe above exception was the direct cause of the following exception:\n\nTraceback (most recent call last):\n  File \"/vllm-workspace/backend_request_func.py\", line 261, in async_request_openai_completions\n    async for chunk_bytes in response.content:\n  File \"/usr/local/lib/python3.10/dist-packages/aiohttp/streams.py\", line 50, in __anext__\n    rv = await self.read_func()\n  File \"/usr/local/lib/python3.10/dist-packages/aiohttp/streams.py\", line 317, in readline\n    return await self.readuntil()\n  File \"/usr/local/lib/python3.10/dist-packages/aiohttp/streams.py\", line 351, in readuntil\n    await self._wait(\"readuntil\")\n  File \"/usr/local/lib/python3.10/dist-packages/aiohttp/streams.py\", line 312, in _wait\n    await waiter\naiohttp.client_exceptions.ClientPayloadError: Response payload is not completed: <TransferEncodingError: 400, message='Not enough data for satisfy transfer length header.'>\n", "Traceback (most recent call last):\n  File \"/usr/local/lib/python3.10/dist-packages/aiohttp/client_proto.py\", line 94, in connection_lost\n    uncompleted = self._parser.feed_eof()\n  File \"aiohttp/_http_parser.pyx\", line 513, in aiohttp._http_parser.HttpParser.feed_eof\naiohttp.http_exceptions.TransferEncodingError: 400, message:\n  Not enough data for satisfy transfer length header.\n\nThe above exception was the direct cause of the following exception:\n\nTraceback (most recent call last):\n  File \"/vllm-workspace/backend_request_func.py\", line 261, in async_request_openai_completions\n    async for chunk_bytes in response.content:\n  File \"/usr/local/lib/python3.10/dist-packages/aiohttp/streams.py\", line 50, in __anext__\n    rv = await self.read_func()\n  File \"/usr/local/lib/python3.10/dist-packages/aiohttp/streams.py\", line 317, in readline\n    return await self.readuntil()\n  File \"/usr/local/lib/python3.10/dist-packages/aiohttp/streams.py\", line 351, in readuntil\n    await self._wait(\"readuntil\")\n  File \"/usr/local/lib/python3.10/dist-packages/aiohttp/streams.py\", line 312, in _wait\n    await waiter\naiohttp.client_exceptions.ClientPayloadError: Response payload is not completed: <TransferEncodingError: 400, message='Not enough data for satisfy transfer length header.'>\n", "Traceback (most recent call last):\n  File \"/usr/local/lib/python3.10/dist-packages/aiohttp/client_proto.py\", line 94, in connection_lost\n    uncompleted = self._parser.feed_eof()\n  File \"aiohttp/_http_parser.pyx\", line 513, in aiohttp._http_parser.HttpParser.feed_eof\naiohttp.http_exceptions.TransferEncodingError: 400, message:\n  Not enough data for satisfy transfer length header.\n\nThe above exception was the direct cause of the following exception:\n\nTraceback (most recent call last):\n  File \"/vllm-workspace/backend_request_func.py\", line 261, in async_request_openai_completions\n    async for chunk_bytes in response.content:\n  File \"/usr/local/lib/python3.10/dist-packages/aiohttp/streams.py\", line 50, in __anext__\n    rv = await self.read_func()\n  File \"/usr/local/lib/python3.10/dist-packages/aiohttp/streams.py\", line 317, in readline\n    return await self.readuntil()\n  File \"/usr/local/lib/python3.10/dist-packages/aiohttp/streams.py\", line 351, in readuntil\n    await self._wait(\"readuntil\")\n  File \"/usr/local/lib/python3.10/dist-packages/aiohttp/streams.py\", line 312, in _wait\n    await waiter\naiohttp.client_exceptions.ClientPayloadError: Response payload is not completed: <TransferEncodingError: 400, message='Not enough data for satisfy transfer length header.'>\n", "Traceback (most recent call last):\n  File \"/usr/local/lib/python3.10/dist-packages/aiohttp/client_proto.py\", line 94, in connection_lost\n    uncompleted = self._parser.feed_eof()\n  File \"aiohttp/_http_parser.pyx\", line 513, in aiohttp._http_parser.HttpParser.feed_eof\naiohttp.http_exceptions.TransferEncodingError: 400, message:\n  Not enough data for satisfy transfer length header.\n\nThe above exception was the direct cause of the following exception:\n\nTraceback (most recent call last):\n  File \"/vllm-workspace/backend_request_func.py\", line 261, in async_request_openai_completions\n    async for chunk_bytes in response.content:\n  File \"/usr/local/lib/python3.10/dist-packages/aiohttp/streams.py\", line 50, in __anext__\n    rv = await self.read_func()\n  File \"/usr/local/lib/python3.10/dist-packages/aiohttp/streams.py\", line 317, in readline\n    return await self.readuntil()\n  File \"/usr/local/lib/python3.10/dist-packages/aiohttp/streams.py\", line 351, in readuntil\n    await self._wait(\"readuntil\")\n  File \"/usr/local/lib/python3.10/dist-packages/aiohttp/streams.py\", line 312, in _wait\n    await waiter\naiohttp.client_exceptions.ClientPayloadError: Response payload is not completed: <TransferEncodingError: 400, message='Not enough data for satisfy transfer length header.'>\n", "Traceback (most recent call last):\n  File \"/usr/local/lib/python3.10/dist-packages/aiohttp/client_proto.py\", line 94, in connection_lost\n    uncompleted = self._parser.feed_eof()\n  File \"aiohttp/_http_parser.pyx\", line 513, in aiohttp._http_parser.HttpParser.feed_eof\naiohttp.http_exceptions.TransferEncodingError: 400, message:\n  Not enough data for satisfy transfer length header.\n\nThe above exception was the direct cause of the following exception:\n\nTraceback (most recent call last):\n  File \"/vllm-workspace/backend_request_func.py\", line 261, in async_request_openai_completions\n    async for chunk_bytes in response.content:\n  File \"/usr/local/lib/python3.10/dist-packages/aiohttp/streams.py\", line 50, in __anext__\n    rv = await self.read_func()\n  File \"/usr/local/lib/python3.10/dist-packages/aiohttp/streams.py\", line 317, in readline\n    return await self.readuntil()\n  File \"/usr/local/lib/python3.10/dist-packages/aiohttp/streams.py\", line 351, in readuntil\n    await self._wait(\"readuntil\")\n  File \"/usr/local/lib/python3.10/dist-packages/aiohttp/streams.py\", line 312, in _wait\n    await waiter\naiohttp.client_exceptions.ClientPayloadError: Response payload is not completed: <TransferEncodingError: 400, message='Not enough data for satisfy transfer length header.'>\n", "Traceback (most recent call last):\n  File \"/usr/local/lib/python3.10/dist-packages/aiohttp/client_proto.py\", line 94, in connection_lost\n    uncompleted = self._parser.feed_eof()\n  File \"aiohttp/_http_parser.pyx\", line 513, in aiohttp._http_parser.HttpParser.feed_eof\naiohttp.http_exceptions.TransferEncodingError: 400, message:\n  Not enough data for satisfy transfer length header.\n\nThe above exception was the direct cause of the following exception:\n\nTraceback (most recent call last):\n  File \"/vllm-workspace/backend_request_func.py\", line 261, in async_request_openai_completions\n    async for chunk_bytes in response.content:\n  File \"/usr/local/lib/python3.10/dist-packages/aiohttp/streams.py\", line 50, in __anext__\n    rv = await self.read_func()\n  File \"/usr/local/lib/python3.10/dist-packages/aiohttp/streams.py\", line 317, in readline\n    return await self.readuntil()\n  File \"/usr/local/lib/python3.10/dist-packages/aiohttp/streams.py\", line 351, in readuntil\n    await self._wait(\"readuntil\")\n  File \"/usr/local/lib/python3.10/dist-packages/aiohttp/streams.py\", line 312, in _wait\n    await waiter\naiohttp.client_exceptions.ClientPayloadError: Response payload is not completed: <TransferEncodingError: 400, message='Not enough data for satisfy transfer length header.'>\n", "Traceback (most recent call last):\n  File \"/usr/local/lib/python3.10/dist-packages/aiohttp/client_proto.py\", line 94, in connection_lost\n    uncompleted = self._parser.feed_eof()\n  File \"aiohttp/_http_parser.pyx\", line 513, in aiohttp._http_parser.HttpParser.feed_eof\naiohttp.http_exceptions.TransferEncodingError: 400, message:\n  Not enough data for satisfy transfer length header.\n\nThe above exception was the direct cause of the following exception:\n\nTraceback (most recent call last):\n  File \"/vllm-workspace/backend_request_func.py\", line 261, in async_request_openai_completions\n    async for chunk_bytes in response.content:\n  File \"/usr/local/lib/python3.10/dist-packages/aiohttp/streams.py\", line 50, in __anext__\n    rv = await self.read_func()\n  File \"/usr/local/lib/python3.10/dist-packages/aiohttp/streams.py\", line 317, in readline\n    return await self.readuntil()\n  File \"/usr/local/lib/python3.10/dist-packages/aiohttp/streams.py\", line 351, in readuntil\n    await self._wait(\"readuntil\")\n  File \"/usr/local/lib/python3.10/dist-packages/aiohttp/streams.py\", line 312, in _wait\n    await waiter\naiohttp.client_exceptions.ClientPayloadError: Response payload is not completed: <TransferEncodingError: 400, message='Not enough data for satisfy transfer length header.'>\n", "Traceback (most recent call last):\n  File \"/usr/local/lib/python3.10/dist-packages/aiohttp/client_proto.py\", line 94, in connection_lost\n    uncompleted = self._parser.feed_eof()\n  File \"aiohttp/_http_parser.pyx\", line 513, in aiohttp._http_parser.HttpParser.feed_eof\naiohttp.http_exceptions.TransferEncodingError: 400, message:\n  Not enough data for satisfy transfer length header.\n\nThe above exception was the direct cause of the following exception:\n\nTraceback (most recent call last):\n  File \"/vllm-workspace/backend_request_func.py\", line 261, in async_request_openai_completions\n    async for chunk_bytes in response.content:\n  File \"/usr/local/lib/python3.10/dist-packages/aiohttp/streams.py\", line 50, in __anext__\n    rv = await self.read_func()\n  File \"/usr/local/lib/python3.10/dist-packages/aiohttp/streams.py\", line 317, in readline\n    return await self.readuntil()\n  File \"/usr/local/lib/python3.10/dist-packages/aiohttp/streams.py\", line 351, in readuntil\n    await self._wait(\"readuntil\")\n  File \"/usr/local/lib/python3.10/dist-packages/aiohttp/streams.py\", line 312, in _wait\n    await waiter\naiohttp.client_exceptions.ClientPayloadError: Response payload is not completed: <TransferEncodingError: 400, message='Not enough data for satisfy transfer length header.'>\n", "Traceback (most recent call last):\n  File \"/usr/local/lib/python3.10/dist-packages/aiohttp/client_proto.py\", line 94, in connection_lost\n    uncompleted = self._parser.feed_eof()\n  File \"aiohttp/_http_parser.pyx\", line 513, in aiohttp._http_parser.HttpParser.feed_eof\naiohttp.http_exceptions.TransferEncodingError: 400, message:\n  Not enough data for satisfy transfer length header.\n\nThe above exception was the direct cause of the following exception:\n\nTraceback (most recent call last):\n  File \"/vllm-workspace/backend_request_func.py\", line 261, in async_request_openai_completions\n    async for chunk_bytes in response.content:\n  File \"/usr/local/lib/python3.10/dist-packages/aiohttp/streams.py\", line 50, in __anext__\n    rv = await self.read_func()\n  File \"/usr/local/lib/python3.10/dist-packages/aiohttp/streams.py\", line 317, in readline\n    return await self.readuntil()\n  File \"/usr/local/lib/python3.10/dist-packages/aiohttp/streams.py\", line 351, in readuntil\n    await self._wait(\"readuntil\")\n  File \"/usr/local/lib/python3.10/dist-packages/aiohttp/streams.py\", line 312, in _wait\n    await waiter\naiohttp.client_exceptions.ClientPayloadError: Response payload is not completed: <TransferEncodingError: 400, message='Not enough data for satisfy transfer length header.'>\n", "Traceback (most recent call last):\n  File \"/usr/local/lib/python3.10/dist-packages/aiohttp/client_proto.py\", line 94, in connection_lost\n    uncompleted = self._parser.feed_eof()\n  File \"aiohttp/_http_parser.pyx\", line 513, in aiohttp._http_parser.HttpParser.feed_eof\naiohttp.http_exceptions.TransferEncodingError: 400, message:\n  Not enough data for satisfy transfer length header.\n\nThe above exception was the direct cause of the following exception:\n\nTraceback (most recent call last):\n  File \"/vllm-workspace/backend_request_func.py\", line 261, in async_request_openai_completions\n    async for chunk_bytes in response.content:\n  File \"/usr/local/lib/python3.10/dist-packages/aiohttp/streams.py\", line 50, in __anext__\n    rv = await self.read_func()\n  File \"/usr/local/lib/python3.10/dist-packages/aiohttp/streams.py\", line 317, in readline\n    return await self.readuntil()\n  File \"/usr/local/lib/python3.10/dist-packages/aiohttp/streams.py\", line 351, in readuntil\n    await self._wait(\"readuntil\")\n  File \"/usr/local/lib/python3.10/dist-packages/aiohttp/streams.py\", line 312, in _wait\n    await waiter\naiohttp.client_exceptions.ClientPayloadError: Response payload is not completed: <TransferEncodingError: 400, message='Not enough data for satisfy transfer length header.'>\n", "Traceback (most recent call last):\n  File \"/usr/local/lib/python3.10/dist-packages/aiohttp/client_proto.py\", line 94, in connection_lost\n    uncompleted = self._parser.feed_eof()\n  File \"aiohttp/_http_parser.pyx\", line 513, in aiohttp._http_parser.HttpParser.feed_eof\naiohttp.http_exceptions.TransferEncodingError: 400, message:\n  Not enough data for satisfy transfer length header.\n\nThe above exception was the direct cause of the following exception:\n\nTraceback (most recent call last):\n  File \"/vllm-workspace/backend_request_func.py\", line 261, in async_request_openai_completions\n    async for chunk_bytes in response.content:\n  File \"/usr/local/lib/python3.10/dist-packages/aiohttp/streams.py\", line 50, in __anext__\n    rv = await self.read_func()\n  File \"/usr/local/lib/python3.10/dist-packages/aiohttp/streams.py\", line 317, in readline\n    return await self.readuntil()\n  File \"/usr/local/lib/python3.10/dist-packages/aiohttp/streams.py\", line 351, in readuntil\n    await self._wait(\"readuntil\")\n  File \"/usr/local/lib/python3.10/dist-packages/aiohttp/streams.py\", line 312, in _wait\n    await waiter\naiohttp.client_exceptions.ClientPayloadError: Response payload is not completed: <TransferEncodingError: 400, message='Not enough data for satisfy transfer length header.'>\n", "Traceback (most recent call last):\n  File \"/usr/local/lib/python3.10/dist-packages/aiohttp/client_proto.py\", line 94, in connection_lost\n    uncompleted = self._parser.feed_eof()\n  File \"aiohttp/_http_parser.pyx\", line 513, in aiohttp._http_parser.HttpParser.feed_eof\naiohttp.http_exceptions.TransferEncodingError: 400, message:\n  Not enough data for satisfy transfer length header.\n\nThe above exception was the direct cause of the following exception:\n\nTraceback (most recent call last):\n  File \"/vllm-workspace/backend_request_func.py\", line 261, in async_request_openai_completions\n    async for chunk_bytes in response.content:\n  File \"/usr/local/lib/python3.10/dist-packages/aiohttp/streams.py\", line 50, in __anext__\n    rv = await self.read_func()\n  File \"/usr/local/lib/python3.10/dist-packages/aiohttp/streams.py\", line 317, in readline\n    return await self.readuntil()\n  File \"/usr/local/lib/python3.10/dist-packages/aiohttp/streams.py\", line 351, in readuntil\n    await self._wait(\"readuntil\")\n  File \"/usr/local/lib/python3.10/dist-packages/aiohttp/streams.py\", line 312, in _wait\n    await waiter\naiohttp.client_exceptions.ClientPayloadError: Response payload is not completed: <TransferEncodingError: 400, message='Not enough data for satisfy transfer length header.'>\n", "Traceback (most recent call last):\n  File \"/usr/local/lib/python3.10/dist-packages/aiohttp/client_proto.py\", line 94, in connection_lost\n    uncompleted = self._parser.feed_eof()\n  File \"aiohttp/_http_parser.pyx\", line 513, in aiohttp._http_parser.HttpParser.feed_eof\naiohttp.http_exceptions.TransferEncodingError: 400, message:\n  Not enough data for satisfy transfer length header.\n\nThe above exception was the direct cause of the following exception:\n\nTraceback (most recent call last):\n  File \"/vllm-workspace/backend_request_func.py\", line 261, in async_request_openai_completions\n    async for chunk_bytes in response.content:\n  File \"/usr/local/lib/python3.10/dist-packages/aiohttp/streams.py\", line 50, in __anext__\n    rv = await self.read_func()\n  File \"/usr/local/lib/python3.10/dist-packages/aiohttp/streams.py\", line 317, in readline\n    return await self.readuntil()\n  File \"/usr/local/lib/python3.10/dist-packages/aiohttp/streams.py\", line 351, in readuntil\n    await self._wait(\"readuntil\")\n  File \"/usr/local/lib/python3.10/dist-packages/aiohttp/streams.py\", line 312, in _wait\n    await waiter\naiohttp.client_exceptions.ClientPayloadError: Response payload is not completed: <TransferEncodingError: 400, message='Not enough data for satisfy transfer length header.'>\n", "Traceback (most recent call last):\n  File \"/usr/local/lib/python3.10/dist-packages/aiohttp/client_proto.py\", line 94, in connection_lost\n    uncompleted = self._parser.feed_eof()\n  File \"aiohttp/_http_parser.pyx\", line 513, in aiohttp._http_parser.HttpParser.feed_eof\naiohttp.http_exceptions.TransferEncodingError: 400, message:\n  Not enough data for satisfy transfer length header.\n\nThe above exception was the direct cause of the following exception:\n\nTraceback (most recent call last):\n  File \"/vllm-workspace/backend_request_func.py\", line 261, in async_request_openai_completions\n    async for chunk_bytes in response.content:\n  File \"/usr/local/lib/python3.10/dist-packages/aiohttp/streams.py\", line 50, in __anext__\n    rv = await self.read_func()\n  File \"/usr/local/lib/python3.10/dist-packages/aiohttp/streams.py\", line 317, in readline\n    return await self.readuntil()\n  File \"/usr/local/lib/python3.10/dist-packages/aiohttp/streams.py\", line 351, in readuntil\n    await self._wait(\"readuntil\")\n  File \"/usr/local/lib/python3.10/dist-packages/aiohttp/streams.py\", line 312, in _wait\n    await waiter\naiohttp.client_exceptions.ClientPayloadError: Response payload is not completed: <TransferEncodingError: 400, message='Not enough data for satisfy transfer length header.'>\n", "Traceback (most recent call last):\n  File \"/usr/local/lib/python3.10/dist-packages/aiohttp/client_proto.py\", line 94, in connection_lost\n    uncompleted = self._parser.feed_eof()\n  File \"aiohttp/_http_parser.pyx\", line 513, in aiohttp._http_parser.HttpParser.feed_eof\naiohttp.http_exceptions.TransferEncodingError: 400, message:\n  Not enough data for satisfy transfer length header.\n\nThe above exception was the direct cause of the following exception:\n\nTraceback (most recent call last):\n  File \"/vllm-workspace/backend_request_func.py\", line 261, in async_request_openai_completions\n    async for chunk_bytes in response.content:\n  File \"/usr/local/lib/python3.10/dist-packages/aiohttp/streams.py\", line 50, in __anext__\n    rv = await self.read_func()\n  File \"/usr/local/lib/python3.10/dist-packages/aiohttp/streams.py\", line 317, in readline\n    return await self.readuntil()\n  File \"/usr/local/lib/python3.10/dist-packages/aiohttp/streams.py\", line 351, in readuntil\n    await self._wait(\"readuntil\")\n  File \"/usr/local/lib/python3.10/dist-packages/aiohttp/streams.py\", line 312, in _wait\n    await waiter\naiohttp.client_exceptions.ClientPayloadError: Response payload is not completed: <TransferEncodingError: 400, message='Not enough data for satisfy transfer length header.'>\n", "Traceback (most recent call last):\n  File \"/usr/local/lib/python3.10/dist-packages/aiohttp/client_proto.py\", line 94, in connection_lost\n    uncompleted = self._parser.feed_eof()\n  File \"aiohttp/_http_parser.pyx\", line 513, in aiohttp._http_parser.HttpParser.feed_eof\naiohttp.http_exceptions.TransferEncodingError: 400, message:\n  Not enough data for satisfy transfer length header.\n\nThe above exception was the direct cause of the following exception:\n\nTraceback (most recent call last):\n  File \"/vllm-workspace/backend_request_func.py\", line 261, in async_request_openai_completions\n    async for chunk_bytes in response.content:\n  File \"/usr/local/lib/python3.10/dist-packages/aiohttp/streams.py\", line 50, in __anext__\n    rv = await self.read_func()\n  File \"/usr/local/lib/python3.10/dist-packages/aiohttp/streams.py\", line 317, in readline\n    return await self.readuntil()\n  File \"/usr/local/lib/python3.10/dist-packages/aiohttp/streams.py\", line 351, in readuntil\n    await self._wait(\"readuntil\")\n  File \"/usr/local/lib/python3.10/dist-packages/aiohttp/streams.py\", line 312, in _wait\n    await waiter\naiohttp.client_exceptions.ClientPayloadError: Response payload is not completed: <TransferEncodingError: 400, message='Not enough data for satisfy transfer length header.'>\n", "Traceback (most recent call last):\n  File \"/usr/local/lib/python3.10/dist-packages/aiohttp/client_proto.py\", line 94, in connection_lost\n    uncompleted = self._parser.feed_eof()\n  File \"aiohttp/_http_parser.pyx\", line 513, in aiohttp._http_parser.HttpParser.feed_eof\naiohttp.http_exceptions.TransferEncodingError: 400, message:\n  Not enough data for satisfy transfer length header.\n\nThe above exception was the direct cause of the following exception:\n\nTraceback (most recent call last):\n  File \"/vllm-workspace/backend_request_func.py\", line 261, in async_request_openai_completions\n    async for chunk_bytes in response.content:\n  File \"/usr/local/lib/python3.10/dist-packages/aiohttp/streams.py\", line 50, in __anext__\n    rv = await self.read_func()\n  File \"/usr/local/lib/python3.10/dist-packages/aiohttp/streams.py\", line 317, in readline\n    return await self.readuntil()\n  File \"/usr/local/lib/python3.10/dist-packages/aiohttp/streams.py\", line 351, in readuntil\n    await self._wait(\"readuntil\")\n  File \"/usr/local/lib/python3.10/dist-packages/aiohttp/streams.py\", line 312, in _wait\n    await waiter\naiohttp.client_exceptions.ClientPayloadError: Response payload is not completed: <TransferEncodingError: 400, message='Not enough data for satisfy transfer length header.'>\n", "Traceback (most recent call last):\n  File \"/usr/local/lib/python3.10/dist-packages/aiohttp/client_proto.py\", line 94, in connection_lost\n    uncompleted = self._parser.feed_eof()\n  File \"aiohttp/_http_parser.pyx\", line 513, in aiohttp._http_parser.HttpParser.feed_eof\naiohttp.http_exceptions.TransferEncodingError: 400, message:\n  Not enough data for satisfy transfer length header.\n\nThe above exception was the direct cause of the following exception:\n\nTraceback (most recent call last):\n  File \"/vllm-workspace/backend_request_func.py\", line 261, in async_request_openai_completions\n    async for chunk_bytes in response.content:\n  File \"/usr/local/lib/python3.10/dist-packages/aiohttp/streams.py\", line 50, in __anext__\n    rv = await self.read_func()\n  File \"/usr/local/lib/python3.10/dist-packages/aiohttp/streams.py\", line 317, in readline\n    return await self.readuntil()\n  File \"/usr/local/lib/python3.10/dist-packages/aiohttp/streams.py\", line 351, in readuntil\n    await self._wait(\"readuntil\")\n  File \"/usr/local/lib/python3.10/dist-packages/aiohttp/streams.py\", line 312, in _wait\n    await waiter\naiohttp.client_exceptions.ClientPayloadError: Response payload is not completed: <TransferEncodingError: 400, message='Not enough data for satisfy transfer length header.'>\n"]}