{"date": "20240907-084229", "backend": "vllm", "model_id": "neuralmagic/Meta-Llama-3.1-70B-Instruct-FP8", "tokenizer_id": "neuralmagic/Meta-Llama-3.1-70B-Instruct-FP8", "best_of": 1, "use_beam_search": false, "num_prompts": 40, "request_rate": "inf", "duration": 1.127381703001447, "completed": 4, "total_input_tokens": 1718, "total_output_tokens": 0, "request_throughput": 3.5480441001931586, "input_throughput": 1523.8849410329617, "output_throughput": 0.0, "mean_ttft_ms": 0.0, "median_ttft_ms": 0.0, "std_ttft_ms": 0.0, "p99_ttft_ms": 0.0, "mean_tpot_ms": 0.0, "median_tpot_ms": 0.0, "std_tpot_ms": 0.0, "p99_tpot_ms": 0.0, "mean_itl_ms": 0.0, "median_itl_ms": 0.0, "std_itl_ms": 0.0, "p99_itl_ms": 0.0, "mean_latency_ms": 75.76035705023969, "median_latency_ms": 0.0, "std_latency_ms": 235.183821950166, "p99_latency_ms": 916.6775144898562, "input_lens": [13, 25, 27, 10, 329, 29, 399, 328, 4, 205, 16, 372, 403, 9, 12, 770, 227, 8, 14, 390, 659, 59, 76, 744, 619, 279, 344, 9, 10, 45, 11, 4, 80, 768, 317, 40, 619, 8, 298, 16], "output_lens": [0, 0, 0, 0, 0, 0, 0, 0, 0, 0, 0, 0, 0, 0, 0, 0, 0, 0, 0, 0, 0, 0, 0, 0, 0, 0, 0, 0, 0, 0, 0, 0, 0, 0, 0, 0, 0, 0, 0, 0], "ttfts": [0.6474874749983428, 0.6471069130057003, 0.6469995329971425, 0.6469077530055074, 0.6468335079989629, 0.6467512930103112, 0.0, 0.0, 0.6464299919898622, 0.6463669829972787, 0.6462667160085402, 0.0, 0.9220703909959411, 0.9218914779921761, 0.6457213440007763, 0.9215234800067265, 0.9212517689884407, 0.9212642469938146, 0.9211868309939746, 0.9211026239936473, 1.087690346990712, 1.0877162879914977, 1.0875165550096426, 1.0875012430042261, 0.0, 0.0, 1.0882385019940557, 0.0, 0.0, 0.0, 0.0, 0.0, 0.0, 0.0, 0.0, 0.0, 0.0, 0.0, 0.0, 0.0], "itls": [[], [], [], [], [], [], [], [], [], [], [], [], [], [], [], [], [], [], [], [], [], [], [], [], [], [], [], [], [], [], [], [], [], [], [], [], [], [], [], []], "generated_texts": ["", "", "", "", "", "", "", "", "", "", "", "", "", "", "", "", "", "", "", "", "", "", "", "", "", "", "", "", "", "", "", "", "", "", "", "", "", "", "", ""], "errors": ["Traceback (most recent call last):\n  File \"/usr/local/lib/python3.10/dist-packages/aiohttp/client_proto.py\", line 94, in connection_lost\n    uncompleted = self._parser.feed_eof()\n  File \"aiohttp/_http_parser.pyx\", line 513, in aiohttp._http_parser.HttpParser.feed_eof\naiohttp.http_exceptions.TransferEncodingError: 400, message:\n  Not enough data for satisfy transfer length header.\n\nThe above exception was the direct cause of the following exception:\n\nTraceback (most recent call last):\n  File \"/vllm-workspace/backend_request_func.py\", line 261, in async_request_openai_completions\n    async for chunk_bytes in response.content:\n  File \"/usr/local/lib/python3.10/dist-packages/aiohttp/streams.py\", line 50, in __anext__\n    rv = await self.read_func()\n  File \"/usr/local/lib/python3.10/dist-packages/aiohttp/streams.py\", line 317, in readline\n    return await self.readuntil()\n  File \"/usr/local/lib/python3.10/dist-packages/aiohttp/streams.py\", line 351, in readuntil\n    await self._wait(\"readuntil\")\n  File \"/usr/local/lib/python3.10/dist-packages/aiohttp/streams.py\", line 312, in _wait\n    await waiter\naiohttp.client_exceptions.ClientPayloadError: Response payload is not completed: <TransferEncodingError: 400, message='Not enough data for satisfy transfer length header.'>\n", "Traceback (most recent call last):\n  File \"/usr/local/lib/python3.10/dist-packages/aiohttp/client_proto.py\", line 94, in connection_lost\n    uncompleted = self._parser.feed_eof()\n  File \"aiohttp/_http_parser.pyx\", line 513, in aiohttp._http_parser.HttpParser.feed_eof\naiohttp.http_exceptions.TransferEncodingError: 400, message:\n  Not enough data for satisfy transfer length header.\n\nThe above exception was the direct cause of the following exception:\n\nTraceback (most recent call last):\n  File \"/vllm-workspace/backend_request_func.py\", line 261, in async_request_openai_completions\n    async for chunk_bytes in response.content:\n  File \"/usr/local/lib/python3.10/dist-packages/aiohttp/streams.py\", line 50, in __anext__\n    rv = await self.read_func()\n  File \"/usr/local/lib/python3.10/dist-packages/aiohttp/streams.py\", line 317, in readline\n    return await self.readuntil()\n  File \"/usr/local/lib/python3.10/dist-packages/aiohttp/streams.py\", line 351, in readuntil\n    await self._wait(\"readuntil\")\n  File \"/usr/local/lib/python3.10/dist-packages/aiohttp/streams.py\", line 312, in _wait\n    await waiter\naiohttp.client_exceptions.ClientPayloadError: Response payload is not completed: <TransferEncodingError: 400, message='Not enough data for satisfy transfer length header.'>\n", "Traceback (most recent call last):\n  File \"/usr/local/lib/python3.10/dist-packages/aiohttp/client_proto.py\", line 94, in connection_lost\n    uncompleted = self._parser.feed_eof()\n  File \"aiohttp/_http_parser.pyx\", line 513, in aiohttp._http_parser.HttpParser.feed_eof\naiohttp.http_exceptions.TransferEncodingError: 400, message:\n  Not enough data for satisfy transfer length header.\n\nThe above exception was the direct cause of the following exception:\n\nTraceback (most recent call last):\n  File \"/vllm-workspace/backend_request_func.py\", line 261, in async_request_openai_completions\n    async for chunk_bytes in response.content:\n  File \"/usr/local/lib/python3.10/dist-packages/aiohttp/streams.py\", line 50, in __anext__\n    rv = await self.read_func()\n  File \"/usr/local/lib/python3.10/dist-packages/aiohttp/streams.py\", line 317, in readline\n    return await self.readuntil()\n  File \"/usr/local/lib/python3.10/dist-packages/aiohttp/streams.py\", line 351, in readuntil\n    await self._wait(\"readuntil\")\n  File \"/usr/local/lib/python3.10/dist-packages/aiohttp/streams.py\", line 312, in _wait\n    await waiter\naiohttp.client_exceptions.ClientPayloadError: Response payload is not completed: <TransferEncodingError: 400, message='Not enough data for satisfy transfer length header.'>\n", "Traceback (most recent call last):\n  File \"/usr/local/lib/python3.10/dist-packages/aiohttp/client_proto.py\", line 94, in connection_lost\n    uncompleted = self._parser.feed_eof()\n  File \"aiohttp/_http_parser.pyx\", line 513, in aiohttp._http_parser.HttpParser.feed_eof\naiohttp.http_exceptions.TransferEncodingError: 400, message:\n  Not enough data for satisfy transfer length header.\n\nThe above exception was the direct cause of the following exception:\n\nTraceback (most recent call last):\n  File \"/vllm-workspace/backend_request_func.py\", line 261, in async_request_openai_completions\n    async for chunk_bytes in response.content:\n  File \"/usr/local/lib/python3.10/dist-packages/aiohttp/streams.py\", line 50, in __anext__\n    rv = await self.read_func()\n  File \"/usr/local/lib/python3.10/dist-packages/aiohttp/streams.py\", line 317, in readline\n    return await self.readuntil()\n  File \"/usr/local/lib/python3.10/dist-packages/aiohttp/streams.py\", line 351, in readuntil\n    await self._wait(\"readuntil\")\n  File \"/usr/local/lib/python3.10/dist-packages/aiohttp/streams.py\", line 312, in _wait\n    await waiter\naiohttp.client_exceptions.ClientPayloadError: Response payload is not completed: <TransferEncodingError: 400, message='Not enough data for satisfy transfer length header.'>\n", "Traceback (most recent call last):\n  File \"/usr/local/lib/python3.10/dist-packages/aiohttp/client_proto.py\", line 94, in connection_lost\n    uncompleted = self._parser.feed_eof()\n  File \"aiohttp/_http_parser.pyx\", line 513, in aiohttp._http_parser.HttpParser.feed_eof\naiohttp.http_exceptions.TransferEncodingError: 400, message:\n  Not enough data for satisfy transfer length header.\n\nThe above exception was the direct cause of the following exception:\n\nTraceback (most recent call last):\n  File \"/vllm-workspace/backend_request_func.py\", line 261, in async_request_openai_completions\n    async for chunk_bytes in response.content:\n  File \"/usr/local/lib/python3.10/dist-packages/aiohttp/streams.py\", line 50, in __anext__\n    rv = await self.read_func()\n  File \"/usr/local/lib/python3.10/dist-packages/aiohttp/streams.py\", line 317, in readline\n    return await self.readuntil()\n  File \"/usr/local/lib/python3.10/dist-packages/aiohttp/streams.py\", line 351, in readuntil\n    await self._wait(\"readuntil\")\n  File \"/usr/local/lib/python3.10/dist-packages/aiohttp/streams.py\", line 312, in _wait\n    await waiter\naiohttp.client_exceptions.ClientPayloadError: Response payload is not completed: <TransferEncodingError: 400, message='Not enough data for satisfy transfer length header.'>\n", "Traceback (most recent call last):\n  File \"/usr/local/lib/python3.10/dist-packages/aiohttp/client_proto.py\", line 94, in connection_lost\n    uncompleted = self._parser.feed_eof()\n  File \"aiohttp/_http_parser.pyx\", line 513, in aiohttp._http_parser.HttpParser.feed_eof\naiohttp.http_exceptions.TransferEncodingError: 400, message:\n  Not enough data for satisfy transfer length header.\n\nThe above exception was the direct cause of the following exception:\n\nTraceback (most recent call last):\n  File \"/vllm-workspace/backend_request_func.py\", line 261, in async_request_openai_completions\n    async for chunk_bytes in response.content:\n  File \"/usr/local/lib/python3.10/dist-packages/aiohttp/streams.py\", line 50, in __anext__\n    rv = await self.read_func()\n  File \"/usr/local/lib/python3.10/dist-packages/aiohttp/streams.py\", line 317, in readline\n    return await self.readuntil()\n  File \"/usr/local/lib/python3.10/dist-packages/aiohttp/streams.py\", line 351, in readuntil\n    await self._wait(\"readuntil\")\n  File \"/usr/local/lib/python3.10/dist-packages/aiohttp/streams.py\", line 312, in _wait\n    await waiter\naiohttp.client_exceptions.ClientPayloadError: Response payload is not completed: <TransferEncodingError: 400, message='Not enough data for satisfy transfer length header.'>\n", "", "", "Traceback (most recent call last):\n  File \"/usr/local/lib/python3.10/dist-packages/aiohttp/client_proto.py\", line 94, in connection_lost\n    uncompleted = self._parser.feed_eof()\n  File \"aiohttp/_http_parser.pyx\", line 513, in aiohttp._http_parser.HttpParser.feed_eof\naiohttp.http_exceptions.TransferEncodingError: 400, message:\n  Not enough data for satisfy transfer length header.\n\nThe above exception was the direct cause of the following exception:\n\nTraceback (most recent call last):\n  File \"/vllm-workspace/backend_request_func.py\", line 261, in async_request_openai_completions\n    async for chunk_bytes in response.content:\n  File \"/usr/local/lib/python3.10/dist-packages/aiohttp/streams.py\", line 50, in __anext__\n    rv = await self.read_func()\n  File \"/usr/local/lib/python3.10/dist-packages/aiohttp/streams.py\", line 317, in readline\n    return await self.readuntil()\n  File \"/usr/local/lib/python3.10/dist-packages/aiohttp/streams.py\", line 351, in readuntil\n    await self._wait(\"readuntil\")\n  File \"/usr/local/lib/python3.10/dist-packages/aiohttp/streams.py\", line 312, in _wait\n    await waiter\naiohttp.client_exceptions.ClientPayloadError: Response payload is not completed: <TransferEncodingError: 400, message='Not enough data for satisfy transfer length header.'>\n", "Traceback (most recent call last):\n  File \"/usr/local/lib/python3.10/dist-packages/aiohttp/client_proto.py\", line 94, in connection_lost\n    uncompleted = self._parser.feed_eof()\n  File \"aiohttp/_http_parser.pyx\", line 513, in aiohttp._http_parser.HttpParser.feed_eof\naiohttp.http_exceptions.TransferEncodingError: 400, message:\n  Not enough data for satisfy transfer length header.\n\nThe above exception was the direct cause of the following exception:\n\nTraceback (most recent call last):\n  File \"/vllm-workspace/backend_request_func.py\", line 261, in async_request_openai_completions\n    async for chunk_bytes in response.content:\n  File \"/usr/local/lib/python3.10/dist-packages/aiohttp/streams.py\", line 50, in __anext__\n    rv = await self.read_func()\n  File \"/usr/local/lib/python3.10/dist-packages/aiohttp/streams.py\", line 317, in readline\n    return await self.readuntil()\n  File \"/usr/local/lib/python3.10/dist-packages/aiohttp/streams.py\", line 351, in readuntil\n    await self._wait(\"readuntil\")\n  File \"/usr/local/lib/python3.10/dist-packages/aiohttp/streams.py\", line 312, in _wait\n    await waiter\naiohttp.client_exceptions.ClientPayloadError: Response payload is not completed: <TransferEncodingError: 400, message='Not enough data for satisfy transfer length header.'>\n", "Traceback (most recent call last):\n  File \"/usr/local/lib/python3.10/dist-packages/aiohttp/client_proto.py\", line 94, in connection_lost\n    uncompleted = self._parser.feed_eof()\n  File \"aiohttp/_http_parser.pyx\", line 513, in aiohttp._http_parser.HttpParser.feed_eof\naiohttp.http_exceptions.TransferEncodingError: 400, message:\n  Not enough data for satisfy transfer length header.\n\nThe above exception was the direct cause of the following exception:\n\nTraceback (most recent call last):\n  File \"/vllm-workspace/backend_request_func.py\", line 261, in async_request_openai_completions\n    async for chunk_bytes in response.content:\n  File \"/usr/local/lib/python3.10/dist-packages/aiohttp/streams.py\", line 50, in __anext__\n    rv = await self.read_func()\n  File \"/usr/local/lib/python3.10/dist-packages/aiohttp/streams.py\", line 317, in readline\n    return await self.readuntil()\n  File \"/usr/local/lib/python3.10/dist-packages/aiohttp/streams.py\", line 351, in readuntil\n    await self._wait(\"readuntil\")\n  File \"/usr/local/lib/python3.10/dist-packages/aiohttp/streams.py\", line 312, in _wait\n    await waiter\naiohttp.client_exceptions.ClientPayloadError: Response payload is not completed: <TransferEncodingError: 400, message='Not enough data for satisfy transfer length header.'>\n", "", "Traceback (most recent call last):\n  File \"/usr/local/lib/python3.10/dist-packages/aiohttp/client_proto.py\", line 94, in connection_lost\n    uncompleted = self._parser.feed_eof()\n  File \"aiohttp/_http_parser.pyx\", line 513, in aiohttp._http_parser.HttpParser.feed_eof\naiohttp.http_exceptions.TransferEncodingError: 400, message:\n  Not enough data for satisfy transfer length header.\n\nThe above exception was the direct cause of the following exception:\n\nTraceback (most recent call last):\n  File \"/vllm-workspace/backend_request_func.py\", line 261, in async_request_openai_completions\n    async for chunk_bytes in response.content:\n  File \"/usr/local/lib/python3.10/dist-packages/aiohttp/streams.py\", line 50, in __anext__\n    rv = await self.read_func()\n  File \"/usr/local/lib/python3.10/dist-packages/aiohttp/streams.py\", line 317, in readline\n    return await self.readuntil()\n  File \"/usr/local/lib/python3.10/dist-packages/aiohttp/streams.py\", line 351, in readuntil\n    await self._wait(\"readuntil\")\n  File \"/usr/local/lib/python3.10/dist-packages/aiohttp/streams.py\", line 312, in _wait\n    await waiter\naiohttp.client_exceptions.ClientPayloadError: Response payload is not completed: <TransferEncodingError: 400, message='Not enough data for satisfy transfer length header.'>\n", "Traceback (most recent call last):\n  File \"/usr/local/lib/python3.10/dist-packages/aiohttp/client_proto.py\", line 94, in connection_lost\n    uncompleted = self._parser.feed_eof()\n  File \"aiohttp/_http_parser.pyx\", line 513, in aiohttp._http_parser.HttpParser.feed_eof\naiohttp.http_exceptions.TransferEncodingError: 400, message:\n  Not enough data for satisfy transfer length header.\n\nThe above exception was the direct cause of the following exception:\n\nTraceback (most recent call last):\n  File \"/vllm-workspace/backend_request_func.py\", line 261, in async_request_openai_completions\n    async for chunk_bytes in response.content:\n  File \"/usr/local/lib/python3.10/dist-packages/aiohttp/streams.py\", line 50, in __anext__\n    rv = await self.read_func()\n  File \"/usr/local/lib/python3.10/dist-packages/aiohttp/streams.py\", line 317, in readline\n    return await self.readuntil()\n  File \"/usr/local/lib/python3.10/dist-packages/aiohttp/streams.py\", line 351, in readuntil\n    await self._wait(\"readuntil\")\n  File \"/usr/local/lib/python3.10/dist-packages/aiohttp/streams.py\", line 312, in _wait\n    await waiter\naiohttp.client_exceptions.ClientPayloadError: Response payload is not completed: <TransferEncodingError: 400, message='Not enough data for satisfy transfer length header.'>\n", "Traceback (most recent call last):\n  File \"/usr/local/lib/python3.10/dist-packages/aiohttp/client_proto.py\", line 94, in connection_lost\n    uncompleted = self._parser.feed_eof()\n  File \"aiohttp/_http_parser.pyx\", line 513, in aiohttp._http_parser.HttpParser.feed_eof\naiohttp.http_exceptions.TransferEncodingError: 400, message:\n  Not enough data for satisfy transfer length header.\n\nThe above exception was the direct cause of the following exception:\n\nTraceback (most recent call last):\n  File \"/vllm-workspace/backend_request_func.py\", line 261, in async_request_openai_completions\n    async for chunk_bytes in response.content:\n  File \"/usr/local/lib/python3.10/dist-packages/aiohttp/streams.py\", line 50, in __anext__\n    rv = await self.read_func()\n  File \"/usr/local/lib/python3.10/dist-packages/aiohttp/streams.py\", line 317, in readline\n    return await self.readuntil()\n  File \"/usr/local/lib/python3.10/dist-packages/aiohttp/streams.py\", line 351, in readuntil\n    await self._wait(\"readuntil\")\n  File \"/usr/local/lib/python3.10/dist-packages/aiohttp/streams.py\", line 312, in _wait\n    await waiter\naiohttp.client_exceptions.ClientPayloadError: Response payload is not completed: <TransferEncodingError: 400, message='Not enough data for satisfy transfer length header.'>\n", "Traceback (most recent call last):\n  File \"/usr/local/lib/python3.10/dist-packages/aiohttp/client_proto.py\", line 94, in connection_lost\n    uncompleted = self._parser.feed_eof()\n  File \"aiohttp/_http_parser.pyx\", line 513, in aiohttp._http_parser.HttpParser.feed_eof\naiohttp.http_exceptions.TransferEncodingError: 400, message:\n  Not enough data for satisfy transfer length header.\n\nThe above exception was the direct cause of the following exception:\n\nTraceback (most recent call last):\n  File \"/vllm-workspace/backend_request_func.py\", line 261, in async_request_openai_completions\n    async for chunk_bytes in response.content:\n  File \"/usr/local/lib/python3.10/dist-packages/aiohttp/streams.py\", line 50, in __anext__\n    rv = await self.read_func()\n  File \"/usr/local/lib/python3.10/dist-packages/aiohttp/streams.py\", line 317, in readline\n    return await self.readuntil()\n  File \"/usr/local/lib/python3.10/dist-packages/aiohttp/streams.py\", line 351, in readuntil\n    await self._wait(\"readuntil\")\n  File \"/usr/local/lib/python3.10/dist-packages/aiohttp/streams.py\", line 312, in _wait\n    await waiter\naiohttp.client_exceptions.ClientPayloadError: Response payload is not completed: <TransferEncodingError: 400, message='Not enough data for satisfy transfer length header.'>\n", "Traceback (most recent call last):\n  File \"/usr/local/lib/python3.10/dist-packages/aiohttp/client_proto.py\", line 94, in connection_lost\n    uncompleted = self._parser.feed_eof()\n  File \"aiohttp/_http_parser.pyx\", line 513, in aiohttp._http_parser.HttpParser.feed_eof\naiohttp.http_exceptions.TransferEncodingError: 400, message:\n  Not enough data for satisfy transfer length header.\n\nThe above exception was the direct cause of the following exception:\n\nTraceback (most recent call last):\n  File \"/vllm-workspace/backend_request_func.py\", line 261, in async_request_openai_completions\n    async for chunk_bytes in response.content:\n  File \"/usr/local/lib/python3.10/dist-packages/aiohttp/streams.py\", line 50, in __anext__\n    rv = await self.read_func()\n  File \"/usr/local/lib/python3.10/dist-packages/aiohttp/streams.py\", line 317, in readline\n    return await self.readuntil()\n  File \"/usr/local/lib/python3.10/dist-packages/aiohttp/streams.py\", line 351, in readuntil\n    await self._wait(\"readuntil\")\n  File \"/usr/local/lib/python3.10/dist-packages/aiohttp/streams.py\", line 312, in _wait\n    await waiter\naiohttp.client_exceptions.ClientPayloadError: Response payload is not completed: <TransferEncodingError: 400, message='Not enough data for satisfy transfer length header.'>\n", "Traceback (most recent call last):\n  File \"/usr/local/lib/python3.10/dist-packages/aiohttp/client_proto.py\", line 94, in connection_lost\n    uncompleted = self._parser.feed_eof()\n  File \"aiohttp/_http_parser.pyx\", line 513, in aiohttp._http_parser.HttpParser.feed_eof\naiohttp.http_exceptions.TransferEncodingError: 400, message:\n  Not enough data for satisfy transfer length header.\n\nThe above exception was the direct cause of the following exception:\n\nTraceback (most recent call last):\n  File \"/vllm-workspace/backend_request_func.py\", line 261, in async_request_openai_completions\n    async for chunk_bytes in response.content:\n  File \"/usr/local/lib/python3.10/dist-packages/aiohttp/streams.py\", line 50, in __anext__\n    rv = await self.read_func()\n  File \"/usr/local/lib/python3.10/dist-packages/aiohttp/streams.py\", line 317, in readline\n    return await self.readuntil()\n  File \"/usr/local/lib/python3.10/dist-packages/aiohttp/streams.py\", line 351, in readuntil\n    await self._wait(\"readuntil\")\n  File \"/usr/local/lib/python3.10/dist-packages/aiohttp/streams.py\", line 312, in _wait\n    await waiter\naiohttp.client_exceptions.ClientPayloadError: Response payload is not completed: <TransferEncodingError: 400, message='Not enough data for satisfy transfer length header.'>\n", "Traceback (most recent call last):\n  File \"/usr/local/lib/python3.10/dist-packages/aiohttp/client_proto.py\", line 94, in connection_lost\n    uncompleted = self._parser.feed_eof()\n  File \"aiohttp/_http_parser.pyx\", line 513, in aiohttp._http_parser.HttpParser.feed_eof\naiohttp.http_exceptions.TransferEncodingError: 400, message:\n  Not enough data for satisfy transfer length header.\n\nThe above exception was the direct cause of the following exception:\n\nTraceback (most recent call last):\n  File \"/vllm-workspace/backend_request_func.py\", line 261, in async_request_openai_completions\n    async for chunk_bytes in response.content:\n  File \"/usr/local/lib/python3.10/dist-packages/aiohttp/streams.py\", line 50, in __anext__\n    rv = await self.read_func()\n  File \"/usr/local/lib/python3.10/dist-packages/aiohttp/streams.py\", line 317, in readline\n    return await self.readuntil()\n  File \"/usr/local/lib/python3.10/dist-packages/aiohttp/streams.py\", line 351, in readuntil\n    await self._wait(\"readuntil\")\n  File \"/usr/local/lib/python3.10/dist-packages/aiohttp/streams.py\", line 312, in _wait\n    await waiter\naiohttp.client_exceptions.ClientPayloadError: Response payload is not completed: <TransferEncodingError: 400, message='Not enough data for satisfy transfer length header.'>\n", "Traceback (most recent call last):\n  File \"/usr/local/lib/python3.10/dist-packages/aiohttp/client_proto.py\", line 94, in connection_lost\n    uncompleted = self._parser.feed_eof()\n  File \"aiohttp/_http_parser.pyx\", line 513, in aiohttp._http_parser.HttpParser.feed_eof\naiohttp.http_exceptions.TransferEncodingError: 400, message:\n  Not enough data for satisfy transfer length header.\n\nThe above exception was the direct cause of the following exception:\n\nTraceback (most recent call last):\n  File \"/vllm-workspace/backend_request_func.py\", line 261, in async_request_openai_completions\n    async for chunk_bytes in response.content:\n  File \"/usr/local/lib/python3.10/dist-packages/aiohttp/streams.py\", line 50, in __anext__\n    rv = await self.read_func()\n  File \"/usr/local/lib/python3.10/dist-packages/aiohttp/streams.py\", line 317, in readline\n    return await self.readuntil()\n  File \"/usr/local/lib/python3.10/dist-packages/aiohttp/streams.py\", line 351, in readuntil\n    await self._wait(\"readuntil\")\n  File \"/usr/local/lib/python3.10/dist-packages/aiohttp/streams.py\", line 312, in _wait\n    await waiter\naiohttp.client_exceptions.ClientPayloadError: Response payload is not completed: <TransferEncodingError: 400, message='Not enough data for satisfy transfer length header.'>\n", "Traceback (most recent call last):\n  File \"/usr/local/lib/python3.10/dist-packages/aiohttp/client_proto.py\", line 94, in connection_lost\n    uncompleted = self._parser.feed_eof()\n  File \"aiohttp/_http_parser.pyx\", line 513, in aiohttp._http_parser.HttpParser.feed_eof\naiohttp.http_exceptions.TransferEncodingError: 400, message:\n  Not enough data for satisfy transfer length header.\n\nThe above exception was the direct cause of the following exception:\n\nTraceback (most recent call last):\n  File \"/vllm-workspace/backend_request_func.py\", line 261, in async_request_openai_completions\n    async for chunk_bytes in response.content:\n  File \"/usr/local/lib/python3.10/dist-packages/aiohttp/streams.py\", line 50, in __anext__\n    rv = await self.read_func()\n  File \"/usr/local/lib/python3.10/dist-packages/aiohttp/streams.py\", line 317, in readline\n    return await self.readuntil()\n  File \"/usr/local/lib/python3.10/dist-packages/aiohttp/streams.py\", line 351, in readuntil\n    await self._wait(\"readuntil\")\n  File \"/usr/local/lib/python3.10/dist-packages/aiohttp/streams.py\", line 312, in _wait\n    await waiter\naiohttp.client_exceptions.ClientPayloadError: Response payload is not completed: <TransferEncodingError: 400, message='Not enough data for satisfy transfer length header.'>\n", "Traceback (most recent call last):\n  File \"/usr/local/lib/python3.10/dist-packages/aiohttp/client_proto.py\", line 94, in connection_lost\n    uncompleted = self._parser.feed_eof()\n  File \"aiohttp/_http_parser.pyx\", line 513, in aiohttp._http_parser.HttpParser.feed_eof\naiohttp.http_exceptions.TransferEncodingError: 400, message:\n  Not enough data for satisfy transfer length header.\n\nThe above exception was the direct cause of the following exception:\n\nTraceback (most recent call last):\n  File \"/vllm-workspace/backend_request_func.py\", line 261, in async_request_openai_completions\n    async for chunk_bytes in response.content:\n  File \"/usr/local/lib/python3.10/dist-packages/aiohttp/streams.py\", line 50, in __anext__\n    rv = await self.read_func()\n  File \"/usr/local/lib/python3.10/dist-packages/aiohttp/streams.py\", line 317, in readline\n    return await self.readuntil()\n  File \"/usr/local/lib/python3.10/dist-packages/aiohttp/streams.py\", line 351, in readuntil\n    await self._wait(\"readuntil\")\n  File \"/usr/local/lib/python3.10/dist-packages/aiohttp/streams.py\", line 312, in _wait\n    await waiter\naiohttp.client_exceptions.ClientPayloadError: Response payload is not completed: <TransferEncodingError: 400, message='Not enough data for satisfy transfer length header.'>\n", "Traceback (most recent call last):\n  File \"/usr/local/lib/python3.10/dist-packages/aiohttp/client_proto.py\", line 94, in connection_lost\n    uncompleted = self._parser.feed_eof()\n  File \"aiohttp/_http_parser.pyx\", line 513, in aiohttp._http_parser.HttpParser.feed_eof\naiohttp.http_exceptions.TransferEncodingError: 400, message:\n  Not enough data for satisfy transfer length header.\n\nThe above exception was the direct cause of the following exception:\n\nTraceback (most recent call last):\n  File \"/vllm-workspace/backend_request_func.py\", line 261, in async_request_openai_completions\n    async for chunk_bytes in response.content:\n  File \"/usr/local/lib/python3.10/dist-packages/aiohttp/streams.py\", line 50, in __anext__\n    rv = await self.read_func()\n  File \"/usr/local/lib/python3.10/dist-packages/aiohttp/streams.py\", line 317, in readline\n    return await self.readuntil()\n  File \"/usr/local/lib/python3.10/dist-packages/aiohttp/streams.py\", line 351, in readuntil\n    await self._wait(\"readuntil\")\n  File \"/usr/local/lib/python3.10/dist-packages/aiohttp/streams.py\", line 312, in _wait\n    await waiter\naiohttp.client_exceptions.ClientPayloadError: Response payload is not completed: <TransferEncodingError: 400, message='Not enough data for satisfy transfer length header.'>\n", "Traceback (most recent call last):\n  File \"/usr/local/lib/python3.10/dist-packages/aiohttp/client_proto.py\", line 94, in connection_lost\n    uncompleted = self._parser.feed_eof()\n  File \"aiohttp/_http_parser.pyx\", line 513, in aiohttp._http_parser.HttpParser.feed_eof\naiohttp.http_exceptions.TransferEncodingError: 400, message:\n  Not enough data for satisfy transfer length header.\n\nThe above exception was the direct cause of the following exception:\n\nTraceback (most recent call last):\n  File \"/vllm-workspace/backend_request_func.py\", line 261, in async_request_openai_completions\n    async for chunk_bytes in response.content:\n  File \"/usr/local/lib/python3.10/dist-packages/aiohttp/streams.py\", line 50, in __anext__\n    rv = await self.read_func()\n  File \"/usr/local/lib/python3.10/dist-packages/aiohttp/streams.py\", line 317, in readline\n    return await self.readuntil()\n  File \"/usr/local/lib/python3.10/dist-packages/aiohttp/streams.py\", line 351, in readuntil\n    await self._wait(\"readuntil\")\n  File \"/usr/local/lib/python3.10/dist-packages/aiohttp/streams.py\", line 312, in _wait\n    await waiter\naiohttp.client_exceptions.ClientPayloadError: Response payload is not completed: <TransferEncodingError: 400, message='Not enough data for satisfy transfer length header.'>\n", "", "Traceback (most recent call last):\n  File \"/usr/local/lib/python3.10/dist-packages/aiohttp/client_proto.py\", line 94, in connection_lost\n    uncompleted = self._parser.feed_eof()\n  File \"aiohttp/_http_parser.pyx\", line 513, in aiohttp._http_parser.HttpParser.feed_eof\naiohttp.http_exceptions.TransferEncodingError: 400, message:\n  Not enough data for satisfy transfer length header.\n\nThe above exception was the direct cause of the following exception:\n\nTraceback (most recent call last):\n  File \"/vllm-workspace/backend_request_func.py\", line 261, in async_request_openai_completions\n    async for chunk_bytes in response.content:\n  File \"/usr/local/lib/python3.10/dist-packages/aiohttp/streams.py\", line 50, in __anext__\n    rv = await self.read_func()\n  File \"/usr/local/lib/python3.10/dist-packages/aiohttp/streams.py\", line 317, in readline\n    return await self.readuntil()\n  File \"/usr/local/lib/python3.10/dist-packages/aiohttp/streams.py\", line 351, in readuntil\n    await self._wait(\"readuntil\")\n  File \"/usr/local/lib/python3.10/dist-packages/aiohttp/streams.py\", line 312, in _wait\n    await waiter\naiohttp.client_exceptions.ClientPayloadError: Response payload is not completed: <TransferEncodingError: 400, message='Not enough data for satisfy transfer length header.'>\n", "Traceback (most recent call last):\n  File \"/usr/local/lib/python3.10/dist-packages/aiohttp/client_proto.py\", line 94, in connection_lost\n    uncompleted = self._parser.feed_eof()\n  File \"aiohttp/_http_parser.pyx\", line 513, in aiohttp._http_parser.HttpParser.feed_eof\naiohttp.http_exceptions.TransferEncodingError: 400, message:\n  Not enough data for satisfy transfer length header.\n\nThe above exception was the direct cause of the following exception:\n\nTraceback (most recent call last):\n  File \"/vllm-workspace/backend_request_func.py\", line 261, in async_request_openai_completions\n    async for chunk_bytes in response.content:\n  File \"/usr/local/lib/python3.10/dist-packages/aiohttp/streams.py\", line 50, in __anext__\n    rv = await self.read_func()\n  File \"/usr/local/lib/python3.10/dist-packages/aiohttp/streams.py\", line 317, in readline\n    return await self.readuntil()\n  File \"/usr/local/lib/python3.10/dist-packages/aiohttp/streams.py\", line 351, in readuntil\n    await self._wait(\"readuntil\")\n  File \"/usr/local/lib/python3.10/dist-packages/aiohttp/streams.py\", line 312, in _wait\n    await waiter\naiohttp.client_exceptions.ClientPayloadError: Response payload is not completed: <TransferEncodingError: 400, message='Not enough data for satisfy transfer length header.'>\n", "Traceback (most recent call last):\n  File \"/usr/local/lib/python3.10/dist-packages/aiohttp/client_proto.py\", line 94, in connection_lost\n    uncompleted = self._parser.feed_eof()\n  File \"aiohttp/_http_parser.pyx\", line 513, in aiohttp._http_parser.HttpParser.feed_eof\naiohttp.http_exceptions.TransferEncodingError: 400, message:\n  Not enough data for satisfy transfer length header.\n\nThe above exception was the direct cause of the following exception:\n\nTraceback (most recent call last):\n  File \"/vllm-workspace/backend_request_func.py\", line 261, in async_request_openai_completions\n    async for chunk_bytes in response.content:\n  File \"/usr/local/lib/python3.10/dist-packages/aiohttp/streams.py\", line 50, in __anext__\n    rv = await self.read_func()\n  File \"/usr/local/lib/python3.10/dist-packages/aiohttp/streams.py\", line 317, in readline\n    return await self.readuntil()\n  File \"/usr/local/lib/python3.10/dist-packages/aiohttp/streams.py\", line 351, in readuntil\n    await self._wait(\"readuntil\")\n  File \"/usr/local/lib/python3.10/dist-packages/aiohttp/streams.py\", line 312, in _wait\n    await waiter\naiohttp.client_exceptions.ClientPayloadError: Response payload is not completed: <TransferEncodingError: 400, message='Not enough data for satisfy transfer length header.'>\n", "Traceback (most recent call last):\n  File \"/usr/local/lib/python3.10/dist-packages/aiohttp/client_proto.py\", line 94, in connection_lost\n    uncompleted = self._parser.feed_eof()\n  File \"aiohttp/_http_parser.pyx\", line 513, in aiohttp._http_parser.HttpParser.feed_eof\naiohttp.http_exceptions.TransferEncodingError: 400, message:\n  Not enough data for satisfy transfer length header.\n\nThe above exception was the direct cause of the following exception:\n\nTraceback (most recent call last):\n  File \"/vllm-workspace/backend_request_func.py\", line 261, in async_request_openai_completions\n    async for chunk_bytes in response.content:\n  File \"/usr/local/lib/python3.10/dist-packages/aiohttp/streams.py\", line 50, in __anext__\n    rv = await self.read_func()\n  File \"/usr/local/lib/python3.10/dist-packages/aiohttp/streams.py\", line 317, in readline\n    return await self.readuntil()\n  File \"/usr/local/lib/python3.10/dist-packages/aiohttp/streams.py\", line 351, in readuntil\n    await self._wait(\"readuntil\")\n  File \"/usr/local/lib/python3.10/dist-packages/aiohttp/streams.py\", line 312, in _wait\n    await waiter\naiohttp.client_exceptions.ClientPayloadError: Response payload is not completed: <TransferEncodingError: 400, message='Not enough data for satisfy transfer length header.'>\n", "Traceback (most recent call last):\n  File \"/usr/local/lib/python3.10/dist-packages/aiohttp/client_proto.py\", line 94, in connection_lost\n    uncompleted = self._parser.feed_eof()\n  File \"aiohttp/_http_parser.pyx\", line 513, in aiohttp._http_parser.HttpParser.feed_eof\naiohttp.http_exceptions.TransferEncodingError: 400, message:\n  Not enough data for satisfy transfer length header.\n\nThe above exception was the direct cause of the following exception:\n\nTraceback (most recent call last):\n  File \"/vllm-workspace/backend_request_func.py\", line 261, in async_request_openai_completions\n    async for chunk_bytes in response.content:\n  File \"/usr/local/lib/python3.10/dist-packages/aiohttp/streams.py\", line 50, in __anext__\n    rv = await self.read_func()\n  File \"/usr/local/lib/python3.10/dist-packages/aiohttp/streams.py\", line 317, in readline\n    return await self.readuntil()\n  File \"/usr/local/lib/python3.10/dist-packages/aiohttp/streams.py\", line 351, in readuntil\n    await self._wait(\"readuntil\")\n  File \"/usr/local/lib/python3.10/dist-packages/aiohttp/streams.py\", line 312, in _wait\n    await waiter\naiohttp.client_exceptions.ClientPayloadError: Response payload is not completed: <TransferEncodingError: 400, message='Not enough data for satisfy transfer length header.'>\n", "Traceback (most recent call last):\n  File \"/usr/local/lib/python3.10/dist-packages/aiohttp/client_proto.py\", line 94, in connection_lost\n    uncompleted = self._parser.feed_eof()\n  File \"aiohttp/_http_parser.pyx\", line 513, in aiohttp._http_parser.HttpParser.feed_eof\naiohttp.http_exceptions.TransferEncodingError: 400, message:\n  Not enough data for satisfy transfer length header.\n\nThe above exception was the direct cause of the following exception:\n\nTraceback (most recent call last):\n  File \"/vllm-workspace/backend_request_func.py\", line 261, in async_request_openai_completions\n    async for chunk_bytes in response.content:\n  File \"/usr/local/lib/python3.10/dist-packages/aiohttp/streams.py\", line 50, in __anext__\n    rv = await self.read_func()\n  File \"/usr/local/lib/python3.10/dist-packages/aiohttp/streams.py\", line 317, in readline\n    return await self.readuntil()\n  File \"/usr/local/lib/python3.10/dist-packages/aiohttp/streams.py\", line 351, in readuntil\n    await self._wait(\"readuntil\")\n  File \"/usr/local/lib/python3.10/dist-packages/aiohttp/streams.py\", line 312, in _wait\n    await waiter\naiohttp.client_exceptions.ClientPayloadError: Response payload is not completed: <TransferEncodingError: 400, message='Not enough data for satisfy transfer length header.'>\n", "Traceback (most recent call last):\n  File \"/usr/local/lib/python3.10/dist-packages/aiohttp/client_proto.py\", line 94, in connection_lost\n    uncompleted = self._parser.feed_eof()\n  File \"aiohttp/_http_parser.pyx\", line 513, in aiohttp._http_parser.HttpParser.feed_eof\naiohttp.http_exceptions.TransferEncodingError: 400, message:\n  Not enough data for satisfy transfer length header.\n\nThe above exception was the direct cause of the following exception:\n\nTraceback (most recent call last):\n  File \"/vllm-workspace/backend_request_func.py\", line 261, in async_request_openai_completions\n    async for chunk_bytes in response.content:\n  File \"/usr/local/lib/python3.10/dist-packages/aiohttp/streams.py\", line 50, in __anext__\n    rv = await self.read_func()\n  File \"/usr/local/lib/python3.10/dist-packages/aiohttp/streams.py\", line 317, in readline\n    return await self.readuntil()\n  File \"/usr/local/lib/python3.10/dist-packages/aiohttp/streams.py\", line 351, in readuntil\n    await self._wait(\"readuntil\")\n  File \"/usr/local/lib/python3.10/dist-packages/aiohttp/streams.py\", line 312, in _wait\n    await waiter\naiohttp.client_exceptions.ClientPayloadError: Response payload is not completed: <TransferEncodingError: 400, message='Not enough data for satisfy transfer length header.'>\n", "Traceback (most recent call last):\n  File \"/usr/local/lib/python3.10/dist-packages/aiohttp/client_proto.py\", line 94, in connection_lost\n    uncompleted = self._parser.feed_eof()\n  File \"aiohttp/_http_parser.pyx\", line 513, in aiohttp._http_parser.HttpParser.feed_eof\naiohttp.http_exceptions.TransferEncodingError: 400, message:\n  Not enough data for satisfy transfer length header.\n\nThe above exception was the direct cause of the following exception:\n\nTraceback (most recent call last):\n  File \"/vllm-workspace/backend_request_func.py\", line 261, in async_request_openai_completions\n    async for chunk_bytes in response.content:\n  File \"/usr/local/lib/python3.10/dist-packages/aiohttp/streams.py\", line 50, in __anext__\n    rv = await self.read_func()\n  File \"/usr/local/lib/python3.10/dist-packages/aiohttp/streams.py\", line 317, in readline\n    return await self.readuntil()\n  File \"/usr/local/lib/python3.10/dist-packages/aiohttp/streams.py\", line 351, in readuntil\n    await self._wait(\"readuntil\")\n  File \"/usr/local/lib/python3.10/dist-packages/aiohttp/streams.py\", line 312, in _wait\n    await waiter\naiohttp.client_exceptions.ClientPayloadError: Response payload is not completed: <TransferEncodingError: 400, message='Not enough data for satisfy transfer length header.'>\n", "Traceback (most recent call last):\n  File \"/usr/local/lib/python3.10/dist-packages/aiohttp/client_proto.py\", line 94, in connection_lost\n    uncompleted = self._parser.feed_eof()\n  File \"aiohttp/_http_parser.pyx\", line 513, in aiohttp._http_parser.HttpParser.feed_eof\naiohttp.http_exceptions.TransferEncodingError: 400, message:\n  Not enough data for satisfy transfer length header.\n\nThe above exception was the direct cause of the following exception:\n\nTraceback (most recent call last):\n  File \"/vllm-workspace/backend_request_func.py\", line 261, in async_request_openai_completions\n    async for chunk_bytes in response.content:\n  File \"/usr/local/lib/python3.10/dist-packages/aiohttp/streams.py\", line 50, in __anext__\n    rv = await self.read_func()\n  File \"/usr/local/lib/python3.10/dist-packages/aiohttp/streams.py\", line 317, in readline\n    return await self.readuntil()\n  File \"/usr/local/lib/python3.10/dist-packages/aiohttp/streams.py\", line 351, in readuntil\n    await self._wait(\"readuntil\")\n  File \"/usr/local/lib/python3.10/dist-packages/aiohttp/streams.py\", line 312, in _wait\n    await waiter\naiohttp.client_exceptions.ClientPayloadError: Response payload is not completed: <TransferEncodingError: 400, message='Not enough data for satisfy transfer length header.'>\n", "Traceback (most recent call last):\n  File \"/usr/local/lib/python3.10/dist-packages/aiohttp/client_proto.py\", line 94, in connection_lost\n    uncompleted = self._parser.feed_eof()\n  File \"aiohttp/_http_parser.pyx\", line 513, in aiohttp._http_parser.HttpParser.feed_eof\naiohttp.http_exceptions.TransferEncodingError: 400, message:\n  Not enough data for satisfy transfer length header.\n\nThe above exception was the direct cause of the following exception:\n\nTraceback (most recent call last):\n  File \"/vllm-workspace/backend_request_func.py\", line 261, in async_request_openai_completions\n    async for chunk_bytes in response.content:\n  File \"/usr/local/lib/python3.10/dist-packages/aiohttp/streams.py\", line 50, in __anext__\n    rv = await self.read_func()\n  File \"/usr/local/lib/python3.10/dist-packages/aiohttp/streams.py\", line 317, in readline\n    return await self.readuntil()\n  File \"/usr/local/lib/python3.10/dist-packages/aiohttp/streams.py\", line 351, in readuntil\n    await self._wait(\"readuntil\")\n  File \"/usr/local/lib/python3.10/dist-packages/aiohttp/streams.py\", line 312, in _wait\n    await waiter\naiohttp.client_exceptions.ClientPayloadError: Response payload is not completed: <TransferEncodingError: 400, message='Not enough data for satisfy transfer length header.'>\n", "Traceback (most recent call last):\n  File \"/usr/local/lib/python3.10/dist-packages/aiohttp/client_proto.py\", line 94, in connection_lost\n    uncompleted = self._parser.feed_eof()\n  File \"aiohttp/_http_parser.pyx\", line 513, in aiohttp._http_parser.HttpParser.feed_eof\naiohttp.http_exceptions.TransferEncodingError: 400, message:\n  Not enough data for satisfy transfer length header.\n\nThe above exception was the direct cause of the following exception:\n\nTraceback (most recent call last):\n  File \"/vllm-workspace/backend_request_func.py\", line 261, in async_request_openai_completions\n    async for chunk_bytes in response.content:\n  File \"/usr/local/lib/python3.10/dist-packages/aiohttp/streams.py\", line 50, in __anext__\n    rv = await self.read_func()\n  File \"/usr/local/lib/python3.10/dist-packages/aiohttp/streams.py\", line 317, in readline\n    return await self.readuntil()\n  File \"/usr/local/lib/python3.10/dist-packages/aiohttp/streams.py\", line 351, in readuntil\n    await self._wait(\"readuntil\")\n  File \"/usr/local/lib/python3.10/dist-packages/aiohttp/streams.py\", line 312, in _wait\n    await waiter\naiohttp.client_exceptions.ClientPayloadError: Response payload is not completed: <TransferEncodingError: 400, message='Not enough data for satisfy transfer length header.'>\n", "Traceback (most recent call last):\n  File \"/usr/local/lib/python3.10/dist-packages/aiohttp/client_proto.py\", line 94, in connection_lost\n    uncompleted = self._parser.feed_eof()\n  File \"aiohttp/_http_parser.pyx\", line 513, in aiohttp._http_parser.HttpParser.feed_eof\naiohttp.http_exceptions.TransferEncodingError: 400, message:\n  Not enough data for satisfy transfer length header.\n\nThe above exception was the direct cause of the following exception:\n\nTraceback (most recent call last):\n  File \"/vllm-workspace/backend_request_func.py\", line 261, in async_request_openai_completions\n    async for chunk_bytes in response.content:\n  File \"/usr/local/lib/python3.10/dist-packages/aiohttp/streams.py\", line 50, in __anext__\n    rv = await self.read_func()\n  File \"/usr/local/lib/python3.10/dist-packages/aiohttp/streams.py\", line 317, in readline\n    return await self.readuntil()\n  File \"/usr/local/lib/python3.10/dist-packages/aiohttp/streams.py\", line 351, in readuntil\n    await self._wait(\"readuntil\")\n  File \"/usr/local/lib/python3.10/dist-packages/aiohttp/streams.py\", line 312, in _wait\n    await waiter\naiohttp.client_exceptions.ClientPayloadError: Response payload is not completed: <TransferEncodingError: 400, message='Not enough data for satisfy transfer length header.'>\n", "Traceback (most recent call last):\n  File \"/usr/local/lib/python3.10/dist-packages/aiohttp/client_proto.py\", line 94, in connection_lost\n    uncompleted = self._parser.feed_eof()\n  File \"aiohttp/_http_parser.pyx\", line 513, in aiohttp._http_parser.HttpParser.feed_eof\naiohttp.http_exceptions.TransferEncodingError: 400, message:\n  Not enough data for satisfy transfer length header.\n\nThe above exception was the direct cause of the following exception:\n\nTraceback (most recent call last):\n  File \"/vllm-workspace/backend_request_func.py\", line 261, in async_request_openai_completions\n    async for chunk_bytes in response.content:\n  File \"/usr/local/lib/python3.10/dist-packages/aiohttp/streams.py\", line 50, in __anext__\n    rv = await self.read_func()\n  File \"/usr/local/lib/python3.10/dist-packages/aiohttp/streams.py\", line 317, in readline\n    return await self.readuntil()\n  File \"/usr/local/lib/python3.10/dist-packages/aiohttp/streams.py\", line 351, in readuntil\n    await self._wait(\"readuntil\")\n  File \"/usr/local/lib/python3.10/dist-packages/aiohttp/streams.py\", line 312, in _wait\n    await waiter\naiohttp.client_exceptions.ClientPayloadError: Response payload is not completed: <TransferEncodingError: 400, message='Not enough data for satisfy transfer length header.'>\n", "Traceback (most recent call last):\n  File \"/usr/local/lib/python3.10/dist-packages/aiohttp/client_proto.py\", line 94, in connection_lost\n    uncompleted = self._parser.feed_eof()\n  File \"aiohttp/_http_parser.pyx\", line 513, in aiohttp._http_parser.HttpParser.feed_eof\naiohttp.http_exceptions.TransferEncodingError: 400, message:\n  Not enough data for satisfy transfer length header.\n\nThe above exception was the direct cause of the following exception:\n\nTraceback (most recent call last):\n  File \"/vllm-workspace/backend_request_func.py\", line 261, in async_request_openai_completions\n    async for chunk_bytes in response.content:\n  File \"/usr/local/lib/python3.10/dist-packages/aiohttp/streams.py\", line 50, in __anext__\n    rv = await self.read_func()\n  File \"/usr/local/lib/python3.10/dist-packages/aiohttp/streams.py\", line 317, in readline\n    return await self.readuntil()\n  File \"/usr/local/lib/python3.10/dist-packages/aiohttp/streams.py\", line 351, in readuntil\n    await self._wait(\"readuntil\")\n  File \"/usr/local/lib/python3.10/dist-packages/aiohttp/streams.py\", line 312, in _wait\n    await waiter\naiohttp.client_exceptions.ClientPayloadError: Response payload is not completed: <TransferEncodingError: 400, message='Not enough data for satisfy transfer length header.'>\n", "Traceback (most recent call last):\n  File \"/usr/local/lib/python3.10/dist-packages/aiohttp/client_proto.py\", line 94, in connection_lost\n    uncompleted = self._parser.feed_eof()\n  File \"aiohttp/_http_parser.pyx\", line 513, in aiohttp._http_parser.HttpParser.feed_eof\naiohttp.http_exceptions.TransferEncodingError: 400, message:\n  Not enough data for satisfy transfer length header.\n\nThe above exception was the direct cause of the following exception:\n\nTraceback (most recent call last):\n  File \"/vllm-workspace/backend_request_func.py\", line 261, in async_request_openai_completions\n    async for chunk_bytes in response.content:\n  File \"/usr/local/lib/python3.10/dist-packages/aiohttp/streams.py\", line 50, in __anext__\n    rv = await self.read_func()\n  File \"/usr/local/lib/python3.10/dist-packages/aiohttp/streams.py\", line 317, in readline\n    return await self.readuntil()\n  File \"/usr/local/lib/python3.10/dist-packages/aiohttp/streams.py\", line 351, in readuntil\n    await self._wait(\"readuntil\")\n  File \"/usr/local/lib/python3.10/dist-packages/aiohttp/streams.py\", line 312, in _wait\n    await waiter\naiohttp.client_exceptions.ClientPayloadError: Response payload is not completed: <TransferEncodingError: 400, message='Not enough data for satisfy transfer length header.'>\n"]}