{"date": "20240908-002644", "backend": "vllm", "model_id": "NousResearch/Hermes-3-Llama-3.1-405B-FP8", "tokenizer_id": "NousResearch/Hermes-3-Llama-3.1-405B-FP8", "best_of": 1, "use_beam_search": false, "num_prompts": 160, "request_rate": "inf", "duration": 27.98893614858389, "completed": 17, "total_input_tokens": 7375, "total_output_tokens": 117, "request_throughput": 0.6073828569172008, "input_throughput": 263.49697469202096, "output_throughput": 4.180223191724265, "mean_ttft_ms": 17077.862360679053, "median_ttft_ms": 15488.324031233788, "std_ttft_ms": 8540.771559707342, "p99_ttft_ms": 27656.599743962288, "mean_tpot_ms": 1667.1956894590573, "median_tpot_ms": 1949.27541539073, "std_tpot_ms": 1471.2479399070398, "p99_tpot_ms": 4326.162047038475, "mean_itl_ms": 16068.689533255316, "median_itl_ms": 17141.841247677803, "std_itl_ms": 4719.662614157349, "p99_itl_ms": 22645.679276436567, "mean_latency_ms": 2920.1039656531066, "median_latency_ms": 0.0, "std_latency_ms": 8469.341952180532, "p99_latency_ms": 27729.98999159783, "input_lens": [13, 25, 27, 10, 329, 29, 399, 328, 4, 205, 16, 372, 403, 9, 12, 770, 227, 8, 14, 390, 659, 59, 76, 744, 619, 279, 344, 9, 10, 45, 11, 4, 80, 768, 317, 40, 619, 8, 298, 16, 17, 696, 575, 11, 7, 281, 12, 147, 481, 770, 336, 6, 331, 9, 45, 222, 802, 481, 93, 641, 22, 15, 16, 77, 32, 689, 178, 9, 628, 480, 42, 336, 24, 515, 761, 112, 113, 348, 82, 467, 245, 11, 24, 343, 13, 387, 258, 32, 28, 225, 248, 35, 133, 98, 27, 23, 58, 363, 203, 140, 140, 230, 310, 521, 768, 317, 298, 336, 491, 19, 10, 59, 48, 20, 20, 54, 107, 53, 72, 18, 10, 768, 7, 933, 239, 277, 26, 35, 462, 386, 25, 23, 17, 20, 44, 661, 631, 349, 53, 71, 37, 10, 21, 37, 496, 8, 9, 353, 10, 595, 5, 49, 286, 305, 56, 43, 52, 310, 35, 7], "output_lens": [0, 0, 0, 0, 0, 0, 9, 0, 6, 0, 0, 0, 0, 0, 0, 5, 0, 0, 0, 0, 0, 0, 0, 0, 0, 0, 0, 0, 0, 4, 5, 0, 0, 11, 0, 0, 0, 0, 0, 0, 0, 0, 0, 0, 0, 0, 0, 0, 0, 0, 0, 0, 11, 0, 0, 0, 0, 6, 0, 3, 0, 5, 0, 0, 0, 0, 0, 0, 0, 0, 0, 0, 0, 0, 0, 0, 0, 0, 0, 8, 0, 0, 0, 0, 0, 0, 0, 0, 0, 0, 0, 0, 0, 0, 0, 0, 0, 0, 0, 0, 0, 0, 0, 0, 7, 5, 11, 0, 0, 0, 0, 0, 0, 0, 0, 0, 0, 0, 0, 0, 0, 9, 0, 0, 0, 0, 0, 0, 0, 0, 0, 0, 0, 0, 0, 2, 10, 0, 0, 0, 0, 0, 0, 0, 0, 0, 0, 0, 0, 0, 0, 0, 0, 0, 0, 0, 0, 0, 0, 0], "ttfts": [8.95963141322136, 8.959124181419611, 8.959091071039438, 8.958983659744263, 8.958678387105465, 8.958552449941635, 10.247125521302223, 10.246994897723198, 10.246876414865255, 10.246892634779215, 10.246581628918648, 10.246651530265808, 10.246547926217318, 10.24611472710967, 10.246250692754984, 27.397405799478292, 11.176878366619349, 11.176497619599104, 11.176145039498806, 12.615612920373678, 11.175947617739439, 11.175915587693453, 11.175829123705626, 12.614927232265472, 27.743735138326883, 27.738268356770277, 27.738183870911598, 12.614354245364666, 14.06489697098732, 14.064814370125532, 14.065266363322735, 14.065490774810314, 14.06504039466381, 15.488324031233788, 14.064534738659859, 14.064513366669416, 16.893329992890358, 14.064482863992453, 27.74158814176917, 16.892290242016315, 16.892158947885036, 27.741187926381826, 27.74110773578286, 16.891424123197794, 16.891485325992107, 16.89139837399125, 16.891363561153412, 16.891250390559435, 16.891153629869223, 18.30126814544201, 27.74070232361555, 19.585005089640617, 16.890496466308832, 18.300656761974096, 18.300557494163513, 18.2998877055943, 19.58390612527728, 27.388929832726717, 19.583694495260715, 27.378333050757647, 20.99432023987174, 19.58316508308053, 20.993870317935944, 19.58311553671956, 19.583030205219984, 19.582527853548527, 19.582368463277817, 20.993034027516842, 20.992957301437855, 27.73880934715271, 20.992670588195324, 27.738305538892746, 22.39551253989339, 22.395164642482996, 22.3952494636178, 22.394960898905993, 24.855444505810738, 23.725438822060823, 3.591778088361025, 27.705970019102097, 27.737122878432274, 23.72468902170658, 23.725223809480667, 27.736912731081247, 23.724635131657124, 27.736760828644037, 24.851121116429567, 24.85027050971985, 23.723352037370205, 24.84963594377041, 24.849747728556395, 24.849706526845694, 27.735921032726765, 24.851062823086977, 24.850920658558607, 24.851917028427124, 24.848719764500856, 27.734988797456026, 3.58710777759552, 24.851045910269022, 3.586848460137844, 27.701124221086502, 3.5866950191557407, 3.5863273814320564, 5.017428759485483, 27.36848758533597, 5.01659119874239, 27.700165141373873, 27.700131379067898, 5.016573753207922, 5.016286537051201, 5.015840619802475, 5.016097530722618, 6.1743234023451805, 6.174168709665537, 7.609811436384916, 6.173845395445824, 7.609025910496712, 6.174016710370779, 6.173607401549816, 6.173189155757427, 6.173031661659479, 6.173257444053888, 6.172827698290348, 7.607442229986191, 7.607458207756281, 8.931741181761026, 8.93134393170476, 27.712975777685642, 7.606691896915436, 7.606795206665993, 8.93081859499216, 7.606614403426647, 8.930036086589098, 7.60613664239645, 27.36142100393772, 8.929992970079184, 25.993575651198626, 8.929811846464872, 8.929273962974548, 8.928779292851686, 25.99243364110589, 8.928837597370148, 25.99240891262889, 25.991707611829042, 24.84160640835762, 25.991914480924606, 25.966786541044712, 24.84112773090601, 25.9905399158597, 25.96624855324626, 25.96615458279848, 27.72447679936886, 25.965921256691217, 25.96576652303338, 25.965627543628216, 25.965513069182634, 27.72396007180214, 25.96534739807248, 25.965255204588175], "itls": [[18.782028790563345], [18.782016810029745], [18.782038431614637], [18.78203796967864], [18.782048992812634], [18.782064359635115], [17.152038097381592], [17.493344742804766], [17.141841247677803], [17.493249591439962], [17.49323980882764], [17.493266612291336], [17.493268251419067], [17.4932671636343], [17.49327291175723], [], [16.562704846262932], [16.562641888856888], [16.562635358422995], [15.12366770580411], [16.562665600329638], [16.562739700078964], [16.562751200050116], [15.123694866895676], [], [], [], [15.123731203377247], [13.678092654794455], [13.319208472967148], [13.318669978529215], [13.677392270416021], [13.6773736551404], [12.22258422523737], [13.677367459982634], [13.677405335009098], [10.849676590412855], [13.677388653159142], [], [10.84963720664382], [10.849681366235018], [], [], [10.849605076014996], [10.849671550095081], [10.849681857973337], [10.849692307412624], [10.849705751985312], [10.849717009812593], [9.439755905419588], [], [8.156080182641745], [10.816667318344116], [9.439643204212189], [9.439655482769012], [9.439685076475143], [8.156044151633978], [], [8.156086973845959], [], [6.745714072138071], [7.7945102117955685], [6.745695900171995], [8.156011998653412], [8.156019121408463], [8.155990421772003], [8.15601309388876], [6.745696380734444], [6.745701842010021], [], [6.745714418590069], [], [5.342940207570791], [5.342933222651482], [5.342993423342705], [5.342958986759186], [2.884333949536085], [4.012459542602301], [24.11449521407485], [], [], [4.012486167252064], [4.012221910059452], [], [4.0122284814715385], [], [2.8858813494443893], [2.8858917877078056], [4.012271881103516], [2.88588634878397], [2.8859046809375286], [2.8858596608042717], [], [2.884370133280754], [2.8843386694788933], [2.88369382917881], [2.886002242565155], [], [24.114454120397568], [2.8836638890206814], [24.114425849169493], [], [24.114450108259916], [24.114515509456396], [22.351132594048977], [], [22.678406685590744], [], [], [22.689816884696484], [22.683619249612093], [22.683813083916903], [22.68984843045473], [21.531513657420874], [21.53152358159423], [20.10589949414134], [21.531565323472023], [20.106106732040644], [21.53145346418023], [21.531437315046787], [21.531534418463707], [21.20158239081502], [21.54074653238058], [21.53145108371973], [20.106194242835045], [20.106035739183426], [18.78212332352996], [18.782151643186808], [], [20.106048937886953], [20.105877980589867], [18.782114673405886], [20.105737540870905], [18.782180603593588], [20.10580448433757], [], [18.758943643420935], [1.7352584339678288], [18.78200452402234], [18.782117191702127], [18.782088223844767], [1.7354368939995766], [18.782022677361965], [1.7352595590054989], [1.7354047037661076], [2.8837435208261013], [1.7352762632071972], [1.7583839111030102], [2.883722972124815], [1.7354060411453247], [1.7583877593278885], [1.7584062926471233], [], [1.7584634013473988], [1.7585158720612526], [1.758519385010004], [1.7585380412638187], [], [1.7585276626050472], [1.7585413604974747]], "generated_texts": ["", "", "", "", "", "", " You may also consider using other task scheduling frameworks", "", ":\nTo create a simple calculator", "", "", "", "", "", "", ".;.;.;.;.;.;.;.;.;.;.;.;.;.;.;.;.;.;.;.;", "", "", "", "", "", "", "", "", "", "", "", "", "", " Acknowledged.", "\nThe Great Barrier Reef", "", "", "umes like beans, lentils, and chickpeas", "", "", "", "", "", "", "", "", "", "", "", "", "", "", "", "", "", "", " chili pepper plants, spaced about 30-45cm", "", "", "", "", ".;.;.;.;.;.;.;.;.;.;.;.;.;.;.;.;.;.;.;.;.;.;.;.;", "", "    }\n   ", "", " I know some people who", "", "", "", "", "", "", "", "", "", "", "", "", "", "", "", "", "", " 2.0, 3.", "", "", "", "", "", "", "", "", "", "", "", "", "", "", "", "", "", "", "", "", "", "", "", "", "'. You may need to modify the", "1) NOT NULL,\n", " These benefits make it an attractive option for businesses of all", "", "", "", "", "", "", "", "", "", "", "", "", "", "", " the `action` property set to `'get", "", "", "", "", "", "", "", "", "", "", "", "", "", "import android", " . Let me know if you have any questions!", "", "", "", "", "", "", "", "", "", "", "", "", "", "", "", "", "", "", "", "", "", "", ""], "errors": ["Traceback (most recent call last):\n  File \"/usr/local/lib/python3.10/dist-packages/aiohttp/client_proto.py\", line 94, in connection_lost\n    uncompleted = self._parser.feed_eof()\n  File \"aiohttp/_http_parser.pyx\", line 513, in aiohttp._http_parser.HttpParser.feed_eof\naiohttp.http_exceptions.TransferEncodingError: 400, message:\n  Not enough data for satisfy transfer length header.\n\nThe above exception was the direct cause of the following exception:\n\nTraceback (most recent call last):\n  File \"/vllm-workspace/backend_request_func.py\", line 261, in async_request_openai_completions\n    async for chunk_bytes in response.content:\n  File \"/usr/local/lib/python3.10/dist-packages/aiohttp/streams.py\", line 50, in __anext__\n    rv = await self.read_func()\n  File \"/usr/local/lib/python3.10/dist-packages/aiohttp/streams.py\", line 317, in readline\n    return await self.readuntil()\n  File \"/usr/local/lib/python3.10/dist-packages/aiohttp/streams.py\", line 351, in readuntil\n    await self._wait(\"readuntil\")\n  File \"/usr/local/lib/python3.10/dist-packages/aiohttp/streams.py\", line 312, in _wait\n    await waiter\naiohttp.client_exceptions.ClientPayloadError: Response payload is not completed: <TransferEncodingError: 400, message='Not enough data for satisfy transfer length header.'>\n", "Traceback (most recent call last):\n  File \"/usr/local/lib/python3.10/dist-packages/aiohttp/client_proto.py\", line 94, in connection_lost\n    uncompleted = self._parser.feed_eof()\n  File \"aiohttp/_http_parser.pyx\", line 513, in aiohttp._http_parser.HttpParser.feed_eof\naiohttp.http_exceptions.TransferEncodingError: 400, message:\n  Not enough data for satisfy transfer length header.\n\nThe above exception was the direct cause of the following exception:\n\nTraceback (most recent call last):\n  File \"/vllm-workspace/backend_request_func.py\", line 261, in async_request_openai_completions\n    async for chunk_bytes in response.content:\n  File \"/usr/local/lib/python3.10/dist-packages/aiohttp/streams.py\", line 50, in __anext__\n    rv = await self.read_func()\n  File \"/usr/local/lib/python3.10/dist-packages/aiohttp/streams.py\", line 317, in readline\n    return await self.readuntil()\n  File \"/usr/local/lib/python3.10/dist-packages/aiohttp/streams.py\", line 351, in readuntil\n    await self._wait(\"readuntil\")\n  File \"/usr/local/lib/python3.10/dist-packages/aiohttp/streams.py\", line 312, in _wait\n    await waiter\naiohttp.client_exceptions.ClientPayloadError: Response payload is not completed: <TransferEncodingError: 400, message='Not enough data for satisfy transfer length header.'>\n", "Traceback (most recent call last):\n  File \"/usr/local/lib/python3.10/dist-packages/aiohttp/client_proto.py\", line 94, in connection_lost\n    uncompleted = self._parser.feed_eof()\n  File \"aiohttp/_http_parser.pyx\", line 513, in aiohttp._http_parser.HttpParser.feed_eof\naiohttp.http_exceptions.TransferEncodingError: 400, message:\n  Not enough data for satisfy transfer length header.\n\nThe above exception was the direct cause of the following exception:\n\nTraceback (most recent call last):\n  File \"/vllm-workspace/backend_request_func.py\", line 261, in async_request_openai_completions\n    async for chunk_bytes in response.content:\n  File \"/usr/local/lib/python3.10/dist-packages/aiohttp/streams.py\", line 50, in __anext__\n    rv = await self.read_func()\n  File \"/usr/local/lib/python3.10/dist-packages/aiohttp/streams.py\", line 317, in readline\n    return await self.readuntil()\n  File \"/usr/local/lib/python3.10/dist-packages/aiohttp/streams.py\", line 351, in readuntil\n    await self._wait(\"readuntil\")\n  File \"/usr/local/lib/python3.10/dist-packages/aiohttp/streams.py\", line 312, in _wait\n    await waiter\naiohttp.client_exceptions.ClientPayloadError: Response payload is not completed: <TransferEncodingError: 400, message='Not enough data for satisfy transfer length header.'>\n", "Traceback (most recent call last):\n  File \"/usr/local/lib/python3.10/dist-packages/aiohttp/client_proto.py\", line 94, in connection_lost\n    uncompleted = self._parser.feed_eof()\n  File \"aiohttp/_http_parser.pyx\", line 513, in aiohttp._http_parser.HttpParser.feed_eof\naiohttp.http_exceptions.TransferEncodingError: 400, message:\n  Not enough data for satisfy transfer length header.\n\nThe above exception was the direct cause of the following exception:\n\nTraceback (most recent call last):\n  File \"/vllm-workspace/backend_request_func.py\", line 261, in async_request_openai_completions\n    async for chunk_bytes in response.content:\n  File \"/usr/local/lib/python3.10/dist-packages/aiohttp/streams.py\", line 50, in __anext__\n    rv = await self.read_func()\n  File \"/usr/local/lib/python3.10/dist-packages/aiohttp/streams.py\", line 317, in readline\n    return await self.readuntil()\n  File \"/usr/local/lib/python3.10/dist-packages/aiohttp/streams.py\", line 351, in readuntil\n    await self._wait(\"readuntil\")\n  File \"/usr/local/lib/python3.10/dist-packages/aiohttp/streams.py\", line 312, in _wait\n    await waiter\naiohttp.client_exceptions.ClientPayloadError: Response payload is not completed: <TransferEncodingError: 400, message='Not enough data for satisfy transfer length header.'>\n", "Traceback (most recent call last):\n  File \"/usr/local/lib/python3.10/dist-packages/aiohttp/client_proto.py\", line 94, in connection_lost\n    uncompleted = self._parser.feed_eof()\n  File \"aiohttp/_http_parser.pyx\", line 513, in aiohttp._http_parser.HttpParser.feed_eof\naiohttp.http_exceptions.TransferEncodingError: 400, message:\n  Not enough data for satisfy transfer length header.\n\nThe above exception was the direct cause of the following exception:\n\nTraceback (most recent call last):\n  File \"/vllm-workspace/backend_request_func.py\", line 261, in async_request_openai_completions\n    async for chunk_bytes in response.content:\n  File \"/usr/local/lib/python3.10/dist-packages/aiohttp/streams.py\", line 50, in __anext__\n    rv = await self.read_func()\n  File \"/usr/local/lib/python3.10/dist-packages/aiohttp/streams.py\", line 317, in readline\n    return await self.readuntil()\n  File \"/usr/local/lib/python3.10/dist-packages/aiohttp/streams.py\", line 351, in readuntil\n    await self._wait(\"readuntil\")\n  File \"/usr/local/lib/python3.10/dist-packages/aiohttp/streams.py\", line 312, in _wait\n    await waiter\naiohttp.client_exceptions.ClientPayloadError: Response payload is not completed: <TransferEncodingError: 400, message='Not enough data for satisfy transfer length header.'>\n", "Traceback (most recent call last):\n  File \"/usr/local/lib/python3.10/dist-packages/aiohttp/client_proto.py\", line 94, in connection_lost\n    uncompleted = self._parser.feed_eof()\n  File \"aiohttp/_http_parser.pyx\", line 513, in aiohttp._http_parser.HttpParser.feed_eof\naiohttp.http_exceptions.TransferEncodingError: 400, message:\n  Not enough data for satisfy transfer length header.\n\nThe above exception was the direct cause of the following exception:\n\nTraceback (most recent call last):\n  File \"/vllm-workspace/backend_request_func.py\", line 261, in async_request_openai_completions\n    async for chunk_bytes in response.content:\n  File \"/usr/local/lib/python3.10/dist-packages/aiohttp/streams.py\", line 50, in __anext__\n    rv = await self.read_func()\n  File \"/usr/local/lib/python3.10/dist-packages/aiohttp/streams.py\", line 317, in readline\n    return await self.readuntil()\n  File \"/usr/local/lib/python3.10/dist-packages/aiohttp/streams.py\", line 351, in readuntil\n    await self._wait(\"readuntil\")\n  File \"/usr/local/lib/python3.10/dist-packages/aiohttp/streams.py\", line 312, in _wait\n    await waiter\naiohttp.client_exceptions.ClientPayloadError: Response payload is not completed: <TransferEncodingError: 400, message='Not enough data for satisfy transfer length header.'>\n", "", "Traceback (most recent call last):\n  File \"/usr/local/lib/python3.10/dist-packages/aiohttp/client_proto.py\", line 94, in connection_lost\n    uncompleted = self._parser.feed_eof()\n  File \"aiohttp/_http_parser.pyx\", line 513, in aiohttp._http_parser.HttpParser.feed_eof\naiohttp.http_exceptions.TransferEncodingError: 400, message:\n  Not enough data for satisfy transfer length header.\n\nThe above exception was the direct cause of the following exception:\n\nTraceback (most recent call last):\n  File \"/vllm-workspace/backend_request_func.py\", line 261, in async_request_openai_completions\n    async for chunk_bytes in response.content:\n  File \"/usr/local/lib/python3.10/dist-packages/aiohttp/streams.py\", line 50, in __anext__\n    rv = await self.read_func()\n  File \"/usr/local/lib/python3.10/dist-packages/aiohttp/streams.py\", line 317, in readline\n    return await self.readuntil()\n  File \"/usr/local/lib/python3.10/dist-packages/aiohttp/streams.py\", line 351, in readuntil\n    await self._wait(\"readuntil\")\n  File \"/usr/local/lib/python3.10/dist-packages/aiohttp/streams.py\", line 312, in _wait\n    await waiter\naiohttp.client_exceptions.ClientPayloadError: Response payload is not completed: <TransferEncodingError: 400, message='Not enough data for satisfy transfer length header.'>\n", "", "Traceback (most recent call last):\n  File \"/usr/local/lib/python3.10/dist-packages/aiohttp/client_proto.py\", line 94, in connection_lost\n    uncompleted = self._parser.feed_eof()\n  File \"aiohttp/_http_parser.pyx\", line 513, in aiohttp._http_parser.HttpParser.feed_eof\naiohttp.http_exceptions.TransferEncodingError: 400, message:\n  Not enough data for satisfy transfer length header.\n\nThe above exception was the direct cause of the following exception:\n\nTraceback (most recent call last):\n  File \"/vllm-workspace/backend_request_func.py\", line 261, in async_request_openai_completions\n    async for chunk_bytes in response.content:\n  File \"/usr/local/lib/python3.10/dist-packages/aiohttp/streams.py\", line 50, in __anext__\n    rv = await self.read_func()\n  File \"/usr/local/lib/python3.10/dist-packages/aiohttp/streams.py\", line 317, in readline\n    return await self.readuntil()\n  File \"/usr/local/lib/python3.10/dist-packages/aiohttp/streams.py\", line 351, in readuntil\n    await self._wait(\"readuntil\")\n  File \"/usr/local/lib/python3.10/dist-packages/aiohttp/streams.py\", line 312, in _wait\n    await waiter\naiohttp.client_exceptions.ClientPayloadError: Response payload is not completed: <TransferEncodingError: 400, message='Not enough data for satisfy transfer length header.'>\n", "Traceback (most recent call last):\n  File \"/usr/local/lib/python3.10/dist-packages/aiohttp/client_proto.py\", line 94, in connection_lost\n    uncompleted = self._parser.feed_eof()\n  File \"aiohttp/_http_parser.pyx\", line 513, in aiohttp._http_parser.HttpParser.feed_eof\naiohttp.http_exceptions.TransferEncodingError: 400, message:\n  Not enough data for satisfy transfer length header.\n\nThe above exception was the direct cause of the following exception:\n\nTraceback (most recent call last):\n  File \"/vllm-workspace/backend_request_func.py\", line 261, in async_request_openai_completions\n    async for chunk_bytes in response.content:\n  File \"/usr/local/lib/python3.10/dist-packages/aiohttp/streams.py\", line 50, in __anext__\n    rv = await self.read_func()\n  File \"/usr/local/lib/python3.10/dist-packages/aiohttp/streams.py\", line 317, in readline\n    return await self.readuntil()\n  File \"/usr/local/lib/python3.10/dist-packages/aiohttp/streams.py\", line 351, in readuntil\n    await self._wait(\"readuntil\")\n  File \"/usr/local/lib/python3.10/dist-packages/aiohttp/streams.py\", line 312, in _wait\n    await waiter\naiohttp.client_exceptions.ClientPayloadError: Response payload is not completed: <TransferEncodingError: 400, message='Not enough data for satisfy transfer length header.'>\n", "Traceback (most recent call last):\n  File \"/usr/local/lib/python3.10/dist-packages/aiohttp/client_proto.py\", line 94, in connection_lost\n    uncompleted = self._parser.feed_eof()\n  File \"aiohttp/_http_parser.pyx\", line 513, in aiohttp._http_parser.HttpParser.feed_eof\naiohttp.http_exceptions.TransferEncodingError: 400, message:\n  Not enough data for satisfy transfer length header.\n\nThe above exception was the direct cause of the following exception:\n\nTraceback (most recent call last):\n  File \"/vllm-workspace/backend_request_func.py\", line 261, in async_request_openai_completions\n    async for chunk_bytes in response.content:\n  File \"/usr/local/lib/python3.10/dist-packages/aiohttp/streams.py\", line 50, in __anext__\n    rv = await self.read_func()\n  File \"/usr/local/lib/python3.10/dist-packages/aiohttp/streams.py\", line 317, in readline\n    return await self.readuntil()\n  File \"/usr/local/lib/python3.10/dist-packages/aiohttp/streams.py\", line 351, in readuntil\n    await self._wait(\"readuntil\")\n  File \"/usr/local/lib/python3.10/dist-packages/aiohttp/streams.py\", line 312, in _wait\n    await waiter\naiohttp.client_exceptions.ClientPayloadError: Response payload is not completed: <TransferEncodingError: 400, message='Not enough data for satisfy transfer length header.'>\n", "Traceback (most recent call last):\n  File \"/usr/local/lib/python3.10/dist-packages/aiohttp/client_proto.py\", line 94, in connection_lost\n    uncompleted = self._parser.feed_eof()\n  File \"aiohttp/_http_parser.pyx\", line 513, in aiohttp._http_parser.HttpParser.feed_eof\naiohttp.http_exceptions.TransferEncodingError: 400, message:\n  Not enough data for satisfy transfer length header.\n\nThe above exception was the direct cause of the following exception:\n\nTraceback (most recent call last):\n  File \"/vllm-workspace/backend_request_func.py\", line 261, in async_request_openai_completions\n    async for chunk_bytes in response.content:\n  File \"/usr/local/lib/python3.10/dist-packages/aiohttp/streams.py\", line 50, in __anext__\n    rv = await self.read_func()\n  File \"/usr/local/lib/python3.10/dist-packages/aiohttp/streams.py\", line 317, in readline\n    return await self.readuntil()\n  File \"/usr/local/lib/python3.10/dist-packages/aiohttp/streams.py\", line 351, in readuntil\n    await self._wait(\"readuntil\")\n  File \"/usr/local/lib/python3.10/dist-packages/aiohttp/streams.py\", line 312, in _wait\n    await waiter\naiohttp.client_exceptions.ClientPayloadError: Response payload is not completed: <TransferEncodingError: 400, message='Not enough data for satisfy transfer length header.'>\n", "Traceback (most recent call last):\n  File \"/usr/local/lib/python3.10/dist-packages/aiohttp/client_proto.py\", line 94, in connection_lost\n    uncompleted = self._parser.feed_eof()\n  File \"aiohttp/_http_parser.pyx\", line 513, in aiohttp._http_parser.HttpParser.feed_eof\naiohttp.http_exceptions.TransferEncodingError: 400, message:\n  Not enough data for satisfy transfer length header.\n\nThe above exception was the direct cause of the following exception:\n\nTraceback (most recent call last):\n  File \"/vllm-workspace/backend_request_func.py\", line 261, in async_request_openai_completions\n    async for chunk_bytes in response.content:\n  File \"/usr/local/lib/python3.10/dist-packages/aiohttp/streams.py\", line 50, in __anext__\n    rv = await self.read_func()\n  File \"/usr/local/lib/python3.10/dist-packages/aiohttp/streams.py\", line 317, in readline\n    return await self.readuntil()\n  File \"/usr/local/lib/python3.10/dist-packages/aiohttp/streams.py\", line 351, in readuntil\n    await self._wait(\"readuntil\")\n  File \"/usr/local/lib/python3.10/dist-packages/aiohttp/streams.py\", line 312, in _wait\n    await waiter\naiohttp.client_exceptions.ClientPayloadError: Response payload is not completed: <TransferEncodingError: 400, message='Not enough data for satisfy transfer length header.'>\n", "Traceback (most recent call last):\n  File \"/usr/local/lib/python3.10/dist-packages/aiohttp/client_proto.py\", line 94, in connection_lost\n    uncompleted = self._parser.feed_eof()\n  File \"aiohttp/_http_parser.pyx\", line 513, in aiohttp._http_parser.HttpParser.feed_eof\naiohttp.http_exceptions.TransferEncodingError: 400, message:\n  Not enough data for satisfy transfer length header.\n\nThe above exception was the direct cause of the following exception:\n\nTraceback (most recent call last):\n  File \"/vllm-workspace/backend_request_func.py\", line 261, in async_request_openai_completions\n    async for chunk_bytes in response.content:\n  File \"/usr/local/lib/python3.10/dist-packages/aiohttp/streams.py\", line 50, in __anext__\n    rv = await self.read_func()\n  File \"/usr/local/lib/python3.10/dist-packages/aiohttp/streams.py\", line 317, in readline\n    return await self.readuntil()\n  File \"/usr/local/lib/python3.10/dist-packages/aiohttp/streams.py\", line 351, in readuntil\n    await self._wait(\"readuntil\")\n  File \"/usr/local/lib/python3.10/dist-packages/aiohttp/streams.py\", line 312, in _wait\n    await waiter\naiohttp.client_exceptions.ClientPayloadError: Response payload is not completed: <TransferEncodingError: 400, message='Not enough data for satisfy transfer length header.'>\n", "", "Traceback (most recent call last):\n  File \"/usr/local/lib/python3.10/dist-packages/aiohttp/client_proto.py\", line 94, in connection_lost\n    uncompleted = self._parser.feed_eof()\n  File \"aiohttp/_http_parser.pyx\", line 513, in aiohttp._http_parser.HttpParser.feed_eof\naiohttp.http_exceptions.TransferEncodingError: 400, message:\n  Not enough data for satisfy transfer length header.\n\nThe above exception was the direct cause of the following exception:\n\nTraceback (most recent call last):\n  File \"/vllm-workspace/backend_request_func.py\", line 261, in async_request_openai_completions\n    async for chunk_bytes in response.content:\n  File \"/usr/local/lib/python3.10/dist-packages/aiohttp/streams.py\", line 50, in __anext__\n    rv = await self.read_func()\n  File \"/usr/local/lib/python3.10/dist-packages/aiohttp/streams.py\", line 317, in readline\n    return await self.readuntil()\n  File \"/usr/local/lib/python3.10/dist-packages/aiohttp/streams.py\", line 351, in readuntil\n    await self._wait(\"readuntil\")\n  File \"/usr/local/lib/python3.10/dist-packages/aiohttp/streams.py\", line 312, in _wait\n    await waiter\naiohttp.client_exceptions.ClientPayloadError: Response payload is not completed: <TransferEncodingError: 400, message='Not enough data for satisfy transfer length header.'>\n", "Traceback (most recent call last):\n  File \"/usr/local/lib/python3.10/dist-packages/aiohttp/client_proto.py\", line 94, in connection_lost\n    uncompleted = self._parser.feed_eof()\n  File \"aiohttp/_http_parser.pyx\", line 513, in aiohttp._http_parser.HttpParser.feed_eof\naiohttp.http_exceptions.TransferEncodingError: 400, message:\n  Not enough data for satisfy transfer length header.\n\nThe above exception was the direct cause of the following exception:\n\nTraceback (most recent call last):\n  File \"/vllm-workspace/backend_request_func.py\", line 261, in async_request_openai_completions\n    async for chunk_bytes in response.content:\n  File \"/usr/local/lib/python3.10/dist-packages/aiohttp/streams.py\", line 50, in __anext__\n    rv = await self.read_func()\n  File \"/usr/local/lib/python3.10/dist-packages/aiohttp/streams.py\", line 317, in readline\n    return await self.readuntil()\n  File \"/usr/local/lib/python3.10/dist-packages/aiohttp/streams.py\", line 351, in readuntil\n    await self._wait(\"readuntil\")\n  File \"/usr/local/lib/python3.10/dist-packages/aiohttp/streams.py\", line 312, in _wait\n    await waiter\naiohttp.client_exceptions.ClientPayloadError: Response payload is not completed: <TransferEncodingError: 400, message='Not enough data for satisfy transfer length header.'>\n", "Traceback (most recent call last):\n  File \"/usr/local/lib/python3.10/dist-packages/aiohttp/client_proto.py\", line 94, in connection_lost\n    uncompleted = self._parser.feed_eof()\n  File \"aiohttp/_http_parser.pyx\", line 513, in aiohttp._http_parser.HttpParser.feed_eof\naiohttp.http_exceptions.TransferEncodingError: 400, message:\n  Not enough data for satisfy transfer length header.\n\nThe above exception was the direct cause of the following exception:\n\nTraceback (most recent call last):\n  File \"/vllm-workspace/backend_request_func.py\", line 261, in async_request_openai_completions\n    async for chunk_bytes in response.content:\n  File \"/usr/local/lib/python3.10/dist-packages/aiohttp/streams.py\", line 50, in __anext__\n    rv = await self.read_func()\n  File \"/usr/local/lib/python3.10/dist-packages/aiohttp/streams.py\", line 317, in readline\n    return await self.readuntil()\n  File \"/usr/local/lib/python3.10/dist-packages/aiohttp/streams.py\", line 351, in readuntil\n    await self._wait(\"readuntil\")\n  File \"/usr/local/lib/python3.10/dist-packages/aiohttp/streams.py\", line 312, in _wait\n    await waiter\naiohttp.client_exceptions.ClientPayloadError: Response payload is not completed: <TransferEncodingError: 400, message='Not enough data for satisfy transfer length header.'>\n", "Traceback (most recent call last):\n  File \"/usr/local/lib/python3.10/dist-packages/aiohttp/client_proto.py\", line 94, in connection_lost\n    uncompleted = self._parser.feed_eof()\n  File \"aiohttp/_http_parser.pyx\", line 513, in aiohttp._http_parser.HttpParser.feed_eof\naiohttp.http_exceptions.TransferEncodingError: 400, message:\n  Not enough data for satisfy transfer length header.\n\nThe above exception was the direct cause of the following exception:\n\nTraceback (most recent call last):\n  File \"/vllm-workspace/backend_request_func.py\", line 261, in async_request_openai_completions\n    async for chunk_bytes in response.content:\n  File \"/usr/local/lib/python3.10/dist-packages/aiohttp/streams.py\", line 50, in __anext__\n    rv = await self.read_func()\n  File \"/usr/local/lib/python3.10/dist-packages/aiohttp/streams.py\", line 317, in readline\n    return await self.readuntil()\n  File \"/usr/local/lib/python3.10/dist-packages/aiohttp/streams.py\", line 351, in readuntil\n    await self._wait(\"readuntil\")\n  File \"/usr/local/lib/python3.10/dist-packages/aiohttp/streams.py\", line 312, in _wait\n    await waiter\naiohttp.client_exceptions.ClientPayloadError: Response payload is not completed: <TransferEncodingError: 400, message='Not enough data for satisfy transfer length header.'>\n", "Traceback (most recent call last):\n  File \"/usr/local/lib/python3.10/dist-packages/aiohttp/client_proto.py\", line 94, in connection_lost\n    uncompleted = self._parser.feed_eof()\n  File \"aiohttp/_http_parser.pyx\", line 513, in aiohttp._http_parser.HttpParser.feed_eof\naiohttp.http_exceptions.TransferEncodingError: 400, message:\n  Not enough data for satisfy transfer length header.\n\nThe above exception was the direct cause of the following exception:\n\nTraceback (most recent call last):\n  File \"/vllm-workspace/backend_request_func.py\", line 261, in async_request_openai_completions\n    async for chunk_bytes in response.content:\n  File \"/usr/local/lib/python3.10/dist-packages/aiohttp/streams.py\", line 50, in __anext__\n    rv = await self.read_func()\n  File \"/usr/local/lib/python3.10/dist-packages/aiohttp/streams.py\", line 317, in readline\n    return await self.readuntil()\n  File \"/usr/local/lib/python3.10/dist-packages/aiohttp/streams.py\", line 351, in readuntil\n    await self._wait(\"readuntil\")\n  File \"/usr/local/lib/python3.10/dist-packages/aiohttp/streams.py\", line 312, in _wait\n    await waiter\naiohttp.client_exceptions.ClientPayloadError: Response payload is not completed: <TransferEncodingError: 400, message='Not enough data for satisfy transfer length header.'>\n", "Traceback (most recent call last):\n  File \"/usr/local/lib/python3.10/dist-packages/aiohttp/client_proto.py\", line 94, in connection_lost\n    uncompleted = self._parser.feed_eof()\n  File \"aiohttp/_http_parser.pyx\", line 513, in aiohttp._http_parser.HttpParser.feed_eof\naiohttp.http_exceptions.TransferEncodingError: 400, message:\n  Not enough data for satisfy transfer length header.\n\nThe above exception was the direct cause of the following exception:\n\nTraceback (most recent call last):\n  File \"/vllm-workspace/backend_request_func.py\", line 261, in async_request_openai_completions\n    async for chunk_bytes in response.content:\n  File \"/usr/local/lib/python3.10/dist-packages/aiohttp/streams.py\", line 50, in __anext__\n    rv = await self.read_func()\n  File \"/usr/local/lib/python3.10/dist-packages/aiohttp/streams.py\", line 317, in readline\n    return await self.readuntil()\n  File \"/usr/local/lib/python3.10/dist-packages/aiohttp/streams.py\", line 351, in readuntil\n    await self._wait(\"readuntil\")\n  File \"/usr/local/lib/python3.10/dist-packages/aiohttp/streams.py\", line 312, in _wait\n    await waiter\naiohttp.client_exceptions.ClientPayloadError: Response payload is not completed: <TransferEncodingError: 400, message='Not enough data for satisfy transfer length header.'>\n", "Traceback (most recent call last):\n  File \"/usr/local/lib/python3.10/dist-packages/aiohttp/client_proto.py\", line 94, in connection_lost\n    uncompleted = self._parser.feed_eof()\n  File \"aiohttp/_http_parser.pyx\", line 513, in aiohttp._http_parser.HttpParser.feed_eof\naiohttp.http_exceptions.TransferEncodingError: 400, message:\n  Not enough data for satisfy transfer length header.\n\nThe above exception was the direct cause of the following exception:\n\nTraceback (most recent call last):\n  File \"/vllm-workspace/backend_request_func.py\", line 261, in async_request_openai_completions\n    async for chunk_bytes in response.content:\n  File \"/usr/local/lib/python3.10/dist-packages/aiohttp/streams.py\", line 50, in __anext__\n    rv = await self.read_func()\n  File \"/usr/local/lib/python3.10/dist-packages/aiohttp/streams.py\", line 317, in readline\n    return await self.readuntil()\n  File \"/usr/local/lib/python3.10/dist-packages/aiohttp/streams.py\", line 351, in readuntil\n    await self._wait(\"readuntil\")\n  File \"/usr/local/lib/python3.10/dist-packages/aiohttp/streams.py\", line 312, in _wait\n    await waiter\naiohttp.client_exceptions.ClientPayloadError: Response payload is not completed: <TransferEncodingError: 400, message='Not enough data for satisfy transfer length header.'>\n", "Traceback (most recent call last):\n  File \"/usr/local/lib/python3.10/dist-packages/aiohttp/client_proto.py\", line 94, in connection_lost\n    uncompleted = self._parser.feed_eof()\n  File \"aiohttp/_http_parser.pyx\", line 513, in aiohttp._http_parser.HttpParser.feed_eof\naiohttp.http_exceptions.TransferEncodingError: 400, message:\n  Not enough data for satisfy transfer length header.\n\nThe above exception was the direct cause of the following exception:\n\nTraceback (most recent call last):\n  File \"/vllm-workspace/backend_request_func.py\", line 261, in async_request_openai_completions\n    async for chunk_bytes in response.content:\n  File \"/usr/local/lib/python3.10/dist-packages/aiohttp/streams.py\", line 50, in __anext__\n    rv = await self.read_func()\n  File \"/usr/local/lib/python3.10/dist-packages/aiohttp/streams.py\", line 317, in readline\n    return await self.readuntil()\n  File \"/usr/local/lib/python3.10/dist-packages/aiohttp/streams.py\", line 351, in readuntil\n    await self._wait(\"readuntil\")\n  File \"/usr/local/lib/python3.10/dist-packages/aiohttp/streams.py\", line 312, in _wait\n    await waiter\naiohttp.client_exceptions.ClientPayloadError: Response payload is not completed: <TransferEncodingError: 400, message='Not enough data for satisfy transfer length header.'>\n", "Traceback (most recent call last):\n  File \"/usr/local/lib/python3.10/dist-packages/aiohttp/client_proto.py\", line 94, in connection_lost\n    uncompleted = self._parser.feed_eof()\n  File \"aiohttp/_http_parser.pyx\", line 513, in aiohttp._http_parser.HttpParser.feed_eof\naiohttp.http_exceptions.TransferEncodingError: 400, message:\n  Not enough data for satisfy transfer length header.\n\nThe above exception was the direct cause of the following exception:\n\nTraceback (most recent call last):\n  File \"/vllm-workspace/backend_request_func.py\", line 261, in async_request_openai_completions\n    async for chunk_bytes in response.content:\n  File \"/usr/local/lib/python3.10/dist-packages/aiohttp/streams.py\", line 50, in __anext__\n    rv = await self.read_func()\n  File \"/usr/local/lib/python3.10/dist-packages/aiohttp/streams.py\", line 317, in readline\n    return await self.readuntil()\n  File \"/usr/local/lib/python3.10/dist-packages/aiohttp/streams.py\", line 351, in readuntil\n    await self._wait(\"readuntil\")\n  File \"/usr/local/lib/python3.10/dist-packages/aiohttp/streams.py\", line 312, in _wait\n    await waiter\naiohttp.client_exceptions.ClientPayloadError: Response payload is not completed: <TransferEncodingError: 400, message='Not enough data for satisfy transfer length header.'>\n", "Traceback (most recent call last):\n  File \"/usr/local/lib/python3.10/dist-packages/aiohttp/client_proto.py\", line 94, in connection_lost\n    uncompleted = self._parser.feed_eof()\n  File \"aiohttp/_http_parser.pyx\", line 513, in aiohttp._http_parser.HttpParser.feed_eof\naiohttp.http_exceptions.TransferEncodingError: 400, message:\n  Not enough data for satisfy transfer length header.\n\nThe above exception was the direct cause of the following exception:\n\nTraceback (most recent call last):\n  File \"/vllm-workspace/backend_request_func.py\", line 261, in async_request_openai_completions\n    async for chunk_bytes in response.content:\n  File \"/usr/local/lib/python3.10/dist-packages/aiohttp/streams.py\", line 50, in __anext__\n    rv = await self.read_func()\n  File \"/usr/local/lib/python3.10/dist-packages/aiohttp/streams.py\", line 317, in readline\n    return await self.readuntil()\n  File \"/usr/local/lib/python3.10/dist-packages/aiohttp/streams.py\", line 351, in readuntil\n    await self._wait(\"readuntil\")\n  File \"/usr/local/lib/python3.10/dist-packages/aiohttp/streams.py\", line 312, in _wait\n    await waiter\naiohttp.client_exceptions.ClientPayloadError: Response payload is not completed: <TransferEncodingError: 400, message='Not enough data for satisfy transfer length header.'>\n", "Traceback (most recent call last):\n  File \"/usr/local/lib/python3.10/dist-packages/aiohttp/client_proto.py\", line 94, in connection_lost\n    uncompleted = self._parser.feed_eof()\n  File \"aiohttp/_http_parser.pyx\", line 513, in aiohttp._http_parser.HttpParser.feed_eof\naiohttp.http_exceptions.TransferEncodingError: 400, message:\n  Not enough data for satisfy transfer length header.\n\nThe above exception was the direct cause of the following exception:\n\nTraceback (most recent call last):\n  File \"/vllm-workspace/backend_request_func.py\", line 261, in async_request_openai_completions\n    async for chunk_bytes in response.content:\n  File \"/usr/local/lib/python3.10/dist-packages/aiohttp/streams.py\", line 50, in __anext__\n    rv = await self.read_func()\n  File \"/usr/local/lib/python3.10/dist-packages/aiohttp/streams.py\", line 317, in readline\n    return await self.readuntil()\n  File \"/usr/local/lib/python3.10/dist-packages/aiohttp/streams.py\", line 351, in readuntil\n    await self._wait(\"readuntil\")\n  File \"/usr/local/lib/python3.10/dist-packages/aiohttp/streams.py\", line 312, in _wait\n    await waiter\naiohttp.client_exceptions.ClientPayloadError: Response payload is not completed: <TransferEncodingError: 400, message='Not enough data for satisfy transfer length header.'>\n", "Traceback (most recent call last):\n  File \"/usr/local/lib/python3.10/dist-packages/aiohttp/client_proto.py\", line 94, in connection_lost\n    uncompleted = self._parser.feed_eof()\n  File \"aiohttp/_http_parser.pyx\", line 513, in aiohttp._http_parser.HttpParser.feed_eof\naiohttp.http_exceptions.TransferEncodingError: 400, message:\n  Not enough data for satisfy transfer length header.\n\nThe above exception was the direct cause of the following exception:\n\nTraceback (most recent call last):\n  File \"/vllm-workspace/backend_request_func.py\", line 261, in async_request_openai_completions\n    async for chunk_bytes in response.content:\n  File \"/usr/local/lib/python3.10/dist-packages/aiohttp/streams.py\", line 50, in __anext__\n    rv = await self.read_func()\n  File \"/usr/local/lib/python3.10/dist-packages/aiohttp/streams.py\", line 317, in readline\n    return await self.readuntil()\n  File \"/usr/local/lib/python3.10/dist-packages/aiohttp/streams.py\", line 351, in readuntil\n    await self._wait(\"readuntil\")\n  File \"/usr/local/lib/python3.10/dist-packages/aiohttp/streams.py\", line 312, in _wait\n    await waiter\naiohttp.client_exceptions.ClientPayloadError: Response payload is not completed: <TransferEncodingError: 400, message='Not enough data for satisfy transfer length header.'>\n", "Traceback (most recent call last):\n  File \"/usr/local/lib/python3.10/dist-packages/aiohttp/client_proto.py\", line 94, in connection_lost\n    uncompleted = self._parser.feed_eof()\n  File \"aiohttp/_http_parser.pyx\", line 513, in aiohttp._http_parser.HttpParser.feed_eof\naiohttp.http_exceptions.TransferEncodingError: 400, message:\n  Not enough data for satisfy transfer length header.\n\nThe above exception was the direct cause of the following exception:\n\nTraceback (most recent call last):\n  File \"/vllm-workspace/backend_request_func.py\", line 261, in async_request_openai_completions\n    async for chunk_bytes in response.content:\n  File \"/usr/local/lib/python3.10/dist-packages/aiohttp/streams.py\", line 50, in __anext__\n    rv = await self.read_func()\n  File \"/usr/local/lib/python3.10/dist-packages/aiohttp/streams.py\", line 317, in readline\n    return await self.readuntil()\n  File \"/usr/local/lib/python3.10/dist-packages/aiohttp/streams.py\", line 351, in readuntil\n    await self._wait(\"readuntil\")\n  File \"/usr/local/lib/python3.10/dist-packages/aiohttp/streams.py\", line 312, in _wait\n    await waiter\naiohttp.client_exceptions.ClientPayloadError: Response payload is not completed: <TransferEncodingError: 400, message='Not enough data for satisfy transfer length header.'>\n", "", "", "Traceback (most recent call last):\n  File \"/usr/local/lib/python3.10/dist-packages/aiohttp/client_proto.py\", line 94, in connection_lost\n    uncompleted = self._parser.feed_eof()\n  File \"aiohttp/_http_parser.pyx\", line 513, in aiohttp._http_parser.HttpParser.feed_eof\naiohttp.http_exceptions.TransferEncodingError: 400, message:\n  Not enough data for satisfy transfer length header.\n\nThe above exception was the direct cause of the following exception:\n\nTraceback (most recent call last):\n  File \"/vllm-workspace/backend_request_func.py\", line 261, in async_request_openai_completions\n    async for chunk_bytes in response.content:\n  File \"/usr/local/lib/python3.10/dist-packages/aiohttp/streams.py\", line 50, in __anext__\n    rv = await self.read_func()\n  File \"/usr/local/lib/python3.10/dist-packages/aiohttp/streams.py\", line 317, in readline\n    return await self.readuntil()\n  File \"/usr/local/lib/python3.10/dist-packages/aiohttp/streams.py\", line 351, in readuntil\n    await self._wait(\"readuntil\")\n  File \"/usr/local/lib/python3.10/dist-packages/aiohttp/streams.py\", line 312, in _wait\n    await waiter\naiohttp.client_exceptions.ClientPayloadError: Response payload is not completed: <TransferEncodingError: 400, message='Not enough data for satisfy transfer length header.'>\n", "Traceback (most recent call last):\n  File \"/usr/local/lib/python3.10/dist-packages/aiohttp/client_proto.py\", line 94, in connection_lost\n    uncompleted = self._parser.feed_eof()\n  File \"aiohttp/_http_parser.pyx\", line 513, in aiohttp._http_parser.HttpParser.feed_eof\naiohttp.http_exceptions.TransferEncodingError: 400, message:\n  Not enough data for satisfy transfer length header.\n\nThe above exception was the direct cause of the following exception:\n\nTraceback (most recent call last):\n  File \"/vllm-workspace/backend_request_func.py\", line 261, in async_request_openai_completions\n    async for chunk_bytes in response.content:\n  File \"/usr/local/lib/python3.10/dist-packages/aiohttp/streams.py\", line 50, in __anext__\n    rv = await self.read_func()\n  File \"/usr/local/lib/python3.10/dist-packages/aiohttp/streams.py\", line 317, in readline\n    return await self.readuntil()\n  File \"/usr/local/lib/python3.10/dist-packages/aiohttp/streams.py\", line 351, in readuntil\n    await self._wait(\"readuntil\")\n  File \"/usr/local/lib/python3.10/dist-packages/aiohttp/streams.py\", line 312, in _wait\n    await waiter\naiohttp.client_exceptions.ClientPayloadError: Response payload is not completed: <TransferEncodingError: 400, message='Not enough data for satisfy transfer length header.'>\n", "", "Traceback (most recent call last):\n  File \"/usr/local/lib/python3.10/dist-packages/aiohttp/client_proto.py\", line 94, in connection_lost\n    uncompleted = self._parser.feed_eof()\n  File \"aiohttp/_http_parser.pyx\", line 513, in aiohttp._http_parser.HttpParser.feed_eof\naiohttp.http_exceptions.TransferEncodingError: 400, message:\n  Not enough data for satisfy transfer length header.\n\nThe above exception was the direct cause of the following exception:\n\nTraceback (most recent call last):\n  File \"/vllm-workspace/backend_request_func.py\", line 261, in async_request_openai_completions\n    async for chunk_bytes in response.content:\n  File \"/usr/local/lib/python3.10/dist-packages/aiohttp/streams.py\", line 50, in __anext__\n    rv = await self.read_func()\n  File \"/usr/local/lib/python3.10/dist-packages/aiohttp/streams.py\", line 317, in readline\n    return await self.readuntil()\n  File \"/usr/local/lib/python3.10/dist-packages/aiohttp/streams.py\", line 351, in readuntil\n    await self._wait(\"readuntil\")\n  File \"/usr/local/lib/python3.10/dist-packages/aiohttp/streams.py\", line 312, in _wait\n    await waiter\naiohttp.client_exceptions.ClientPayloadError: Response payload is not completed: <TransferEncodingError: 400, message='Not enough data for satisfy transfer length header.'>\n", "Traceback (most recent call last):\n  File \"/usr/local/lib/python3.10/dist-packages/aiohttp/client_proto.py\", line 94, in connection_lost\n    uncompleted = self._parser.feed_eof()\n  File \"aiohttp/_http_parser.pyx\", line 513, in aiohttp._http_parser.HttpParser.feed_eof\naiohttp.http_exceptions.TransferEncodingError: 400, message:\n  Not enough data for satisfy transfer length header.\n\nThe above exception was the direct cause of the following exception:\n\nTraceback (most recent call last):\n  File \"/vllm-workspace/backend_request_func.py\", line 261, in async_request_openai_completions\n    async for chunk_bytes in response.content:\n  File \"/usr/local/lib/python3.10/dist-packages/aiohttp/streams.py\", line 50, in __anext__\n    rv = await self.read_func()\n  File \"/usr/local/lib/python3.10/dist-packages/aiohttp/streams.py\", line 317, in readline\n    return await self.readuntil()\n  File \"/usr/local/lib/python3.10/dist-packages/aiohttp/streams.py\", line 351, in readuntil\n    await self._wait(\"readuntil\")\n  File \"/usr/local/lib/python3.10/dist-packages/aiohttp/streams.py\", line 312, in _wait\n    await waiter\naiohttp.client_exceptions.ClientPayloadError: Response payload is not completed: <TransferEncodingError: 400, message='Not enough data for satisfy transfer length header.'>\n", "Traceback (most recent call last):\n  File \"/usr/local/lib/python3.10/dist-packages/aiohttp/client_proto.py\", line 94, in connection_lost\n    uncompleted = self._parser.feed_eof()\n  File \"aiohttp/_http_parser.pyx\", line 513, in aiohttp._http_parser.HttpParser.feed_eof\naiohttp.http_exceptions.TransferEncodingError: 400, message:\n  Not enough data for satisfy transfer length header.\n\nThe above exception was the direct cause of the following exception:\n\nTraceback (most recent call last):\n  File \"/vllm-workspace/backend_request_func.py\", line 261, in async_request_openai_completions\n    async for chunk_bytes in response.content:\n  File \"/usr/local/lib/python3.10/dist-packages/aiohttp/streams.py\", line 50, in __anext__\n    rv = await self.read_func()\n  File \"/usr/local/lib/python3.10/dist-packages/aiohttp/streams.py\", line 317, in readline\n    return await self.readuntil()\n  File \"/usr/local/lib/python3.10/dist-packages/aiohttp/streams.py\", line 351, in readuntil\n    await self._wait(\"readuntil\")\n  File \"/usr/local/lib/python3.10/dist-packages/aiohttp/streams.py\", line 312, in _wait\n    await waiter\naiohttp.client_exceptions.ClientPayloadError: Response payload is not completed: <TransferEncodingError: 400, message='Not enough data for satisfy transfer length header.'>\n", "Traceback (most recent call last):\n  File \"/usr/local/lib/python3.10/dist-packages/aiohttp/client_proto.py\", line 94, in connection_lost\n    uncompleted = self._parser.feed_eof()\n  File \"aiohttp/_http_parser.pyx\", line 513, in aiohttp._http_parser.HttpParser.feed_eof\naiohttp.http_exceptions.TransferEncodingError: 400, message:\n  Not enough data for satisfy transfer length header.\n\nThe above exception was the direct cause of the following exception:\n\nTraceback (most recent call last):\n  File \"/vllm-workspace/backend_request_func.py\", line 261, in async_request_openai_completions\n    async for chunk_bytes in response.content:\n  File \"/usr/local/lib/python3.10/dist-packages/aiohttp/streams.py\", line 50, in __anext__\n    rv = await self.read_func()\n  File \"/usr/local/lib/python3.10/dist-packages/aiohttp/streams.py\", line 317, in readline\n    return await self.readuntil()\n  File \"/usr/local/lib/python3.10/dist-packages/aiohttp/streams.py\", line 351, in readuntil\n    await self._wait(\"readuntil\")\n  File \"/usr/local/lib/python3.10/dist-packages/aiohttp/streams.py\", line 312, in _wait\n    await waiter\naiohttp.client_exceptions.ClientPayloadError: Response payload is not completed: <TransferEncodingError: 400, message='Not enough data for satisfy transfer length header.'>\n", "Traceback (most recent call last):\n  File \"/usr/local/lib/python3.10/dist-packages/aiohttp/client_proto.py\", line 94, in connection_lost\n    uncompleted = self._parser.feed_eof()\n  File \"aiohttp/_http_parser.pyx\", line 513, in aiohttp._http_parser.HttpParser.feed_eof\naiohttp.http_exceptions.TransferEncodingError: 400, message:\n  Not enough data for satisfy transfer length header.\n\nThe above exception was the direct cause of the following exception:\n\nTraceback (most recent call last):\n  File \"/vllm-workspace/backend_request_func.py\", line 261, in async_request_openai_completions\n    async for chunk_bytes in response.content:\n  File \"/usr/local/lib/python3.10/dist-packages/aiohttp/streams.py\", line 50, in __anext__\n    rv = await self.read_func()\n  File \"/usr/local/lib/python3.10/dist-packages/aiohttp/streams.py\", line 317, in readline\n    return await self.readuntil()\n  File \"/usr/local/lib/python3.10/dist-packages/aiohttp/streams.py\", line 351, in readuntil\n    await self._wait(\"readuntil\")\n  File \"/usr/local/lib/python3.10/dist-packages/aiohttp/streams.py\", line 312, in _wait\n    await waiter\naiohttp.client_exceptions.ClientPayloadError: Response payload is not completed: <TransferEncodingError: 400, message='Not enough data for satisfy transfer length header.'>\n", "Traceback (most recent call last):\n  File \"/usr/local/lib/python3.10/dist-packages/aiohttp/client_proto.py\", line 94, in connection_lost\n    uncompleted = self._parser.feed_eof()\n  File \"aiohttp/_http_parser.pyx\", line 513, in aiohttp._http_parser.HttpParser.feed_eof\naiohttp.http_exceptions.TransferEncodingError: 400, message:\n  Not enough data for satisfy transfer length header.\n\nThe above exception was the direct cause of the following exception:\n\nTraceback (most recent call last):\n  File \"/vllm-workspace/backend_request_func.py\", line 261, in async_request_openai_completions\n    async for chunk_bytes in response.content:\n  File \"/usr/local/lib/python3.10/dist-packages/aiohttp/streams.py\", line 50, in __anext__\n    rv = await self.read_func()\n  File \"/usr/local/lib/python3.10/dist-packages/aiohttp/streams.py\", line 317, in readline\n    return await self.readuntil()\n  File \"/usr/local/lib/python3.10/dist-packages/aiohttp/streams.py\", line 351, in readuntil\n    await self._wait(\"readuntil\")\n  File \"/usr/local/lib/python3.10/dist-packages/aiohttp/streams.py\", line 312, in _wait\n    await waiter\naiohttp.client_exceptions.ClientPayloadError: Response payload is not completed: <TransferEncodingError: 400, message='Not enough data for satisfy transfer length header.'>\n", "Traceback (most recent call last):\n  File \"/usr/local/lib/python3.10/dist-packages/aiohttp/client_proto.py\", line 94, in connection_lost\n    uncompleted = self._parser.feed_eof()\n  File \"aiohttp/_http_parser.pyx\", line 513, in aiohttp._http_parser.HttpParser.feed_eof\naiohttp.http_exceptions.TransferEncodingError: 400, message:\n  Not enough data for satisfy transfer length header.\n\nThe above exception was the direct cause of the following exception:\n\nTraceback (most recent call last):\n  File \"/vllm-workspace/backend_request_func.py\", line 261, in async_request_openai_completions\n    async for chunk_bytes in response.content:\n  File \"/usr/local/lib/python3.10/dist-packages/aiohttp/streams.py\", line 50, in __anext__\n    rv = await self.read_func()\n  File \"/usr/local/lib/python3.10/dist-packages/aiohttp/streams.py\", line 317, in readline\n    return await self.readuntil()\n  File \"/usr/local/lib/python3.10/dist-packages/aiohttp/streams.py\", line 351, in readuntil\n    await self._wait(\"readuntil\")\n  File \"/usr/local/lib/python3.10/dist-packages/aiohttp/streams.py\", line 312, in _wait\n    await waiter\naiohttp.client_exceptions.ClientPayloadError: Response payload is not completed: <TransferEncodingError: 400, message='Not enough data for satisfy transfer length header.'>\n", "Traceback (most recent call last):\n  File \"/usr/local/lib/python3.10/dist-packages/aiohttp/client_proto.py\", line 94, in connection_lost\n    uncompleted = self._parser.feed_eof()\n  File \"aiohttp/_http_parser.pyx\", line 513, in aiohttp._http_parser.HttpParser.feed_eof\naiohttp.http_exceptions.TransferEncodingError: 400, message:\n  Not enough data for satisfy transfer length header.\n\nThe above exception was the direct cause of the following exception:\n\nTraceback (most recent call last):\n  File \"/vllm-workspace/backend_request_func.py\", line 261, in async_request_openai_completions\n    async for chunk_bytes in response.content:\n  File \"/usr/local/lib/python3.10/dist-packages/aiohttp/streams.py\", line 50, in __anext__\n    rv = await self.read_func()\n  File \"/usr/local/lib/python3.10/dist-packages/aiohttp/streams.py\", line 317, in readline\n    return await self.readuntil()\n  File \"/usr/local/lib/python3.10/dist-packages/aiohttp/streams.py\", line 351, in readuntil\n    await self._wait(\"readuntil\")\n  File \"/usr/local/lib/python3.10/dist-packages/aiohttp/streams.py\", line 312, in _wait\n    await waiter\naiohttp.client_exceptions.ClientPayloadError: Response payload is not completed: <TransferEncodingError: 400, message='Not enough data for satisfy transfer length header.'>\n", "Traceback (most recent call last):\n  File \"/usr/local/lib/python3.10/dist-packages/aiohttp/client_proto.py\", line 94, in connection_lost\n    uncompleted = self._parser.feed_eof()\n  File \"aiohttp/_http_parser.pyx\", line 513, in aiohttp._http_parser.HttpParser.feed_eof\naiohttp.http_exceptions.TransferEncodingError: 400, message:\n  Not enough data for satisfy transfer length header.\n\nThe above exception was the direct cause of the following exception:\n\nTraceback (most recent call last):\n  File \"/vllm-workspace/backend_request_func.py\", line 261, in async_request_openai_completions\n    async for chunk_bytes in response.content:\n  File \"/usr/local/lib/python3.10/dist-packages/aiohttp/streams.py\", line 50, in __anext__\n    rv = await self.read_func()\n  File \"/usr/local/lib/python3.10/dist-packages/aiohttp/streams.py\", line 317, in readline\n    return await self.readuntil()\n  File \"/usr/local/lib/python3.10/dist-packages/aiohttp/streams.py\", line 351, in readuntil\n    await self._wait(\"readuntil\")\n  File \"/usr/local/lib/python3.10/dist-packages/aiohttp/streams.py\", line 312, in _wait\n    await waiter\naiohttp.client_exceptions.ClientPayloadError: Response payload is not completed: <TransferEncodingError: 400, message='Not enough data for satisfy transfer length header.'>\n", "Traceback (most recent call last):\n  File \"/usr/local/lib/python3.10/dist-packages/aiohttp/client_proto.py\", line 94, in connection_lost\n    uncompleted = self._parser.feed_eof()\n  File \"aiohttp/_http_parser.pyx\", line 513, in aiohttp._http_parser.HttpParser.feed_eof\naiohttp.http_exceptions.TransferEncodingError: 400, message:\n  Not enough data for satisfy transfer length header.\n\nThe above exception was the direct cause of the following exception:\n\nTraceback (most recent call last):\n  File \"/vllm-workspace/backend_request_func.py\", line 261, in async_request_openai_completions\n    async for chunk_bytes in response.content:\n  File \"/usr/local/lib/python3.10/dist-packages/aiohttp/streams.py\", line 50, in __anext__\n    rv = await self.read_func()\n  File \"/usr/local/lib/python3.10/dist-packages/aiohttp/streams.py\", line 317, in readline\n    return await self.readuntil()\n  File \"/usr/local/lib/python3.10/dist-packages/aiohttp/streams.py\", line 351, in readuntil\n    await self._wait(\"readuntil\")\n  File \"/usr/local/lib/python3.10/dist-packages/aiohttp/streams.py\", line 312, in _wait\n    await waiter\naiohttp.client_exceptions.ClientPayloadError: Response payload is not completed: <TransferEncodingError: 400, message='Not enough data for satisfy transfer length header.'>\n", "Traceback (most recent call last):\n  File \"/usr/local/lib/python3.10/dist-packages/aiohttp/client_proto.py\", line 94, in connection_lost\n    uncompleted = self._parser.feed_eof()\n  File \"aiohttp/_http_parser.pyx\", line 513, in aiohttp._http_parser.HttpParser.feed_eof\naiohttp.http_exceptions.TransferEncodingError: 400, message:\n  Not enough data for satisfy transfer length header.\n\nThe above exception was the direct cause of the following exception:\n\nTraceback (most recent call last):\n  File \"/vllm-workspace/backend_request_func.py\", line 261, in async_request_openai_completions\n    async for chunk_bytes in response.content:\n  File \"/usr/local/lib/python3.10/dist-packages/aiohttp/streams.py\", line 50, in __anext__\n    rv = await self.read_func()\n  File \"/usr/local/lib/python3.10/dist-packages/aiohttp/streams.py\", line 317, in readline\n    return await self.readuntil()\n  File \"/usr/local/lib/python3.10/dist-packages/aiohttp/streams.py\", line 351, in readuntil\n    await self._wait(\"readuntil\")\n  File \"/usr/local/lib/python3.10/dist-packages/aiohttp/streams.py\", line 312, in _wait\n    await waiter\naiohttp.client_exceptions.ClientPayloadError: Response payload is not completed: <TransferEncodingError: 400, message='Not enough data for satisfy transfer length header.'>\n", "Traceback (most recent call last):\n  File \"/usr/local/lib/python3.10/dist-packages/aiohttp/client_proto.py\", line 94, in connection_lost\n    uncompleted = self._parser.feed_eof()\n  File \"aiohttp/_http_parser.pyx\", line 513, in aiohttp._http_parser.HttpParser.feed_eof\naiohttp.http_exceptions.TransferEncodingError: 400, message:\n  Not enough data for satisfy transfer length header.\n\nThe above exception was the direct cause of the following exception:\n\nTraceback (most recent call last):\n  File \"/vllm-workspace/backend_request_func.py\", line 261, in async_request_openai_completions\n    async for chunk_bytes in response.content:\n  File \"/usr/local/lib/python3.10/dist-packages/aiohttp/streams.py\", line 50, in __anext__\n    rv = await self.read_func()\n  File \"/usr/local/lib/python3.10/dist-packages/aiohttp/streams.py\", line 317, in readline\n    return await self.readuntil()\n  File \"/usr/local/lib/python3.10/dist-packages/aiohttp/streams.py\", line 351, in readuntil\n    await self._wait(\"readuntil\")\n  File \"/usr/local/lib/python3.10/dist-packages/aiohttp/streams.py\", line 312, in _wait\n    await waiter\naiohttp.client_exceptions.ClientPayloadError: Response payload is not completed: <TransferEncodingError: 400, message='Not enough data for satisfy transfer length header.'>\n", "Traceback (most recent call last):\n  File \"/usr/local/lib/python3.10/dist-packages/aiohttp/client_proto.py\", line 94, in connection_lost\n    uncompleted = self._parser.feed_eof()\n  File \"aiohttp/_http_parser.pyx\", line 513, in aiohttp._http_parser.HttpParser.feed_eof\naiohttp.http_exceptions.TransferEncodingError: 400, message:\n  Not enough data for satisfy transfer length header.\n\nThe above exception was the direct cause of the following exception:\n\nTraceback (most recent call last):\n  File \"/vllm-workspace/backend_request_func.py\", line 261, in async_request_openai_completions\n    async for chunk_bytes in response.content:\n  File \"/usr/local/lib/python3.10/dist-packages/aiohttp/streams.py\", line 50, in __anext__\n    rv = await self.read_func()\n  File \"/usr/local/lib/python3.10/dist-packages/aiohttp/streams.py\", line 317, in readline\n    return await self.readuntil()\n  File \"/usr/local/lib/python3.10/dist-packages/aiohttp/streams.py\", line 351, in readuntil\n    await self._wait(\"readuntil\")\n  File \"/usr/local/lib/python3.10/dist-packages/aiohttp/streams.py\", line 312, in _wait\n    await waiter\naiohttp.client_exceptions.ClientPayloadError: Response payload is not completed: <TransferEncodingError: 400, message='Not enough data for satisfy transfer length header.'>\n", "Traceback (most recent call last):\n  File \"/usr/local/lib/python3.10/dist-packages/aiohttp/client_proto.py\", line 94, in connection_lost\n    uncompleted = self._parser.feed_eof()\n  File \"aiohttp/_http_parser.pyx\", line 513, in aiohttp._http_parser.HttpParser.feed_eof\naiohttp.http_exceptions.TransferEncodingError: 400, message:\n  Not enough data for satisfy transfer length header.\n\nThe above exception was the direct cause of the following exception:\n\nTraceback (most recent call last):\n  File \"/vllm-workspace/backend_request_func.py\", line 261, in async_request_openai_completions\n    async for chunk_bytes in response.content:\n  File \"/usr/local/lib/python3.10/dist-packages/aiohttp/streams.py\", line 50, in __anext__\n    rv = await self.read_func()\n  File \"/usr/local/lib/python3.10/dist-packages/aiohttp/streams.py\", line 317, in readline\n    return await self.readuntil()\n  File \"/usr/local/lib/python3.10/dist-packages/aiohttp/streams.py\", line 351, in readuntil\n    await self._wait(\"readuntil\")\n  File \"/usr/local/lib/python3.10/dist-packages/aiohttp/streams.py\", line 312, in _wait\n    await waiter\naiohttp.client_exceptions.ClientPayloadError: Response payload is not completed: <TransferEncodingError: 400, message='Not enough data for satisfy transfer length header.'>\n", "Traceback (most recent call last):\n  File \"/usr/local/lib/python3.10/dist-packages/aiohttp/client_proto.py\", line 94, in connection_lost\n    uncompleted = self._parser.feed_eof()\n  File \"aiohttp/_http_parser.pyx\", line 513, in aiohttp._http_parser.HttpParser.feed_eof\naiohttp.http_exceptions.TransferEncodingError: 400, message:\n  Not enough data for satisfy transfer length header.\n\nThe above exception was the direct cause of the following exception:\n\nTraceback (most recent call last):\n  File \"/vllm-workspace/backend_request_func.py\", line 261, in async_request_openai_completions\n    async for chunk_bytes in response.content:\n  File \"/usr/local/lib/python3.10/dist-packages/aiohttp/streams.py\", line 50, in __anext__\n    rv = await self.read_func()\n  File \"/usr/local/lib/python3.10/dist-packages/aiohttp/streams.py\", line 317, in readline\n    return await self.readuntil()\n  File \"/usr/local/lib/python3.10/dist-packages/aiohttp/streams.py\", line 351, in readuntil\n    await self._wait(\"readuntil\")\n  File \"/usr/local/lib/python3.10/dist-packages/aiohttp/streams.py\", line 312, in _wait\n    await waiter\naiohttp.client_exceptions.ClientPayloadError: Response payload is not completed: <TransferEncodingError: 400, message='Not enough data for satisfy transfer length header.'>\n", "Traceback (most recent call last):\n  File \"/usr/local/lib/python3.10/dist-packages/aiohttp/client_proto.py\", line 94, in connection_lost\n    uncompleted = self._parser.feed_eof()\n  File \"aiohttp/_http_parser.pyx\", line 513, in aiohttp._http_parser.HttpParser.feed_eof\naiohttp.http_exceptions.TransferEncodingError: 400, message:\n  Not enough data for satisfy transfer length header.\n\nThe above exception was the direct cause of the following exception:\n\nTraceback (most recent call last):\n  File \"/vllm-workspace/backend_request_func.py\", line 261, in async_request_openai_completions\n    async for chunk_bytes in response.content:\n  File \"/usr/local/lib/python3.10/dist-packages/aiohttp/streams.py\", line 50, in __anext__\n    rv = await self.read_func()\n  File \"/usr/local/lib/python3.10/dist-packages/aiohttp/streams.py\", line 317, in readline\n    return await self.readuntil()\n  File \"/usr/local/lib/python3.10/dist-packages/aiohttp/streams.py\", line 351, in readuntil\n    await self._wait(\"readuntil\")\n  File \"/usr/local/lib/python3.10/dist-packages/aiohttp/streams.py\", line 312, in _wait\n    await waiter\naiohttp.client_exceptions.ClientPayloadError: Response payload is not completed: <TransferEncodingError: 400, message='Not enough data for satisfy transfer length header.'>\n", "Traceback (most recent call last):\n  File \"/usr/local/lib/python3.10/dist-packages/aiohttp/client_proto.py\", line 94, in connection_lost\n    uncompleted = self._parser.feed_eof()\n  File \"aiohttp/_http_parser.pyx\", line 513, in aiohttp._http_parser.HttpParser.feed_eof\naiohttp.http_exceptions.TransferEncodingError: 400, message:\n  Not enough data for satisfy transfer length header.\n\nThe above exception was the direct cause of the following exception:\n\nTraceback (most recent call last):\n  File \"/vllm-workspace/backend_request_func.py\", line 261, in async_request_openai_completions\n    async for chunk_bytes in response.content:\n  File \"/usr/local/lib/python3.10/dist-packages/aiohttp/streams.py\", line 50, in __anext__\n    rv = await self.read_func()\n  File \"/usr/local/lib/python3.10/dist-packages/aiohttp/streams.py\", line 317, in readline\n    return await self.readuntil()\n  File \"/usr/local/lib/python3.10/dist-packages/aiohttp/streams.py\", line 351, in readuntil\n    await self._wait(\"readuntil\")\n  File \"/usr/local/lib/python3.10/dist-packages/aiohttp/streams.py\", line 312, in _wait\n    await waiter\naiohttp.client_exceptions.ClientPayloadError: Response payload is not completed: <TransferEncodingError: 400, message='Not enough data for satisfy transfer length header.'>\n", "Traceback (most recent call last):\n  File \"/usr/local/lib/python3.10/dist-packages/aiohttp/client_proto.py\", line 94, in connection_lost\n    uncompleted = self._parser.feed_eof()\n  File \"aiohttp/_http_parser.pyx\", line 513, in aiohttp._http_parser.HttpParser.feed_eof\naiohttp.http_exceptions.TransferEncodingError: 400, message:\n  Not enough data for satisfy transfer length header.\n\nThe above exception was the direct cause of the following exception:\n\nTraceback (most recent call last):\n  File \"/vllm-workspace/backend_request_func.py\", line 261, in async_request_openai_completions\n    async for chunk_bytes in response.content:\n  File \"/usr/local/lib/python3.10/dist-packages/aiohttp/streams.py\", line 50, in __anext__\n    rv = await self.read_func()\n  File \"/usr/local/lib/python3.10/dist-packages/aiohttp/streams.py\", line 317, in readline\n    return await self.readuntil()\n  File \"/usr/local/lib/python3.10/dist-packages/aiohttp/streams.py\", line 351, in readuntil\n    await self._wait(\"readuntil\")\n  File \"/usr/local/lib/python3.10/dist-packages/aiohttp/streams.py\", line 312, in _wait\n    await waiter\naiohttp.client_exceptions.ClientPayloadError: Response payload is not completed: <TransferEncodingError: 400, message='Not enough data for satisfy transfer length header.'>\n", "", "Traceback (most recent call last):\n  File \"/usr/local/lib/python3.10/dist-packages/aiohttp/client_proto.py\", line 94, in connection_lost\n    uncompleted = self._parser.feed_eof()\n  File \"aiohttp/_http_parser.pyx\", line 513, in aiohttp._http_parser.HttpParser.feed_eof\naiohttp.http_exceptions.TransferEncodingError: 400, message:\n  Not enough data for satisfy transfer length header.\n\nThe above exception was the direct cause of the following exception:\n\nTraceback (most recent call last):\n  File \"/vllm-workspace/backend_request_func.py\", line 261, in async_request_openai_completions\n    async for chunk_bytes in response.content:\n  File \"/usr/local/lib/python3.10/dist-packages/aiohttp/streams.py\", line 50, in __anext__\n    rv = await self.read_func()\n  File \"/usr/local/lib/python3.10/dist-packages/aiohttp/streams.py\", line 317, in readline\n    return await self.readuntil()\n  File \"/usr/local/lib/python3.10/dist-packages/aiohttp/streams.py\", line 351, in readuntil\n    await self._wait(\"readuntil\")\n  File \"/usr/local/lib/python3.10/dist-packages/aiohttp/streams.py\", line 312, in _wait\n    await waiter\naiohttp.client_exceptions.ClientPayloadError: Response payload is not completed: <TransferEncodingError: 400, message='Not enough data for satisfy transfer length header.'>\n", "Traceback (most recent call last):\n  File \"/usr/local/lib/python3.10/dist-packages/aiohttp/client_proto.py\", line 94, in connection_lost\n    uncompleted = self._parser.feed_eof()\n  File \"aiohttp/_http_parser.pyx\", line 513, in aiohttp._http_parser.HttpParser.feed_eof\naiohttp.http_exceptions.TransferEncodingError: 400, message:\n  Not enough data for satisfy transfer length header.\n\nThe above exception was the direct cause of the following exception:\n\nTraceback (most recent call last):\n  File \"/vllm-workspace/backend_request_func.py\", line 261, in async_request_openai_completions\n    async for chunk_bytes in response.content:\n  File \"/usr/local/lib/python3.10/dist-packages/aiohttp/streams.py\", line 50, in __anext__\n    rv = await self.read_func()\n  File \"/usr/local/lib/python3.10/dist-packages/aiohttp/streams.py\", line 317, in readline\n    return await self.readuntil()\n  File \"/usr/local/lib/python3.10/dist-packages/aiohttp/streams.py\", line 351, in readuntil\n    await self._wait(\"readuntil\")\n  File \"/usr/local/lib/python3.10/dist-packages/aiohttp/streams.py\", line 312, in _wait\n    await waiter\naiohttp.client_exceptions.ClientPayloadError: Response payload is not completed: <TransferEncodingError: 400, message='Not enough data for satisfy transfer length header.'>\n", "Traceback (most recent call last):\n  File \"/usr/local/lib/python3.10/dist-packages/aiohttp/client_proto.py\", line 94, in connection_lost\n    uncompleted = self._parser.feed_eof()\n  File \"aiohttp/_http_parser.pyx\", line 513, in aiohttp._http_parser.HttpParser.feed_eof\naiohttp.http_exceptions.TransferEncodingError: 400, message:\n  Not enough data for satisfy transfer length header.\n\nThe above exception was the direct cause of the following exception:\n\nTraceback (most recent call last):\n  File \"/vllm-workspace/backend_request_func.py\", line 261, in async_request_openai_completions\n    async for chunk_bytes in response.content:\n  File \"/usr/local/lib/python3.10/dist-packages/aiohttp/streams.py\", line 50, in __anext__\n    rv = await self.read_func()\n  File \"/usr/local/lib/python3.10/dist-packages/aiohttp/streams.py\", line 317, in readline\n    return await self.readuntil()\n  File \"/usr/local/lib/python3.10/dist-packages/aiohttp/streams.py\", line 351, in readuntil\n    await self._wait(\"readuntil\")\n  File \"/usr/local/lib/python3.10/dist-packages/aiohttp/streams.py\", line 312, in _wait\n    await waiter\naiohttp.client_exceptions.ClientPayloadError: Response payload is not completed: <TransferEncodingError: 400, message='Not enough data for satisfy transfer length header.'>\n", "Traceback (most recent call last):\n  File \"/usr/local/lib/python3.10/dist-packages/aiohttp/client_proto.py\", line 94, in connection_lost\n    uncompleted = self._parser.feed_eof()\n  File \"aiohttp/_http_parser.pyx\", line 513, in aiohttp._http_parser.HttpParser.feed_eof\naiohttp.http_exceptions.TransferEncodingError: 400, message:\n  Not enough data for satisfy transfer length header.\n\nThe above exception was the direct cause of the following exception:\n\nTraceback (most recent call last):\n  File \"/vllm-workspace/backend_request_func.py\", line 261, in async_request_openai_completions\n    async for chunk_bytes in response.content:\n  File \"/usr/local/lib/python3.10/dist-packages/aiohttp/streams.py\", line 50, in __anext__\n    rv = await self.read_func()\n  File \"/usr/local/lib/python3.10/dist-packages/aiohttp/streams.py\", line 317, in readline\n    return await self.readuntil()\n  File \"/usr/local/lib/python3.10/dist-packages/aiohttp/streams.py\", line 351, in readuntil\n    await self._wait(\"readuntil\")\n  File \"/usr/local/lib/python3.10/dist-packages/aiohttp/streams.py\", line 312, in _wait\n    await waiter\naiohttp.client_exceptions.ClientPayloadError: Response payload is not completed: <TransferEncodingError: 400, message='Not enough data for satisfy transfer length header.'>\n", "", "Traceback (most recent call last):\n  File \"/usr/local/lib/python3.10/dist-packages/aiohttp/client_proto.py\", line 94, in connection_lost\n    uncompleted = self._parser.feed_eof()\n  File \"aiohttp/_http_parser.pyx\", line 513, in aiohttp._http_parser.HttpParser.feed_eof\naiohttp.http_exceptions.TransferEncodingError: 400, message:\n  Not enough data for satisfy transfer length header.\n\nThe above exception was the direct cause of the following exception:\n\nTraceback (most recent call last):\n  File \"/vllm-workspace/backend_request_func.py\", line 261, in async_request_openai_completions\n    async for chunk_bytes in response.content:\n  File \"/usr/local/lib/python3.10/dist-packages/aiohttp/streams.py\", line 50, in __anext__\n    rv = await self.read_func()\n  File \"/usr/local/lib/python3.10/dist-packages/aiohttp/streams.py\", line 317, in readline\n    return await self.readuntil()\n  File \"/usr/local/lib/python3.10/dist-packages/aiohttp/streams.py\", line 351, in readuntil\n    await self._wait(\"readuntil\")\n  File \"/usr/local/lib/python3.10/dist-packages/aiohttp/streams.py\", line 312, in _wait\n    await waiter\naiohttp.client_exceptions.ClientPayloadError: Response payload is not completed: <TransferEncodingError: 400, message='Not enough data for satisfy transfer length header.'>\n", "", "Traceback (most recent call last):\n  File \"/usr/local/lib/python3.10/dist-packages/aiohttp/client_proto.py\", line 94, in connection_lost\n    uncompleted = self._parser.feed_eof()\n  File \"aiohttp/_http_parser.pyx\", line 513, in aiohttp._http_parser.HttpParser.feed_eof\naiohttp.http_exceptions.TransferEncodingError: 400, message:\n  Not enough data for satisfy transfer length header.\n\nThe above exception was the direct cause of the following exception:\n\nTraceback (most recent call last):\n  File \"/vllm-workspace/backend_request_func.py\", line 261, in async_request_openai_completions\n    async for chunk_bytes in response.content:\n  File \"/usr/local/lib/python3.10/dist-packages/aiohttp/streams.py\", line 50, in __anext__\n    rv = await self.read_func()\n  File \"/usr/local/lib/python3.10/dist-packages/aiohttp/streams.py\", line 317, in readline\n    return await self.readuntil()\n  File \"/usr/local/lib/python3.10/dist-packages/aiohttp/streams.py\", line 351, in readuntil\n    await self._wait(\"readuntil\")\n  File \"/usr/local/lib/python3.10/dist-packages/aiohttp/streams.py\", line 312, in _wait\n    await waiter\naiohttp.client_exceptions.ClientPayloadError: Response payload is not completed: <TransferEncodingError: 400, message='Not enough data for satisfy transfer length header.'>\n", "", "Traceback (most recent call last):\n  File \"/usr/local/lib/python3.10/dist-packages/aiohttp/client_proto.py\", line 94, in connection_lost\n    uncompleted = self._parser.feed_eof()\n  File \"aiohttp/_http_parser.pyx\", line 513, in aiohttp._http_parser.HttpParser.feed_eof\naiohttp.http_exceptions.TransferEncodingError: 400, message:\n  Not enough data for satisfy transfer length header.\n\nThe above exception was the direct cause of the following exception:\n\nTraceback (most recent call last):\n  File \"/vllm-workspace/backend_request_func.py\", line 261, in async_request_openai_completions\n    async for chunk_bytes in response.content:\n  File \"/usr/local/lib/python3.10/dist-packages/aiohttp/streams.py\", line 50, in __anext__\n    rv = await self.read_func()\n  File \"/usr/local/lib/python3.10/dist-packages/aiohttp/streams.py\", line 317, in readline\n    return await self.readuntil()\n  File \"/usr/local/lib/python3.10/dist-packages/aiohttp/streams.py\", line 351, in readuntil\n    await self._wait(\"readuntil\")\n  File \"/usr/local/lib/python3.10/dist-packages/aiohttp/streams.py\", line 312, in _wait\n    await waiter\naiohttp.client_exceptions.ClientPayloadError: Response payload is not completed: <TransferEncodingError: 400, message='Not enough data for satisfy transfer length header.'>\n", "Traceback (most recent call last):\n  File \"/usr/local/lib/python3.10/dist-packages/aiohttp/client_proto.py\", line 94, in connection_lost\n    uncompleted = self._parser.feed_eof()\n  File \"aiohttp/_http_parser.pyx\", line 513, in aiohttp._http_parser.HttpParser.feed_eof\naiohttp.http_exceptions.TransferEncodingError: 400, message:\n  Not enough data for satisfy transfer length header.\n\nThe above exception was the direct cause of the following exception:\n\nTraceback (most recent call last):\n  File \"/vllm-workspace/backend_request_func.py\", line 261, in async_request_openai_completions\n    async for chunk_bytes in response.content:\n  File \"/usr/local/lib/python3.10/dist-packages/aiohttp/streams.py\", line 50, in __anext__\n    rv = await self.read_func()\n  File \"/usr/local/lib/python3.10/dist-packages/aiohttp/streams.py\", line 317, in readline\n    return await self.readuntil()\n  File \"/usr/local/lib/python3.10/dist-packages/aiohttp/streams.py\", line 351, in readuntil\n    await self._wait(\"readuntil\")\n  File \"/usr/local/lib/python3.10/dist-packages/aiohttp/streams.py\", line 312, in _wait\n    await waiter\naiohttp.client_exceptions.ClientPayloadError: Response payload is not completed: <TransferEncodingError: 400, message='Not enough data for satisfy transfer length header.'>\n", "Traceback (most recent call last):\n  File \"/usr/local/lib/python3.10/dist-packages/aiohttp/client_proto.py\", line 94, in connection_lost\n    uncompleted = self._parser.feed_eof()\n  File \"aiohttp/_http_parser.pyx\", line 513, in aiohttp._http_parser.HttpParser.feed_eof\naiohttp.http_exceptions.TransferEncodingError: 400, message:\n  Not enough data for satisfy transfer length header.\n\nThe above exception was the direct cause of the following exception:\n\nTraceback (most recent call last):\n  File \"/vllm-workspace/backend_request_func.py\", line 261, in async_request_openai_completions\n    async for chunk_bytes in response.content:\n  File \"/usr/local/lib/python3.10/dist-packages/aiohttp/streams.py\", line 50, in __anext__\n    rv = await self.read_func()\n  File \"/usr/local/lib/python3.10/dist-packages/aiohttp/streams.py\", line 317, in readline\n    return await self.readuntil()\n  File \"/usr/local/lib/python3.10/dist-packages/aiohttp/streams.py\", line 351, in readuntil\n    await self._wait(\"readuntil\")\n  File \"/usr/local/lib/python3.10/dist-packages/aiohttp/streams.py\", line 312, in _wait\n    await waiter\naiohttp.client_exceptions.ClientPayloadError: Response payload is not completed: <TransferEncodingError: 400, message='Not enough data for satisfy transfer length header.'>\n", "Traceback (most recent call last):\n  File \"/usr/local/lib/python3.10/dist-packages/aiohttp/client_proto.py\", line 94, in connection_lost\n    uncompleted = self._parser.feed_eof()\n  File \"aiohttp/_http_parser.pyx\", line 513, in aiohttp._http_parser.HttpParser.feed_eof\naiohttp.http_exceptions.TransferEncodingError: 400, message:\n  Not enough data for satisfy transfer length header.\n\nThe above exception was the direct cause of the following exception:\n\nTraceback (most recent call last):\n  File \"/vllm-workspace/backend_request_func.py\", line 261, in async_request_openai_completions\n    async for chunk_bytes in response.content:\n  File \"/usr/local/lib/python3.10/dist-packages/aiohttp/streams.py\", line 50, in __anext__\n    rv = await self.read_func()\n  File \"/usr/local/lib/python3.10/dist-packages/aiohttp/streams.py\", line 317, in readline\n    return await self.readuntil()\n  File \"/usr/local/lib/python3.10/dist-packages/aiohttp/streams.py\", line 351, in readuntil\n    await self._wait(\"readuntil\")\n  File \"/usr/local/lib/python3.10/dist-packages/aiohttp/streams.py\", line 312, in _wait\n    await waiter\naiohttp.client_exceptions.ClientPayloadError: Response payload is not completed: <TransferEncodingError: 400, message='Not enough data for satisfy transfer length header.'>\n", "Traceback (most recent call last):\n  File \"/usr/local/lib/python3.10/dist-packages/aiohttp/client_proto.py\", line 94, in connection_lost\n    uncompleted = self._parser.feed_eof()\n  File \"aiohttp/_http_parser.pyx\", line 513, in aiohttp._http_parser.HttpParser.feed_eof\naiohttp.http_exceptions.TransferEncodingError: 400, message:\n  Not enough data for satisfy transfer length header.\n\nThe above exception was the direct cause of the following exception:\n\nTraceback (most recent call last):\n  File \"/vllm-workspace/backend_request_func.py\", line 261, in async_request_openai_completions\n    async for chunk_bytes in response.content:\n  File \"/usr/local/lib/python3.10/dist-packages/aiohttp/streams.py\", line 50, in __anext__\n    rv = await self.read_func()\n  File \"/usr/local/lib/python3.10/dist-packages/aiohttp/streams.py\", line 317, in readline\n    return await self.readuntil()\n  File \"/usr/local/lib/python3.10/dist-packages/aiohttp/streams.py\", line 351, in readuntil\n    await self._wait(\"readuntil\")\n  File \"/usr/local/lib/python3.10/dist-packages/aiohttp/streams.py\", line 312, in _wait\n    await waiter\naiohttp.client_exceptions.ClientPayloadError: Response payload is not completed: <TransferEncodingError: 400, message='Not enough data for satisfy transfer length header.'>\n", "Traceback (most recent call last):\n  File \"/usr/local/lib/python3.10/dist-packages/aiohttp/client_proto.py\", line 94, in connection_lost\n    uncompleted = self._parser.feed_eof()\n  File \"aiohttp/_http_parser.pyx\", line 513, in aiohttp._http_parser.HttpParser.feed_eof\naiohttp.http_exceptions.TransferEncodingError: 400, message:\n  Not enough data for satisfy transfer length header.\n\nThe above exception was the direct cause of the following exception:\n\nTraceback (most recent call last):\n  File \"/vllm-workspace/backend_request_func.py\", line 261, in async_request_openai_completions\n    async for chunk_bytes in response.content:\n  File \"/usr/local/lib/python3.10/dist-packages/aiohttp/streams.py\", line 50, in __anext__\n    rv = await self.read_func()\n  File \"/usr/local/lib/python3.10/dist-packages/aiohttp/streams.py\", line 317, in readline\n    return await self.readuntil()\n  File \"/usr/local/lib/python3.10/dist-packages/aiohttp/streams.py\", line 351, in readuntil\n    await self._wait(\"readuntil\")\n  File \"/usr/local/lib/python3.10/dist-packages/aiohttp/streams.py\", line 312, in _wait\n    await waiter\naiohttp.client_exceptions.ClientPayloadError: Response payload is not completed: <TransferEncodingError: 400, message='Not enough data for satisfy transfer length header.'>\n", "Traceback (most recent call last):\n  File \"/usr/local/lib/python3.10/dist-packages/aiohttp/client_proto.py\", line 94, in connection_lost\n    uncompleted = self._parser.feed_eof()\n  File \"aiohttp/_http_parser.pyx\", line 513, in aiohttp._http_parser.HttpParser.feed_eof\naiohttp.http_exceptions.TransferEncodingError: 400, message:\n  Not enough data for satisfy transfer length header.\n\nThe above exception was the direct cause of the following exception:\n\nTraceback (most recent call last):\n  File \"/vllm-workspace/backend_request_func.py\", line 261, in async_request_openai_completions\n    async for chunk_bytes in response.content:\n  File \"/usr/local/lib/python3.10/dist-packages/aiohttp/streams.py\", line 50, in __anext__\n    rv = await self.read_func()\n  File \"/usr/local/lib/python3.10/dist-packages/aiohttp/streams.py\", line 317, in readline\n    return await self.readuntil()\n  File \"/usr/local/lib/python3.10/dist-packages/aiohttp/streams.py\", line 351, in readuntil\n    await self._wait(\"readuntil\")\n  File \"/usr/local/lib/python3.10/dist-packages/aiohttp/streams.py\", line 312, in _wait\n    await waiter\naiohttp.client_exceptions.ClientPayloadError: Response payload is not completed: <TransferEncodingError: 400, message='Not enough data for satisfy transfer length header.'>\n", "Traceback (most recent call last):\n  File \"/usr/local/lib/python3.10/dist-packages/aiohttp/client_proto.py\", line 94, in connection_lost\n    uncompleted = self._parser.feed_eof()\n  File \"aiohttp/_http_parser.pyx\", line 513, in aiohttp._http_parser.HttpParser.feed_eof\naiohttp.http_exceptions.TransferEncodingError: 400, message:\n  Not enough data for satisfy transfer length header.\n\nThe above exception was the direct cause of the following exception:\n\nTraceback (most recent call last):\n  File \"/vllm-workspace/backend_request_func.py\", line 261, in async_request_openai_completions\n    async for chunk_bytes in response.content:\n  File \"/usr/local/lib/python3.10/dist-packages/aiohttp/streams.py\", line 50, in __anext__\n    rv = await self.read_func()\n  File \"/usr/local/lib/python3.10/dist-packages/aiohttp/streams.py\", line 317, in readline\n    return await self.readuntil()\n  File \"/usr/local/lib/python3.10/dist-packages/aiohttp/streams.py\", line 351, in readuntil\n    await self._wait(\"readuntil\")\n  File \"/usr/local/lib/python3.10/dist-packages/aiohttp/streams.py\", line 312, in _wait\n    await waiter\naiohttp.client_exceptions.ClientPayloadError: Response payload is not completed: <TransferEncodingError: 400, message='Not enough data for satisfy transfer length header.'>\n", "Traceback (most recent call last):\n  File \"/usr/local/lib/python3.10/dist-packages/aiohttp/client_proto.py\", line 94, in connection_lost\n    uncompleted = self._parser.feed_eof()\n  File \"aiohttp/_http_parser.pyx\", line 513, in aiohttp._http_parser.HttpParser.feed_eof\naiohttp.http_exceptions.TransferEncodingError: 400, message:\n  Not enough data for satisfy transfer length header.\n\nThe above exception was the direct cause of the following exception:\n\nTraceback (most recent call last):\n  File \"/vllm-workspace/backend_request_func.py\", line 261, in async_request_openai_completions\n    async for chunk_bytes in response.content:\n  File \"/usr/local/lib/python3.10/dist-packages/aiohttp/streams.py\", line 50, in __anext__\n    rv = await self.read_func()\n  File \"/usr/local/lib/python3.10/dist-packages/aiohttp/streams.py\", line 317, in readline\n    return await self.readuntil()\n  File \"/usr/local/lib/python3.10/dist-packages/aiohttp/streams.py\", line 351, in readuntil\n    await self._wait(\"readuntil\")\n  File \"/usr/local/lib/python3.10/dist-packages/aiohttp/streams.py\", line 312, in _wait\n    await waiter\naiohttp.client_exceptions.ClientPayloadError: Response payload is not completed: <TransferEncodingError: 400, message='Not enough data for satisfy transfer length header.'>\n", "Traceback (most recent call last):\n  File \"/usr/local/lib/python3.10/dist-packages/aiohttp/client_proto.py\", line 94, in connection_lost\n    uncompleted = self._parser.feed_eof()\n  File \"aiohttp/_http_parser.pyx\", line 513, in aiohttp._http_parser.HttpParser.feed_eof\naiohttp.http_exceptions.TransferEncodingError: 400, message:\n  Not enough data for satisfy transfer length header.\n\nThe above exception was the direct cause of the following exception:\n\nTraceback (most recent call last):\n  File \"/vllm-workspace/backend_request_func.py\", line 261, in async_request_openai_completions\n    async for chunk_bytes in response.content:\n  File \"/usr/local/lib/python3.10/dist-packages/aiohttp/streams.py\", line 50, in __anext__\n    rv = await self.read_func()\n  File \"/usr/local/lib/python3.10/dist-packages/aiohttp/streams.py\", line 317, in readline\n    return await self.readuntil()\n  File \"/usr/local/lib/python3.10/dist-packages/aiohttp/streams.py\", line 351, in readuntil\n    await self._wait(\"readuntil\")\n  File \"/usr/local/lib/python3.10/dist-packages/aiohttp/streams.py\", line 312, in _wait\n    await waiter\naiohttp.client_exceptions.ClientPayloadError: Response payload is not completed: <TransferEncodingError: 400, message='Not enough data for satisfy transfer length header.'>\n", "Traceback (most recent call last):\n  File \"/usr/local/lib/python3.10/dist-packages/aiohttp/client_proto.py\", line 94, in connection_lost\n    uncompleted = self._parser.feed_eof()\n  File \"aiohttp/_http_parser.pyx\", line 513, in aiohttp._http_parser.HttpParser.feed_eof\naiohttp.http_exceptions.TransferEncodingError: 400, message:\n  Not enough data for satisfy transfer length header.\n\nThe above exception was the direct cause of the following exception:\n\nTraceback (most recent call last):\n  File \"/vllm-workspace/backend_request_func.py\", line 261, in async_request_openai_completions\n    async for chunk_bytes in response.content:\n  File \"/usr/local/lib/python3.10/dist-packages/aiohttp/streams.py\", line 50, in __anext__\n    rv = await self.read_func()\n  File \"/usr/local/lib/python3.10/dist-packages/aiohttp/streams.py\", line 317, in readline\n    return await self.readuntil()\n  File \"/usr/local/lib/python3.10/dist-packages/aiohttp/streams.py\", line 351, in readuntil\n    await self._wait(\"readuntil\")\n  File \"/usr/local/lib/python3.10/dist-packages/aiohttp/streams.py\", line 312, in _wait\n    await waiter\naiohttp.client_exceptions.ClientPayloadError: Response payload is not completed: <TransferEncodingError: 400, message='Not enough data for satisfy transfer length header.'>\n", "Traceback (most recent call last):\n  File \"/usr/local/lib/python3.10/dist-packages/aiohttp/client_proto.py\", line 94, in connection_lost\n    uncompleted = self._parser.feed_eof()\n  File \"aiohttp/_http_parser.pyx\", line 513, in aiohttp._http_parser.HttpParser.feed_eof\naiohttp.http_exceptions.TransferEncodingError: 400, message:\n  Not enough data for satisfy transfer length header.\n\nThe above exception was the direct cause of the following exception:\n\nTraceback (most recent call last):\n  File \"/vllm-workspace/backend_request_func.py\", line 261, in async_request_openai_completions\n    async for chunk_bytes in response.content:\n  File \"/usr/local/lib/python3.10/dist-packages/aiohttp/streams.py\", line 50, in __anext__\n    rv = await self.read_func()\n  File \"/usr/local/lib/python3.10/dist-packages/aiohttp/streams.py\", line 317, in readline\n    return await self.readuntil()\n  File \"/usr/local/lib/python3.10/dist-packages/aiohttp/streams.py\", line 351, in readuntil\n    await self._wait(\"readuntil\")\n  File \"/usr/local/lib/python3.10/dist-packages/aiohttp/streams.py\", line 312, in _wait\n    await waiter\naiohttp.client_exceptions.ClientPayloadError: Response payload is not completed: <TransferEncodingError: 400, message='Not enough data for satisfy transfer length header.'>\n", "Traceback (most recent call last):\n  File \"/usr/local/lib/python3.10/dist-packages/aiohttp/client_proto.py\", line 94, in connection_lost\n    uncompleted = self._parser.feed_eof()\n  File \"aiohttp/_http_parser.pyx\", line 513, in aiohttp._http_parser.HttpParser.feed_eof\naiohttp.http_exceptions.TransferEncodingError: 400, message:\n  Not enough data for satisfy transfer length header.\n\nThe above exception was the direct cause of the following exception:\n\nTraceback (most recent call last):\n  File \"/vllm-workspace/backend_request_func.py\", line 261, in async_request_openai_completions\n    async for chunk_bytes in response.content:\n  File \"/usr/local/lib/python3.10/dist-packages/aiohttp/streams.py\", line 50, in __anext__\n    rv = await self.read_func()\n  File \"/usr/local/lib/python3.10/dist-packages/aiohttp/streams.py\", line 317, in readline\n    return await self.readuntil()\n  File \"/usr/local/lib/python3.10/dist-packages/aiohttp/streams.py\", line 351, in readuntil\n    await self._wait(\"readuntil\")\n  File \"/usr/local/lib/python3.10/dist-packages/aiohttp/streams.py\", line 312, in _wait\n    await waiter\naiohttp.client_exceptions.ClientPayloadError: Response payload is not completed: <TransferEncodingError: 400, message='Not enough data for satisfy transfer length header.'>\n", "Traceback (most recent call last):\n  File \"/usr/local/lib/python3.10/dist-packages/aiohttp/client_proto.py\", line 94, in connection_lost\n    uncompleted = self._parser.feed_eof()\n  File \"aiohttp/_http_parser.pyx\", line 513, in aiohttp._http_parser.HttpParser.feed_eof\naiohttp.http_exceptions.TransferEncodingError: 400, message:\n  Not enough data for satisfy transfer length header.\n\nThe above exception was the direct cause of the following exception:\n\nTraceback (most recent call last):\n  File \"/vllm-workspace/backend_request_func.py\", line 261, in async_request_openai_completions\n    async for chunk_bytes in response.content:\n  File \"/usr/local/lib/python3.10/dist-packages/aiohttp/streams.py\", line 50, in __anext__\n    rv = await self.read_func()\n  File \"/usr/local/lib/python3.10/dist-packages/aiohttp/streams.py\", line 317, in readline\n    return await self.readuntil()\n  File \"/usr/local/lib/python3.10/dist-packages/aiohttp/streams.py\", line 351, in readuntil\n    await self._wait(\"readuntil\")\n  File \"/usr/local/lib/python3.10/dist-packages/aiohttp/streams.py\", line 312, in _wait\n    await waiter\naiohttp.client_exceptions.ClientPayloadError: Response payload is not completed: <TransferEncodingError: 400, message='Not enough data for satisfy transfer length header.'>\n", "Traceback (most recent call last):\n  File \"/usr/local/lib/python3.10/dist-packages/aiohttp/client_proto.py\", line 94, in connection_lost\n    uncompleted = self._parser.feed_eof()\n  File \"aiohttp/_http_parser.pyx\", line 513, in aiohttp._http_parser.HttpParser.feed_eof\naiohttp.http_exceptions.TransferEncodingError: 400, message:\n  Not enough data for satisfy transfer length header.\n\nThe above exception was the direct cause of the following exception:\n\nTraceback (most recent call last):\n  File \"/vllm-workspace/backend_request_func.py\", line 261, in async_request_openai_completions\n    async for chunk_bytes in response.content:\n  File \"/usr/local/lib/python3.10/dist-packages/aiohttp/streams.py\", line 50, in __anext__\n    rv = await self.read_func()\n  File \"/usr/local/lib/python3.10/dist-packages/aiohttp/streams.py\", line 317, in readline\n    return await self.readuntil()\n  File \"/usr/local/lib/python3.10/dist-packages/aiohttp/streams.py\", line 351, in readuntil\n    await self._wait(\"readuntil\")\n  File \"/usr/local/lib/python3.10/dist-packages/aiohttp/streams.py\", line 312, in _wait\n    await waiter\naiohttp.client_exceptions.ClientPayloadError: Response payload is not completed: <TransferEncodingError: 400, message='Not enough data for satisfy transfer length header.'>\n", "Traceback (most recent call last):\n  File \"/usr/local/lib/python3.10/dist-packages/aiohttp/client_proto.py\", line 94, in connection_lost\n    uncompleted = self._parser.feed_eof()\n  File \"aiohttp/_http_parser.pyx\", line 513, in aiohttp._http_parser.HttpParser.feed_eof\naiohttp.http_exceptions.TransferEncodingError: 400, message:\n  Not enough data for satisfy transfer length header.\n\nThe above exception was the direct cause of the following exception:\n\nTraceback (most recent call last):\n  File \"/vllm-workspace/backend_request_func.py\", line 261, in async_request_openai_completions\n    async for chunk_bytes in response.content:\n  File \"/usr/local/lib/python3.10/dist-packages/aiohttp/streams.py\", line 50, in __anext__\n    rv = await self.read_func()\n  File \"/usr/local/lib/python3.10/dist-packages/aiohttp/streams.py\", line 317, in readline\n    return await self.readuntil()\n  File \"/usr/local/lib/python3.10/dist-packages/aiohttp/streams.py\", line 351, in readuntil\n    await self._wait(\"readuntil\")\n  File \"/usr/local/lib/python3.10/dist-packages/aiohttp/streams.py\", line 312, in _wait\n    await waiter\naiohttp.client_exceptions.ClientPayloadError: Response payload is not completed: <TransferEncodingError: 400, message='Not enough data for satisfy transfer length header.'>\n", "Traceback (most recent call last):\n  File \"/usr/local/lib/python3.10/dist-packages/aiohttp/client_proto.py\", line 94, in connection_lost\n    uncompleted = self._parser.feed_eof()\n  File \"aiohttp/_http_parser.pyx\", line 513, in aiohttp._http_parser.HttpParser.feed_eof\naiohttp.http_exceptions.TransferEncodingError: 400, message:\n  Not enough data for satisfy transfer length header.\n\nThe above exception was the direct cause of the following exception:\n\nTraceback (most recent call last):\n  File \"/vllm-workspace/backend_request_func.py\", line 261, in async_request_openai_completions\n    async for chunk_bytes in response.content:\n  File \"/usr/local/lib/python3.10/dist-packages/aiohttp/streams.py\", line 50, in __anext__\n    rv = await self.read_func()\n  File \"/usr/local/lib/python3.10/dist-packages/aiohttp/streams.py\", line 317, in readline\n    return await self.readuntil()\n  File \"/usr/local/lib/python3.10/dist-packages/aiohttp/streams.py\", line 351, in readuntil\n    await self._wait(\"readuntil\")\n  File \"/usr/local/lib/python3.10/dist-packages/aiohttp/streams.py\", line 312, in _wait\n    await waiter\naiohttp.client_exceptions.ClientPayloadError: Response payload is not completed: <TransferEncodingError: 400, message='Not enough data for satisfy transfer length header.'>\n", "", "Traceback (most recent call last):\n  File \"/usr/local/lib/python3.10/dist-packages/aiohttp/client_proto.py\", line 94, in connection_lost\n    uncompleted = self._parser.feed_eof()\n  File \"aiohttp/_http_parser.pyx\", line 513, in aiohttp._http_parser.HttpParser.feed_eof\naiohttp.http_exceptions.TransferEncodingError: 400, message:\n  Not enough data for satisfy transfer length header.\n\nThe above exception was the direct cause of the following exception:\n\nTraceback (most recent call last):\n  File \"/vllm-workspace/backend_request_func.py\", line 261, in async_request_openai_completions\n    async for chunk_bytes in response.content:\n  File \"/usr/local/lib/python3.10/dist-packages/aiohttp/streams.py\", line 50, in __anext__\n    rv = await self.read_func()\n  File \"/usr/local/lib/python3.10/dist-packages/aiohttp/streams.py\", line 317, in readline\n    return await self.readuntil()\n  File \"/usr/local/lib/python3.10/dist-packages/aiohttp/streams.py\", line 351, in readuntil\n    await self._wait(\"readuntil\")\n  File \"/usr/local/lib/python3.10/dist-packages/aiohttp/streams.py\", line 312, in _wait\n    await waiter\naiohttp.client_exceptions.ClientPayloadError: Response payload is not completed: <TransferEncodingError: 400, message='Not enough data for satisfy transfer length header.'>\n", "Traceback (most recent call last):\n  File \"/usr/local/lib/python3.10/dist-packages/aiohttp/client_proto.py\", line 94, in connection_lost\n    uncompleted = self._parser.feed_eof()\n  File \"aiohttp/_http_parser.pyx\", line 513, in aiohttp._http_parser.HttpParser.feed_eof\naiohttp.http_exceptions.TransferEncodingError: 400, message:\n  Not enough data for satisfy transfer length header.\n\nThe above exception was the direct cause of the following exception:\n\nTraceback (most recent call last):\n  File \"/vllm-workspace/backend_request_func.py\", line 261, in async_request_openai_completions\n    async for chunk_bytes in response.content:\n  File \"/usr/local/lib/python3.10/dist-packages/aiohttp/streams.py\", line 50, in __anext__\n    rv = await self.read_func()\n  File \"/usr/local/lib/python3.10/dist-packages/aiohttp/streams.py\", line 317, in readline\n    return await self.readuntil()\n  File \"/usr/local/lib/python3.10/dist-packages/aiohttp/streams.py\", line 351, in readuntil\n    await self._wait(\"readuntil\")\n  File \"/usr/local/lib/python3.10/dist-packages/aiohttp/streams.py\", line 312, in _wait\n    await waiter\naiohttp.client_exceptions.ClientPayloadError: Response payload is not completed: <TransferEncodingError: 400, message='Not enough data for satisfy transfer length header.'>\n", "Traceback (most recent call last):\n  File \"/usr/local/lib/python3.10/dist-packages/aiohttp/client_proto.py\", line 94, in connection_lost\n    uncompleted = self._parser.feed_eof()\n  File \"aiohttp/_http_parser.pyx\", line 513, in aiohttp._http_parser.HttpParser.feed_eof\naiohttp.http_exceptions.TransferEncodingError: 400, message:\n  Not enough data for satisfy transfer length header.\n\nThe above exception was the direct cause of the following exception:\n\nTraceback (most recent call last):\n  File \"/vllm-workspace/backend_request_func.py\", line 261, in async_request_openai_completions\n    async for chunk_bytes in response.content:\n  File \"/usr/local/lib/python3.10/dist-packages/aiohttp/streams.py\", line 50, in __anext__\n    rv = await self.read_func()\n  File \"/usr/local/lib/python3.10/dist-packages/aiohttp/streams.py\", line 317, in readline\n    return await self.readuntil()\n  File \"/usr/local/lib/python3.10/dist-packages/aiohttp/streams.py\", line 351, in readuntil\n    await self._wait(\"readuntil\")\n  File \"/usr/local/lib/python3.10/dist-packages/aiohttp/streams.py\", line 312, in _wait\n    await waiter\naiohttp.client_exceptions.ClientPayloadError: Response payload is not completed: <TransferEncodingError: 400, message='Not enough data for satisfy transfer length header.'>\n", "Traceback (most recent call last):\n  File \"/usr/local/lib/python3.10/dist-packages/aiohttp/client_proto.py\", line 94, in connection_lost\n    uncompleted = self._parser.feed_eof()\n  File \"aiohttp/_http_parser.pyx\", line 513, in aiohttp._http_parser.HttpParser.feed_eof\naiohttp.http_exceptions.TransferEncodingError: 400, message:\n  Not enough data for satisfy transfer length header.\n\nThe above exception was the direct cause of the following exception:\n\nTraceback (most recent call last):\n  File \"/vllm-workspace/backend_request_func.py\", line 261, in async_request_openai_completions\n    async for chunk_bytes in response.content:\n  File \"/usr/local/lib/python3.10/dist-packages/aiohttp/streams.py\", line 50, in __anext__\n    rv = await self.read_func()\n  File \"/usr/local/lib/python3.10/dist-packages/aiohttp/streams.py\", line 317, in readline\n    return await self.readuntil()\n  File \"/usr/local/lib/python3.10/dist-packages/aiohttp/streams.py\", line 351, in readuntil\n    await self._wait(\"readuntil\")\n  File \"/usr/local/lib/python3.10/dist-packages/aiohttp/streams.py\", line 312, in _wait\n    await waiter\naiohttp.client_exceptions.ClientPayloadError: Response payload is not completed: <TransferEncodingError: 400, message='Not enough data for satisfy transfer length header.'>\n", "Traceback (most recent call last):\n  File \"/usr/local/lib/python3.10/dist-packages/aiohttp/client_proto.py\", line 94, in connection_lost\n    uncompleted = self._parser.feed_eof()\n  File \"aiohttp/_http_parser.pyx\", line 513, in aiohttp._http_parser.HttpParser.feed_eof\naiohttp.http_exceptions.TransferEncodingError: 400, message:\n  Not enough data for satisfy transfer length header.\n\nThe above exception was the direct cause of the following exception:\n\nTraceback (most recent call last):\n  File \"/vllm-workspace/backend_request_func.py\", line 261, in async_request_openai_completions\n    async for chunk_bytes in response.content:\n  File \"/usr/local/lib/python3.10/dist-packages/aiohttp/streams.py\", line 50, in __anext__\n    rv = await self.read_func()\n  File \"/usr/local/lib/python3.10/dist-packages/aiohttp/streams.py\", line 317, in readline\n    return await self.readuntil()\n  File \"/usr/local/lib/python3.10/dist-packages/aiohttp/streams.py\", line 351, in readuntil\n    await self._wait(\"readuntil\")\n  File \"/usr/local/lib/python3.10/dist-packages/aiohttp/streams.py\", line 312, in _wait\n    await waiter\naiohttp.client_exceptions.ClientPayloadError: Response payload is not completed: <TransferEncodingError: 400, message='Not enough data for satisfy transfer length header.'>\n", "Traceback (most recent call last):\n  File \"/usr/local/lib/python3.10/dist-packages/aiohttp/client_proto.py\", line 94, in connection_lost\n    uncompleted = self._parser.feed_eof()\n  File \"aiohttp/_http_parser.pyx\", line 513, in aiohttp._http_parser.HttpParser.feed_eof\naiohttp.http_exceptions.TransferEncodingError: 400, message:\n  Not enough data for satisfy transfer length header.\n\nThe above exception was the direct cause of the following exception:\n\nTraceback (most recent call last):\n  File \"/vllm-workspace/backend_request_func.py\", line 261, in async_request_openai_completions\n    async for chunk_bytes in response.content:\n  File \"/usr/local/lib/python3.10/dist-packages/aiohttp/streams.py\", line 50, in __anext__\n    rv = await self.read_func()\n  File \"/usr/local/lib/python3.10/dist-packages/aiohttp/streams.py\", line 317, in readline\n    return await self.readuntil()\n  File \"/usr/local/lib/python3.10/dist-packages/aiohttp/streams.py\", line 351, in readuntil\n    await self._wait(\"readuntil\")\n  File \"/usr/local/lib/python3.10/dist-packages/aiohttp/streams.py\", line 312, in _wait\n    await waiter\naiohttp.client_exceptions.ClientPayloadError: Response payload is not completed: <TransferEncodingError: 400, message='Not enough data for satisfy transfer length header.'>\n", "Traceback (most recent call last):\n  File \"/usr/local/lib/python3.10/dist-packages/aiohttp/client_proto.py\", line 94, in connection_lost\n    uncompleted = self._parser.feed_eof()\n  File \"aiohttp/_http_parser.pyx\", line 513, in aiohttp._http_parser.HttpParser.feed_eof\naiohttp.http_exceptions.TransferEncodingError: 400, message:\n  Not enough data for satisfy transfer length header.\n\nThe above exception was the direct cause of the following exception:\n\nTraceback (most recent call last):\n  File \"/vllm-workspace/backend_request_func.py\", line 261, in async_request_openai_completions\n    async for chunk_bytes in response.content:\n  File \"/usr/local/lib/python3.10/dist-packages/aiohttp/streams.py\", line 50, in __anext__\n    rv = await self.read_func()\n  File \"/usr/local/lib/python3.10/dist-packages/aiohttp/streams.py\", line 317, in readline\n    return await self.readuntil()\n  File \"/usr/local/lib/python3.10/dist-packages/aiohttp/streams.py\", line 351, in readuntil\n    await self._wait(\"readuntil\")\n  File \"/usr/local/lib/python3.10/dist-packages/aiohttp/streams.py\", line 312, in _wait\n    await waiter\naiohttp.client_exceptions.ClientPayloadError: Response payload is not completed: <TransferEncodingError: 400, message='Not enough data for satisfy transfer length header.'>\n", "Traceback (most recent call last):\n  File \"/usr/local/lib/python3.10/dist-packages/aiohttp/client_proto.py\", line 94, in connection_lost\n    uncompleted = self._parser.feed_eof()\n  File \"aiohttp/_http_parser.pyx\", line 513, in aiohttp._http_parser.HttpParser.feed_eof\naiohttp.http_exceptions.TransferEncodingError: 400, message:\n  Not enough data for satisfy transfer length header.\n\nThe above exception was the direct cause of the following exception:\n\nTraceback (most recent call last):\n  File \"/vllm-workspace/backend_request_func.py\", line 261, in async_request_openai_completions\n    async for chunk_bytes in response.content:\n  File \"/usr/local/lib/python3.10/dist-packages/aiohttp/streams.py\", line 50, in __anext__\n    rv = await self.read_func()\n  File \"/usr/local/lib/python3.10/dist-packages/aiohttp/streams.py\", line 317, in readline\n    return await self.readuntil()\n  File \"/usr/local/lib/python3.10/dist-packages/aiohttp/streams.py\", line 351, in readuntil\n    await self._wait(\"readuntil\")\n  File \"/usr/local/lib/python3.10/dist-packages/aiohttp/streams.py\", line 312, in _wait\n    await waiter\naiohttp.client_exceptions.ClientPayloadError: Response payload is not completed: <TransferEncodingError: 400, message='Not enough data for satisfy transfer length header.'>\n", "Traceback (most recent call last):\n  File \"/usr/local/lib/python3.10/dist-packages/aiohttp/client_proto.py\", line 94, in connection_lost\n    uncompleted = self._parser.feed_eof()\n  File \"aiohttp/_http_parser.pyx\", line 513, in aiohttp._http_parser.HttpParser.feed_eof\naiohttp.http_exceptions.TransferEncodingError: 400, message:\n  Not enough data for satisfy transfer length header.\n\nThe above exception was the direct cause of the following exception:\n\nTraceback (most recent call last):\n  File \"/vllm-workspace/backend_request_func.py\", line 261, in async_request_openai_completions\n    async for chunk_bytes in response.content:\n  File \"/usr/local/lib/python3.10/dist-packages/aiohttp/streams.py\", line 50, in __anext__\n    rv = await self.read_func()\n  File \"/usr/local/lib/python3.10/dist-packages/aiohttp/streams.py\", line 317, in readline\n    return await self.readuntil()\n  File \"/usr/local/lib/python3.10/dist-packages/aiohttp/streams.py\", line 351, in readuntil\n    await self._wait(\"readuntil\")\n  File \"/usr/local/lib/python3.10/dist-packages/aiohttp/streams.py\", line 312, in _wait\n    await waiter\naiohttp.client_exceptions.ClientPayloadError: Response payload is not completed: <TransferEncodingError: 400, message='Not enough data for satisfy transfer length header.'>\n", "Traceback (most recent call last):\n  File \"/usr/local/lib/python3.10/dist-packages/aiohttp/client_proto.py\", line 94, in connection_lost\n    uncompleted = self._parser.feed_eof()\n  File \"aiohttp/_http_parser.pyx\", line 513, in aiohttp._http_parser.HttpParser.feed_eof\naiohttp.http_exceptions.TransferEncodingError: 400, message:\n  Not enough data for satisfy transfer length header.\n\nThe above exception was the direct cause of the following exception:\n\nTraceback (most recent call last):\n  File \"/vllm-workspace/backend_request_func.py\", line 261, in async_request_openai_completions\n    async for chunk_bytes in response.content:\n  File \"/usr/local/lib/python3.10/dist-packages/aiohttp/streams.py\", line 50, in __anext__\n    rv = await self.read_func()\n  File \"/usr/local/lib/python3.10/dist-packages/aiohttp/streams.py\", line 317, in readline\n    return await self.readuntil()\n  File \"/usr/local/lib/python3.10/dist-packages/aiohttp/streams.py\", line 351, in readuntil\n    await self._wait(\"readuntil\")\n  File \"/usr/local/lib/python3.10/dist-packages/aiohttp/streams.py\", line 312, in _wait\n    await waiter\naiohttp.client_exceptions.ClientPayloadError: Response payload is not completed: <TransferEncodingError: 400, message='Not enough data for satisfy transfer length header.'>\n", "Traceback (most recent call last):\n  File \"/usr/local/lib/python3.10/dist-packages/aiohttp/client_proto.py\", line 94, in connection_lost\n    uncompleted = self._parser.feed_eof()\n  File \"aiohttp/_http_parser.pyx\", line 513, in aiohttp._http_parser.HttpParser.feed_eof\naiohttp.http_exceptions.TransferEncodingError: 400, message:\n  Not enough data for satisfy transfer length header.\n\nThe above exception was the direct cause of the following exception:\n\nTraceback (most recent call last):\n  File \"/vllm-workspace/backend_request_func.py\", line 261, in async_request_openai_completions\n    async for chunk_bytes in response.content:\n  File \"/usr/local/lib/python3.10/dist-packages/aiohttp/streams.py\", line 50, in __anext__\n    rv = await self.read_func()\n  File \"/usr/local/lib/python3.10/dist-packages/aiohttp/streams.py\", line 317, in readline\n    return await self.readuntil()\n  File \"/usr/local/lib/python3.10/dist-packages/aiohttp/streams.py\", line 351, in readuntil\n    await self._wait(\"readuntil\")\n  File \"/usr/local/lib/python3.10/dist-packages/aiohttp/streams.py\", line 312, in _wait\n    await waiter\naiohttp.client_exceptions.ClientPayloadError: Response payload is not completed: <TransferEncodingError: 400, message='Not enough data for satisfy transfer length header.'>\n", "Traceback (most recent call last):\n  File \"/usr/local/lib/python3.10/dist-packages/aiohttp/client_proto.py\", line 94, in connection_lost\n    uncompleted = self._parser.feed_eof()\n  File \"aiohttp/_http_parser.pyx\", line 513, in aiohttp._http_parser.HttpParser.feed_eof\naiohttp.http_exceptions.TransferEncodingError: 400, message:\n  Not enough data for satisfy transfer length header.\n\nThe above exception was the direct cause of the following exception:\n\nTraceback (most recent call last):\n  File \"/vllm-workspace/backend_request_func.py\", line 261, in async_request_openai_completions\n    async for chunk_bytes in response.content:\n  File \"/usr/local/lib/python3.10/dist-packages/aiohttp/streams.py\", line 50, in __anext__\n    rv = await self.read_func()\n  File \"/usr/local/lib/python3.10/dist-packages/aiohttp/streams.py\", line 317, in readline\n    return await self.readuntil()\n  File \"/usr/local/lib/python3.10/dist-packages/aiohttp/streams.py\", line 351, in readuntil\n    await self._wait(\"readuntil\")\n  File \"/usr/local/lib/python3.10/dist-packages/aiohttp/streams.py\", line 312, in _wait\n    await waiter\naiohttp.client_exceptions.ClientPayloadError: Response payload is not completed: <TransferEncodingError: 400, message='Not enough data for satisfy transfer length header.'>\n", "Traceback (most recent call last):\n  File \"/usr/local/lib/python3.10/dist-packages/aiohttp/client_proto.py\", line 94, in connection_lost\n    uncompleted = self._parser.feed_eof()\n  File \"aiohttp/_http_parser.pyx\", line 513, in aiohttp._http_parser.HttpParser.feed_eof\naiohttp.http_exceptions.TransferEncodingError: 400, message:\n  Not enough data for satisfy transfer length header.\n\nThe above exception was the direct cause of the following exception:\n\nTraceback (most recent call last):\n  File \"/vllm-workspace/backend_request_func.py\", line 261, in async_request_openai_completions\n    async for chunk_bytes in response.content:\n  File \"/usr/local/lib/python3.10/dist-packages/aiohttp/streams.py\", line 50, in __anext__\n    rv = await self.read_func()\n  File \"/usr/local/lib/python3.10/dist-packages/aiohttp/streams.py\", line 317, in readline\n    return await self.readuntil()\n  File \"/usr/local/lib/python3.10/dist-packages/aiohttp/streams.py\", line 351, in readuntil\n    await self._wait(\"readuntil\")\n  File \"/usr/local/lib/python3.10/dist-packages/aiohttp/streams.py\", line 312, in _wait\n    await waiter\naiohttp.client_exceptions.ClientPayloadError: Response payload is not completed: <TransferEncodingError: 400, message='Not enough data for satisfy transfer length header.'>\n", "Traceback (most recent call last):\n  File \"/usr/local/lib/python3.10/dist-packages/aiohttp/client_proto.py\", line 94, in connection_lost\n    uncompleted = self._parser.feed_eof()\n  File \"aiohttp/_http_parser.pyx\", line 513, in aiohttp._http_parser.HttpParser.feed_eof\naiohttp.http_exceptions.TransferEncodingError: 400, message:\n  Not enough data for satisfy transfer length header.\n\nThe above exception was the direct cause of the following exception:\n\nTraceback (most recent call last):\n  File \"/vllm-workspace/backend_request_func.py\", line 261, in async_request_openai_completions\n    async for chunk_bytes in response.content:\n  File \"/usr/local/lib/python3.10/dist-packages/aiohttp/streams.py\", line 50, in __anext__\n    rv = await self.read_func()\n  File \"/usr/local/lib/python3.10/dist-packages/aiohttp/streams.py\", line 317, in readline\n    return await self.readuntil()\n  File \"/usr/local/lib/python3.10/dist-packages/aiohttp/streams.py\", line 351, in readuntil\n    await self._wait(\"readuntil\")\n  File \"/usr/local/lib/python3.10/dist-packages/aiohttp/streams.py\", line 312, in _wait\n    await waiter\naiohttp.client_exceptions.ClientPayloadError: Response payload is not completed: <TransferEncodingError: 400, message='Not enough data for satisfy transfer length header.'>\n", "Traceback (most recent call last):\n  File \"/usr/local/lib/python3.10/dist-packages/aiohttp/client_proto.py\", line 94, in connection_lost\n    uncompleted = self._parser.feed_eof()\n  File \"aiohttp/_http_parser.pyx\", line 513, in aiohttp._http_parser.HttpParser.feed_eof\naiohttp.http_exceptions.TransferEncodingError: 400, message:\n  Not enough data for satisfy transfer length header.\n\nThe above exception was the direct cause of the following exception:\n\nTraceback (most recent call last):\n  File \"/vllm-workspace/backend_request_func.py\", line 261, in async_request_openai_completions\n    async for chunk_bytes in response.content:\n  File \"/usr/local/lib/python3.10/dist-packages/aiohttp/streams.py\", line 50, in __anext__\n    rv = await self.read_func()\n  File \"/usr/local/lib/python3.10/dist-packages/aiohttp/streams.py\", line 317, in readline\n    return await self.readuntil()\n  File \"/usr/local/lib/python3.10/dist-packages/aiohttp/streams.py\", line 351, in readuntil\n    await self._wait(\"readuntil\")\n  File \"/usr/local/lib/python3.10/dist-packages/aiohttp/streams.py\", line 312, in _wait\n    await waiter\naiohttp.client_exceptions.ClientPayloadError: Response payload is not completed: <TransferEncodingError: 400, message='Not enough data for satisfy transfer length header.'>\n", "Traceback (most recent call last):\n  File \"/usr/local/lib/python3.10/dist-packages/aiohttp/client_proto.py\", line 94, in connection_lost\n    uncompleted = self._parser.feed_eof()\n  File \"aiohttp/_http_parser.pyx\", line 513, in aiohttp._http_parser.HttpParser.feed_eof\naiohttp.http_exceptions.TransferEncodingError: 400, message:\n  Not enough data for satisfy transfer length header.\n\nThe above exception was the direct cause of the following exception:\n\nTraceback (most recent call last):\n  File \"/vllm-workspace/backend_request_func.py\", line 261, in async_request_openai_completions\n    async for chunk_bytes in response.content:\n  File \"/usr/local/lib/python3.10/dist-packages/aiohttp/streams.py\", line 50, in __anext__\n    rv = await self.read_func()\n  File \"/usr/local/lib/python3.10/dist-packages/aiohttp/streams.py\", line 317, in readline\n    return await self.readuntil()\n  File \"/usr/local/lib/python3.10/dist-packages/aiohttp/streams.py\", line 351, in readuntil\n    await self._wait(\"readuntil\")\n  File \"/usr/local/lib/python3.10/dist-packages/aiohttp/streams.py\", line 312, in _wait\n    await waiter\naiohttp.client_exceptions.ClientPayloadError: Response payload is not completed: <TransferEncodingError: 400, message='Not enough data for satisfy transfer length header.'>\n", "Traceback (most recent call last):\n  File \"/usr/local/lib/python3.10/dist-packages/aiohttp/client_proto.py\", line 94, in connection_lost\n    uncompleted = self._parser.feed_eof()\n  File \"aiohttp/_http_parser.pyx\", line 513, in aiohttp._http_parser.HttpParser.feed_eof\naiohttp.http_exceptions.TransferEncodingError: 400, message:\n  Not enough data for satisfy transfer length header.\n\nThe above exception was the direct cause of the following exception:\n\nTraceback (most recent call last):\n  File \"/vllm-workspace/backend_request_func.py\", line 261, in async_request_openai_completions\n    async for chunk_bytes in response.content:\n  File \"/usr/local/lib/python3.10/dist-packages/aiohttp/streams.py\", line 50, in __anext__\n    rv = await self.read_func()\n  File \"/usr/local/lib/python3.10/dist-packages/aiohttp/streams.py\", line 317, in readline\n    return await self.readuntil()\n  File \"/usr/local/lib/python3.10/dist-packages/aiohttp/streams.py\", line 351, in readuntil\n    await self._wait(\"readuntil\")\n  File \"/usr/local/lib/python3.10/dist-packages/aiohttp/streams.py\", line 312, in _wait\n    await waiter\naiohttp.client_exceptions.ClientPayloadError: Response payload is not completed: <TransferEncodingError: 400, message='Not enough data for satisfy transfer length header.'>\n", "Traceback (most recent call last):\n  File \"/usr/local/lib/python3.10/dist-packages/aiohttp/client_proto.py\", line 94, in connection_lost\n    uncompleted = self._parser.feed_eof()\n  File \"aiohttp/_http_parser.pyx\", line 513, in aiohttp._http_parser.HttpParser.feed_eof\naiohttp.http_exceptions.TransferEncodingError: 400, message:\n  Not enough data for satisfy transfer length header.\n\nThe above exception was the direct cause of the following exception:\n\nTraceback (most recent call last):\n  File \"/vllm-workspace/backend_request_func.py\", line 261, in async_request_openai_completions\n    async for chunk_bytes in response.content:\n  File \"/usr/local/lib/python3.10/dist-packages/aiohttp/streams.py\", line 50, in __anext__\n    rv = await self.read_func()\n  File \"/usr/local/lib/python3.10/dist-packages/aiohttp/streams.py\", line 317, in readline\n    return await self.readuntil()\n  File \"/usr/local/lib/python3.10/dist-packages/aiohttp/streams.py\", line 351, in readuntil\n    await self._wait(\"readuntil\")\n  File \"/usr/local/lib/python3.10/dist-packages/aiohttp/streams.py\", line 312, in _wait\n    await waiter\naiohttp.client_exceptions.ClientPayloadError: Response payload is not completed: <TransferEncodingError: 400, message='Not enough data for satisfy transfer length header.'>\n", "Traceback (most recent call last):\n  File \"/usr/local/lib/python3.10/dist-packages/aiohttp/client_proto.py\", line 94, in connection_lost\n    uncompleted = self._parser.feed_eof()\n  File \"aiohttp/_http_parser.pyx\", line 513, in aiohttp._http_parser.HttpParser.feed_eof\naiohttp.http_exceptions.TransferEncodingError: 400, message:\n  Not enough data for satisfy transfer length header.\n\nThe above exception was the direct cause of the following exception:\n\nTraceback (most recent call last):\n  File \"/vllm-workspace/backend_request_func.py\", line 261, in async_request_openai_completions\n    async for chunk_bytes in response.content:\n  File \"/usr/local/lib/python3.10/dist-packages/aiohttp/streams.py\", line 50, in __anext__\n    rv = await self.read_func()\n  File \"/usr/local/lib/python3.10/dist-packages/aiohttp/streams.py\", line 317, in readline\n    return await self.readuntil()\n  File \"/usr/local/lib/python3.10/dist-packages/aiohttp/streams.py\", line 351, in readuntil\n    await self._wait(\"readuntil\")\n  File \"/usr/local/lib/python3.10/dist-packages/aiohttp/streams.py\", line 312, in _wait\n    await waiter\naiohttp.client_exceptions.ClientPayloadError: Response payload is not completed: <TransferEncodingError: 400, message='Not enough data for satisfy transfer length header.'>\n", "Traceback (most recent call last):\n  File \"/usr/local/lib/python3.10/dist-packages/aiohttp/client_proto.py\", line 94, in connection_lost\n    uncompleted = self._parser.feed_eof()\n  File \"aiohttp/_http_parser.pyx\", line 513, in aiohttp._http_parser.HttpParser.feed_eof\naiohttp.http_exceptions.TransferEncodingError: 400, message:\n  Not enough data for satisfy transfer length header.\n\nThe above exception was the direct cause of the following exception:\n\nTraceback (most recent call last):\n  File \"/vllm-workspace/backend_request_func.py\", line 261, in async_request_openai_completions\n    async for chunk_bytes in response.content:\n  File \"/usr/local/lib/python3.10/dist-packages/aiohttp/streams.py\", line 50, in __anext__\n    rv = await self.read_func()\n  File \"/usr/local/lib/python3.10/dist-packages/aiohttp/streams.py\", line 317, in readline\n    return await self.readuntil()\n  File \"/usr/local/lib/python3.10/dist-packages/aiohttp/streams.py\", line 351, in readuntil\n    await self._wait(\"readuntil\")\n  File \"/usr/local/lib/python3.10/dist-packages/aiohttp/streams.py\", line 312, in _wait\n    await waiter\naiohttp.client_exceptions.ClientPayloadError: Response payload is not completed: <TransferEncodingError: 400, message='Not enough data for satisfy transfer length header.'>\n", "Traceback (most recent call last):\n  File \"/usr/local/lib/python3.10/dist-packages/aiohttp/client_proto.py\", line 94, in connection_lost\n    uncompleted = self._parser.feed_eof()\n  File \"aiohttp/_http_parser.pyx\", line 513, in aiohttp._http_parser.HttpParser.feed_eof\naiohttp.http_exceptions.TransferEncodingError: 400, message:\n  Not enough data for satisfy transfer length header.\n\nThe above exception was the direct cause of the following exception:\n\nTraceback (most recent call last):\n  File \"/vllm-workspace/backend_request_func.py\", line 261, in async_request_openai_completions\n    async for chunk_bytes in response.content:\n  File \"/usr/local/lib/python3.10/dist-packages/aiohttp/streams.py\", line 50, in __anext__\n    rv = await self.read_func()\n  File \"/usr/local/lib/python3.10/dist-packages/aiohttp/streams.py\", line 317, in readline\n    return await self.readuntil()\n  File \"/usr/local/lib/python3.10/dist-packages/aiohttp/streams.py\", line 351, in readuntil\n    await self._wait(\"readuntil\")\n  File \"/usr/local/lib/python3.10/dist-packages/aiohttp/streams.py\", line 312, in _wait\n    await waiter\naiohttp.client_exceptions.ClientPayloadError: Response payload is not completed: <TransferEncodingError: 400, message='Not enough data for satisfy transfer length header.'>\n", "Traceback (most recent call last):\n  File \"/usr/local/lib/python3.10/dist-packages/aiohttp/client_proto.py\", line 94, in connection_lost\n    uncompleted = self._parser.feed_eof()\n  File \"aiohttp/_http_parser.pyx\", line 513, in aiohttp._http_parser.HttpParser.feed_eof\naiohttp.http_exceptions.TransferEncodingError: 400, message:\n  Not enough data for satisfy transfer length header.\n\nThe above exception was the direct cause of the following exception:\n\nTraceback (most recent call last):\n  File \"/vllm-workspace/backend_request_func.py\", line 261, in async_request_openai_completions\n    async for chunk_bytes in response.content:\n  File \"/usr/local/lib/python3.10/dist-packages/aiohttp/streams.py\", line 50, in __anext__\n    rv = await self.read_func()\n  File \"/usr/local/lib/python3.10/dist-packages/aiohttp/streams.py\", line 317, in readline\n    return await self.readuntil()\n  File \"/usr/local/lib/python3.10/dist-packages/aiohttp/streams.py\", line 351, in readuntil\n    await self._wait(\"readuntil\")\n  File \"/usr/local/lib/python3.10/dist-packages/aiohttp/streams.py\", line 312, in _wait\n    await waiter\naiohttp.client_exceptions.ClientPayloadError: Response payload is not completed: <TransferEncodingError: 400, message='Not enough data for satisfy transfer length header.'>\n", "Traceback (most recent call last):\n  File \"/usr/local/lib/python3.10/dist-packages/aiohttp/client_proto.py\", line 94, in connection_lost\n    uncompleted = self._parser.feed_eof()\n  File \"aiohttp/_http_parser.pyx\", line 513, in aiohttp._http_parser.HttpParser.feed_eof\naiohttp.http_exceptions.TransferEncodingError: 400, message:\n  Not enough data for satisfy transfer length header.\n\nThe above exception was the direct cause of the following exception:\n\nTraceback (most recent call last):\n  File \"/vllm-workspace/backend_request_func.py\", line 261, in async_request_openai_completions\n    async for chunk_bytes in response.content:\n  File \"/usr/local/lib/python3.10/dist-packages/aiohttp/streams.py\", line 50, in __anext__\n    rv = await self.read_func()\n  File \"/usr/local/lib/python3.10/dist-packages/aiohttp/streams.py\", line 317, in readline\n    return await self.readuntil()\n  File \"/usr/local/lib/python3.10/dist-packages/aiohttp/streams.py\", line 351, in readuntil\n    await self._wait(\"readuntil\")\n  File \"/usr/local/lib/python3.10/dist-packages/aiohttp/streams.py\", line 312, in _wait\n    await waiter\naiohttp.client_exceptions.ClientPayloadError: Response payload is not completed: <TransferEncodingError: 400, message='Not enough data for satisfy transfer length header.'>\n", "Traceback (most recent call last):\n  File \"/usr/local/lib/python3.10/dist-packages/aiohttp/client_proto.py\", line 94, in connection_lost\n    uncompleted = self._parser.feed_eof()\n  File \"aiohttp/_http_parser.pyx\", line 513, in aiohttp._http_parser.HttpParser.feed_eof\naiohttp.http_exceptions.TransferEncodingError: 400, message:\n  Not enough data for satisfy transfer length header.\n\nThe above exception was the direct cause of the following exception:\n\nTraceback (most recent call last):\n  File \"/vllm-workspace/backend_request_func.py\", line 261, in async_request_openai_completions\n    async for chunk_bytes in response.content:\n  File \"/usr/local/lib/python3.10/dist-packages/aiohttp/streams.py\", line 50, in __anext__\n    rv = await self.read_func()\n  File \"/usr/local/lib/python3.10/dist-packages/aiohttp/streams.py\", line 317, in readline\n    return await self.readuntil()\n  File \"/usr/local/lib/python3.10/dist-packages/aiohttp/streams.py\", line 351, in readuntil\n    await self._wait(\"readuntil\")\n  File \"/usr/local/lib/python3.10/dist-packages/aiohttp/streams.py\", line 312, in _wait\n    await waiter\naiohttp.client_exceptions.ClientPayloadError: Response payload is not completed: <TransferEncodingError: 400, message='Not enough data for satisfy transfer length header.'>\n", "", "", "", "Traceback (most recent call last):\n  File \"/usr/local/lib/python3.10/dist-packages/aiohttp/client_proto.py\", line 94, in connection_lost\n    uncompleted = self._parser.feed_eof()\n  File \"aiohttp/_http_parser.pyx\", line 513, in aiohttp._http_parser.HttpParser.feed_eof\naiohttp.http_exceptions.TransferEncodingError: 400, message:\n  Not enough data for satisfy transfer length header.\n\nThe above exception was the direct cause of the following exception:\n\nTraceback (most recent call last):\n  File \"/vllm-workspace/backend_request_func.py\", line 261, in async_request_openai_completions\n    async for chunk_bytes in response.content:\n  File \"/usr/local/lib/python3.10/dist-packages/aiohttp/streams.py\", line 50, in __anext__\n    rv = await self.read_func()\n  File \"/usr/local/lib/python3.10/dist-packages/aiohttp/streams.py\", line 317, in readline\n    return await self.readuntil()\n  File \"/usr/local/lib/python3.10/dist-packages/aiohttp/streams.py\", line 351, in readuntil\n    await self._wait(\"readuntil\")\n  File \"/usr/local/lib/python3.10/dist-packages/aiohttp/streams.py\", line 312, in _wait\n    await waiter\naiohttp.client_exceptions.ClientPayloadError: Response payload is not completed: <TransferEncodingError: 400, message='Not enough data for satisfy transfer length header.'>\n", "Traceback (most recent call last):\n  File \"/usr/local/lib/python3.10/dist-packages/aiohttp/client_proto.py\", line 94, in connection_lost\n    uncompleted = self._parser.feed_eof()\n  File \"aiohttp/_http_parser.pyx\", line 513, in aiohttp._http_parser.HttpParser.feed_eof\naiohttp.http_exceptions.TransferEncodingError: 400, message:\n  Not enough data for satisfy transfer length header.\n\nThe above exception was the direct cause of the following exception:\n\nTraceback (most recent call last):\n  File \"/vllm-workspace/backend_request_func.py\", line 261, in async_request_openai_completions\n    async for chunk_bytes in response.content:\n  File \"/usr/local/lib/python3.10/dist-packages/aiohttp/streams.py\", line 50, in __anext__\n    rv = await self.read_func()\n  File \"/usr/local/lib/python3.10/dist-packages/aiohttp/streams.py\", line 317, in readline\n    return await self.readuntil()\n  File \"/usr/local/lib/python3.10/dist-packages/aiohttp/streams.py\", line 351, in readuntil\n    await self._wait(\"readuntil\")\n  File \"/usr/local/lib/python3.10/dist-packages/aiohttp/streams.py\", line 312, in _wait\n    await waiter\naiohttp.client_exceptions.ClientPayloadError: Response payload is not completed: <TransferEncodingError: 400, message='Not enough data for satisfy transfer length header.'>\n", "Traceback (most recent call last):\n  File \"/usr/local/lib/python3.10/dist-packages/aiohttp/client_proto.py\", line 94, in connection_lost\n    uncompleted = self._parser.feed_eof()\n  File \"aiohttp/_http_parser.pyx\", line 513, in aiohttp._http_parser.HttpParser.feed_eof\naiohttp.http_exceptions.TransferEncodingError: 400, message:\n  Not enough data for satisfy transfer length header.\n\nThe above exception was the direct cause of the following exception:\n\nTraceback (most recent call last):\n  File \"/vllm-workspace/backend_request_func.py\", line 261, in async_request_openai_completions\n    async for chunk_bytes in response.content:\n  File \"/usr/local/lib/python3.10/dist-packages/aiohttp/streams.py\", line 50, in __anext__\n    rv = await self.read_func()\n  File \"/usr/local/lib/python3.10/dist-packages/aiohttp/streams.py\", line 317, in readline\n    return await self.readuntil()\n  File \"/usr/local/lib/python3.10/dist-packages/aiohttp/streams.py\", line 351, in readuntil\n    await self._wait(\"readuntil\")\n  File \"/usr/local/lib/python3.10/dist-packages/aiohttp/streams.py\", line 312, in _wait\n    await waiter\naiohttp.client_exceptions.ClientPayloadError: Response payload is not completed: <TransferEncodingError: 400, message='Not enough data for satisfy transfer length header.'>\n", "Traceback (most recent call last):\n  File \"/usr/local/lib/python3.10/dist-packages/aiohttp/client_proto.py\", line 94, in connection_lost\n    uncompleted = self._parser.feed_eof()\n  File \"aiohttp/_http_parser.pyx\", line 513, in aiohttp._http_parser.HttpParser.feed_eof\naiohttp.http_exceptions.TransferEncodingError: 400, message:\n  Not enough data for satisfy transfer length header.\n\nThe above exception was the direct cause of the following exception:\n\nTraceback (most recent call last):\n  File \"/vllm-workspace/backend_request_func.py\", line 261, in async_request_openai_completions\n    async for chunk_bytes in response.content:\n  File \"/usr/local/lib/python3.10/dist-packages/aiohttp/streams.py\", line 50, in __anext__\n    rv = await self.read_func()\n  File \"/usr/local/lib/python3.10/dist-packages/aiohttp/streams.py\", line 317, in readline\n    return await self.readuntil()\n  File \"/usr/local/lib/python3.10/dist-packages/aiohttp/streams.py\", line 351, in readuntil\n    await self._wait(\"readuntil\")\n  File \"/usr/local/lib/python3.10/dist-packages/aiohttp/streams.py\", line 312, in _wait\n    await waiter\naiohttp.client_exceptions.ClientPayloadError: Response payload is not completed: <TransferEncodingError: 400, message='Not enough data for satisfy transfer length header.'>\n", "Traceback (most recent call last):\n  File \"/usr/local/lib/python3.10/dist-packages/aiohttp/client_proto.py\", line 94, in connection_lost\n    uncompleted = self._parser.feed_eof()\n  File \"aiohttp/_http_parser.pyx\", line 513, in aiohttp._http_parser.HttpParser.feed_eof\naiohttp.http_exceptions.TransferEncodingError: 400, message:\n  Not enough data for satisfy transfer length header.\n\nThe above exception was the direct cause of the following exception:\n\nTraceback (most recent call last):\n  File \"/vllm-workspace/backend_request_func.py\", line 261, in async_request_openai_completions\n    async for chunk_bytes in response.content:\n  File \"/usr/local/lib/python3.10/dist-packages/aiohttp/streams.py\", line 50, in __anext__\n    rv = await self.read_func()\n  File \"/usr/local/lib/python3.10/dist-packages/aiohttp/streams.py\", line 317, in readline\n    return await self.readuntil()\n  File \"/usr/local/lib/python3.10/dist-packages/aiohttp/streams.py\", line 351, in readuntil\n    await self._wait(\"readuntil\")\n  File \"/usr/local/lib/python3.10/dist-packages/aiohttp/streams.py\", line 312, in _wait\n    await waiter\naiohttp.client_exceptions.ClientPayloadError: Response payload is not completed: <TransferEncodingError: 400, message='Not enough data for satisfy transfer length header.'>\n", "Traceback (most recent call last):\n  File \"/usr/local/lib/python3.10/dist-packages/aiohttp/client_proto.py\", line 94, in connection_lost\n    uncompleted = self._parser.feed_eof()\n  File \"aiohttp/_http_parser.pyx\", line 513, in aiohttp._http_parser.HttpParser.feed_eof\naiohttp.http_exceptions.TransferEncodingError: 400, message:\n  Not enough data for satisfy transfer length header.\n\nThe above exception was the direct cause of the following exception:\n\nTraceback (most recent call last):\n  File \"/vllm-workspace/backend_request_func.py\", line 261, in async_request_openai_completions\n    async for chunk_bytes in response.content:\n  File \"/usr/local/lib/python3.10/dist-packages/aiohttp/streams.py\", line 50, in __anext__\n    rv = await self.read_func()\n  File \"/usr/local/lib/python3.10/dist-packages/aiohttp/streams.py\", line 317, in readline\n    return await self.readuntil()\n  File \"/usr/local/lib/python3.10/dist-packages/aiohttp/streams.py\", line 351, in readuntil\n    await self._wait(\"readuntil\")\n  File \"/usr/local/lib/python3.10/dist-packages/aiohttp/streams.py\", line 312, in _wait\n    await waiter\naiohttp.client_exceptions.ClientPayloadError: Response payload is not completed: <TransferEncodingError: 400, message='Not enough data for satisfy transfer length header.'>\n", "Traceback (most recent call last):\n  File \"/usr/local/lib/python3.10/dist-packages/aiohttp/client_proto.py\", line 94, in connection_lost\n    uncompleted = self._parser.feed_eof()\n  File \"aiohttp/_http_parser.pyx\", line 513, in aiohttp._http_parser.HttpParser.feed_eof\naiohttp.http_exceptions.TransferEncodingError: 400, message:\n  Not enough data for satisfy transfer length header.\n\nThe above exception was the direct cause of the following exception:\n\nTraceback (most recent call last):\n  File \"/vllm-workspace/backend_request_func.py\", line 261, in async_request_openai_completions\n    async for chunk_bytes in response.content:\n  File \"/usr/local/lib/python3.10/dist-packages/aiohttp/streams.py\", line 50, in __anext__\n    rv = await self.read_func()\n  File \"/usr/local/lib/python3.10/dist-packages/aiohttp/streams.py\", line 317, in readline\n    return await self.readuntil()\n  File \"/usr/local/lib/python3.10/dist-packages/aiohttp/streams.py\", line 351, in readuntil\n    await self._wait(\"readuntil\")\n  File \"/usr/local/lib/python3.10/dist-packages/aiohttp/streams.py\", line 312, in _wait\n    await waiter\naiohttp.client_exceptions.ClientPayloadError: Response payload is not completed: <TransferEncodingError: 400, message='Not enough data for satisfy transfer length header.'>\n", "Traceback (most recent call last):\n  File \"/usr/local/lib/python3.10/dist-packages/aiohttp/client_proto.py\", line 94, in connection_lost\n    uncompleted = self._parser.feed_eof()\n  File \"aiohttp/_http_parser.pyx\", line 513, in aiohttp._http_parser.HttpParser.feed_eof\naiohttp.http_exceptions.TransferEncodingError: 400, message:\n  Not enough data for satisfy transfer length header.\n\nThe above exception was the direct cause of the following exception:\n\nTraceback (most recent call last):\n  File \"/vllm-workspace/backend_request_func.py\", line 261, in async_request_openai_completions\n    async for chunk_bytes in response.content:\n  File \"/usr/local/lib/python3.10/dist-packages/aiohttp/streams.py\", line 50, in __anext__\n    rv = await self.read_func()\n  File \"/usr/local/lib/python3.10/dist-packages/aiohttp/streams.py\", line 317, in readline\n    return await self.readuntil()\n  File \"/usr/local/lib/python3.10/dist-packages/aiohttp/streams.py\", line 351, in readuntil\n    await self._wait(\"readuntil\")\n  File \"/usr/local/lib/python3.10/dist-packages/aiohttp/streams.py\", line 312, in _wait\n    await waiter\naiohttp.client_exceptions.ClientPayloadError: Response payload is not completed: <TransferEncodingError: 400, message='Not enough data for satisfy transfer length header.'>\n", "Traceback (most recent call last):\n  File \"/usr/local/lib/python3.10/dist-packages/aiohttp/client_proto.py\", line 94, in connection_lost\n    uncompleted = self._parser.feed_eof()\n  File \"aiohttp/_http_parser.pyx\", line 513, in aiohttp._http_parser.HttpParser.feed_eof\naiohttp.http_exceptions.TransferEncodingError: 400, message:\n  Not enough data for satisfy transfer length header.\n\nThe above exception was the direct cause of the following exception:\n\nTraceback (most recent call last):\n  File \"/vllm-workspace/backend_request_func.py\", line 261, in async_request_openai_completions\n    async for chunk_bytes in response.content:\n  File \"/usr/local/lib/python3.10/dist-packages/aiohttp/streams.py\", line 50, in __anext__\n    rv = await self.read_func()\n  File \"/usr/local/lib/python3.10/dist-packages/aiohttp/streams.py\", line 317, in readline\n    return await self.readuntil()\n  File \"/usr/local/lib/python3.10/dist-packages/aiohttp/streams.py\", line 351, in readuntil\n    await self._wait(\"readuntil\")\n  File \"/usr/local/lib/python3.10/dist-packages/aiohttp/streams.py\", line 312, in _wait\n    await waiter\naiohttp.client_exceptions.ClientPayloadError: Response payload is not completed: <TransferEncodingError: 400, message='Not enough data for satisfy transfer length header.'>\n", "Traceback (most recent call last):\n  File \"/usr/local/lib/python3.10/dist-packages/aiohttp/client_proto.py\", line 94, in connection_lost\n    uncompleted = self._parser.feed_eof()\n  File \"aiohttp/_http_parser.pyx\", line 513, in aiohttp._http_parser.HttpParser.feed_eof\naiohttp.http_exceptions.TransferEncodingError: 400, message:\n  Not enough data for satisfy transfer length header.\n\nThe above exception was the direct cause of the following exception:\n\nTraceback (most recent call last):\n  File \"/vllm-workspace/backend_request_func.py\", line 261, in async_request_openai_completions\n    async for chunk_bytes in response.content:\n  File \"/usr/local/lib/python3.10/dist-packages/aiohttp/streams.py\", line 50, in __anext__\n    rv = await self.read_func()\n  File \"/usr/local/lib/python3.10/dist-packages/aiohttp/streams.py\", line 317, in readline\n    return await self.readuntil()\n  File \"/usr/local/lib/python3.10/dist-packages/aiohttp/streams.py\", line 351, in readuntil\n    await self._wait(\"readuntil\")\n  File \"/usr/local/lib/python3.10/dist-packages/aiohttp/streams.py\", line 312, in _wait\n    await waiter\naiohttp.client_exceptions.ClientPayloadError: Response payload is not completed: <TransferEncodingError: 400, message='Not enough data for satisfy transfer length header.'>\n", "Traceback (most recent call last):\n  File \"/usr/local/lib/python3.10/dist-packages/aiohttp/client_proto.py\", line 94, in connection_lost\n    uncompleted = self._parser.feed_eof()\n  File \"aiohttp/_http_parser.pyx\", line 513, in aiohttp._http_parser.HttpParser.feed_eof\naiohttp.http_exceptions.TransferEncodingError: 400, message:\n  Not enough data for satisfy transfer length header.\n\nThe above exception was the direct cause of the following exception:\n\nTraceback (most recent call last):\n  File \"/vllm-workspace/backend_request_func.py\", line 261, in async_request_openai_completions\n    async for chunk_bytes in response.content:\n  File \"/usr/local/lib/python3.10/dist-packages/aiohttp/streams.py\", line 50, in __anext__\n    rv = await self.read_func()\n  File \"/usr/local/lib/python3.10/dist-packages/aiohttp/streams.py\", line 317, in readline\n    return await self.readuntil()\n  File \"/usr/local/lib/python3.10/dist-packages/aiohttp/streams.py\", line 351, in readuntil\n    await self._wait(\"readuntil\")\n  File \"/usr/local/lib/python3.10/dist-packages/aiohttp/streams.py\", line 312, in _wait\n    await waiter\naiohttp.client_exceptions.ClientPayloadError: Response payload is not completed: <TransferEncodingError: 400, message='Not enough data for satisfy transfer length header.'>\n", "Traceback (most recent call last):\n  File \"/usr/local/lib/python3.10/dist-packages/aiohttp/client_proto.py\", line 94, in connection_lost\n    uncompleted = self._parser.feed_eof()\n  File \"aiohttp/_http_parser.pyx\", line 513, in aiohttp._http_parser.HttpParser.feed_eof\naiohttp.http_exceptions.TransferEncodingError: 400, message:\n  Not enough data for satisfy transfer length header.\n\nThe above exception was the direct cause of the following exception:\n\nTraceback (most recent call last):\n  File \"/vllm-workspace/backend_request_func.py\", line 261, in async_request_openai_completions\n    async for chunk_bytes in response.content:\n  File \"/usr/local/lib/python3.10/dist-packages/aiohttp/streams.py\", line 50, in __anext__\n    rv = await self.read_func()\n  File \"/usr/local/lib/python3.10/dist-packages/aiohttp/streams.py\", line 317, in readline\n    return await self.readuntil()\n  File \"/usr/local/lib/python3.10/dist-packages/aiohttp/streams.py\", line 351, in readuntil\n    await self._wait(\"readuntil\")\n  File \"/usr/local/lib/python3.10/dist-packages/aiohttp/streams.py\", line 312, in _wait\n    await waiter\naiohttp.client_exceptions.ClientPayloadError: Response payload is not completed: <TransferEncodingError: 400, message='Not enough data for satisfy transfer length header.'>\n", "Traceback (most recent call last):\n  File \"/usr/local/lib/python3.10/dist-packages/aiohttp/client_proto.py\", line 94, in connection_lost\n    uncompleted = self._parser.feed_eof()\n  File \"aiohttp/_http_parser.pyx\", line 513, in aiohttp._http_parser.HttpParser.feed_eof\naiohttp.http_exceptions.TransferEncodingError: 400, message:\n  Not enough data for satisfy transfer length header.\n\nThe above exception was the direct cause of the following exception:\n\nTraceback (most recent call last):\n  File \"/vllm-workspace/backend_request_func.py\", line 261, in async_request_openai_completions\n    async for chunk_bytes in response.content:\n  File \"/usr/local/lib/python3.10/dist-packages/aiohttp/streams.py\", line 50, in __anext__\n    rv = await self.read_func()\n  File \"/usr/local/lib/python3.10/dist-packages/aiohttp/streams.py\", line 317, in readline\n    return await self.readuntil()\n  File \"/usr/local/lib/python3.10/dist-packages/aiohttp/streams.py\", line 351, in readuntil\n    await self._wait(\"readuntil\")\n  File \"/usr/local/lib/python3.10/dist-packages/aiohttp/streams.py\", line 312, in _wait\n    await waiter\naiohttp.client_exceptions.ClientPayloadError: Response payload is not completed: <TransferEncodingError: 400, message='Not enough data for satisfy transfer length header.'>\n", "Traceback (most recent call last):\n  File \"/usr/local/lib/python3.10/dist-packages/aiohttp/client_proto.py\", line 94, in connection_lost\n    uncompleted = self._parser.feed_eof()\n  File \"aiohttp/_http_parser.pyx\", line 513, in aiohttp._http_parser.HttpParser.feed_eof\naiohttp.http_exceptions.TransferEncodingError: 400, message:\n  Not enough data for satisfy transfer length header.\n\nThe above exception was the direct cause of the following exception:\n\nTraceback (most recent call last):\n  File \"/vllm-workspace/backend_request_func.py\", line 261, in async_request_openai_completions\n    async for chunk_bytes in response.content:\n  File \"/usr/local/lib/python3.10/dist-packages/aiohttp/streams.py\", line 50, in __anext__\n    rv = await self.read_func()\n  File \"/usr/local/lib/python3.10/dist-packages/aiohttp/streams.py\", line 317, in readline\n    return await self.readuntil()\n  File \"/usr/local/lib/python3.10/dist-packages/aiohttp/streams.py\", line 351, in readuntil\n    await self._wait(\"readuntil\")\n  File \"/usr/local/lib/python3.10/dist-packages/aiohttp/streams.py\", line 312, in _wait\n    await waiter\naiohttp.client_exceptions.ClientPayloadError: Response payload is not completed: <TransferEncodingError: 400, message='Not enough data for satisfy transfer length header.'>\n", "", "Traceback (most recent call last):\n  File \"/usr/local/lib/python3.10/dist-packages/aiohttp/client_proto.py\", line 94, in connection_lost\n    uncompleted = self._parser.feed_eof()\n  File \"aiohttp/_http_parser.pyx\", line 513, in aiohttp._http_parser.HttpParser.feed_eof\naiohttp.http_exceptions.TransferEncodingError: 400, message:\n  Not enough data for satisfy transfer length header.\n\nThe above exception was the direct cause of the following exception:\n\nTraceback (most recent call last):\n  File \"/vllm-workspace/backend_request_func.py\", line 261, in async_request_openai_completions\n    async for chunk_bytes in response.content:\n  File \"/usr/local/lib/python3.10/dist-packages/aiohttp/streams.py\", line 50, in __anext__\n    rv = await self.read_func()\n  File \"/usr/local/lib/python3.10/dist-packages/aiohttp/streams.py\", line 317, in readline\n    return await self.readuntil()\n  File \"/usr/local/lib/python3.10/dist-packages/aiohttp/streams.py\", line 351, in readuntil\n    await self._wait(\"readuntil\")\n  File \"/usr/local/lib/python3.10/dist-packages/aiohttp/streams.py\", line 312, in _wait\n    await waiter\naiohttp.client_exceptions.ClientPayloadError: Response payload is not completed: <TransferEncodingError: 400, message='Not enough data for satisfy transfer length header.'>\n", "Traceback (most recent call last):\n  File \"/usr/local/lib/python3.10/dist-packages/aiohttp/client_proto.py\", line 94, in connection_lost\n    uncompleted = self._parser.feed_eof()\n  File \"aiohttp/_http_parser.pyx\", line 513, in aiohttp._http_parser.HttpParser.feed_eof\naiohttp.http_exceptions.TransferEncodingError: 400, message:\n  Not enough data for satisfy transfer length header.\n\nThe above exception was the direct cause of the following exception:\n\nTraceback (most recent call last):\n  File \"/vllm-workspace/backend_request_func.py\", line 261, in async_request_openai_completions\n    async for chunk_bytes in response.content:\n  File \"/usr/local/lib/python3.10/dist-packages/aiohttp/streams.py\", line 50, in __anext__\n    rv = await self.read_func()\n  File \"/usr/local/lib/python3.10/dist-packages/aiohttp/streams.py\", line 317, in readline\n    return await self.readuntil()\n  File \"/usr/local/lib/python3.10/dist-packages/aiohttp/streams.py\", line 351, in readuntil\n    await self._wait(\"readuntil\")\n  File \"/usr/local/lib/python3.10/dist-packages/aiohttp/streams.py\", line 312, in _wait\n    await waiter\naiohttp.client_exceptions.ClientPayloadError: Response payload is not completed: <TransferEncodingError: 400, message='Not enough data for satisfy transfer length header.'>\n", "Traceback (most recent call last):\n  File \"/usr/local/lib/python3.10/dist-packages/aiohttp/client_proto.py\", line 94, in connection_lost\n    uncompleted = self._parser.feed_eof()\n  File \"aiohttp/_http_parser.pyx\", line 513, in aiohttp._http_parser.HttpParser.feed_eof\naiohttp.http_exceptions.TransferEncodingError: 400, message:\n  Not enough data for satisfy transfer length header.\n\nThe above exception was the direct cause of the following exception:\n\nTraceback (most recent call last):\n  File \"/vllm-workspace/backend_request_func.py\", line 261, in async_request_openai_completions\n    async for chunk_bytes in response.content:\n  File \"/usr/local/lib/python3.10/dist-packages/aiohttp/streams.py\", line 50, in __anext__\n    rv = await self.read_func()\n  File \"/usr/local/lib/python3.10/dist-packages/aiohttp/streams.py\", line 317, in readline\n    return await self.readuntil()\n  File \"/usr/local/lib/python3.10/dist-packages/aiohttp/streams.py\", line 351, in readuntil\n    await self._wait(\"readuntil\")\n  File \"/usr/local/lib/python3.10/dist-packages/aiohttp/streams.py\", line 312, in _wait\n    await waiter\naiohttp.client_exceptions.ClientPayloadError: Response payload is not completed: <TransferEncodingError: 400, message='Not enough data for satisfy transfer length header.'>\n", "Traceback (most recent call last):\n  File \"/usr/local/lib/python3.10/dist-packages/aiohttp/client_proto.py\", line 94, in connection_lost\n    uncompleted = self._parser.feed_eof()\n  File \"aiohttp/_http_parser.pyx\", line 513, in aiohttp._http_parser.HttpParser.feed_eof\naiohttp.http_exceptions.TransferEncodingError: 400, message:\n  Not enough data for satisfy transfer length header.\n\nThe above exception was the direct cause of the following exception:\n\nTraceback (most recent call last):\n  File \"/vllm-workspace/backend_request_func.py\", line 261, in async_request_openai_completions\n    async for chunk_bytes in response.content:\n  File \"/usr/local/lib/python3.10/dist-packages/aiohttp/streams.py\", line 50, in __anext__\n    rv = await self.read_func()\n  File \"/usr/local/lib/python3.10/dist-packages/aiohttp/streams.py\", line 317, in readline\n    return await self.readuntil()\n  File \"/usr/local/lib/python3.10/dist-packages/aiohttp/streams.py\", line 351, in readuntil\n    await self._wait(\"readuntil\")\n  File \"/usr/local/lib/python3.10/dist-packages/aiohttp/streams.py\", line 312, in _wait\n    await waiter\naiohttp.client_exceptions.ClientPayloadError: Response payload is not completed: <TransferEncodingError: 400, message='Not enough data for satisfy transfer length header.'>\n", "Traceback (most recent call last):\n  File \"/usr/local/lib/python3.10/dist-packages/aiohttp/client_proto.py\", line 94, in connection_lost\n    uncompleted = self._parser.feed_eof()\n  File \"aiohttp/_http_parser.pyx\", line 513, in aiohttp._http_parser.HttpParser.feed_eof\naiohttp.http_exceptions.TransferEncodingError: 400, message:\n  Not enough data for satisfy transfer length header.\n\nThe above exception was the direct cause of the following exception:\n\nTraceback (most recent call last):\n  File \"/vllm-workspace/backend_request_func.py\", line 261, in async_request_openai_completions\n    async for chunk_bytes in response.content:\n  File \"/usr/local/lib/python3.10/dist-packages/aiohttp/streams.py\", line 50, in __anext__\n    rv = await self.read_func()\n  File \"/usr/local/lib/python3.10/dist-packages/aiohttp/streams.py\", line 317, in readline\n    return await self.readuntil()\n  File \"/usr/local/lib/python3.10/dist-packages/aiohttp/streams.py\", line 351, in readuntil\n    await self._wait(\"readuntil\")\n  File \"/usr/local/lib/python3.10/dist-packages/aiohttp/streams.py\", line 312, in _wait\n    await waiter\naiohttp.client_exceptions.ClientPayloadError: Response payload is not completed: <TransferEncodingError: 400, message='Not enough data for satisfy transfer length header.'>\n", "Traceback (most recent call last):\n  File \"/usr/local/lib/python3.10/dist-packages/aiohttp/client_proto.py\", line 94, in connection_lost\n    uncompleted = self._parser.feed_eof()\n  File \"aiohttp/_http_parser.pyx\", line 513, in aiohttp._http_parser.HttpParser.feed_eof\naiohttp.http_exceptions.TransferEncodingError: 400, message:\n  Not enough data for satisfy transfer length header.\n\nThe above exception was the direct cause of the following exception:\n\nTraceback (most recent call last):\n  File \"/vllm-workspace/backend_request_func.py\", line 261, in async_request_openai_completions\n    async for chunk_bytes in response.content:\n  File \"/usr/local/lib/python3.10/dist-packages/aiohttp/streams.py\", line 50, in __anext__\n    rv = await self.read_func()\n  File \"/usr/local/lib/python3.10/dist-packages/aiohttp/streams.py\", line 317, in readline\n    return await self.readuntil()\n  File \"/usr/local/lib/python3.10/dist-packages/aiohttp/streams.py\", line 351, in readuntil\n    await self._wait(\"readuntil\")\n  File \"/usr/local/lib/python3.10/dist-packages/aiohttp/streams.py\", line 312, in _wait\n    await waiter\naiohttp.client_exceptions.ClientPayloadError: Response payload is not completed: <TransferEncodingError: 400, message='Not enough data for satisfy transfer length header.'>\n", "Traceback (most recent call last):\n  File \"/usr/local/lib/python3.10/dist-packages/aiohttp/client_proto.py\", line 94, in connection_lost\n    uncompleted = self._parser.feed_eof()\n  File \"aiohttp/_http_parser.pyx\", line 513, in aiohttp._http_parser.HttpParser.feed_eof\naiohttp.http_exceptions.TransferEncodingError: 400, message:\n  Not enough data for satisfy transfer length header.\n\nThe above exception was the direct cause of the following exception:\n\nTraceback (most recent call last):\n  File \"/vllm-workspace/backend_request_func.py\", line 261, in async_request_openai_completions\n    async for chunk_bytes in response.content:\n  File \"/usr/local/lib/python3.10/dist-packages/aiohttp/streams.py\", line 50, in __anext__\n    rv = await self.read_func()\n  File \"/usr/local/lib/python3.10/dist-packages/aiohttp/streams.py\", line 317, in readline\n    return await self.readuntil()\n  File \"/usr/local/lib/python3.10/dist-packages/aiohttp/streams.py\", line 351, in readuntil\n    await self._wait(\"readuntil\")\n  File \"/usr/local/lib/python3.10/dist-packages/aiohttp/streams.py\", line 312, in _wait\n    await waiter\naiohttp.client_exceptions.ClientPayloadError: Response payload is not completed: <TransferEncodingError: 400, message='Not enough data for satisfy transfer length header.'>\n", "Traceback (most recent call last):\n  File \"/usr/local/lib/python3.10/dist-packages/aiohttp/client_proto.py\", line 94, in connection_lost\n    uncompleted = self._parser.feed_eof()\n  File \"aiohttp/_http_parser.pyx\", line 513, in aiohttp._http_parser.HttpParser.feed_eof\naiohttp.http_exceptions.TransferEncodingError: 400, message:\n  Not enough data for satisfy transfer length header.\n\nThe above exception was the direct cause of the following exception:\n\nTraceback (most recent call last):\n  File \"/vllm-workspace/backend_request_func.py\", line 261, in async_request_openai_completions\n    async for chunk_bytes in response.content:\n  File \"/usr/local/lib/python3.10/dist-packages/aiohttp/streams.py\", line 50, in __anext__\n    rv = await self.read_func()\n  File \"/usr/local/lib/python3.10/dist-packages/aiohttp/streams.py\", line 317, in readline\n    return await self.readuntil()\n  File \"/usr/local/lib/python3.10/dist-packages/aiohttp/streams.py\", line 351, in readuntil\n    await self._wait(\"readuntil\")\n  File \"/usr/local/lib/python3.10/dist-packages/aiohttp/streams.py\", line 312, in _wait\n    await waiter\naiohttp.client_exceptions.ClientPayloadError: Response payload is not completed: <TransferEncodingError: 400, message='Not enough data for satisfy transfer length header.'>\n", "Traceback (most recent call last):\n  File \"/usr/local/lib/python3.10/dist-packages/aiohttp/client_proto.py\", line 94, in connection_lost\n    uncompleted = self._parser.feed_eof()\n  File \"aiohttp/_http_parser.pyx\", line 513, in aiohttp._http_parser.HttpParser.feed_eof\naiohttp.http_exceptions.TransferEncodingError: 400, message:\n  Not enough data for satisfy transfer length header.\n\nThe above exception was the direct cause of the following exception:\n\nTraceback (most recent call last):\n  File \"/vllm-workspace/backend_request_func.py\", line 261, in async_request_openai_completions\n    async for chunk_bytes in response.content:\n  File \"/usr/local/lib/python3.10/dist-packages/aiohttp/streams.py\", line 50, in __anext__\n    rv = await self.read_func()\n  File \"/usr/local/lib/python3.10/dist-packages/aiohttp/streams.py\", line 317, in readline\n    return await self.readuntil()\n  File \"/usr/local/lib/python3.10/dist-packages/aiohttp/streams.py\", line 351, in readuntil\n    await self._wait(\"readuntil\")\n  File \"/usr/local/lib/python3.10/dist-packages/aiohttp/streams.py\", line 312, in _wait\n    await waiter\naiohttp.client_exceptions.ClientPayloadError: Response payload is not completed: <TransferEncodingError: 400, message='Not enough data for satisfy transfer length header.'>\n", "Traceback (most recent call last):\n  File \"/usr/local/lib/python3.10/dist-packages/aiohttp/client_proto.py\", line 94, in connection_lost\n    uncompleted = self._parser.feed_eof()\n  File \"aiohttp/_http_parser.pyx\", line 513, in aiohttp._http_parser.HttpParser.feed_eof\naiohttp.http_exceptions.TransferEncodingError: 400, message:\n  Not enough data for satisfy transfer length header.\n\nThe above exception was the direct cause of the following exception:\n\nTraceback (most recent call last):\n  File \"/vllm-workspace/backend_request_func.py\", line 261, in async_request_openai_completions\n    async for chunk_bytes in response.content:\n  File \"/usr/local/lib/python3.10/dist-packages/aiohttp/streams.py\", line 50, in __anext__\n    rv = await self.read_func()\n  File \"/usr/local/lib/python3.10/dist-packages/aiohttp/streams.py\", line 317, in readline\n    return await self.readuntil()\n  File \"/usr/local/lib/python3.10/dist-packages/aiohttp/streams.py\", line 351, in readuntil\n    await self._wait(\"readuntil\")\n  File \"/usr/local/lib/python3.10/dist-packages/aiohttp/streams.py\", line 312, in _wait\n    await waiter\naiohttp.client_exceptions.ClientPayloadError: Response payload is not completed: <TransferEncodingError: 400, message='Not enough data for satisfy transfer length header.'>\n", "Traceback (most recent call last):\n  File \"/usr/local/lib/python3.10/dist-packages/aiohttp/client_proto.py\", line 94, in connection_lost\n    uncompleted = self._parser.feed_eof()\n  File \"aiohttp/_http_parser.pyx\", line 513, in aiohttp._http_parser.HttpParser.feed_eof\naiohttp.http_exceptions.TransferEncodingError: 400, message:\n  Not enough data for satisfy transfer length header.\n\nThe above exception was the direct cause of the following exception:\n\nTraceback (most recent call last):\n  File \"/vllm-workspace/backend_request_func.py\", line 261, in async_request_openai_completions\n    async for chunk_bytes in response.content:\n  File \"/usr/local/lib/python3.10/dist-packages/aiohttp/streams.py\", line 50, in __anext__\n    rv = await self.read_func()\n  File \"/usr/local/lib/python3.10/dist-packages/aiohttp/streams.py\", line 317, in readline\n    return await self.readuntil()\n  File \"/usr/local/lib/python3.10/dist-packages/aiohttp/streams.py\", line 351, in readuntil\n    await self._wait(\"readuntil\")\n  File \"/usr/local/lib/python3.10/dist-packages/aiohttp/streams.py\", line 312, in _wait\n    await waiter\naiohttp.client_exceptions.ClientPayloadError: Response payload is not completed: <TransferEncodingError: 400, message='Not enough data for satisfy transfer length header.'>\n", "Traceback (most recent call last):\n  File \"/usr/local/lib/python3.10/dist-packages/aiohttp/client_proto.py\", line 94, in connection_lost\n    uncompleted = self._parser.feed_eof()\n  File \"aiohttp/_http_parser.pyx\", line 513, in aiohttp._http_parser.HttpParser.feed_eof\naiohttp.http_exceptions.TransferEncodingError: 400, message:\n  Not enough data for satisfy transfer length header.\n\nThe above exception was the direct cause of the following exception:\n\nTraceback (most recent call last):\n  File \"/vllm-workspace/backend_request_func.py\", line 261, in async_request_openai_completions\n    async for chunk_bytes in response.content:\n  File \"/usr/local/lib/python3.10/dist-packages/aiohttp/streams.py\", line 50, in __anext__\n    rv = await self.read_func()\n  File \"/usr/local/lib/python3.10/dist-packages/aiohttp/streams.py\", line 317, in readline\n    return await self.readuntil()\n  File \"/usr/local/lib/python3.10/dist-packages/aiohttp/streams.py\", line 351, in readuntil\n    await self._wait(\"readuntil\")\n  File \"/usr/local/lib/python3.10/dist-packages/aiohttp/streams.py\", line 312, in _wait\n    await waiter\naiohttp.client_exceptions.ClientPayloadError: Response payload is not completed: <TransferEncodingError: 400, message='Not enough data for satisfy transfer length header.'>\n", "Traceback (most recent call last):\n  File \"/usr/local/lib/python3.10/dist-packages/aiohttp/client_proto.py\", line 94, in connection_lost\n    uncompleted = self._parser.feed_eof()\n  File \"aiohttp/_http_parser.pyx\", line 513, in aiohttp._http_parser.HttpParser.feed_eof\naiohttp.http_exceptions.TransferEncodingError: 400, message:\n  Not enough data for satisfy transfer length header.\n\nThe above exception was the direct cause of the following exception:\n\nTraceback (most recent call last):\n  File \"/vllm-workspace/backend_request_func.py\", line 261, in async_request_openai_completions\n    async for chunk_bytes in response.content:\n  File \"/usr/local/lib/python3.10/dist-packages/aiohttp/streams.py\", line 50, in __anext__\n    rv = await self.read_func()\n  File \"/usr/local/lib/python3.10/dist-packages/aiohttp/streams.py\", line 317, in readline\n    return await self.readuntil()\n  File \"/usr/local/lib/python3.10/dist-packages/aiohttp/streams.py\", line 351, in readuntil\n    await self._wait(\"readuntil\")\n  File \"/usr/local/lib/python3.10/dist-packages/aiohttp/streams.py\", line 312, in _wait\n    await waiter\naiohttp.client_exceptions.ClientPayloadError: Response payload is not completed: <TransferEncodingError: 400, message='Not enough data for satisfy transfer length header.'>\n", "", "", "Traceback (most recent call last):\n  File \"/usr/local/lib/python3.10/dist-packages/aiohttp/client_proto.py\", line 94, in connection_lost\n    uncompleted = self._parser.feed_eof()\n  File \"aiohttp/_http_parser.pyx\", line 513, in aiohttp._http_parser.HttpParser.feed_eof\naiohttp.http_exceptions.TransferEncodingError: 400, message:\n  Not enough data for satisfy transfer length header.\n\nThe above exception was the direct cause of the following exception:\n\nTraceback (most recent call last):\n  File \"/vllm-workspace/backend_request_func.py\", line 261, in async_request_openai_completions\n    async for chunk_bytes in response.content:\n  File \"/usr/local/lib/python3.10/dist-packages/aiohttp/streams.py\", line 50, in __anext__\n    rv = await self.read_func()\n  File \"/usr/local/lib/python3.10/dist-packages/aiohttp/streams.py\", line 317, in readline\n    return await self.readuntil()\n  File \"/usr/local/lib/python3.10/dist-packages/aiohttp/streams.py\", line 351, in readuntil\n    await self._wait(\"readuntil\")\n  File \"/usr/local/lib/python3.10/dist-packages/aiohttp/streams.py\", line 312, in _wait\n    await waiter\naiohttp.client_exceptions.ClientPayloadError: Response payload is not completed: <TransferEncodingError: 400, message='Not enough data for satisfy transfer length header.'>\n", "Traceback (most recent call last):\n  File \"/usr/local/lib/python3.10/dist-packages/aiohttp/client_proto.py\", line 94, in connection_lost\n    uncompleted = self._parser.feed_eof()\n  File \"aiohttp/_http_parser.pyx\", line 513, in aiohttp._http_parser.HttpParser.feed_eof\naiohttp.http_exceptions.TransferEncodingError: 400, message:\n  Not enough data for satisfy transfer length header.\n\nThe above exception was the direct cause of the following exception:\n\nTraceback (most recent call last):\n  File \"/vllm-workspace/backend_request_func.py\", line 261, in async_request_openai_completions\n    async for chunk_bytes in response.content:\n  File \"/usr/local/lib/python3.10/dist-packages/aiohttp/streams.py\", line 50, in __anext__\n    rv = await self.read_func()\n  File \"/usr/local/lib/python3.10/dist-packages/aiohttp/streams.py\", line 317, in readline\n    return await self.readuntil()\n  File \"/usr/local/lib/python3.10/dist-packages/aiohttp/streams.py\", line 351, in readuntil\n    await self._wait(\"readuntil\")\n  File \"/usr/local/lib/python3.10/dist-packages/aiohttp/streams.py\", line 312, in _wait\n    await waiter\naiohttp.client_exceptions.ClientPayloadError: Response payload is not completed: <TransferEncodingError: 400, message='Not enough data for satisfy transfer length header.'>\n", "Traceback (most recent call last):\n  File \"/usr/local/lib/python3.10/dist-packages/aiohttp/client_proto.py\", line 94, in connection_lost\n    uncompleted = self._parser.feed_eof()\n  File \"aiohttp/_http_parser.pyx\", line 513, in aiohttp._http_parser.HttpParser.feed_eof\naiohttp.http_exceptions.TransferEncodingError: 400, message:\n  Not enough data for satisfy transfer length header.\n\nThe above exception was the direct cause of the following exception:\n\nTraceback (most recent call last):\n  File \"/vllm-workspace/backend_request_func.py\", line 261, in async_request_openai_completions\n    async for chunk_bytes in response.content:\n  File \"/usr/local/lib/python3.10/dist-packages/aiohttp/streams.py\", line 50, in __anext__\n    rv = await self.read_func()\n  File \"/usr/local/lib/python3.10/dist-packages/aiohttp/streams.py\", line 317, in readline\n    return await self.readuntil()\n  File \"/usr/local/lib/python3.10/dist-packages/aiohttp/streams.py\", line 351, in readuntil\n    await self._wait(\"readuntil\")\n  File \"/usr/local/lib/python3.10/dist-packages/aiohttp/streams.py\", line 312, in _wait\n    await waiter\naiohttp.client_exceptions.ClientPayloadError: Response payload is not completed: <TransferEncodingError: 400, message='Not enough data for satisfy transfer length header.'>\n", "Traceback (most recent call last):\n  File \"/usr/local/lib/python3.10/dist-packages/aiohttp/client_proto.py\", line 94, in connection_lost\n    uncompleted = self._parser.feed_eof()\n  File \"aiohttp/_http_parser.pyx\", line 513, in aiohttp._http_parser.HttpParser.feed_eof\naiohttp.http_exceptions.TransferEncodingError: 400, message:\n  Not enough data for satisfy transfer length header.\n\nThe above exception was the direct cause of the following exception:\n\nTraceback (most recent call last):\n  File \"/vllm-workspace/backend_request_func.py\", line 261, in async_request_openai_completions\n    async for chunk_bytes in response.content:\n  File \"/usr/local/lib/python3.10/dist-packages/aiohttp/streams.py\", line 50, in __anext__\n    rv = await self.read_func()\n  File \"/usr/local/lib/python3.10/dist-packages/aiohttp/streams.py\", line 317, in readline\n    return await self.readuntil()\n  File \"/usr/local/lib/python3.10/dist-packages/aiohttp/streams.py\", line 351, in readuntil\n    await self._wait(\"readuntil\")\n  File \"/usr/local/lib/python3.10/dist-packages/aiohttp/streams.py\", line 312, in _wait\n    await waiter\naiohttp.client_exceptions.ClientPayloadError: Response payload is not completed: <TransferEncodingError: 400, message='Not enough data for satisfy transfer length header.'>\n", "Traceback (most recent call last):\n  File \"/usr/local/lib/python3.10/dist-packages/aiohttp/client_proto.py\", line 94, in connection_lost\n    uncompleted = self._parser.feed_eof()\n  File \"aiohttp/_http_parser.pyx\", line 513, in aiohttp._http_parser.HttpParser.feed_eof\naiohttp.http_exceptions.TransferEncodingError: 400, message:\n  Not enough data for satisfy transfer length header.\n\nThe above exception was the direct cause of the following exception:\n\nTraceback (most recent call last):\n  File \"/vllm-workspace/backend_request_func.py\", line 261, in async_request_openai_completions\n    async for chunk_bytes in response.content:\n  File \"/usr/local/lib/python3.10/dist-packages/aiohttp/streams.py\", line 50, in __anext__\n    rv = await self.read_func()\n  File \"/usr/local/lib/python3.10/dist-packages/aiohttp/streams.py\", line 317, in readline\n    return await self.readuntil()\n  File \"/usr/local/lib/python3.10/dist-packages/aiohttp/streams.py\", line 351, in readuntil\n    await self._wait(\"readuntil\")\n  File \"/usr/local/lib/python3.10/dist-packages/aiohttp/streams.py\", line 312, in _wait\n    await waiter\naiohttp.client_exceptions.ClientPayloadError: Response payload is not completed: <TransferEncodingError: 400, message='Not enough data for satisfy transfer length header.'>\n", "Traceback (most recent call last):\n  File \"/usr/local/lib/python3.10/dist-packages/aiohttp/client_proto.py\", line 94, in connection_lost\n    uncompleted = self._parser.feed_eof()\n  File \"aiohttp/_http_parser.pyx\", line 513, in aiohttp._http_parser.HttpParser.feed_eof\naiohttp.http_exceptions.TransferEncodingError: 400, message:\n  Not enough data for satisfy transfer length header.\n\nThe above exception was the direct cause of the following exception:\n\nTraceback (most recent call last):\n  File \"/vllm-workspace/backend_request_func.py\", line 261, in async_request_openai_completions\n    async for chunk_bytes in response.content:\n  File \"/usr/local/lib/python3.10/dist-packages/aiohttp/streams.py\", line 50, in __anext__\n    rv = await self.read_func()\n  File \"/usr/local/lib/python3.10/dist-packages/aiohttp/streams.py\", line 317, in readline\n    return await self.readuntil()\n  File \"/usr/local/lib/python3.10/dist-packages/aiohttp/streams.py\", line 351, in readuntil\n    await self._wait(\"readuntil\")\n  File \"/usr/local/lib/python3.10/dist-packages/aiohttp/streams.py\", line 312, in _wait\n    await waiter\naiohttp.client_exceptions.ClientPayloadError: Response payload is not completed: <TransferEncodingError: 400, message='Not enough data for satisfy transfer length header.'>\n", "Traceback (most recent call last):\n  File \"/usr/local/lib/python3.10/dist-packages/aiohttp/client_proto.py\", line 94, in connection_lost\n    uncompleted = self._parser.feed_eof()\n  File \"aiohttp/_http_parser.pyx\", line 513, in aiohttp._http_parser.HttpParser.feed_eof\naiohttp.http_exceptions.TransferEncodingError: 400, message:\n  Not enough data for satisfy transfer length header.\n\nThe above exception was the direct cause of the following exception:\n\nTraceback (most recent call last):\n  File \"/vllm-workspace/backend_request_func.py\", line 261, in async_request_openai_completions\n    async for chunk_bytes in response.content:\n  File \"/usr/local/lib/python3.10/dist-packages/aiohttp/streams.py\", line 50, in __anext__\n    rv = await self.read_func()\n  File \"/usr/local/lib/python3.10/dist-packages/aiohttp/streams.py\", line 317, in readline\n    return await self.readuntil()\n  File \"/usr/local/lib/python3.10/dist-packages/aiohttp/streams.py\", line 351, in readuntil\n    await self._wait(\"readuntil\")\n  File \"/usr/local/lib/python3.10/dist-packages/aiohttp/streams.py\", line 312, in _wait\n    await waiter\naiohttp.client_exceptions.ClientPayloadError: Response payload is not completed: <TransferEncodingError: 400, message='Not enough data for satisfy transfer length header.'>\n", "Traceback (most recent call last):\n  File \"/usr/local/lib/python3.10/dist-packages/aiohttp/client_proto.py\", line 94, in connection_lost\n    uncompleted = self._parser.feed_eof()\n  File \"aiohttp/_http_parser.pyx\", line 513, in aiohttp._http_parser.HttpParser.feed_eof\naiohttp.http_exceptions.TransferEncodingError: 400, message:\n  Not enough data for satisfy transfer length header.\n\nThe above exception was the direct cause of the following exception:\n\nTraceback (most recent call last):\n  File \"/vllm-workspace/backend_request_func.py\", line 261, in async_request_openai_completions\n    async for chunk_bytes in response.content:\n  File \"/usr/local/lib/python3.10/dist-packages/aiohttp/streams.py\", line 50, in __anext__\n    rv = await self.read_func()\n  File \"/usr/local/lib/python3.10/dist-packages/aiohttp/streams.py\", line 317, in readline\n    return await self.readuntil()\n  File \"/usr/local/lib/python3.10/dist-packages/aiohttp/streams.py\", line 351, in readuntil\n    await self._wait(\"readuntil\")\n  File \"/usr/local/lib/python3.10/dist-packages/aiohttp/streams.py\", line 312, in _wait\n    await waiter\naiohttp.client_exceptions.ClientPayloadError: Response payload is not completed: <TransferEncodingError: 400, message='Not enough data for satisfy transfer length header.'>\n", "Traceback (most recent call last):\n  File \"/usr/local/lib/python3.10/dist-packages/aiohttp/client_proto.py\", line 94, in connection_lost\n    uncompleted = self._parser.feed_eof()\n  File \"aiohttp/_http_parser.pyx\", line 513, in aiohttp._http_parser.HttpParser.feed_eof\naiohttp.http_exceptions.TransferEncodingError: 400, message:\n  Not enough data for satisfy transfer length header.\n\nThe above exception was the direct cause of the following exception:\n\nTraceback (most recent call last):\n  File \"/vllm-workspace/backend_request_func.py\", line 261, in async_request_openai_completions\n    async for chunk_bytes in response.content:\n  File \"/usr/local/lib/python3.10/dist-packages/aiohttp/streams.py\", line 50, in __anext__\n    rv = await self.read_func()\n  File \"/usr/local/lib/python3.10/dist-packages/aiohttp/streams.py\", line 317, in readline\n    return await self.readuntil()\n  File \"/usr/local/lib/python3.10/dist-packages/aiohttp/streams.py\", line 351, in readuntil\n    await self._wait(\"readuntil\")\n  File \"/usr/local/lib/python3.10/dist-packages/aiohttp/streams.py\", line 312, in _wait\n    await waiter\naiohttp.client_exceptions.ClientPayloadError: Response payload is not completed: <TransferEncodingError: 400, message='Not enough data for satisfy transfer length header.'>\n", "Traceback (most recent call last):\n  File \"/usr/local/lib/python3.10/dist-packages/aiohttp/client_proto.py\", line 94, in connection_lost\n    uncompleted = self._parser.feed_eof()\n  File \"aiohttp/_http_parser.pyx\", line 513, in aiohttp._http_parser.HttpParser.feed_eof\naiohttp.http_exceptions.TransferEncodingError: 400, message:\n  Not enough data for satisfy transfer length header.\n\nThe above exception was the direct cause of the following exception:\n\nTraceback (most recent call last):\n  File \"/vllm-workspace/backend_request_func.py\", line 261, in async_request_openai_completions\n    async for chunk_bytes in response.content:\n  File \"/usr/local/lib/python3.10/dist-packages/aiohttp/streams.py\", line 50, in __anext__\n    rv = await self.read_func()\n  File \"/usr/local/lib/python3.10/dist-packages/aiohttp/streams.py\", line 317, in readline\n    return await self.readuntil()\n  File \"/usr/local/lib/python3.10/dist-packages/aiohttp/streams.py\", line 351, in readuntil\n    await self._wait(\"readuntil\")\n  File \"/usr/local/lib/python3.10/dist-packages/aiohttp/streams.py\", line 312, in _wait\n    await waiter\naiohttp.client_exceptions.ClientPayloadError: Response payload is not completed: <TransferEncodingError: 400, message='Not enough data for satisfy transfer length header.'>\n", "Traceback (most recent call last):\n  File \"/usr/local/lib/python3.10/dist-packages/aiohttp/client_proto.py\", line 94, in connection_lost\n    uncompleted = self._parser.feed_eof()\n  File \"aiohttp/_http_parser.pyx\", line 513, in aiohttp._http_parser.HttpParser.feed_eof\naiohttp.http_exceptions.TransferEncodingError: 400, message:\n  Not enough data for satisfy transfer length header.\n\nThe above exception was the direct cause of the following exception:\n\nTraceback (most recent call last):\n  File \"/vllm-workspace/backend_request_func.py\", line 261, in async_request_openai_completions\n    async for chunk_bytes in response.content:\n  File \"/usr/local/lib/python3.10/dist-packages/aiohttp/streams.py\", line 50, in __anext__\n    rv = await self.read_func()\n  File \"/usr/local/lib/python3.10/dist-packages/aiohttp/streams.py\", line 317, in readline\n    return await self.readuntil()\n  File \"/usr/local/lib/python3.10/dist-packages/aiohttp/streams.py\", line 351, in readuntil\n    await self._wait(\"readuntil\")\n  File \"/usr/local/lib/python3.10/dist-packages/aiohttp/streams.py\", line 312, in _wait\n    await waiter\naiohttp.client_exceptions.ClientPayloadError: Response payload is not completed: <TransferEncodingError: 400, message='Not enough data for satisfy transfer length header.'>\n", "Traceback (most recent call last):\n  File \"/usr/local/lib/python3.10/dist-packages/aiohttp/client_proto.py\", line 94, in connection_lost\n    uncompleted = self._parser.feed_eof()\n  File \"aiohttp/_http_parser.pyx\", line 513, in aiohttp._http_parser.HttpParser.feed_eof\naiohttp.http_exceptions.TransferEncodingError: 400, message:\n  Not enough data for satisfy transfer length header.\n\nThe above exception was the direct cause of the following exception:\n\nTraceback (most recent call last):\n  File \"/vllm-workspace/backend_request_func.py\", line 261, in async_request_openai_completions\n    async for chunk_bytes in response.content:\n  File \"/usr/local/lib/python3.10/dist-packages/aiohttp/streams.py\", line 50, in __anext__\n    rv = await self.read_func()\n  File \"/usr/local/lib/python3.10/dist-packages/aiohttp/streams.py\", line 317, in readline\n    return await self.readuntil()\n  File \"/usr/local/lib/python3.10/dist-packages/aiohttp/streams.py\", line 351, in readuntil\n    await self._wait(\"readuntil\")\n  File \"/usr/local/lib/python3.10/dist-packages/aiohttp/streams.py\", line 312, in _wait\n    await waiter\naiohttp.client_exceptions.ClientPayloadError: Response payload is not completed: <TransferEncodingError: 400, message='Not enough data for satisfy transfer length header.'>\n", "Traceback (most recent call last):\n  File \"/usr/local/lib/python3.10/dist-packages/aiohttp/client_proto.py\", line 94, in connection_lost\n    uncompleted = self._parser.feed_eof()\n  File \"aiohttp/_http_parser.pyx\", line 513, in aiohttp._http_parser.HttpParser.feed_eof\naiohttp.http_exceptions.TransferEncodingError: 400, message:\n  Not enough data for satisfy transfer length header.\n\nThe above exception was the direct cause of the following exception:\n\nTraceback (most recent call last):\n  File \"/vllm-workspace/backend_request_func.py\", line 261, in async_request_openai_completions\n    async for chunk_bytes in response.content:\n  File \"/usr/local/lib/python3.10/dist-packages/aiohttp/streams.py\", line 50, in __anext__\n    rv = await self.read_func()\n  File \"/usr/local/lib/python3.10/dist-packages/aiohttp/streams.py\", line 317, in readline\n    return await self.readuntil()\n  File \"/usr/local/lib/python3.10/dist-packages/aiohttp/streams.py\", line 351, in readuntil\n    await self._wait(\"readuntil\")\n  File \"/usr/local/lib/python3.10/dist-packages/aiohttp/streams.py\", line 312, in _wait\n    await waiter\naiohttp.client_exceptions.ClientPayloadError: Response payload is not completed: <TransferEncodingError: 400, message='Not enough data for satisfy transfer length header.'>\n", "Traceback (most recent call last):\n  File \"/usr/local/lib/python3.10/dist-packages/aiohttp/client_proto.py\", line 94, in connection_lost\n    uncompleted = self._parser.feed_eof()\n  File \"aiohttp/_http_parser.pyx\", line 513, in aiohttp._http_parser.HttpParser.feed_eof\naiohttp.http_exceptions.TransferEncodingError: 400, message:\n  Not enough data for satisfy transfer length header.\n\nThe above exception was the direct cause of the following exception:\n\nTraceback (most recent call last):\n  File \"/vllm-workspace/backend_request_func.py\", line 261, in async_request_openai_completions\n    async for chunk_bytes in response.content:\n  File \"/usr/local/lib/python3.10/dist-packages/aiohttp/streams.py\", line 50, in __anext__\n    rv = await self.read_func()\n  File \"/usr/local/lib/python3.10/dist-packages/aiohttp/streams.py\", line 317, in readline\n    return await self.readuntil()\n  File \"/usr/local/lib/python3.10/dist-packages/aiohttp/streams.py\", line 351, in readuntil\n    await self._wait(\"readuntil\")\n  File \"/usr/local/lib/python3.10/dist-packages/aiohttp/streams.py\", line 312, in _wait\n    await waiter\naiohttp.client_exceptions.ClientPayloadError: Response payload is not completed: <TransferEncodingError: 400, message='Not enough data for satisfy transfer length header.'>\n", "Traceback (most recent call last):\n  File \"/usr/local/lib/python3.10/dist-packages/aiohttp/client_proto.py\", line 94, in connection_lost\n    uncompleted = self._parser.feed_eof()\n  File \"aiohttp/_http_parser.pyx\", line 513, in aiohttp._http_parser.HttpParser.feed_eof\naiohttp.http_exceptions.TransferEncodingError: 400, message:\n  Not enough data for satisfy transfer length header.\n\nThe above exception was the direct cause of the following exception:\n\nTraceback (most recent call last):\n  File \"/vllm-workspace/backend_request_func.py\", line 261, in async_request_openai_completions\n    async for chunk_bytes in response.content:\n  File \"/usr/local/lib/python3.10/dist-packages/aiohttp/streams.py\", line 50, in __anext__\n    rv = await self.read_func()\n  File \"/usr/local/lib/python3.10/dist-packages/aiohttp/streams.py\", line 317, in readline\n    return await self.readuntil()\n  File \"/usr/local/lib/python3.10/dist-packages/aiohttp/streams.py\", line 351, in readuntil\n    await self._wait(\"readuntil\")\n  File \"/usr/local/lib/python3.10/dist-packages/aiohttp/streams.py\", line 312, in _wait\n    await waiter\naiohttp.client_exceptions.ClientPayloadError: Response payload is not completed: <TransferEncodingError: 400, message='Not enough data for satisfy transfer length header.'>\n", "Traceback (most recent call last):\n  File \"/usr/local/lib/python3.10/dist-packages/aiohttp/client_proto.py\", line 94, in connection_lost\n    uncompleted = self._parser.feed_eof()\n  File \"aiohttp/_http_parser.pyx\", line 513, in aiohttp._http_parser.HttpParser.feed_eof\naiohttp.http_exceptions.TransferEncodingError: 400, message:\n  Not enough data for satisfy transfer length header.\n\nThe above exception was the direct cause of the following exception:\n\nTraceback (most recent call last):\n  File \"/vllm-workspace/backend_request_func.py\", line 261, in async_request_openai_completions\n    async for chunk_bytes in response.content:\n  File \"/usr/local/lib/python3.10/dist-packages/aiohttp/streams.py\", line 50, in __anext__\n    rv = await self.read_func()\n  File \"/usr/local/lib/python3.10/dist-packages/aiohttp/streams.py\", line 317, in readline\n    return await self.readuntil()\n  File \"/usr/local/lib/python3.10/dist-packages/aiohttp/streams.py\", line 351, in readuntil\n    await self._wait(\"readuntil\")\n  File \"/usr/local/lib/python3.10/dist-packages/aiohttp/streams.py\", line 312, in _wait\n    await waiter\naiohttp.client_exceptions.ClientPayloadError: Response payload is not completed: <TransferEncodingError: 400, message='Not enough data for satisfy transfer length header.'>\n", "Traceback (most recent call last):\n  File \"/usr/local/lib/python3.10/dist-packages/aiohttp/client_proto.py\", line 94, in connection_lost\n    uncompleted = self._parser.feed_eof()\n  File \"aiohttp/_http_parser.pyx\", line 513, in aiohttp._http_parser.HttpParser.feed_eof\naiohttp.http_exceptions.TransferEncodingError: 400, message:\n  Not enough data for satisfy transfer length header.\n\nThe above exception was the direct cause of the following exception:\n\nTraceback (most recent call last):\n  File \"/vllm-workspace/backend_request_func.py\", line 261, in async_request_openai_completions\n    async for chunk_bytes in response.content:\n  File \"/usr/local/lib/python3.10/dist-packages/aiohttp/streams.py\", line 50, in __anext__\n    rv = await self.read_func()\n  File \"/usr/local/lib/python3.10/dist-packages/aiohttp/streams.py\", line 317, in readline\n    return await self.readuntil()\n  File \"/usr/local/lib/python3.10/dist-packages/aiohttp/streams.py\", line 351, in readuntil\n    await self._wait(\"readuntil\")\n  File \"/usr/local/lib/python3.10/dist-packages/aiohttp/streams.py\", line 312, in _wait\n    await waiter\naiohttp.client_exceptions.ClientPayloadError: Response payload is not completed: <TransferEncodingError: 400, message='Not enough data for satisfy transfer length header.'>\n", "Traceback (most recent call last):\n  File \"/usr/local/lib/python3.10/dist-packages/aiohttp/client_proto.py\", line 94, in connection_lost\n    uncompleted = self._parser.feed_eof()\n  File \"aiohttp/_http_parser.pyx\", line 513, in aiohttp._http_parser.HttpParser.feed_eof\naiohttp.http_exceptions.TransferEncodingError: 400, message:\n  Not enough data for satisfy transfer length header.\n\nThe above exception was the direct cause of the following exception:\n\nTraceback (most recent call last):\n  File \"/vllm-workspace/backend_request_func.py\", line 261, in async_request_openai_completions\n    async for chunk_bytes in response.content:\n  File \"/usr/local/lib/python3.10/dist-packages/aiohttp/streams.py\", line 50, in __anext__\n    rv = await self.read_func()\n  File \"/usr/local/lib/python3.10/dist-packages/aiohttp/streams.py\", line 317, in readline\n    return await self.readuntil()\n  File \"/usr/local/lib/python3.10/dist-packages/aiohttp/streams.py\", line 351, in readuntil\n    await self._wait(\"readuntil\")\n  File \"/usr/local/lib/python3.10/dist-packages/aiohttp/streams.py\", line 312, in _wait\n    await waiter\naiohttp.client_exceptions.ClientPayloadError: Response payload is not completed: <TransferEncodingError: 400, message='Not enough data for satisfy transfer length header.'>\n", "Traceback (most recent call last):\n  File \"/usr/local/lib/python3.10/dist-packages/aiohttp/client_proto.py\", line 94, in connection_lost\n    uncompleted = self._parser.feed_eof()\n  File \"aiohttp/_http_parser.pyx\", line 513, in aiohttp._http_parser.HttpParser.feed_eof\naiohttp.http_exceptions.TransferEncodingError: 400, message:\n  Not enough data for satisfy transfer length header.\n\nThe above exception was the direct cause of the following exception:\n\nTraceback (most recent call last):\n  File \"/vllm-workspace/backend_request_func.py\", line 261, in async_request_openai_completions\n    async for chunk_bytes in response.content:\n  File \"/usr/local/lib/python3.10/dist-packages/aiohttp/streams.py\", line 50, in __anext__\n    rv = await self.read_func()\n  File \"/usr/local/lib/python3.10/dist-packages/aiohttp/streams.py\", line 317, in readline\n    return await self.readuntil()\n  File \"/usr/local/lib/python3.10/dist-packages/aiohttp/streams.py\", line 351, in readuntil\n    await self._wait(\"readuntil\")\n  File \"/usr/local/lib/python3.10/dist-packages/aiohttp/streams.py\", line 312, in _wait\n    await waiter\naiohttp.client_exceptions.ClientPayloadError: Response payload is not completed: <TransferEncodingError: 400, message='Not enough data for satisfy transfer length header.'>\n", "Traceback (most recent call last):\n  File \"/usr/local/lib/python3.10/dist-packages/aiohttp/client_proto.py\", line 94, in connection_lost\n    uncompleted = self._parser.feed_eof()\n  File \"aiohttp/_http_parser.pyx\", line 513, in aiohttp._http_parser.HttpParser.feed_eof\naiohttp.http_exceptions.TransferEncodingError: 400, message:\n  Not enough data for satisfy transfer length header.\n\nThe above exception was the direct cause of the following exception:\n\nTraceback (most recent call last):\n  File \"/vllm-workspace/backend_request_func.py\", line 261, in async_request_openai_completions\n    async for chunk_bytes in response.content:\n  File \"/usr/local/lib/python3.10/dist-packages/aiohttp/streams.py\", line 50, in __anext__\n    rv = await self.read_func()\n  File \"/usr/local/lib/python3.10/dist-packages/aiohttp/streams.py\", line 317, in readline\n    return await self.readuntil()\n  File \"/usr/local/lib/python3.10/dist-packages/aiohttp/streams.py\", line 351, in readuntil\n    await self._wait(\"readuntil\")\n  File \"/usr/local/lib/python3.10/dist-packages/aiohttp/streams.py\", line 312, in _wait\n    await waiter\naiohttp.client_exceptions.ClientPayloadError: Response payload is not completed: <TransferEncodingError: 400, message='Not enough data for satisfy transfer length header.'>\n", "Traceback (most recent call last):\n  File \"/usr/local/lib/python3.10/dist-packages/aiohttp/client_proto.py\", line 94, in connection_lost\n    uncompleted = self._parser.feed_eof()\n  File \"aiohttp/_http_parser.pyx\", line 513, in aiohttp._http_parser.HttpParser.feed_eof\naiohttp.http_exceptions.TransferEncodingError: 400, message:\n  Not enough data for satisfy transfer length header.\n\nThe above exception was the direct cause of the following exception:\n\nTraceback (most recent call last):\n  File \"/vllm-workspace/backend_request_func.py\", line 261, in async_request_openai_completions\n    async for chunk_bytes in response.content:\n  File \"/usr/local/lib/python3.10/dist-packages/aiohttp/streams.py\", line 50, in __anext__\n    rv = await self.read_func()\n  File \"/usr/local/lib/python3.10/dist-packages/aiohttp/streams.py\", line 317, in readline\n    return await self.readuntil()\n  File \"/usr/local/lib/python3.10/dist-packages/aiohttp/streams.py\", line 351, in readuntil\n    await self._wait(\"readuntil\")\n  File \"/usr/local/lib/python3.10/dist-packages/aiohttp/streams.py\", line 312, in _wait\n    await waiter\naiohttp.client_exceptions.ClientPayloadError: Response payload is not completed: <TransferEncodingError: 400, message='Not enough data for satisfy transfer length header.'>\n", "Traceback (most recent call last):\n  File \"/usr/local/lib/python3.10/dist-packages/aiohttp/client_proto.py\", line 94, in connection_lost\n    uncompleted = self._parser.feed_eof()\n  File \"aiohttp/_http_parser.pyx\", line 513, in aiohttp._http_parser.HttpParser.feed_eof\naiohttp.http_exceptions.TransferEncodingError: 400, message:\n  Not enough data for satisfy transfer length header.\n\nThe above exception was the direct cause of the following exception:\n\nTraceback (most recent call last):\n  File \"/vllm-workspace/backend_request_func.py\", line 261, in async_request_openai_completions\n    async for chunk_bytes in response.content:\n  File \"/usr/local/lib/python3.10/dist-packages/aiohttp/streams.py\", line 50, in __anext__\n    rv = await self.read_func()\n  File \"/usr/local/lib/python3.10/dist-packages/aiohttp/streams.py\", line 317, in readline\n    return await self.readuntil()\n  File \"/usr/local/lib/python3.10/dist-packages/aiohttp/streams.py\", line 351, in readuntil\n    await self._wait(\"readuntil\")\n  File \"/usr/local/lib/python3.10/dist-packages/aiohttp/streams.py\", line 312, in _wait\n    await waiter\naiohttp.client_exceptions.ClientPayloadError: Response payload is not completed: <TransferEncodingError: 400, message='Not enough data for satisfy transfer length header.'>\n", "Traceback (most recent call last):\n  File \"/usr/local/lib/python3.10/dist-packages/aiohttp/client_proto.py\", line 94, in connection_lost\n    uncompleted = self._parser.feed_eof()\n  File \"aiohttp/_http_parser.pyx\", line 513, in aiohttp._http_parser.HttpParser.feed_eof\naiohttp.http_exceptions.TransferEncodingError: 400, message:\n  Not enough data for satisfy transfer length header.\n\nThe above exception was the direct cause of the following exception:\n\nTraceback (most recent call last):\n  File \"/vllm-workspace/backend_request_func.py\", line 261, in async_request_openai_completions\n    async for chunk_bytes in response.content:\n  File \"/usr/local/lib/python3.10/dist-packages/aiohttp/streams.py\", line 50, in __anext__\n    rv = await self.read_func()\n  File \"/usr/local/lib/python3.10/dist-packages/aiohttp/streams.py\", line 317, in readline\n    return await self.readuntil()\n  File \"/usr/local/lib/python3.10/dist-packages/aiohttp/streams.py\", line 351, in readuntil\n    await self._wait(\"readuntil\")\n  File \"/usr/local/lib/python3.10/dist-packages/aiohttp/streams.py\", line 312, in _wait\n    await waiter\naiohttp.client_exceptions.ClientPayloadError: Response payload is not completed: <TransferEncodingError: 400, message='Not enough data for satisfy transfer length header.'>\n"]}