{"date": "20240907-092234", "backend": "vllm", "model_id": "neuralmagic/Meta-Llama-3.1-70B-Instruct-FP8", "tokenizer_id": "neuralmagic/Meta-Llama-3.1-70B-Instruct-FP8", "best_of": 1, "use_beam_search": false, "num_prompts": 160, "request_rate": "inf", "duration": 21.681084658950567, "completed": 33, "total_input_tokens": 9317, "total_output_tokens": 1104, "request_throughput": 1.5220640719363947, "input_throughput": 429.72942297670875, "output_throughput": 50.91996167932666, "mean_ttft_ms": 5527.641322350863, "median_ttft_ms": 7177.97502502799, "std_ttft_ms": 4123.882499680706, "p99_ttft_ms": 12789.403529316185, "mean_tpot_ms": 244.7804846873552, "median_tpot_ms": 194.95472152318274, "std_tpot_ms": 212.90687124908655, "p99_tpot_ms": 889.5232584327462, "mean_itl_ms": 1289.129028644632, "median_itl_ms": 882.1079321205616, "std_itl_ms": 1142.5883920198582, "p99_itl_ms": 5534.769824594259, "mean_latency_ms": 2571.3691532611847, "median_latency_ms": 0.0, "std_latency_ms": 5494.742906644011, "p99_latency_ms": 20815.289925597608, "input_lens": [13, 25, 27, 10, 329, 29, 399, 328, 4, 205, 16, 372, 403, 9, 12, 770, 227, 8, 14, 390, 659, 59, 76, 744, 619, 279, 344, 9, 10, 45, 11, 4, 80, 768, 317, 40, 619, 8, 298, 16, 17, 696, 575, 11, 7, 281, 12, 147, 481, 770, 336, 6, 331, 9, 45, 222, 802, 481, 93, 641, 22, 15, 16, 77, 32, 689, 178, 9, 628, 480, 42, 336, 24, 515, 761, 112, 113, 348, 82, 467, 245, 11, 24, 343, 13, 387, 258, 32, 28, 225, 248, 35, 133, 98, 27, 23, 58, 363, 203, 140, 140, 230, 310, 521, 768, 317, 298, 336, 491, 19, 10, 59, 48, 20, 20, 54, 107, 53, 72, 18, 10, 768, 7, 933, 239, 277, 26, 35, 462, 386, 25, 23, 17, 20, 44, 661, 631, 349, 53, 71, 37, 10, 21, 37, 496, 8, 9, 353, 10, 595, 5, 49, 286, 305, 56, 43, 52, 310, 35, 7], "output_lens": [120, 0, 88, 0, 0, 0, 0, 0, 6, 49, 0, 0, 0, 45, 0, 9, 0, 0, 0, 0, 0, 0, 0, 0, 0, 0, 0, 0, 0, 0, 0, 0, 0, 0, 0, 0, 0, 0, 0, 0, 0, 0, 0, 0, 0, 0, 0, 0, 0, 0, 0, 0, 0, 0, 0, 0, 0, 0, 0, 0, 0, 0, 0, 0, 0, 0, 0, 0, 0, 0, 0, 0, 0, 0, 0, 0, 0, 0, 0, 0, 0, 0, 0, 0, 0, 0, 0, 0, 0, 0, 0, 0, 0, 0, 0, 0, 0, 0, 0, 0, 0, 0, 0, 0, 7, 0, 11, 0, 0, 0, 0, 0, 0, 0, 23, 0, 27, 39, 0, 0, 0, 9, 0, 0, 0, 21, 0, 0, 0, 141, 36, 26, 0, 0, 125, 4, 0, 0, 63, 24, 0, 0, 110, 0, 0, 99, 0, 22, 0, 0, 0, 0, 0, 0, 0, 0, 0, 0, 0, 0], "ttfts": [8.756980989128351, 8.756688956171274, 8.756853189319372, 8.75675006955862, 11.366636469960213, 11.366537008434534, 0.0, 0.0, 11.36611869186163, 11.365812484174967, 11.365819334983826, 0.0, 11.373840935528278, 11.373099822551012, 11.37302190810442, 13.455899391323328, 13.459488108754158, 13.4595004953444, 13.460056770592928, 14.705932103097439, 0.0, 0.0, 13.45938777551055, 0.0, 0.0, 0.0, 0.0, 0.0, 0.0, 0.0, 0.0, 0.0, 0.0, 0.0, 0.0, 0.0, 0.0, 0.0, 0.0, 0.0, 0.0, 0.0, 0.0, 0.0, 0.0, 0.0, 0.0, 0.0, 0.0, 0.0, 0.0, 0.0, 0.0, 0.0, 0.0, 0.0, 0.0, 0.0, 0.0, 0.0, 0.0, 0.0, 0.0, 0.0, 0.0, 0.0, 0.0, 0.0, 0.0, 0.0, 0.0, 0.0, 0.0, 0.0, 0.0, 0.0, 0.0, 0.0, 0.0, 0.0, 0.0, 0.0, 0.0, 0.0, 0.0, 0.0, 0.0, 0.0, 0.0, 0.0, 0.0, 0.0, 0.0, 0.0, 3.6438242197036743, 0.0, 0.0, 0.0, 0.0, 3.6427751518785954, 0.0, 0.0, 5.207318279892206, 0.0, 3.641921892762184, 0.0, 5.206715829670429, 0.0, 0.0, 5.2059835866093636, 5.20620996132493, 5.205834414809942, 5.205736979842186, 5.205783512443304, 5.2057579308748245, 5.205487582832575, 5.205616906285286, 5.205334685742855, 7.18096624314785, 5.205172538757324, 6.413633171468973, 6.413238991051912, 5.204646520316601, 6.412716533988714, 6.412703316658735, 7.179455291479826, 7.618185259401798, 7.1792878322303295, 0.0, 8.72552616149187, 7.17874289304018, 7.6170706413686275, 8.727698918431997, 7.616857945919037, 7.178108211606741, 7.17797502502799, 0.0, 8.723247554153204, 7.616085942834616, 7.616000637412071, 8.72307125478983, 7.615443557500839, 8.72283224761486, 8.722318917512894, 0.0, 8.72215173393488, 8.721612215042114, 8.724864047020674, 0.0, 0.0, 0.0, 0.0, 0.0, 0.0, 0.0, 0.0, 0.0, 0.0, 0.0, 0.0], "itls": [[2.61013226211071, 0.6247937306761742, 1.1579614989459515, 1.558249406516552, 0.5781935900449753, 0.8820370547473431, 0.8000269755721092, 0.5706600807607174, 0.557029202580452, 0.7585532888770103, 0.8854972757399082, 0.5575006045401096, 0.5335825569927692], [2.6101228147745132, 0.6248139403760433, 1.157981250435114, 1.5581571236252785, 0.578218650072813, 0.8820698261260986, 0.8000327870249748, 0.5706674009561539, 0.5569946430623531, 0.7585983276367188, 0.8854833766818047, 0.5574565008282661, 0.6617293953895569, 0.554874662309885], [2.609839577227831, 0.6247916184365749, 1.1579965502023697, 1.558111198246479, 0.5782470293343067, 0.8820856437087059, 0.8000184074044228, 0.5706676915287971, 0.556998148560524, 0.5487271063029766], [2.6098277755081654, 0.6247990801930428, 1.157996479421854, 1.5580519028007984, 0.5783023834228516, 0.8820763938128948, 0.8000249341130257, 0.5706686824560165, 0.5569949150085449, 0.7584955841302872, 0.8854853548109531, 0.5574643239378929, 0.6623893268406391, 0.5542050339281559], [0.624426819384098, 1.1579957194626331, 1.5580349452793598, 0.5783211924135685, 0.8820881620049477, 0.8000085689127445, 0.5706733390688896, 0.5569859445095062, 0.7585048116743565, 0.8862259313464165], [0.6244138590991497, 1.1579979620873928, 1.558044534176588, 0.578311450779438, 0.8820799961686134, 0.8000141754746437, 0.5706739276647568, 0.5569993294775486, 0.7590666860342026], [], [], [0.5993577428162098], [0.6244205012917519, 1.158001348376274, 1.5580327436327934, 0.5783192552626133, 0.54533551633358], [0.624322347342968, 1.1580148413777351, 1.5580173209309578, 0.5783206522464752, 0.8819762840867043, 0.8000122085213661, 0.5706735178828239, 0.5575674436986446, 0.7585110887885094], [], [0.6161253340542316, 1.1580197103321552, 1.558020256459713, 0.5783184319734573, 0.8818755075335503, 0.8000059276819229], [0.6164603196084499, 1.1580173410475254, 1.5580124631524086, 0.578322883695364, 0.5450241006910801], [0.6164460852742195, 1.1580160893499851, 1.558016862720251, 0.578322283923626, 0.8818740323185921, 0.8000080026686192, 0.5706755593419075, 0.5575760267674923], [0.5698037557303905], [1.2466372661292553, 0.5774988196790218, 0.8827685341238976, 0.8002161420881748], [1.2465548776090145, 0.5774706937372684, 0.8827742114663124, 0.8002141192555428], [1.2458594180643559, 0.577462762594223, 0.8827778398990631, 0.8002178706228733], [], [], [], [1.2458425648510456, 0.5774697177112103, 0.8827722556889057], [], [], [], [], [], [], [], [], [], [], [], [], [], [], [], [], [], [], [], [], [], [], [], [], [], [], [], [], [], [], [], [], [], [], [], [], [], [], [], [], [], [], [], [], [], [], [], [], [], [], [], [], [], [], [], [], [], [], [], [], [], [], [], [], [], [], [], [], [], [], [], [7.098200548440218, 1.222844187170267, 1.1576736010611057, 1.5574036128818989, 0.5739709436893463, 0.8873906917870045, 0.8012684807181358, 0.5710632167756557, 0.5509703941643238, 0.7645889632403851, 0.8859076462686062, 0.5533347278833389, 0.6663818284869194, 0.5555997081100941], [], [], [], [], [7.096224747598171, 1.2248272746801376, 1.1576811634004116, 1.5573815144598484, 0.5739954225718975, 0.887381162494421, 0.8012701012194157, 0.5710267350077629, 0.551016055047512, 0.7645828351378441, 0.8859066553413868, 0.5531532913446426, 0.6665619648993015, 0.5555657558143139], [], [], [5.53321847692132, 1.222867339849472, 1.1576837934553623, 1.557328224182129, 0.5749831162393093, 0.886448547244072, 0.802188329398632, 0.5701040960848331, 0.5512310899794102, 0.7643554210662842, 0.885854933410883, 0.5550160296261311, 0.6647574082016945, 0.555573146790266], [], [5.651536263525486], [], [5.530785519629717], [], [], [5.53326240926981, 1.2228397652506828, 1.1602165885269642, 1.5547902956604958, 0.5750063918530941, 0.8864379674196243, 0.8022006973624229, 0.571211438626051, 0.5523700788617134, 0.762098278850317, 0.8868122324347496, 0.5540683604776859, 0.6655707247555256, 0.55476513504982], [5.533172979950905, 1.2243821546435356, 1.158696111291647, 1.557641427963972, 0.5747443586587906, 0.8857855424284935, 0.8004949428141117, 0.5709635466337204, 0.5542261153459549, 0.7613222971558571, 0.8857295401394367, 0.5551571920514107, 0.6644724905490875, 0.5547520443797112], [5.533143658190966, 1.2228645645081997, 1.1602268926799297, 1.554777704179287, 0.577592208981514, 0.8857674226164818, 0.8005206175148487, 0.5709711834788322, 0.5523717887699604, 0.7631615214049816, 0.8857471533119678, 0.5551358424127102, 0.6644901521503925, 0.5547639429569244], [5.533168915659189, 1.2243762500584126, 1.1587117910385132, 1.5576275698840618, 0.5747508965432644, 0.8857679888606071, 0.8005125969648361, 0.5709727443754673, 0.5541877634823322, 0.7613473683595657, 0.885744322091341, 0.5551423579454422, 0.6644908376038074, 0.5547439306974411], [5.533150747418404, 1.22439069673419, 1.158647634088993, 1.5576831065118313, 0.5747377946972847, 0.8857864141464233, 0.8004945069551468, 0.5709792524576187, 0.5542234145104885, 0.7613081187009811, 0.8857445977628231, 0.555143591016531, 0.6644853726029396, 0.5547482557594776], [5.534741215407848, 1.2227998450398445, 0.5495788305997849], [5.5347060561180115, 1.2228093668818474, 1.1586604937911034, 1.5576925091445446, 0.5747378431260586, 0.8857719637453556, 0.8005187287926674, 0.5709460116922855, 0.5542253032326698, 0.7613279148936272, 0.8857234716415405, 0.5551555901765823, 0.6644732765853405, 0.554740771651268], [5.5347737446427345, 1.222745817154646, 0.5501769185066223], [5.53475196659565, 1.222761895507574, 1.1585466340184212, 0.8826955631375313], [3.5598619617521763, 1.222660694271326, 1.1583367548882961, 1.5575917437672615, 0.5771892219781876, 0.8833523876965046, 0.8017610237002373, 0.5706255286931992, 0.55511474609375, 0.7594934850931168, 0.8867306672036648, 0.5568383634090424, 0.6617831140756607, 0.554748922586441], [5.534763894975185, 1.2227427884936333, 1.1584524251520634, 1.5575761087238789, 0.5747489035129547, 0.8857748433947563, 0.8005090057849884, 0.5709528848528862, 0.5542366243898869, 0.7613068670034409, 0.8857335112988949, 0.5567844808101654, 0.6628425717353821, 0.5547578558325768], [4.326555982232094, 1.2227276675403118, 1.1584387347102165, 1.5575973987579346, 0.5771636515855789, 0.8833687752485275, 0.8017574734985828, 0.5706234350800514, 0.5551267601549625, 0.7594857327640057, 0.886691689491272, 0.5568961054086685, 0.6617691107094288, 0.5547415539622307], [2.876998692750931], [5.53475558757782, 1.2227462828159332, 1.1584415026009083, 1.557592075318098, 0.5747411772608757, 0.8857850208878517, 0.800499465316534, 0.5709534771740437, 0.5542331896722317, 0.7613114081323147, 0.8857434429228306, 0.5567854903638363, 0.6628310531377792, 0.5547551922500134], [4.32661459967494, 1.22272277623415, 1.1584516987204552, 1.5575729943811893, 0.5771705023944378, 0.8833699189126492, 0.8004928976297379, 0.570956651121378, 0.5542450174689293, 0.7613006420433521, 0.8866836801171303, 0.5558606460690498, 0.6628134287893772, 0.5547483861446381], [4.326534800231457, 1.2227251268923283, 1.1584393680095673, 1.5575927309691906, 0.5771799422800541, 0.883355900645256, 0.8017477281391621, 0.5696955919265747, 0.5560496859252453, 0.7594982944428921, 0.8866930566728115, 0.5568860955536366, 0.6617778949439526, 0.5547481216490269], [3.559787381440401, 1.2227338962256908], [3.1215159967541695, 1.2239315547049046, 1.1583978161215782, 1.556099072098732, 0.5790674835443497, 0.8814782649278641, 0.8017457872629166, 0.5706382803618908, 0.5551134496927261, 0.7594955340027809, 0.8866726979613304, 0.5569193214178085, 0.6623848266899586, 0.5549552589654922], [3.5598346181213856, 1.2226667627692223, 1.1583362892270088, 1.5575932748615742, 0.5790524147450924, 0.8814857639372349, 0.801756177097559, 0.5706368908286095, 0.5551281422376633, 0.7594784311950207, 0.8866821080446243, 0.5569072030484676, 0.6624856777489185, 0.554948877543211], [], [2.0157977044582367, 1.2227788977324963, 1.1580663621425629, 1.5581001341342926, 0.5782963111996651, 0.8821156062185764, 0.7999996654689312, 0.570655569434166, 0.5569983050227165, 0.7585990875959396, 0.8854753561317921, 0.5574826113879681, 0.6618094258010387, 0.5515230931341648], [3.5597923398017883, 1.2239417806267738, 1.1571031026542187, 0.8817889876663685], [3.121475402265787, 1.2239568270742893, 0.5476277135312557], [2.013251069933176, 1.2227052226662636, 1.158066239207983, 1.5582529082894325, 0.5782269313931465, 0.882042434066534, 0.8000267781317234, 0.5706198774278164, 0.5570545494556427, 0.758567813783884, 0.8854610361158848, 0.5575354248285294, 0.6617486737668514, 0.5548818148672581], [3.1215354837477207, 1.2239593602716923, 1.158298034220934, 1.5561724603176117, 0.5790646784007549, 0.8831150643527508, 0.8001136258244514, 0.5706496685743332, 0.5551004186272621, 0.7605458050966263, 0.885630376636982, 0.5569053217768669, 0.6623953990638256, 0.5549453049898148], [3.559780988842249, 1.2239443063735962, 1.1585376486182213, 1.5560656487941742, 0.5790622159838676, 0.8814664520323277, 0.8017684407532215, 0.5706232599914074, 0.5551220998167992, 0.7594958432018757, 0.886681817471981, 0.5568963326513767, 0.535154789686203], [2.108735613524914], [], [2.0158604085445404, 1.222828857600689, 1.1580543108284473, 1.556332390755415, 0.580027624964714, 0.8821998871862888, 0.7999609857797623, 0.57065873965621, 0.5569393523037434, 0.758716057986021, 0.8856087699532509, 0.5574909970164299, 0.6618082895874977, 0.5549509599804878], [3.122610531747341, 1.222844760864973, 1.158203411847353, 1.5562787503004074, 0.5790740288794041, 0.8831695131957531, 0.5536276921629906], [3.1226176247000694, 1.2228396572172642, 0.5470003075897694], [2.0158127956092358, 1.2228030897676945, 1.1580635271966457, 1.5563255324959755, 0.5800336636602879, 0.882155567407608, 0.7999954074621201, 0.5706556774675846, 0.5569927133619785, 0.7587008103728294, 0.885577879846096, 0.5574941411614418, 0.6618023365736008, 0.554990615695715], [3.121502101421356, 1.223947610706091, 1.1582540236413479, 1.5562269277870655, 0.5790801793336868, 0.8831594921648502, 0.8000557608902454, 0.5706526562571526, 0.5550933107733727, 0.7605588324368, 0.885615598410368, 0.5574822649359703, 0.6618155539035797, 0.5549625158309937], [2.0158128142356873, 1.222788017243147, 1.1580666415393353, 1.558085922151804, 0.578293465077877, 0.8821079321205616, 0.800022266805172, 0.570653710514307, 0.5569955930113792, 0.7585990466177464, 0.5444627217948437], [2.0158087238669395, 1.2228121869266033, 1.1580734811723232, 1.5563209019601345, 0.5800411552190781, 0.8821599967777729, 0.7999821454286575, 0.5706559792160988, 0.5569948144257069, 0.7587051279842854, 0.8855682089924812, 0.5574859715998173, 0.6618150360882282, 0.5549679659307003], [], [2.015813644975424, 1.2227926962077618, 1.1580762900412083, 1.558069534599781, 0.5782913118600845, 0.8821290470659733, 0.8000104576349258, 0.5706543885171413, 0.5569952130317688, 0.5494321547448635], [2.015819527208805, 1.2228166349232197, 1.1580762714147568, 1.5563126429915428, 0.5800373516976833, 0.8821801878511906, 0.799971166998148, 0.5706566795706749, 0.5569744147360325, 0.7586826272308826, 0.8856086991727352, 0.5574939846992493, 0.6618159636855125, 0.5549439564347267], [2.611111044883728, 0.6248048283159733, 1.1510769911110401], [], [], [], [], [], [], [], [], [], [], [], []], "generated_texts": ["? It\u2019s a great book about how to run a business using the Entrepreneurial Operating System (EOS). One of the key concepts in the book is the idea of a \u201cVisionary\u201d and an \u201cIntegrator.\u201d The Visionary is the person who has the big ideas and is always looking to the future, while the Integrator is the person who takes those ideas and makes them a reality.\nIn many businesses, the Visionary and the Integrator are two different people. The Visionary is often the founder or CEO, while the Integrator is a key member of the leadership team. However", "", " and understand. Also, you need to add some new information to the \"How to use\" part. Please see the attached file for more details.\nI can help you reformat the Filters part and add new information to the \"How to use\" part. I'll make sure to make it easy to read and understand. Please provide the attached file so I can get started on the \"second draft\". I'm ready when you are!", "", "", "", "", "", " is a simple, open-source", " is a noun that refers to a procedure for evaluating or determining the quality or truth of something, and it can also refer to a series of questions or exercises used to measure an individual's skills or knowledge. True or False?\n\nAnswer: True.", "", "", "", " According to various sources, including Bible Gateway and YouVersion, the most quoted biblical verse is:\n\"For God so loved the world that he gave his one and only begotten Son, that whoever believes in him shall not perish but", "", "swift\nextension AppDelegate: GIDSignInDelegate", "", "", "", "", "", "", "", "", "", "", "", "", "", "", "", "", "", "", "", "", "", "", "", "", "", "", "", "", "", "", "", "", "", "", "", "", "", "", "", "", "", "", "", "", "", "", "", "", "", "", "", "", "", "", "", "", "", "", "", "", "", "", "", "", "", "", "", "", "", "", "", "", "", "", "", "", "", "", "", "", "", "", "", "", "", "", "", "", "'.\n\nHere's an example usage of", "", " By leveraging cloud computing, businesses can improve their operations,", "", "", "", "", "", "", "", " of the article.\nHere is the article:\n\n\"Imagine a world where you can travel anywhere, anytime, without worrying", "", " The total amount paid by the guest is \u20ac247.98, and the total amount received by the host is \u20ac215.64.", " He also stated that the town and county have not been adequately informed about the project and that the public has not been given enough time to review the proposal. He also stated that the town and county", "", "", "", " the `action` property set to `'get", "", "", "", " Let me know if you have any further questions or if there's anything else I can help you with!", "", "", "", " of here\nThe speaker is discussing the current situation of Andrew Tate and his brother Tristan Tate, who are both in jail. The speaker notes that while Andrew Tate is well-known on the internet, Tristan Tate is not getting as much attention. However, Tristan recently tweeted something interesting, saying that Andrew sent him a Quran (the holy book of Islam) because he had run out of books to read. The speaker finds this interesting because Andrew Tate has converted to Islam, and wonders if Tristan might also convert. The speaker invites viewers to share their thoughts on this in the comments. \n\nNote: The speaker also takes a brief detour to promote their own course on starting a YouTube channel, but this is not", " In Canada, visitors without money can access emergency medical care, but may be billed later. Some provinces offer limited free care for non-residents, while others may require payment upfront.", " The boat can only carry 8 people at a time.\n## Step 1: Calculate the total number of trips needed to accommodate", "", "", "\n\n## Step 1: Determine the minimum number of races needed to find the fastest three horses.\nTo find the fastest three horses, we need to consider the worst-case scenario where the fastest three horses are not in the same initial group of five.\n\n## Step 2: Calculate the number of races needed to narrow down the options.\nIn the first race, we can eliminate two horses (the slowest two), leaving us with 23 horses. We need to continue racing until we have a group of three that we are confident are the fastest.\n\n## Step 3: Consider the process of elimination.\nAfter the first race", "\n\n\n\n| Search Intent", "", "", ".\nThe Act also prohibits the sale of any article of food which is not of the nature, substance, or quality of the article demanded by the purchaser, under a penalty not exceeding \\(\\mathcal{E}50\\).\nThe Act also provides that the sale of any article of food which is not of the", " req.params.user;\n res.json({ answers });\n});\n\n// I want to add a new api that gets a request like:", "", "", "?\nVietnam is a better choice over China for Japan to shift their IT service business offshoring due to several reasons:\n\n1. **Language**: Vietnamese language is more similar to Japanese language compared to Chinese. Vietnamese language uses a Latin alphabet and has a more phonetic pronunciation system, making it easier for Japanese to learn and communicate.\n2. **Cultural similarity**: Vietnam and Japan share some cultural similarities, such as a strong emphasis on respect for elders, hard work, and loyalty. This cultural affinity can facilitate smoother communication and collaboration between Japanese and", "", "", " The distance between Boston and Boston is 0 miles (0 km).\nHow far is Boston from New York City? The distance between Boston and New York City is 215 miles (346 km).\nHow far is Boston from Los Angeles? The distance between Boston and Los Angeles is 2,796 miles (4,498 km).\nHow far is Boston from Chicago? The distance between Boston and Chicago is 867 miles (1,395 km).\nHow far is Boston from San Francisco? The distance", "", " \n\nI understand the instructions. You'd like me to:\n\n1. Receive data for each of the 7", "", "", "", "", "", "", "", "", "", "", "", ""], "errors": ["", "Traceback (most recent call last):\n  File \"/usr/local/lib/python3.10/dist-packages/aiohttp/client_proto.py\", line 94, in connection_lost\n    uncompleted = self._parser.feed_eof()\n  File \"aiohttp/_http_parser.pyx\", line 513, in aiohttp._http_parser.HttpParser.feed_eof\naiohttp.http_exceptions.TransferEncodingError: 400, message:\n  Not enough data for satisfy transfer length header.\n\nThe above exception was the direct cause of the following exception:\n\nTraceback (most recent call last):\n  File \"/vllm-workspace/backend_request_func.py\", line 261, in async_request_openai_completions\n    async for chunk_bytes in response.content:\n  File \"/usr/local/lib/python3.10/dist-packages/aiohttp/streams.py\", line 50, in __anext__\n    rv = await self.read_func()\n  File \"/usr/local/lib/python3.10/dist-packages/aiohttp/streams.py\", line 317, in readline\n    return await self.readuntil()\n  File \"/usr/local/lib/python3.10/dist-packages/aiohttp/streams.py\", line 351, in readuntil\n    await self._wait(\"readuntil\")\n  File \"/usr/local/lib/python3.10/dist-packages/aiohttp/streams.py\", line 312, in _wait\n    await waiter\naiohttp.client_exceptions.ClientPayloadError: Response payload is not completed: <TransferEncodingError: 400, message='Not enough data for satisfy transfer length header.'>\n", "", "Traceback (most recent call last):\n  File \"/usr/local/lib/python3.10/dist-packages/aiohttp/client_proto.py\", line 94, in connection_lost\n    uncompleted = self._parser.feed_eof()\n  File \"aiohttp/_http_parser.pyx\", line 513, in aiohttp._http_parser.HttpParser.feed_eof\naiohttp.http_exceptions.TransferEncodingError: 400, message:\n  Not enough data for satisfy transfer length header.\n\nThe above exception was the direct cause of the following exception:\n\nTraceback (most recent call last):\n  File \"/vllm-workspace/backend_request_func.py\", line 261, in async_request_openai_completions\n    async for chunk_bytes in response.content:\n  File \"/usr/local/lib/python3.10/dist-packages/aiohttp/streams.py\", line 50, in __anext__\n    rv = await self.read_func()\n  File \"/usr/local/lib/python3.10/dist-packages/aiohttp/streams.py\", line 317, in readline\n    return await self.readuntil()\n  File \"/usr/local/lib/python3.10/dist-packages/aiohttp/streams.py\", line 351, in readuntil\n    await self._wait(\"readuntil\")\n  File \"/usr/local/lib/python3.10/dist-packages/aiohttp/streams.py\", line 312, in _wait\n    await waiter\naiohttp.client_exceptions.ClientPayloadError: Response payload is not completed: <TransferEncodingError: 400, message='Not enough data for satisfy transfer length header.'>\n", "Traceback (most recent call last):\n  File \"/usr/local/lib/python3.10/dist-packages/aiohttp/client_proto.py\", line 94, in connection_lost\n    uncompleted = self._parser.feed_eof()\n  File \"aiohttp/_http_parser.pyx\", line 513, in aiohttp._http_parser.HttpParser.feed_eof\naiohttp.http_exceptions.TransferEncodingError: 400, message:\n  Not enough data for satisfy transfer length header.\n\nThe above exception was the direct cause of the following exception:\n\nTraceback (most recent call last):\n  File \"/vllm-workspace/backend_request_func.py\", line 261, in async_request_openai_completions\n    async for chunk_bytes in response.content:\n  File \"/usr/local/lib/python3.10/dist-packages/aiohttp/streams.py\", line 50, in __anext__\n    rv = await self.read_func()\n  File \"/usr/local/lib/python3.10/dist-packages/aiohttp/streams.py\", line 317, in readline\n    return await self.readuntil()\n  File \"/usr/local/lib/python3.10/dist-packages/aiohttp/streams.py\", line 351, in readuntil\n    await self._wait(\"readuntil\")\n  File \"/usr/local/lib/python3.10/dist-packages/aiohttp/streams.py\", line 312, in _wait\n    await waiter\naiohttp.client_exceptions.ClientPayloadError: Response payload is not completed: <TransferEncodingError: 400, message='Not enough data for satisfy transfer length header.'>\n", "Traceback (most recent call last):\n  File \"/usr/local/lib/python3.10/dist-packages/aiohttp/client_proto.py\", line 94, in connection_lost\n    uncompleted = self._parser.feed_eof()\n  File \"aiohttp/_http_parser.pyx\", line 513, in aiohttp._http_parser.HttpParser.feed_eof\naiohttp.http_exceptions.TransferEncodingError: 400, message:\n  Not enough data for satisfy transfer length header.\n\nThe above exception was the direct cause of the following exception:\n\nTraceback (most recent call last):\n  File \"/vllm-workspace/backend_request_func.py\", line 261, in async_request_openai_completions\n    async for chunk_bytes in response.content:\n  File \"/usr/local/lib/python3.10/dist-packages/aiohttp/streams.py\", line 50, in __anext__\n    rv = await self.read_func()\n  File \"/usr/local/lib/python3.10/dist-packages/aiohttp/streams.py\", line 317, in readline\n    return await self.readuntil()\n  File \"/usr/local/lib/python3.10/dist-packages/aiohttp/streams.py\", line 351, in readuntil\n    await self._wait(\"readuntil\")\n  File \"/usr/local/lib/python3.10/dist-packages/aiohttp/streams.py\", line 312, in _wait\n    await waiter\naiohttp.client_exceptions.ClientPayloadError: Response payload is not completed: <TransferEncodingError: 400, message='Not enough data for satisfy transfer length header.'>\n", "", "", "", "", "Traceback (most recent call last):\n  File \"/usr/local/lib/python3.10/dist-packages/aiohttp/client_proto.py\", line 94, in connection_lost\n    uncompleted = self._parser.feed_eof()\n  File \"aiohttp/_http_parser.pyx\", line 513, in aiohttp._http_parser.HttpParser.feed_eof\naiohttp.http_exceptions.TransferEncodingError: 400, message:\n  Not enough data for satisfy transfer length header.\n\nThe above exception was the direct cause of the following exception:\n\nTraceback (most recent call last):\n  File \"/vllm-workspace/backend_request_func.py\", line 261, in async_request_openai_completions\n    async for chunk_bytes in response.content:\n  File \"/usr/local/lib/python3.10/dist-packages/aiohttp/streams.py\", line 50, in __anext__\n    rv = await self.read_func()\n  File \"/usr/local/lib/python3.10/dist-packages/aiohttp/streams.py\", line 317, in readline\n    return await self.readuntil()\n  File \"/usr/local/lib/python3.10/dist-packages/aiohttp/streams.py\", line 351, in readuntil\n    await self._wait(\"readuntil\")\n  File \"/usr/local/lib/python3.10/dist-packages/aiohttp/streams.py\", line 312, in _wait\n    await waiter\naiohttp.client_exceptions.ClientPayloadError: Response payload is not completed: <TransferEncodingError: 400, message='Not enough data for satisfy transfer length header.'>\n", "", "Traceback (most recent call last):\n  File \"/usr/local/lib/python3.10/dist-packages/aiohttp/client_proto.py\", line 94, in connection_lost\n    uncompleted = self._parser.feed_eof()\n  File \"aiohttp/_http_parser.pyx\", line 513, in aiohttp._http_parser.HttpParser.feed_eof\naiohttp.http_exceptions.TransferEncodingError: 400, message:\n  Not enough data for satisfy transfer length header.\n\nThe above exception was the direct cause of the following exception:\n\nTraceback (most recent call last):\n  File \"/vllm-workspace/backend_request_func.py\", line 261, in async_request_openai_completions\n    async for chunk_bytes in response.content:\n  File \"/usr/local/lib/python3.10/dist-packages/aiohttp/streams.py\", line 50, in __anext__\n    rv = await self.read_func()\n  File \"/usr/local/lib/python3.10/dist-packages/aiohttp/streams.py\", line 317, in readline\n    return await self.readuntil()\n  File \"/usr/local/lib/python3.10/dist-packages/aiohttp/streams.py\", line 351, in readuntil\n    await self._wait(\"readuntil\")\n  File \"/usr/local/lib/python3.10/dist-packages/aiohttp/streams.py\", line 312, in _wait\n    await waiter\naiohttp.client_exceptions.ClientPayloadError: Response payload is not completed: <TransferEncodingError: 400, message='Not enough data for satisfy transfer length header.'>\n", "", "Traceback (most recent call last):\n  File \"/usr/local/lib/python3.10/dist-packages/aiohttp/client_proto.py\", line 94, in connection_lost\n    uncompleted = self._parser.feed_eof()\n  File \"aiohttp/_http_parser.pyx\", line 513, in aiohttp._http_parser.HttpParser.feed_eof\naiohttp.http_exceptions.TransferEncodingError: 400, message:\n  Not enough data for satisfy transfer length header.\n\nThe above exception was the direct cause of the following exception:\n\nTraceback (most recent call last):\n  File \"/vllm-workspace/backend_request_func.py\", line 261, in async_request_openai_completions\n    async for chunk_bytes in response.content:\n  File \"/usr/local/lib/python3.10/dist-packages/aiohttp/streams.py\", line 50, in __anext__\n    rv = await self.read_func()\n  File \"/usr/local/lib/python3.10/dist-packages/aiohttp/streams.py\", line 317, in readline\n    return await self.readuntil()\n  File \"/usr/local/lib/python3.10/dist-packages/aiohttp/streams.py\", line 351, in readuntil\n    await self._wait(\"readuntil\")\n  File \"/usr/local/lib/python3.10/dist-packages/aiohttp/streams.py\", line 312, in _wait\n    await waiter\naiohttp.client_exceptions.ClientPayloadError: Response payload is not completed: <TransferEncodingError: 400, message='Not enough data for satisfy transfer length header.'>\n", "", "Traceback (most recent call last):\n  File \"/usr/local/lib/python3.10/dist-packages/aiohttp/client_proto.py\", line 94, in connection_lost\n    uncompleted = self._parser.feed_eof()\n  File \"aiohttp/_http_parser.pyx\", line 513, in aiohttp._http_parser.HttpParser.feed_eof\naiohttp.http_exceptions.TransferEncodingError: 400, message:\n  Not enough data for satisfy transfer length header.\n\nThe above exception was the direct cause of the following exception:\n\nTraceback (most recent call last):\n  File \"/vllm-workspace/backend_request_func.py\", line 261, in async_request_openai_completions\n    async for chunk_bytes in response.content:\n  File \"/usr/local/lib/python3.10/dist-packages/aiohttp/streams.py\", line 50, in __anext__\n    rv = await self.read_func()\n  File \"/usr/local/lib/python3.10/dist-packages/aiohttp/streams.py\", line 317, in readline\n    return await self.readuntil()\n  File \"/usr/local/lib/python3.10/dist-packages/aiohttp/streams.py\", line 351, in readuntil\n    await self._wait(\"readuntil\")\n  File \"/usr/local/lib/python3.10/dist-packages/aiohttp/streams.py\", line 312, in _wait\n    await waiter\naiohttp.client_exceptions.ClientPayloadError: Response payload is not completed: <TransferEncodingError: 400, message='Not enough data for satisfy transfer length header.'>\n", "Traceback (most recent call last):\n  File \"/usr/local/lib/python3.10/dist-packages/aiohttp/client_proto.py\", line 94, in connection_lost\n    uncompleted = self._parser.feed_eof()\n  File \"aiohttp/_http_parser.pyx\", line 513, in aiohttp._http_parser.HttpParser.feed_eof\naiohttp.http_exceptions.TransferEncodingError: 400, message:\n  Not enough data for satisfy transfer length header.\n\nThe above exception was the direct cause of the following exception:\n\nTraceback (most recent call last):\n  File \"/vllm-workspace/backend_request_func.py\", line 261, in async_request_openai_completions\n    async for chunk_bytes in response.content:\n  File \"/usr/local/lib/python3.10/dist-packages/aiohttp/streams.py\", line 50, in __anext__\n    rv = await self.read_func()\n  File \"/usr/local/lib/python3.10/dist-packages/aiohttp/streams.py\", line 317, in readline\n    return await self.readuntil()\n  File \"/usr/local/lib/python3.10/dist-packages/aiohttp/streams.py\", line 351, in readuntil\n    await self._wait(\"readuntil\")\n  File \"/usr/local/lib/python3.10/dist-packages/aiohttp/streams.py\", line 312, in _wait\n    await waiter\naiohttp.client_exceptions.ClientPayloadError: Response payload is not completed: <TransferEncodingError: 400, message='Not enough data for satisfy transfer length header.'>\n", "Traceback (most recent call last):\n  File \"/usr/local/lib/python3.10/dist-packages/aiohttp/client_proto.py\", line 94, in connection_lost\n    uncompleted = self._parser.feed_eof()\n  File \"aiohttp/_http_parser.pyx\", line 513, in aiohttp._http_parser.HttpParser.feed_eof\naiohttp.http_exceptions.TransferEncodingError: 400, message:\n  Not enough data for satisfy transfer length header.\n\nThe above exception was the direct cause of the following exception:\n\nTraceback (most recent call last):\n  File \"/vllm-workspace/backend_request_func.py\", line 261, in async_request_openai_completions\n    async for chunk_bytes in response.content:\n  File \"/usr/local/lib/python3.10/dist-packages/aiohttp/streams.py\", line 50, in __anext__\n    rv = await self.read_func()\n  File \"/usr/local/lib/python3.10/dist-packages/aiohttp/streams.py\", line 317, in readline\n    return await self.readuntil()\n  File \"/usr/local/lib/python3.10/dist-packages/aiohttp/streams.py\", line 351, in readuntil\n    await self._wait(\"readuntil\")\n  File \"/usr/local/lib/python3.10/dist-packages/aiohttp/streams.py\", line 312, in _wait\n    await waiter\naiohttp.client_exceptions.ClientPayloadError: Response payload is not completed: <TransferEncodingError: 400, message='Not enough data for satisfy transfer length header.'>\n", "Traceback (most recent call last):\n  File \"/usr/local/lib/python3.10/dist-packages/aiohttp/client_proto.py\", line 94, in connection_lost\n    uncompleted = self._parser.feed_eof()\n  File \"aiohttp/_http_parser.pyx\", line 513, in aiohttp._http_parser.HttpParser.feed_eof\naiohttp.http_exceptions.TransferEncodingError: 400, message:\n  Not enough data for satisfy transfer length header.\n\nThe above exception was the direct cause of the following exception:\n\nTraceback (most recent call last):\n  File \"/vllm-workspace/backend_request_func.py\", line 261, in async_request_openai_completions\n    async for chunk_bytes in response.content:\n  File \"/usr/local/lib/python3.10/dist-packages/aiohttp/streams.py\", line 50, in __anext__\n    rv = await self.read_func()\n  File \"/usr/local/lib/python3.10/dist-packages/aiohttp/streams.py\", line 317, in readline\n    return await self.readuntil()\n  File \"/usr/local/lib/python3.10/dist-packages/aiohttp/streams.py\", line 351, in readuntil\n    await self._wait(\"readuntil\")\n  File \"/usr/local/lib/python3.10/dist-packages/aiohttp/streams.py\", line 312, in _wait\n    await waiter\naiohttp.client_exceptions.ClientPayloadError: Response payload is not completed: <TransferEncodingError: 400, message='Not enough data for satisfy transfer length header.'>\n", "Traceback (most recent call last):\n  File \"/usr/local/lib/python3.10/dist-packages/aiohttp/client_proto.py\", line 94, in connection_lost\n    uncompleted = self._parser.feed_eof()\n  File \"aiohttp/_http_parser.pyx\", line 513, in aiohttp._http_parser.HttpParser.feed_eof\naiohttp.http_exceptions.TransferEncodingError: 400, message:\n  Not enough data for satisfy transfer length header.\n\nThe above exception was the direct cause of the following exception:\n\nTraceback (most recent call last):\n  File \"/vllm-workspace/backend_request_func.py\", line 261, in async_request_openai_completions\n    async for chunk_bytes in response.content:\n  File \"/usr/local/lib/python3.10/dist-packages/aiohttp/streams.py\", line 50, in __anext__\n    rv = await self.read_func()\n  File \"/usr/local/lib/python3.10/dist-packages/aiohttp/streams.py\", line 317, in readline\n    return await self.readuntil()\n  File \"/usr/local/lib/python3.10/dist-packages/aiohttp/streams.py\", line 351, in readuntil\n    await self._wait(\"readuntil\")\n  File \"/usr/local/lib/python3.10/dist-packages/aiohttp/streams.py\", line 312, in _wait\n    await waiter\naiohttp.client_exceptions.ClientPayloadError: Response payload is not completed: <TransferEncodingError: 400, message='Not enough data for satisfy transfer length header.'>\n", "Traceback (most recent call last):\n  File \"/usr/local/lib/python3.10/dist-packages/aiohttp/client_proto.py\", line 94, in connection_lost\n    uncompleted = self._parser.feed_eof()\n  File \"aiohttp/_http_parser.pyx\", line 513, in aiohttp._http_parser.HttpParser.feed_eof\naiohttp.http_exceptions.TransferEncodingError: 400, message:\n  Not enough data for satisfy transfer length header.\n\nThe above exception was the direct cause of the following exception:\n\nTraceback (most recent call last):\n  File \"/vllm-workspace/backend_request_func.py\", line 261, in async_request_openai_completions\n    async for chunk_bytes in response.content:\n  File \"/usr/local/lib/python3.10/dist-packages/aiohttp/streams.py\", line 50, in __anext__\n    rv = await self.read_func()\n  File \"/usr/local/lib/python3.10/dist-packages/aiohttp/streams.py\", line 317, in readline\n    return await self.readuntil()\n  File \"/usr/local/lib/python3.10/dist-packages/aiohttp/streams.py\", line 351, in readuntil\n    await self._wait(\"readuntil\")\n  File \"/usr/local/lib/python3.10/dist-packages/aiohttp/streams.py\", line 312, in _wait\n    await waiter\naiohttp.client_exceptions.ClientPayloadError: Response payload is not completed: <TransferEncodingError: 400, message='Not enough data for satisfy transfer length header.'>\n", "Traceback (most recent call last):\n  File \"/usr/local/lib/python3.10/dist-packages/aiohttp/client_proto.py\", line 94, in connection_lost\n    uncompleted = self._parser.feed_eof()\n  File \"aiohttp/_http_parser.pyx\", line 513, in aiohttp._http_parser.HttpParser.feed_eof\naiohttp.http_exceptions.TransferEncodingError: 400, message:\n  Not enough data for satisfy transfer length header.\n\nThe above exception was the direct cause of the following exception:\n\nTraceback (most recent call last):\n  File \"/vllm-workspace/backend_request_func.py\", line 261, in async_request_openai_completions\n    async for chunk_bytes in response.content:\n  File \"/usr/local/lib/python3.10/dist-packages/aiohttp/streams.py\", line 50, in __anext__\n    rv = await self.read_func()\n  File \"/usr/local/lib/python3.10/dist-packages/aiohttp/streams.py\", line 317, in readline\n    return await self.readuntil()\n  File \"/usr/local/lib/python3.10/dist-packages/aiohttp/streams.py\", line 351, in readuntil\n    await self._wait(\"readuntil\")\n  File \"/usr/local/lib/python3.10/dist-packages/aiohttp/streams.py\", line 312, in _wait\n    await waiter\naiohttp.client_exceptions.ClientPayloadError: Response payload is not completed: <TransferEncodingError: 400, message='Not enough data for satisfy transfer length header.'>\n", "Traceback (most recent call last):\n  File \"/usr/local/lib/python3.10/dist-packages/aiohttp/client_proto.py\", line 94, in connection_lost\n    uncompleted = self._parser.feed_eof()\n  File \"aiohttp/_http_parser.pyx\", line 513, in aiohttp._http_parser.HttpParser.feed_eof\naiohttp.http_exceptions.TransferEncodingError: 400, message:\n  Not enough data for satisfy transfer length header.\n\nThe above exception was the direct cause of the following exception:\n\nTraceback (most recent call last):\n  File \"/vllm-workspace/backend_request_func.py\", line 261, in async_request_openai_completions\n    async for chunk_bytes in response.content:\n  File \"/usr/local/lib/python3.10/dist-packages/aiohttp/streams.py\", line 50, in __anext__\n    rv = await self.read_func()\n  File \"/usr/local/lib/python3.10/dist-packages/aiohttp/streams.py\", line 317, in readline\n    return await self.readuntil()\n  File \"/usr/local/lib/python3.10/dist-packages/aiohttp/streams.py\", line 351, in readuntil\n    await self._wait(\"readuntil\")\n  File \"/usr/local/lib/python3.10/dist-packages/aiohttp/streams.py\", line 312, in _wait\n    await waiter\naiohttp.client_exceptions.ClientPayloadError: Response payload is not completed: <TransferEncodingError: 400, message='Not enough data for satisfy transfer length header.'>\n", "Traceback (most recent call last):\n  File \"/usr/local/lib/python3.10/dist-packages/aiohttp/client_proto.py\", line 94, in connection_lost\n    uncompleted = self._parser.feed_eof()\n  File \"aiohttp/_http_parser.pyx\", line 513, in aiohttp._http_parser.HttpParser.feed_eof\naiohttp.http_exceptions.TransferEncodingError: 400, message:\n  Not enough data for satisfy transfer length header.\n\nThe above exception was the direct cause of the following exception:\n\nTraceback (most recent call last):\n  File \"/vllm-workspace/backend_request_func.py\", line 261, in async_request_openai_completions\n    async for chunk_bytes in response.content:\n  File \"/usr/local/lib/python3.10/dist-packages/aiohttp/streams.py\", line 50, in __anext__\n    rv = await self.read_func()\n  File \"/usr/local/lib/python3.10/dist-packages/aiohttp/streams.py\", line 317, in readline\n    return await self.readuntil()\n  File \"/usr/local/lib/python3.10/dist-packages/aiohttp/streams.py\", line 351, in readuntil\n    await self._wait(\"readuntil\")\n  File \"/usr/local/lib/python3.10/dist-packages/aiohttp/streams.py\", line 312, in _wait\n    await waiter\naiohttp.client_exceptions.ClientPayloadError: Response payload is not completed: <TransferEncodingError: 400, message='Not enough data for satisfy transfer length header.'>\n", "Traceback (most recent call last):\n  File \"/usr/local/lib/python3.10/dist-packages/aiohttp/client_proto.py\", line 94, in connection_lost\n    uncompleted = self._parser.feed_eof()\n  File \"aiohttp/_http_parser.pyx\", line 513, in aiohttp._http_parser.HttpParser.feed_eof\naiohttp.http_exceptions.TransferEncodingError: 400, message:\n  Not enough data for satisfy transfer length header.\n\nThe above exception was the direct cause of the following exception:\n\nTraceback (most recent call last):\n  File \"/vllm-workspace/backend_request_func.py\", line 261, in async_request_openai_completions\n    async for chunk_bytes in response.content:\n  File \"/usr/local/lib/python3.10/dist-packages/aiohttp/streams.py\", line 50, in __anext__\n    rv = await self.read_func()\n  File \"/usr/local/lib/python3.10/dist-packages/aiohttp/streams.py\", line 317, in readline\n    return await self.readuntil()\n  File \"/usr/local/lib/python3.10/dist-packages/aiohttp/streams.py\", line 351, in readuntil\n    await self._wait(\"readuntil\")\n  File \"/usr/local/lib/python3.10/dist-packages/aiohttp/streams.py\", line 312, in _wait\n    await waiter\naiohttp.client_exceptions.ClientPayloadError: Response payload is not completed: <TransferEncodingError: 400, message='Not enough data for satisfy transfer length header.'>\n", "Traceback (most recent call last):\n  File \"/usr/local/lib/python3.10/dist-packages/aiohttp/client_proto.py\", line 94, in connection_lost\n    uncompleted = self._parser.feed_eof()\n  File \"aiohttp/_http_parser.pyx\", line 513, in aiohttp._http_parser.HttpParser.feed_eof\naiohttp.http_exceptions.TransferEncodingError: 400, message:\n  Not enough data for satisfy transfer length header.\n\nThe above exception was the direct cause of the following exception:\n\nTraceback (most recent call last):\n  File \"/vllm-workspace/backend_request_func.py\", line 261, in async_request_openai_completions\n    async for chunk_bytes in response.content:\n  File \"/usr/local/lib/python3.10/dist-packages/aiohttp/streams.py\", line 50, in __anext__\n    rv = await self.read_func()\n  File \"/usr/local/lib/python3.10/dist-packages/aiohttp/streams.py\", line 317, in readline\n    return await self.readuntil()\n  File \"/usr/local/lib/python3.10/dist-packages/aiohttp/streams.py\", line 351, in readuntil\n    await self._wait(\"readuntil\")\n  File \"/usr/local/lib/python3.10/dist-packages/aiohttp/streams.py\", line 312, in _wait\n    await waiter\naiohttp.client_exceptions.ClientPayloadError: Response payload is not completed: <TransferEncodingError: 400, message='Not enough data for satisfy transfer length header.'>\n", "Traceback (most recent call last):\n  File \"/usr/local/lib/python3.10/dist-packages/aiohttp/client_proto.py\", line 94, in connection_lost\n    uncompleted = self._parser.feed_eof()\n  File \"aiohttp/_http_parser.pyx\", line 513, in aiohttp._http_parser.HttpParser.feed_eof\naiohttp.http_exceptions.TransferEncodingError: 400, message:\n  Not enough data for satisfy transfer length header.\n\nThe above exception was the direct cause of the following exception:\n\nTraceback (most recent call last):\n  File \"/vllm-workspace/backend_request_func.py\", line 261, in async_request_openai_completions\n    async for chunk_bytes in response.content:\n  File \"/usr/local/lib/python3.10/dist-packages/aiohttp/streams.py\", line 50, in __anext__\n    rv = await self.read_func()\n  File \"/usr/local/lib/python3.10/dist-packages/aiohttp/streams.py\", line 317, in readline\n    return await self.readuntil()\n  File \"/usr/local/lib/python3.10/dist-packages/aiohttp/streams.py\", line 351, in readuntil\n    await self._wait(\"readuntil\")\n  File \"/usr/local/lib/python3.10/dist-packages/aiohttp/streams.py\", line 312, in _wait\n    await waiter\naiohttp.client_exceptions.ClientPayloadError: Response payload is not completed: <TransferEncodingError: 400, message='Not enough data for satisfy transfer length header.'>\n", "Traceback (most recent call last):\n  File \"/usr/local/lib/python3.10/dist-packages/aiohttp/client_proto.py\", line 94, in connection_lost\n    uncompleted = self._parser.feed_eof()\n  File \"aiohttp/_http_parser.pyx\", line 513, in aiohttp._http_parser.HttpParser.feed_eof\naiohttp.http_exceptions.TransferEncodingError: 400, message:\n  Not enough data for satisfy transfer length header.\n\nThe above exception was the direct cause of the following exception:\n\nTraceback (most recent call last):\n  File \"/vllm-workspace/backend_request_func.py\", line 261, in async_request_openai_completions\n    async for chunk_bytes in response.content:\n  File \"/usr/local/lib/python3.10/dist-packages/aiohttp/streams.py\", line 50, in __anext__\n    rv = await self.read_func()\n  File \"/usr/local/lib/python3.10/dist-packages/aiohttp/streams.py\", line 317, in readline\n    return await self.readuntil()\n  File \"/usr/local/lib/python3.10/dist-packages/aiohttp/streams.py\", line 351, in readuntil\n    await self._wait(\"readuntil\")\n  File \"/usr/local/lib/python3.10/dist-packages/aiohttp/streams.py\", line 312, in _wait\n    await waiter\naiohttp.client_exceptions.ClientPayloadError: Response payload is not completed: <TransferEncodingError: 400, message='Not enough data for satisfy transfer length header.'>\n", "Traceback (most recent call last):\n  File \"/usr/local/lib/python3.10/dist-packages/aiohttp/client_proto.py\", line 94, in connection_lost\n    uncompleted = self._parser.feed_eof()\n  File \"aiohttp/_http_parser.pyx\", line 513, in aiohttp._http_parser.HttpParser.feed_eof\naiohttp.http_exceptions.TransferEncodingError: 400, message:\n  Not enough data for satisfy transfer length header.\n\nThe above exception was the direct cause of the following exception:\n\nTraceback (most recent call last):\n  File \"/vllm-workspace/backend_request_func.py\", line 261, in async_request_openai_completions\n    async for chunk_bytes in response.content:\n  File \"/usr/local/lib/python3.10/dist-packages/aiohttp/streams.py\", line 50, in __anext__\n    rv = await self.read_func()\n  File \"/usr/local/lib/python3.10/dist-packages/aiohttp/streams.py\", line 317, in readline\n    return await self.readuntil()\n  File \"/usr/local/lib/python3.10/dist-packages/aiohttp/streams.py\", line 351, in readuntil\n    await self._wait(\"readuntil\")\n  File \"/usr/local/lib/python3.10/dist-packages/aiohttp/streams.py\", line 312, in _wait\n    await waiter\naiohttp.client_exceptions.ClientPayloadError: Response payload is not completed: <TransferEncodingError: 400, message='Not enough data for satisfy transfer length header.'>\n", "Traceback (most recent call last):\n  File \"/usr/local/lib/python3.10/dist-packages/aiohttp/client_proto.py\", line 94, in connection_lost\n    uncompleted = self._parser.feed_eof()\n  File \"aiohttp/_http_parser.pyx\", line 513, in aiohttp._http_parser.HttpParser.feed_eof\naiohttp.http_exceptions.TransferEncodingError: 400, message:\n  Not enough data for satisfy transfer length header.\n\nThe above exception was the direct cause of the following exception:\n\nTraceback (most recent call last):\n  File \"/vllm-workspace/backend_request_func.py\", line 261, in async_request_openai_completions\n    async for chunk_bytes in response.content:\n  File \"/usr/local/lib/python3.10/dist-packages/aiohttp/streams.py\", line 50, in __anext__\n    rv = await self.read_func()\n  File \"/usr/local/lib/python3.10/dist-packages/aiohttp/streams.py\", line 317, in readline\n    return await self.readuntil()\n  File \"/usr/local/lib/python3.10/dist-packages/aiohttp/streams.py\", line 351, in readuntil\n    await self._wait(\"readuntil\")\n  File \"/usr/local/lib/python3.10/dist-packages/aiohttp/streams.py\", line 312, in _wait\n    await waiter\naiohttp.client_exceptions.ClientPayloadError: Response payload is not completed: <TransferEncodingError: 400, message='Not enough data for satisfy transfer length header.'>\n", "Traceback (most recent call last):\n  File \"/usr/local/lib/python3.10/dist-packages/aiohttp/client_proto.py\", line 94, in connection_lost\n    uncompleted = self._parser.feed_eof()\n  File \"aiohttp/_http_parser.pyx\", line 513, in aiohttp._http_parser.HttpParser.feed_eof\naiohttp.http_exceptions.TransferEncodingError: 400, message:\n  Not enough data for satisfy transfer length header.\n\nThe above exception was the direct cause of the following exception:\n\nTraceback (most recent call last):\n  File \"/vllm-workspace/backend_request_func.py\", line 261, in async_request_openai_completions\n    async for chunk_bytes in response.content:\n  File \"/usr/local/lib/python3.10/dist-packages/aiohttp/streams.py\", line 50, in __anext__\n    rv = await self.read_func()\n  File \"/usr/local/lib/python3.10/dist-packages/aiohttp/streams.py\", line 317, in readline\n    return await self.readuntil()\n  File \"/usr/local/lib/python3.10/dist-packages/aiohttp/streams.py\", line 351, in readuntil\n    await self._wait(\"readuntil\")\n  File \"/usr/local/lib/python3.10/dist-packages/aiohttp/streams.py\", line 312, in _wait\n    await waiter\naiohttp.client_exceptions.ClientPayloadError: Response payload is not completed: <TransferEncodingError: 400, message='Not enough data for satisfy transfer length header.'>\n", "Traceback (most recent call last):\n  File \"/usr/local/lib/python3.10/dist-packages/aiohttp/client_proto.py\", line 94, in connection_lost\n    uncompleted = self._parser.feed_eof()\n  File \"aiohttp/_http_parser.pyx\", line 513, in aiohttp._http_parser.HttpParser.feed_eof\naiohttp.http_exceptions.TransferEncodingError: 400, message:\n  Not enough data for satisfy transfer length header.\n\nThe above exception was the direct cause of the following exception:\n\nTraceback (most recent call last):\n  File \"/vllm-workspace/backend_request_func.py\", line 261, in async_request_openai_completions\n    async for chunk_bytes in response.content:\n  File \"/usr/local/lib/python3.10/dist-packages/aiohttp/streams.py\", line 50, in __anext__\n    rv = await self.read_func()\n  File \"/usr/local/lib/python3.10/dist-packages/aiohttp/streams.py\", line 317, in readline\n    return await self.readuntil()\n  File \"/usr/local/lib/python3.10/dist-packages/aiohttp/streams.py\", line 351, in readuntil\n    await self._wait(\"readuntil\")\n  File \"/usr/local/lib/python3.10/dist-packages/aiohttp/streams.py\", line 312, in _wait\n    await waiter\naiohttp.client_exceptions.ClientPayloadError: Response payload is not completed: <TransferEncodingError: 400, message='Not enough data for satisfy transfer length header.'>\n", "Traceback (most recent call last):\n  File \"/usr/local/lib/python3.10/dist-packages/aiohttp/client_proto.py\", line 94, in connection_lost\n    uncompleted = self._parser.feed_eof()\n  File \"aiohttp/_http_parser.pyx\", line 513, in aiohttp._http_parser.HttpParser.feed_eof\naiohttp.http_exceptions.TransferEncodingError: 400, message:\n  Not enough data for satisfy transfer length header.\n\nThe above exception was the direct cause of the following exception:\n\nTraceback (most recent call last):\n  File \"/vllm-workspace/backend_request_func.py\", line 261, in async_request_openai_completions\n    async for chunk_bytes in response.content:\n  File \"/usr/local/lib/python3.10/dist-packages/aiohttp/streams.py\", line 50, in __anext__\n    rv = await self.read_func()\n  File \"/usr/local/lib/python3.10/dist-packages/aiohttp/streams.py\", line 317, in readline\n    return await self.readuntil()\n  File \"/usr/local/lib/python3.10/dist-packages/aiohttp/streams.py\", line 351, in readuntil\n    await self._wait(\"readuntil\")\n  File \"/usr/local/lib/python3.10/dist-packages/aiohttp/streams.py\", line 312, in _wait\n    await waiter\naiohttp.client_exceptions.ClientPayloadError: Response payload is not completed: <TransferEncodingError: 400, message='Not enough data for satisfy transfer length header.'>\n", "Traceback (most recent call last):\n  File \"/usr/local/lib/python3.10/dist-packages/aiohttp/client_proto.py\", line 94, in connection_lost\n    uncompleted = self._parser.feed_eof()\n  File \"aiohttp/_http_parser.pyx\", line 513, in aiohttp._http_parser.HttpParser.feed_eof\naiohttp.http_exceptions.TransferEncodingError: 400, message:\n  Not enough data for satisfy transfer length header.\n\nThe above exception was the direct cause of the following exception:\n\nTraceback (most recent call last):\n  File \"/vllm-workspace/backend_request_func.py\", line 261, in async_request_openai_completions\n    async for chunk_bytes in response.content:\n  File \"/usr/local/lib/python3.10/dist-packages/aiohttp/streams.py\", line 50, in __anext__\n    rv = await self.read_func()\n  File \"/usr/local/lib/python3.10/dist-packages/aiohttp/streams.py\", line 317, in readline\n    return await self.readuntil()\n  File \"/usr/local/lib/python3.10/dist-packages/aiohttp/streams.py\", line 351, in readuntil\n    await self._wait(\"readuntil\")\n  File \"/usr/local/lib/python3.10/dist-packages/aiohttp/streams.py\", line 312, in _wait\n    await waiter\naiohttp.client_exceptions.ClientPayloadError: Response payload is not completed: <TransferEncodingError: 400, message='Not enough data for satisfy transfer length header.'>\n", "Traceback (most recent call last):\n  File \"/usr/local/lib/python3.10/dist-packages/aiohttp/client_proto.py\", line 94, in connection_lost\n    uncompleted = self._parser.feed_eof()\n  File \"aiohttp/_http_parser.pyx\", line 513, in aiohttp._http_parser.HttpParser.feed_eof\naiohttp.http_exceptions.TransferEncodingError: 400, message:\n  Not enough data for satisfy transfer length header.\n\nThe above exception was the direct cause of the following exception:\n\nTraceback (most recent call last):\n  File \"/vllm-workspace/backend_request_func.py\", line 261, in async_request_openai_completions\n    async for chunk_bytes in response.content:\n  File \"/usr/local/lib/python3.10/dist-packages/aiohttp/streams.py\", line 50, in __anext__\n    rv = await self.read_func()\n  File \"/usr/local/lib/python3.10/dist-packages/aiohttp/streams.py\", line 317, in readline\n    return await self.readuntil()\n  File \"/usr/local/lib/python3.10/dist-packages/aiohttp/streams.py\", line 351, in readuntil\n    await self._wait(\"readuntil\")\n  File \"/usr/local/lib/python3.10/dist-packages/aiohttp/streams.py\", line 312, in _wait\n    await waiter\naiohttp.client_exceptions.ClientPayloadError: Response payload is not completed: <TransferEncodingError: 400, message='Not enough data for satisfy transfer length header.'>\n", "Traceback (most recent call last):\n  File \"/usr/local/lib/python3.10/dist-packages/aiohttp/client_proto.py\", line 94, in connection_lost\n    uncompleted = self._parser.feed_eof()\n  File \"aiohttp/_http_parser.pyx\", line 513, in aiohttp._http_parser.HttpParser.feed_eof\naiohttp.http_exceptions.TransferEncodingError: 400, message:\n  Not enough data for satisfy transfer length header.\n\nThe above exception was the direct cause of the following exception:\n\nTraceback (most recent call last):\n  File \"/vllm-workspace/backend_request_func.py\", line 261, in async_request_openai_completions\n    async for chunk_bytes in response.content:\n  File \"/usr/local/lib/python3.10/dist-packages/aiohttp/streams.py\", line 50, in __anext__\n    rv = await self.read_func()\n  File \"/usr/local/lib/python3.10/dist-packages/aiohttp/streams.py\", line 317, in readline\n    return await self.readuntil()\n  File \"/usr/local/lib/python3.10/dist-packages/aiohttp/streams.py\", line 351, in readuntil\n    await self._wait(\"readuntil\")\n  File \"/usr/local/lib/python3.10/dist-packages/aiohttp/streams.py\", line 312, in _wait\n    await waiter\naiohttp.client_exceptions.ClientPayloadError: Response payload is not completed: <TransferEncodingError: 400, message='Not enough data for satisfy transfer length header.'>\n", "Traceback (most recent call last):\n  File \"/usr/local/lib/python3.10/dist-packages/aiohttp/client_proto.py\", line 94, in connection_lost\n    uncompleted = self._parser.feed_eof()\n  File \"aiohttp/_http_parser.pyx\", line 513, in aiohttp._http_parser.HttpParser.feed_eof\naiohttp.http_exceptions.TransferEncodingError: 400, message:\n  Not enough data for satisfy transfer length header.\n\nThe above exception was the direct cause of the following exception:\n\nTraceback (most recent call last):\n  File \"/vllm-workspace/backend_request_func.py\", line 261, in async_request_openai_completions\n    async for chunk_bytes in response.content:\n  File \"/usr/local/lib/python3.10/dist-packages/aiohttp/streams.py\", line 50, in __anext__\n    rv = await self.read_func()\n  File \"/usr/local/lib/python3.10/dist-packages/aiohttp/streams.py\", line 317, in readline\n    return await self.readuntil()\n  File \"/usr/local/lib/python3.10/dist-packages/aiohttp/streams.py\", line 351, in readuntil\n    await self._wait(\"readuntil\")\n  File \"/usr/local/lib/python3.10/dist-packages/aiohttp/streams.py\", line 312, in _wait\n    await waiter\naiohttp.client_exceptions.ClientPayloadError: Response payload is not completed: <TransferEncodingError: 400, message='Not enough data for satisfy transfer length header.'>\n", "Traceback (most recent call last):\n  File \"/usr/local/lib/python3.10/dist-packages/aiohttp/client_proto.py\", line 94, in connection_lost\n    uncompleted = self._parser.feed_eof()\n  File \"aiohttp/_http_parser.pyx\", line 513, in aiohttp._http_parser.HttpParser.feed_eof\naiohttp.http_exceptions.TransferEncodingError: 400, message:\n  Not enough data for satisfy transfer length header.\n\nThe above exception was the direct cause of the following exception:\n\nTraceback (most recent call last):\n  File \"/vllm-workspace/backend_request_func.py\", line 261, in async_request_openai_completions\n    async for chunk_bytes in response.content:\n  File \"/usr/local/lib/python3.10/dist-packages/aiohttp/streams.py\", line 50, in __anext__\n    rv = await self.read_func()\n  File \"/usr/local/lib/python3.10/dist-packages/aiohttp/streams.py\", line 317, in readline\n    return await self.readuntil()\n  File \"/usr/local/lib/python3.10/dist-packages/aiohttp/streams.py\", line 351, in readuntil\n    await self._wait(\"readuntil\")\n  File \"/usr/local/lib/python3.10/dist-packages/aiohttp/streams.py\", line 312, in _wait\n    await waiter\naiohttp.client_exceptions.ClientPayloadError: Response payload is not completed: <TransferEncodingError: 400, message='Not enough data for satisfy transfer length header.'>\n", "Traceback (most recent call last):\n  File \"/usr/local/lib/python3.10/dist-packages/aiohttp/client_proto.py\", line 94, in connection_lost\n    uncompleted = self._parser.feed_eof()\n  File \"aiohttp/_http_parser.pyx\", line 513, in aiohttp._http_parser.HttpParser.feed_eof\naiohttp.http_exceptions.TransferEncodingError: 400, message:\n  Not enough data for satisfy transfer length header.\n\nThe above exception was the direct cause of the following exception:\n\nTraceback (most recent call last):\n  File \"/vllm-workspace/backend_request_func.py\", line 261, in async_request_openai_completions\n    async for chunk_bytes in response.content:\n  File \"/usr/local/lib/python3.10/dist-packages/aiohttp/streams.py\", line 50, in __anext__\n    rv = await self.read_func()\n  File \"/usr/local/lib/python3.10/dist-packages/aiohttp/streams.py\", line 317, in readline\n    return await self.readuntil()\n  File \"/usr/local/lib/python3.10/dist-packages/aiohttp/streams.py\", line 351, in readuntil\n    await self._wait(\"readuntil\")\n  File \"/usr/local/lib/python3.10/dist-packages/aiohttp/streams.py\", line 312, in _wait\n    await waiter\naiohttp.client_exceptions.ClientPayloadError: Response payload is not completed: <TransferEncodingError: 400, message='Not enough data for satisfy transfer length header.'>\n", "Traceback (most recent call last):\n  File \"/usr/local/lib/python3.10/dist-packages/aiohttp/client_proto.py\", line 94, in connection_lost\n    uncompleted = self._parser.feed_eof()\n  File \"aiohttp/_http_parser.pyx\", line 513, in aiohttp._http_parser.HttpParser.feed_eof\naiohttp.http_exceptions.TransferEncodingError: 400, message:\n  Not enough data for satisfy transfer length header.\n\nThe above exception was the direct cause of the following exception:\n\nTraceback (most recent call last):\n  File \"/vllm-workspace/backend_request_func.py\", line 261, in async_request_openai_completions\n    async for chunk_bytes in response.content:\n  File \"/usr/local/lib/python3.10/dist-packages/aiohttp/streams.py\", line 50, in __anext__\n    rv = await self.read_func()\n  File \"/usr/local/lib/python3.10/dist-packages/aiohttp/streams.py\", line 317, in readline\n    return await self.readuntil()\n  File \"/usr/local/lib/python3.10/dist-packages/aiohttp/streams.py\", line 351, in readuntil\n    await self._wait(\"readuntil\")\n  File \"/usr/local/lib/python3.10/dist-packages/aiohttp/streams.py\", line 312, in _wait\n    await waiter\naiohttp.client_exceptions.ClientPayloadError: Response payload is not completed: <TransferEncodingError: 400, message='Not enough data for satisfy transfer length header.'>\n", "Traceback (most recent call last):\n  File \"/usr/local/lib/python3.10/dist-packages/aiohttp/client_proto.py\", line 94, in connection_lost\n    uncompleted = self._parser.feed_eof()\n  File \"aiohttp/_http_parser.pyx\", line 513, in aiohttp._http_parser.HttpParser.feed_eof\naiohttp.http_exceptions.TransferEncodingError: 400, message:\n  Not enough data for satisfy transfer length header.\n\nThe above exception was the direct cause of the following exception:\n\nTraceback (most recent call last):\n  File \"/vllm-workspace/backend_request_func.py\", line 261, in async_request_openai_completions\n    async for chunk_bytes in response.content:\n  File \"/usr/local/lib/python3.10/dist-packages/aiohttp/streams.py\", line 50, in __anext__\n    rv = await self.read_func()\n  File \"/usr/local/lib/python3.10/dist-packages/aiohttp/streams.py\", line 317, in readline\n    return await self.readuntil()\n  File \"/usr/local/lib/python3.10/dist-packages/aiohttp/streams.py\", line 351, in readuntil\n    await self._wait(\"readuntil\")\n  File \"/usr/local/lib/python3.10/dist-packages/aiohttp/streams.py\", line 312, in _wait\n    await waiter\naiohttp.client_exceptions.ClientPayloadError: Response payload is not completed: <TransferEncodingError: 400, message='Not enough data for satisfy transfer length header.'>\n", "Traceback (most recent call last):\n  File \"/usr/local/lib/python3.10/dist-packages/aiohttp/client_proto.py\", line 94, in connection_lost\n    uncompleted = self._parser.feed_eof()\n  File \"aiohttp/_http_parser.pyx\", line 513, in aiohttp._http_parser.HttpParser.feed_eof\naiohttp.http_exceptions.TransferEncodingError: 400, message:\n  Not enough data for satisfy transfer length header.\n\nThe above exception was the direct cause of the following exception:\n\nTraceback (most recent call last):\n  File \"/vllm-workspace/backend_request_func.py\", line 261, in async_request_openai_completions\n    async for chunk_bytes in response.content:\n  File \"/usr/local/lib/python3.10/dist-packages/aiohttp/streams.py\", line 50, in __anext__\n    rv = await self.read_func()\n  File \"/usr/local/lib/python3.10/dist-packages/aiohttp/streams.py\", line 317, in readline\n    return await self.readuntil()\n  File \"/usr/local/lib/python3.10/dist-packages/aiohttp/streams.py\", line 351, in readuntil\n    await self._wait(\"readuntil\")\n  File \"/usr/local/lib/python3.10/dist-packages/aiohttp/streams.py\", line 312, in _wait\n    await waiter\naiohttp.client_exceptions.ClientPayloadError: Response payload is not completed: <TransferEncodingError: 400, message='Not enough data for satisfy transfer length header.'>\n", "Traceback (most recent call last):\n  File \"/usr/local/lib/python3.10/dist-packages/aiohttp/client_proto.py\", line 94, in connection_lost\n    uncompleted = self._parser.feed_eof()\n  File \"aiohttp/_http_parser.pyx\", line 513, in aiohttp._http_parser.HttpParser.feed_eof\naiohttp.http_exceptions.TransferEncodingError: 400, message:\n  Not enough data for satisfy transfer length header.\n\nThe above exception was the direct cause of the following exception:\n\nTraceback (most recent call last):\n  File \"/vllm-workspace/backend_request_func.py\", line 261, in async_request_openai_completions\n    async for chunk_bytes in response.content:\n  File \"/usr/local/lib/python3.10/dist-packages/aiohttp/streams.py\", line 50, in __anext__\n    rv = await self.read_func()\n  File \"/usr/local/lib/python3.10/dist-packages/aiohttp/streams.py\", line 317, in readline\n    return await self.readuntil()\n  File \"/usr/local/lib/python3.10/dist-packages/aiohttp/streams.py\", line 351, in readuntil\n    await self._wait(\"readuntil\")\n  File \"/usr/local/lib/python3.10/dist-packages/aiohttp/streams.py\", line 312, in _wait\n    await waiter\naiohttp.client_exceptions.ClientPayloadError: Response payload is not completed: <TransferEncodingError: 400, message='Not enough data for satisfy transfer length header.'>\n", "Traceback (most recent call last):\n  File \"/usr/local/lib/python3.10/dist-packages/aiohttp/client_proto.py\", line 94, in connection_lost\n    uncompleted = self._parser.feed_eof()\n  File \"aiohttp/_http_parser.pyx\", line 513, in aiohttp._http_parser.HttpParser.feed_eof\naiohttp.http_exceptions.TransferEncodingError: 400, message:\n  Not enough data for satisfy transfer length header.\n\nThe above exception was the direct cause of the following exception:\n\nTraceback (most recent call last):\n  File \"/vllm-workspace/backend_request_func.py\", line 261, in async_request_openai_completions\n    async for chunk_bytes in response.content:\n  File \"/usr/local/lib/python3.10/dist-packages/aiohttp/streams.py\", line 50, in __anext__\n    rv = await self.read_func()\n  File \"/usr/local/lib/python3.10/dist-packages/aiohttp/streams.py\", line 317, in readline\n    return await self.readuntil()\n  File \"/usr/local/lib/python3.10/dist-packages/aiohttp/streams.py\", line 351, in readuntil\n    await self._wait(\"readuntil\")\n  File \"/usr/local/lib/python3.10/dist-packages/aiohttp/streams.py\", line 312, in _wait\n    await waiter\naiohttp.client_exceptions.ClientPayloadError: Response payload is not completed: <TransferEncodingError: 400, message='Not enough data for satisfy transfer length header.'>\n", "Traceback (most recent call last):\n  File \"/usr/local/lib/python3.10/dist-packages/aiohttp/client_proto.py\", line 94, in connection_lost\n    uncompleted = self._parser.feed_eof()\n  File \"aiohttp/_http_parser.pyx\", line 513, in aiohttp._http_parser.HttpParser.feed_eof\naiohttp.http_exceptions.TransferEncodingError: 400, message:\n  Not enough data for satisfy transfer length header.\n\nThe above exception was the direct cause of the following exception:\n\nTraceback (most recent call last):\n  File \"/vllm-workspace/backend_request_func.py\", line 261, in async_request_openai_completions\n    async for chunk_bytes in response.content:\n  File \"/usr/local/lib/python3.10/dist-packages/aiohttp/streams.py\", line 50, in __anext__\n    rv = await self.read_func()\n  File \"/usr/local/lib/python3.10/dist-packages/aiohttp/streams.py\", line 317, in readline\n    return await self.readuntil()\n  File \"/usr/local/lib/python3.10/dist-packages/aiohttp/streams.py\", line 351, in readuntil\n    await self._wait(\"readuntil\")\n  File \"/usr/local/lib/python3.10/dist-packages/aiohttp/streams.py\", line 312, in _wait\n    await waiter\naiohttp.client_exceptions.ClientPayloadError: Response payload is not completed: <TransferEncodingError: 400, message='Not enough data for satisfy transfer length header.'>\n", "Traceback (most recent call last):\n  File \"/usr/local/lib/python3.10/dist-packages/aiohttp/client_proto.py\", line 94, in connection_lost\n    uncompleted = self._parser.feed_eof()\n  File \"aiohttp/_http_parser.pyx\", line 513, in aiohttp._http_parser.HttpParser.feed_eof\naiohttp.http_exceptions.TransferEncodingError: 400, message:\n  Not enough data for satisfy transfer length header.\n\nThe above exception was the direct cause of the following exception:\n\nTraceback (most recent call last):\n  File \"/vllm-workspace/backend_request_func.py\", line 261, in async_request_openai_completions\n    async for chunk_bytes in response.content:\n  File \"/usr/local/lib/python3.10/dist-packages/aiohttp/streams.py\", line 50, in __anext__\n    rv = await self.read_func()\n  File \"/usr/local/lib/python3.10/dist-packages/aiohttp/streams.py\", line 317, in readline\n    return await self.readuntil()\n  File \"/usr/local/lib/python3.10/dist-packages/aiohttp/streams.py\", line 351, in readuntil\n    await self._wait(\"readuntil\")\n  File \"/usr/local/lib/python3.10/dist-packages/aiohttp/streams.py\", line 312, in _wait\n    await waiter\naiohttp.client_exceptions.ClientPayloadError: Response payload is not completed: <TransferEncodingError: 400, message='Not enough data for satisfy transfer length header.'>\n", "Traceback (most recent call last):\n  File \"/usr/local/lib/python3.10/dist-packages/aiohttp/client_proto.py\", line 94, in connection_lost\n    uncompleted = self._parser.feed_eof()\n  File \"aiohttp/_http_parser.pyx\", line 513, in aiohttp._http_parser.HttpParser.feed_eof\naiohttp.http_exceptions.TransferEncodingError: 400, message:\n  Not enough data for satisfy transfer length header.\n\nThe above exception was the direct cause of the following exception:\n\nTraceback (most recent call last):\n  File \"/vllm-workspace/backend_request_func.py\", line 261, in async_request_openai_completions\n    async for chunk_bytes in response.content:\n  File \"/usr/local/lib/python3.10/dist-packages/aiohttp/streams.py\", line 50, in __anext__\n    rv = await self.read_func()\n  File \"/usr/local/lib/python3.10/dist-packages/aiohttp/streams.py\", line 317, in readline\n    return await self.readuntil()\n  File \"/usr/local/lib/python3.10/dist-packages/aiohttp/streams.py\", line 351, in readuntil\n    await self._wait(\"readuntil\")\n  File \"/usr/local/lib/python3.10/dist-packages/aiohttp/streams.py\", line 312, in _wait\n    await waiter\naiohttp.client_exceptions.ClientPayloadError: Response payload is not completed: <TransferEncodingError: 400, message='Not enough data for satisfy transfer length header.'>\n", "Traceback (most recent call last):\n  File \"/usr/local/lib/python3.10/dist-packages/aiohttp/client_proto.py\", line 94, in connection_lost\n    uncompleted = self._parser.feed_eof()\n  File \"aiohttp/_http_parser.pyx\", line 513, in aiohttp._http_parser.HttpParser.feed_eof\naiohttp.http_exceptions.TransferEncodingError: 400, message:\n  Not enough data for satisfy transfer length header.\n\nThe above exception was the direct cause of the following exception:\n\nTraceback (most recent call last):\n  File \"/vllm-workspace/backend_request_func.py\", line 261, in async_request_openai_completions\n    async for chunk_bytes in response.content:\n  File \"/usr/local/lib/python3.10/dist-packages/aiohttp/streams.py\", line 50, in __anext__\n    rv = await self.read_func()\n  File \"/usr/local/lib/python3.10/dist-packages/aiohttp/streams.py\", line 317, in readline\n    return await self.readuntil()\n  File \"/usr/local/lib/python3.10/dist-packages/aiohttp/streams.py\", line 351, in readuntil\n    await self._wait(\"readuntil\")\n  File \"/usr/local/lib/python3.10/dist-packages/aiohttp/streams.py\", line 312, in _wait\n    await waiter\naiohttp.client_exceptions.ClientPayloadError: Response payload is not completed: <TransferEncodingError: 400, message='Not enough data for satisfy transfer length header.'>\n", "Traceback (most recent call last):\n  File \"/usr/local/lib/python3.10/dist-packages/aiohttp/client_proto.py\", line 94, in connection_lost\n    uncompleted = self._parser.feed_eof()\n  File \"aiohttp/_http_parser.pyx\", line 513, in aiohttp._http_parser.HttpParser.feed_eof\naiohttp.http_exceptions.TransferEncodingError: 400, message:\n  Not enough data for satisfy transfer length header.\n\nThe above exception was the direct cause of the following exception:\n\nTraceback (most recent call last):\n  File \"/vllm-workspace/backend_request_func.py\", line 261, in async_request_openai_completions\n    async for chunk_bytes in response.content:\n  File \"/usr/local/lib/python3.10/dist-packages/aiohttp/streams.py\", line 50, in __anext__\n    rv = await self.read_func()\n  File \"/usr/local/lib/python3.10/dist-packages/aiohttp/streams.py\", line 317, in readline\n    return await self.readuntil()\n  File \"/usr/local/lib/python3.10/dist-packages/aiohttp/streams.py\", line 351, in readuntil\n    await self._wait(\"readuntil\")\n  File \"/usr/local/lib/python3.10/dist-packages/aiohttp/streams.py\", line 312, in _wait\n    await waiter\naiohttp.client_exceptions.ClientPayloadError: Response payload is not completed: <TransferEncodingError: 400, message='Not enough data for satisfy transfer length header.'>\n", "Traceback (most recent call last):\n  File \"/usr/local/lib/python3.10/dist-packages/aiohttp/client_proto.py\", line 94, in connection_lost\n    uncompleted = self._parser.feed_eof()\n  File \"aiohttp/_http_parser.pyx\", line 513, in aiohttp._http_parser.HttpParser.feed_eof\naiohttp.http_exceptions.TransferEncodingError: 400, message:\n  Not enough data for satisfy transfer length header.\n\nThe above exception was the direct cause of the following exception:\n\nTraceback (most recent call last):\n  File \"/vllm-workspace/backend_request_func.py\", line 261, in async_request_openai_completions\n    async for chunk_bytes in response.content:\n  File \"/usr/local/lib/python3.10/dist-packages/aiohttp/streams.py\", line 50, in __anext__\n    rv = await self.read_func()\n  File \"/usr/local/lib/python3.10/dist-packages/aiohttp/streams.py\", line 317, in readline\n    return await self.readuntil()\n  File \"/usr/local/lib/python3.10/dist-packages/aiohttp/streams.py\", line 351, in readuntil\n    await self._wait(\"readuntil\")\n  File \"/usr/local/lib/python3.10/dist-packages/aiohttp/streams.py\", line 312, in _wait\n    await waiter\naiohttp.client_exceptions.ClientPayloadError: Response payload is not completed: <TransferEncodingError: 400, message='Not enough data for satisfy transfer length header.'>\n", "Traceback (most recent call last):\n  File \"/usr/local/lib/python3.10/dist-packages/aiohttp/client_proto.py\", line 94, in connection_lost\n    uncompleted = self._parser.feed_eof()\n  File \"aiohttp/_http_parser.pyx\", line 513, in aiohttp._http_parser.HttpParser.feed_eof\naiohttp.http_exceptions.TransferEncodingError: 400, message:\n  Not enough data for satisfy transfer length header.\n\nThe above exception was the direct cause of the following exception:\n\nTraceback (most recent call last):\n  File \"/vllm-workspace/backend_request_func.py\", line 261, in async_request_openai_completions\n    async for chunk_bytes in response.content:\n  File \"/usr/local/lib/python3.10/dist-packages/aiohttp/streams.py\", line 50, in __anext__\n    rv = await self.read_func()\n  File \"/usr/local/lib/python3.10/dist-packages/aiohttp/streams.py\", line 317, in readline\n    return await self.readuntil()\n  File \"/usr/local/lib/python3.10/dist-packages/aiohttp/streams.py\", line 351, in readuntil\n    await self._wait(\"readuntil\")\n  File \"/usr/local/lib/python3.10/dist-packages/aiohttp/streams.py\", line 312, in _wait\n    await waiter\naiohttp.client_exceptions.ClientPayloadError: Response payload is not completed: <TransferEncodingError: 400, message='Not enough data for satisfy transfer length header.'>\n", "Traceback (most recent call last):\n  File \"/usr/local/lib/python3.10/dist-packages/aiohttp/client_proto.py\", line 94, in connection_lost\n    uncompleted = self._parser.feed_eof()\n  File \"aiohttp/_http_parser.pyx\", line 513, in aiohttp._http_parser.HttpParser.feed_eof\naiohttp.http_exceptions.TransferEncodingError: 400, message:\n  Not enough data for satisfy transfer length header.\n\nThe above exception was the direct cause of the following exception:\n\nTraceback (most recent call last):\n  File \"/vllm-workspace/backend_request_func.py\", line 261, in async_request_openai_completions\n    async for chunk_bytes in response.content:\n  File \"/usr/local/lib/python3.10/dist-packages/aiohttp/streams.py\", line 50, in __anext__\n    rv = await self.read_func()\n  File \"/usr/local/lib/python3.10/dist-packages/aiohttp/streams.py\", line 317, in readline\n    return await self.readuntil()\n  File \"/usr/local/lib/python3.10/dist-packages/aiohttp/streams.py\", line 351, in readuntil\n    await self._wait(\"readuntil\")\n  File \"/usr/local/lib/python3.10/dist-packages/aiohttp/streams.py\", line 312, in _wait\n    await waiter\naiohttp.client_exceptions.ClientPayloadError: Response payload is not completed: <TransferEncodingError: 400, message='Not enough data for satisfy transfer length header.'>\n", "Traceback (most recent call last):\n  File \"/usr/local/lib/python3.10/dist-packages/aiohttp/client_proto.py\", line 94, in connection_lost\n    uncompleted = self._parser.feed_eof()\n  File \"aiohttp/_http_parser.pyx\", line 513, in aiohttp._http_parser.HttpParser.feed_eof\naiohttp.http_exceptions.TransferEncodingError: 400, message:\n  Not enough data for satisfy transfer length header.\n\nThe above exception was the direct cause of the following exception:\n\nTraceback (most recent call last):\n  File \"/vllm-workspace/backend_request_func.py\", line 261, in async_request_openai_completions\n    async for chunk_bytes in response.content:\n  File \"/usr/local/lib/python3.10/dist-packages/aiohttp/streams.py\", line 50, in __anext__\n    rv = await self.read_func()\n  File \"/usr/local/lib/python3.10/dist-packages/aiohttp/streams.py\", line 317, in readline\n    return await self.readuntil()\n  File \"/usr/local/lib/python3.10/dist-packages/aiohttp/streams.py\", line 351, in readuntil\n    await self._wait(\"readuntil\")\n  File \"/usr/local/lib/python3.10/dist-packages/aiohttp/streams.py\", line 312, in _wait\n    await waiter\naiohttp.client_exceptions.ClientPayloadError: Response payload is not completed: <TransferEncodingError: 400, message='Not enough data for satisfy transfer length header.'>\n", "Traceback (most recent call last):\n  File \"/usr/local/lib/python3.10/dist-packages/aiohttp/client_proto.py\", line 94, in connection_lost\n    uncompleted = self._parser.feed_eof()\n  File \"aiohttp/_http_parser.pyx\", line 513, in aiohttp._http_parser.HttpParser.feed_eof\naiohttp.http_exceptions.TransferEncodingError: 400, message:\n  Not enough data for satisfy transfer length header.\n\nThe above exception was the direct cause of the following exception:\n\nTraceback (most recent call last):\n  File \"/vllm-workspace/backend_request_func.py\", line 261, in async_request_openai_completions\n    async for chunk_bytes in response.content:\n  File \"/usr/local/lib/python3.10/dist-packages/aiohttp/streams.py\", line 50, in __anext__\n    rv = await self.read_func()\n  File \"/usr/local/lib/python3.10/dist-packages/aiohttp/streams.py\", line 317, in readline\n    return await self.readuntil()\n  File \"/usr/local/lib/python3.10/dist-packages/aiohttp/streams.py\", line 351, in readuntil\n    await self._wait(\"readuntil\")\n  File \"/usr/local/lib/python3.10/dist-packages/aiohttp/streams.py\", line 312, in _wait\n    await waiter\naiohttp.client_exceptions.ClientPayloadError: Response payload is not completed: <TransferEncodingError: 400, message='Not enough data for satisfy transfer length header.'>\n", "Traceback (most recent call last):\n  File \"/usr/local/lib/python3.10/dist-packages/aiohttp/client_proto.py\", line 94, in connection_lost\n    uncompleted = self._parser.feed_eof()\n  File \"aiohttp/_http_parser.pyx\", line 513, in aiohttp._http_parser.HttpParser.feed_eof\naiohttp.http_exceptions.TransferEncodingError: 400, message:\n  Not enough data for satisfy transfer length header.\n\nThe above exception was the direct cause of the following exception:\n\nTraceback (most recent call last):\n  File \"/vllm-workspace/backend_request_func.py\", line 261, in async_request_openai_completions\n    async for chunk_bytes in response.content:\n  File \"/usr/local/lib/python3.10/dist-packages/aiohttp/streams.py\", line 50, in __anext__\n    rv = await self.read_func()\n  File \"/usr/local/lib/python3.10/dist-packages/aiohttp/streams.py\", line 317, in readline\n    return await self.readuntil()\n  File \"/usr/local/lib/python3.10/dist-packages/aiohttp/streams.py\", line 351, in readuntil\n    await self._wait(\"readuntil\")\n  File \"/usr/local/lib/python3.10/dist-packages/aiohttp/streams.py\", line 312, in _wait\n    await waiter\naiohttp.client_exceptions.ClientPayloadError: Response payload is not completed: <TransferEncodingError: 400, message='Not enough data for satisfy transfer length header.'>\n", "Traceback (most recent call last):\n  File \"/usr/local/lib/python3.10/dist-packages/aiohttp/client_proto.py\", line 94, in connection_lost\n    uncompleted = self._parser.feed_eof()\n  File \"aiohttp/_http_parser.pyx\", line 513, in aiohttp._http_parser.HttpParser.feed_eof\naiohttp.http_exceptions.TransferEncodingError: 400, message:\n  Not enough data for satisfy transfer length header.\n\nThe above exception was the direct cause of the following exception:\n\nTraceback (most recent call last):\n  File \"/vllm-workspace/backend_request_func.py\", line 261, in async_request_openai_completions\n    async for chunk_bytes in response.content:\n  File \"/usr/local/lib/python3.10/dist-packages/aiohttp/streams.py\", line 50, in __anext__\n    rv = await self.read_func()\n  File \"/usr/local/lib/python3.10/dist-packages/aiohttp/streams.py\", line 317, in readline\n    return await self.readuntil()\n  File \"/usr/local/lib/python3.10/dist-packages/aiohttp/streams.py\", line 351, in readuntil\n    await self._wait(\"readuntil\")\n  File \"/usr/local/lib/python3.10/dist-packages/aiohttp/streams.py\", line 312, in _wait\n    await waiter\naiohttp.client_exceptions.ClientPayloadError: Response payload is not completed: <TransferEncodingError: 400, message='Not enough data for satisfy transfer length header.'>\n", "Traceback (most recent call last):\n  File \"/usr/local/lib/python3.10/dist-packages/aiohttp/client_proto.py\", line 94, in connection_lost\n    uncompleted = self._parser.feed_eof()\n  File \"aiohttp/_http_parser.pyx\", line 513, in aiohttp._http_parser.HttpParser.feed_eof\naiohttp.http_exceptions.TransferEncodingError: 400, message:\n  Not enough data for satisfy transfer length header.\n\nThe above exception was the direct cause of the following exception:\n\nTraceback (most recent call last):\n  File \"/vllm-workspace/backend_request_func.py\", line 261, in async_request_openai_completions\n    async for chunk_bytes in response.content:\n  File \"/usr/local/lib/python3.10/dist-packages/aiohttp/streams.py\", line 50, in __anext__\n    rv = await self.read_func()\n  File \"/usr/local/lib/python3.10/dist-packages/aiohttp/streams.py\", line 317, in readline\n    return await self.readuntil()\n  File \"/usr/local/lib/python3.10/dist-packages/aiohttp/streams.py\", line 351, in readuntil\n    await self._wait(\"readuntil\")\n  File \"/usr/local/lib/python3.10/dist-packages/aiohttp/streams.py\", line 312, in _wait\n    await waiter\naiohttp.client_exceptions.ClientPayloadError: Response payload is not completed: <TransferEncodingError: 400, message='Not enough data for satisfy transfer length header.'>\n", "Traceback (most recent call last):\n  File \"/usr/local/lib/python3.10/dist-packages/aiohttp/client_proto.py\", line 94, in connection_lost\n    uncompleted = self._parser.feed_eof()\n  File \"aiohttp/_http_parser.pyx\", line 513, in aiohttp._http_parser.HttpParser.feed_eof\naiohttp.http_exceptions.TransferEncodingError: 400, message:\n  Not enough data for satisfy transfer length header.\n\nThe above exception was the direct cause of the following exception:\n\nTraceback (most recent call last):\n  File \"/vllm-workspace/backend_request_func.py\", line 261, in async_request_openai_completions\n    async for chunk_bytes in response.content:\n  File \"/usr/local/lib/python3.10/dist-packages/aiohttp/streams.py\", line 50, in __anext__\n    rv = await self.read_func()\n  File \"/usr/local/lib/python3.10/dist-packages/aiohttp/streams.py\", line 317, in readline\n    return await self.readuntil()\n  File \"/usr/local/lib/python3.10/dist-packages/aiohttp/streams.py\", line 351, in readuntil\n    await self._wait(\"readuntil\")\n  File \"/usr/local/lib/python3.10/dist-packages/aiohttp/streams.py\", line 312, in _wait\n    await waiter\naiohttp.client_exceptions.ClientPayloadError: Response payload is not completed: <TransferEncodingError: 400, message='Not enough data for satisfy transfer length header.'>\n", "Traceback (most recent call last):\n  File \"/usr/local/lib/python3.10/dist-packages/aiohttp/client_proto.py\", line 94, in connection_lost\n    uncompleted = self._parser.feed_eof()\n  File \"aiohttp/_http_parser.pyx\", line 513, in aiohttp._http_parser.HttpParser.feed_eof\naiohttp.http_exceptions.TransferEncodingError: 400, message:\n  Not enough data for satisfy transfer length header.\n\nThe above exception was the direct cause of the following exception:\n\nTraceback (most recent call last):\n  File \"/vllm-workspace/backend_request_func.py\", line 261, in async_request_openai_completions\n    async for chunk_bytes in response.content:\n  File \"/usr/local/lib/python3.10/dist-packages/aiohttp/streams.py\", line 50, in __anext__\n    rv = await self.read_func()\n  File \"/usr/local/lib/python3.10/dist-packages/aiohttp/streams.py\", line 317, in readline\n    return await self.readuntil()\n  File \"/usr/local/lib/python3.10/dist-packages/aiohttp/streams.py\", line 351, in readuntil\n    await self._wait(\"readuntil\")\n  File \"/usr/local/lib/python3.10/dist-packages/aiohttp/streams.py\", line 312, in _wait\n    await waiter\naiohttp.client_exceptions.ClientPayloadError: Response payload is not completed: <TransferEncodingError: 400, message='Not enough data for satisfy transfer length header.'>\n", "Traceback (most recent call last):\n  File \"/usr/local/lib/python3.10/dist-packages/aiohttp/client_proto.py\", line 94, in connection_lost\n    uncompleted = self._parser.feed_eof()\n  File \"aiohttp/_http_parser.pyx\", line 513, in aiohttp._http_parser.HttpParser.feed_eof\naiohttp.http_exceptions.TransferEncodingError: 400, message:\n  Not enough data for satisfy transfer length header.\n\nThe above exception was the direct cause of the following exception:\n\nTraceback (most recent call last):\n  File \"/vllm-workspace/backend_request_func.py\", line 261, in async_request_openai_completions\n    async for chunk_bytes in response.content:\n  File \"/usr/local/lib/python3.10/dist-packages/aiohttp/streams.py\", line 50, in __anext__\n    rv = await self.read_func()\n  File \"/usr/local/lib/python3.10/dist-packages/aiohttp/streams.py\", line 317, in readline\n    return await self.readuntil()\n  File \"/usr/local/lib/python3.10/dist-packages/aiohttp/streams.py\", line 351, in readuntil\n    await self._wait(\"readuntil\")\n  File \"/usr/local/lib/python3.10/dist-packages/aiohttp/streams.py\", line 312, in _wait\n    await waiter\naiohttp.client_exceptions.ClientPayloadError: Response payload is not completed: <TransferEncodingError: 400, message='Not enough data for satisfy transfer length header.'>\n", "Traceback (most recent call last):\n  File \"/usr/local/lib/python3.10/dist-packages/aiohttp/client_proto.py\", line 94, in connection_lost\n    uncompleted = self._parser.feed_eof()\n  File \"aiohttp/_http_parser.pyx\", line 513, in aiohttp._http_parser.HttpParser.feed_eof\naiohttp.http_exceptions.TransferEncodingError: 400, message:\n  Not enough data for satisfy transfer length header.\n\nThe above exception was the direct cause of the following exception:\n\nTraceback (most recent call last):\n  File \"/vllm-workspace/backend_request_func.py\", line 261, in async_request_openai_completions\n    async for chunk_bytes in response.content:\n  File \"/usr/local/lib/python3.10/dist-packages/aiohttp/streams.py\", line 50, in __anext__\n    rv = await self.read_func()\n  File \"/usr/local/lib/python3.10/dist-packages/aiohttp/streams.py\", line 317, in readline\n    return await self.readuntil()\n  File \"/usr/local/lib/python3.10/dist-packages/aiohttp/streams.py\", line 351, in readuntil\n    await self._wait(\"readuntil\")\n  File \"/usr/local/lib/python3.10/dist-packages/aiohttp/streams.py\", line 312, in _wait\n    await waiter\naiohttp.client_exceptions.ClientPayloadError: Response payload is not completed: <TransferEncodingError: 400, message='Not enough data for satisfy transfer length header.'>\n", "Traceback (most recent call last):\n  File \"/usr/local/lib/python3.10/dist-packages/aiohttp/client_proto.py\", line 94, in connection_lost\n    uncompleted = self._parser.feed_eof()\n  File \"aiohttp/_http_parser.pyx\", line 513, in aiohttp._http_parser.HttpParser.feed_eof\naiohttp.http_exceptions.TransferEncodingError: 400, message:\n  Not enough data for satisfy transfer length header.\n\nThe above exception was the direct cause of the following exception:\n\nTraceback (most recent call last):\n  File \"/vllm-workspace/backend_request_func.py\", line 261, in async_request_openai_completions\n    async for chunk_bytes in response.content:\n  File \"/usr/local/lib/python3.10/dist-packages/aiohttp/streams.py\", line 50, in __anext__\n    rv = await self.read_func()\n  File \"/usr/local/lib/python3.10/dist-packages/aiohttp/streams.py\", line 317, in readline\n    return await self.readuntil()\n  File \"/usr/local/lib/python3.10/dist-packages/aiohttp/streams.py\", line 351, in readuntil\n    await self._wait(\"readuntil\")\n  File \"/usr/local/lib/python3.10/dist-packages/aiohttp/streams.py\", line 312, in _wait\n    await waiter\naiohttp.client_exceptions.ClientPayloadError: Response payload is not completed: <TransferEncodingError: 400, message='Not enough data for satisfy transfer length header.'>\n", "Traceback (most recent call last):\n  File \"/usr/local/lib/python3.10/dist-packages/aiohttp/client_proto.py\", line 94, in connection_lost\n    uncompleted = self._parser.feed_eof()\n  File \"aiohttp/_http_parser.pyx\", line 513, in aiohttp._http_parser.HttpParser.feed_eof\naiohttp.http_exceptions.TransferEncodingError: 400, message:\n  Not enough data for satisfy transfer length header.\n\nThe above exception was the direct cause of the following exception:\n\nTraceback (most recent call last):\n  File \"/vllm-workspace/backend_request_func.py\", line 261, in async_request_openai_completions\n    async for chunk_bytes in response.content:\n  File \"/usr/local/lib/python3.10/dist-packages/aiohttp/streams.py\", line 50, in __anext__\n    rv = await self.read_func()\n  File \"/usr/local/lib/python3.10/dist-packages/aiohttp/streams.py\", line 317, in readline\n    return await self.readuntil()\n  File \"/usr/local/lib/python3.10/dist-packages/aiohttp/streams.py\", line 351, in readuntil\n    await self._wait(\"readuntil\")\n  File \"/usr/local/lib/python3.10/dist-packages/aiohttp/streams.py\", line 312, in _wait\n    await waiter\naiohttp.client_exceptions.ClientPayloadError: Response payload is not completed: <TransferEncodingError: 400, message='Not enough data for satisfy transfer length header.'>\n", "Traceback (most recent call last):\n  File \"/usr/local/lib/python3.10/dist-packages/aiohttp/client_proto.py\", line 94, in connection_lost\n    uncompleted = self._parser.feed_eof()\n  File \"aiohttp/_http_parser.pyx\", line 513, in aiohttp._http_parser.HttpParser.feed_eof\naiohttp.http_exceptions.TransferEncodingError: 400, message:\n  Not enough data for satisfy transfer length header.\n\nThe above exception was the direct cause of the following exception:\n\nTraceback (most recent call last):\n  File \"/vllm-workspace/backend_request_func.py\", line 261, in async_request_openai_completions\n    async for chunk_bytes in response.content:\n  File \"/usr/local/lib/python3.10/dist-packages/aiohttp/streams.py\", line 50, in __anext__\n    rv = await self.read_func()\n  File \"/usr/local/lib/python3.10/dist-packages/aiohttp/streams.py\", line 317, in readline\n    return await self.readuntil()\n  File \"/usr/local/lib/python3.10/dist-packages/aiohttp/streams.py\", line 351, in readuntil\n    await self._wait(\"readuntil\")\n  File \"/usr/local/lib/python3.10/dist-packages/aiohttp/streams.py\", line 312, in _wait\n    await waiter\naiohttp.client_exceptions.ClientPayloadError: Response payload is not completed: <TransferEncodingError: 400, message='Not enough data for satisfy transfer length header.'>\n", "Traceback (most recent call last):\n  File \"/usr/local/lib/python3.10/dist-packages/aiohttp/client_proto.py\", line 94, in connection_lost\n    uncompleted = self._parser.feed_eof()\n  File \"aiohttp/_http_parser.pyx\", line 513, in aiohttp._http_parser.HttpParser.feed_eof\naiohttp.http_exceptions.TransferEncodingError: 400, message:\n  Not enough data for satisfy transfer length header.\n\nThe above exception was the direct cause of the following exception:\n\nTraceback (most recent call last):\n  File \"/vllm-workspace/backend_request_func.py\", line 261, in async_request_openai_completions\n    async for chunk_bytes in response.content:\n  File \"/usr/local/lib/python3.10/dist-packages/aiohttp/streams.py\", line 50, in __anext__\n    rv = await self.read_func()\n  File \"/usr/local/lib/python3.10/dist-packages/aiohttp/streams.py\", line 317, in readline\n    return await self.readuntil()\n  File \"/usr/local/lib/python3.10/dist-packages/aiohttp/streams.py\", line 351, in readuntil\n    await self._wait(\"readuntil\")\n  File \"/usr/local/lib/python3.10/dist-packages/aiohttp/streams.py\", line 312, in _wait\n    await waiter\naiohttp.client_exceptions.ClientPayloadError: Response payload is not completed: <TransferEncodingError: 400, message='Not enough data for satisfy transfer length header.'>\n", "Traceback (most recent call last):\n  File \"/usr/local/lib/python3.10/dist-packages/aiohttp/client_proto.py\", line 94, in connection_lost\n    uncompleted = self._parser.feed_eof()\n  File \"aiohttp/_http_parser.pyx\", line 513, in aiohttp._http_parser.HttpParser.feed_eof\naiohttp.http_exceptions.TransferEncodingError: 400, message:\n  Not enough data for satisfy transfer length header.\n\nThe above exception was the direct cause of the following exception:\n\nTraceback (most recent call last):\n  File \"/vllm-workspace/backend_request_func.py\", line 261, in async_request_openai_completions\n    async for chunk_bytes in response.content:\n  File \"/usr/local/lib/python3.10/dist-packages/aiohttp/streams.py\", line 50, in __anext__\n    rv = await self.read_func()\n  File \"/usr/local/lib/python3.10/dist-packages/aiohttp/streams.py\", line 317, in readline\n    return await self.readuntil()\n  File \"/usr/local/lib/python3.10/dist-packages/aiohttp/streams.py\", line 351, in readuntil\n    await self._wait(\"readuntil\")\n  File \"/usr/local/lib/python3.10/dist-packages/aiohttp/streams.py\", line 312, in _wait\n    await waiter\naiohttp.client_exceptions.ClientPayloadError: Response payload is not completed: <TransferEncodingError: 400, message='Not enough data for satisfy transfer length header.'>\n", "Traceback (most recent call last):\n  File \"/usr/local/lib/python3.10/dist-packages/aiohttp/client_proto.py\", line 94, in connection_lost\n    uncompleted = self._parser.feed_eof()\n  File \"aiohttp/_http_parser.pyx\", line 513, in aiohttp._http_parser.HttpParser.feed_eof\naiohttp.http_exceptions.TransferEncodingError: 400, message:\n  Not enough data for satisfy transfer length header.\n\nThe above exception was the direct cause of the following exception:\n\nTraceback (most recent call last):\n  File \"/vllm-workspace/backend_request_func.py\", line 261, in async_request_openai_completions\n    async for chunk_bytes in response.content:\n  File \"/usr/local/lib/python3.10/dist-packages/aiohttp/streams.py\", line 50, in __anext__\n    rv = await self.read_func()\n  File \"/usr/local/lib/python3.10/dist-packages/aiohttp/streams.py\", line 317, in readline\n    return await self.readuntil()\n  File \"/usr/local/lib/python3.10/dist-packages/aiohttp/streams.py\", line 351, in readuntil\n    await self._wait(\"readuntil\")\n  File \"/usr/local/lib/python3.10/dist-packages/aiohttp/streams.py\", line 312, in _wait\n    await waiter\naiohttp.client_exceptions.ClientPayloadError: Response payload is not completed: <TransferEncodingError: 400, message='Not enough data for satisfy transfer length header.'>\n", "Traceback (most recent call last):\n  File \"/usr/local/lib/python3.10/dist-packages/aiohttp/client_proto.py\", line 94, in connection_lost\n    uncompleted = self._parser.feed_eof()\n  File \"aiohttp/_http_parser.pyx\", line 513, in aiohttp._http_parser.HttpParser.feed_eof\naiohttp.http_exceptions.TransferEncodingError: 400, message:\n  Not enough data for satisfy transfer length header.\n\nThe above exception was the direct cause of the following exception:\n\nTraceback (most recent call last):\n  File \"/vllm-workspace/backend_request_func.py\", line 261, in async_request_openai_completions\n    async for chunk_bytes in response.content:\n  File \"/usr/local/lib/python3.10/dist-packages/aiohttp/streams.py\", line 50, in __anext__\n    rv = await self.read_func()\n  File \"/usr/local/lib/python3.10/dist-packages/aiohttp/streams.py\", line 317, in readline\n    return await self.readuntil()\n  File \"/usr/local/lib/python3.10/dist-packages/aiohttp/streams.py\", line 351, in readuntil\n    await self._wait(\"readuntil\")\n  File \"/usr/local/lib/python3.10/dist-packages/aiohttp/streams.py\", line 312, in _wait\n    await waiter\naiohttp.client_exceptions.ClientPayloadError: Response payload is not completed: <TransferEncodingError: 400, message='Not enough data for satisfy transfer length header.'>\n", "Traceback (most recent call last):\n  File \"/usr/local/lib/python3.10/dist-packages/aiohttp/client_proto.py\", line 94, in connection_lost\n    uncompleted = self._parser.feed_eof()\n  File \"aiohttp/_http_parser.pyx\", line 513, in aiohttp._http_parser.HttpParser.feed_eof\naiohttp.http_exceptions.TransferEncodingError: 400, message:\n  Not enough data for satisfy transfer length header.\n\nThe above exception was the direct cause of the following exception:\n\nTraceback (most recent call last):\n  File \"/vllm-workspace/backend_request_func.py\", line 261, in async_request_openai_completions\n    async for chunk_bytes in response.content:\n  File \"/usr/local/lib/python3.10/dist-packages/aiohttp/streams.py\", line 50, in __anext__\n    rv = await self.read_func()\n  File \"/usr/local/lib/python3.10/dist-packages/aiohttp/streams.py\", line 317, in readline\n    return await self.readuntil()\n  File \"/usr/local/lib/python3.10/dist-packages/aiohttp/streams.py\", line 351, in readuntil\n    await self._wait(\"readuntil\")\n  File \"/usr/local/lib/python3.10/dist-packages/aiohttp/streams.py\", line 312, in _wait\n    await waiter\naiohttp.client_exceptions.ClientPayloadError: Response payload is not completed: <TransferEncodingError: 400, message='Not enough data for satisfy transfer length header.'>\n", "Traceback (most recent call last):\n  File \"/usr/local/lib/python3.10/dist-packages/aiohttp/client_proto.py\", line 94, in connection_lost\n    uncompleted = self._parser.feed_eof()\n  File \"aiohttp/_http_parser.pyx\", line 513, in aiohttp._http_parser.HttpParser.feed_eof\naiohttp.http_exceptions.TransferEncodingError: 400, message:\n  Not enough data for satisfy transfer length header.\n\nThe above exception was the direct cause of the following exception:\n\nTraceback (most recent call last):\n  File \"/vllm-workspace/backend_request_func.py\", line 261, in async_request_openai_completions\n    async for chunk_bytes in response.content:\n  File \"/usr/local/lib/python3.10/dist-packages/aiohttp/streams.py\", line 50, in __anext__\n    rv = await self.read_func()\n  File \"/usr/local/lib/python3.10/dist-packages/aiohttp/streams.py\", line 317, in readline\n    return await self.readuntil()\n  File \"/usr/local/lib/python3.10/dist-packages/aiohttp/streams.py\", line 351, in readuntil\n    await self._wait(\"readuntil\")\n  File \"/usr/local/lib/python3.10/dist-packages/aiohttp/streams.py\", line 312, in _wait\n    await waiter\naiohttp.client_exceptions.ClientPayloadError: Response payload is not completed: <TransferEncodingError: 400, message='Not enough data for satisfy transfer length header.'>\n", "Traceback (most recent call last):\n  File \"/usr/local/lib/python3.10/dist-packages/aiohttp/client_proto.py\", line 94, in connection_lost\n    uncompleted = self._parser.feed_eof()\n  File \"aiohttp/_http_parser.pyx\", line 513, in aiohttp._http_parser.HttpParser.feed_eof\naiohttp.http_exceptions.TransferEncodingError: 400, message:\n  Not enough data for satisfy transfer length header.\n\nThe above exception was the direct cause of the following exception:\n\nTraceback (most recent call last):\n  File \"/vllm-workspace/backend_request_func.py\", line 261, in async_request_openai_completions\n    async for chunk_bytes in response.content:\n  File \"/usr/local/lib/python3.10/dist-packages/aiohttp/streams.py\", line 50, in __anext__\n    rv = await self.read_func()\n  File \"/usr/local/lib/python3.10/dist-packages/aiohttp/streams.py\", line 317, in readline\n    return await self.readuntil()\n  File \"/usr/local/lib/python3.10/dist-packages/aiohttp/streams.py\", line 351, in readuntil\n    await self._wait(\"readuntil\")\n  File \"/usr/local/lib/python3.10/dist-packages/aiohttp/streams.py\", line 312, in _wait\n    await waiter\naiohttp.client_exceptions.ClientPayloadError: Response payload is not completed: <TransferEncodingError: 400, message='Not enough data for satisfy transfer length header.'>\n", "Traceback (most recent call last):\n  File \"/usr/local/lib/python3.10/dist-packages/aiohttp/client_proto.py\", line 94, in connection_lost\n    uncompleted = self._parser.feed_eof()\n  File \"aiohttp/_http_parser.pyx\", line 513, in aiohttp._http_parser.HttpParser.feed_eof\naiohttp.http_exceptions.TransferEncodingError: 400, message:\n  Not enough data for satisfy transfer length header.\n\nThe above exception was the direct cause of the following exception:\n\nTraceback (most recent call last):\n  File \"/vllm-workspace/backend_request_func.py\", line 261, in async_request_openai_completions\n    async for chunk_bytes in response.content:\n  File \"/usr/local/lib/python3.10/dist-packages/aiohttp/streams.py\", line 50, in __anext__\n    rv = await self.read_func()\n  File \"/usr/local/lib/python3.10/dist-packages/aiohttp/streams.py\", line 317, in readline\n    return await self.readuntil()\n  File \"/usr/local/lib/python3.10/dist-packages/aiohttp/streams.py\", line 351, in readuntil\n    await self._wait(\"readuntil\")\n  File \"/usr/local/lib/python3.10/dist-packages/aiohttp/streams.py\", line 312, in _wait\n    await waiter\naiohttp.client_exceptions.ClientPayloadError: Response payload is not completed: <TransferEncodingError: 400, message='Not enough data for satisfy transfer length header.'>\n", "Traceback (most recent call last):\n  File \"/usr/local/lib/python3.10/dist-packages/aiohttp/client_proto.py\", line 94, in connection_lost\n    uncompleted = self._parser.feed_eof()\n  File \"aiohttp/_http_parser.pyx\", line 513, in aiohttp._http_parser.HttpParser.feed_eof\naiohttp.http_exceptions.TransferEncodingError: 400, message:\n  Not enough data for satisfy transfer length header.\n\nThe above exception was the direct cause of the following exception:\n\nTraceback (most recent call last):\n  File \"/vllm-workspace/backend_request_func.py\", line 261, in async_request_openai_completions\n    async for chunk_bytes in response.content:\n  File \"/usr/local/lib/python3.10/dist-packages/aiohttp/streams.py\", line 50, in __anext__\n    rv = await self.read_func()\n  File \"/usr/local/lib/python3.10/dist-packages/aiohttp/streams.py\", line 317, in readline\n    return await self.readuntil()\n  File \"/usr/local/lib/python3.10/dist-packages/aiohttp/streams.py\", line 351, in readuntil\n    await self._wait(\"readuntil\")\n  File \"/usr/local/lib/python3.10/dist-packages/aiohttp/streams.py\", line 312, in _wait\n    await waiter\naiohttp.client_exceptions.ClientPayloadError: Response payload is not completed: <TransferEncodingError: 400, message='Not enough data for satisfy transfer length header.'>\n", "Traceback (most recent call last):\n  File \"/usr/local/lib/python3.10/dist-packages/aiohttp/client_proto.py\", line 94, in connection_lost\n    uncompleted = self._parser.feed_eof()\n  File \"aiohttp/_http_parser.pyx\", line 513, in aiohttp._http_parser.HttpParser.feed_eof\naiohttp.http_exceptions.TransferEncodingError: 400, message:\n  Not enough data for satisfy transfer length header.\n\nThe above exception was the direct cause of the following exception:\n\nTraceback (most recent call last):\n  File \"/vllm-workspace/backend_request_func.py\", line 261, in async_request_openai_completions\n    async for chunk_bytes in response.content:\n  File \"/usr/local/lib/python3.10/dist-packages/aiohttp/streams.py\", line 50, in __anext__\n    rv = await self.read_func()\n  File \"/usr/local/lib/python3.10/dist-packages/aiohttp/streams.py\", line 317, in readline\n    return await self.readuntil()\n  File \"/usr/local/lib/python3.10/dist-packages/aiohttp/streams.py\", line 351, in readuntil\n    await self._wait(\"readuntil\")\n  File \"/usr/local/lib/python3.10/dist-packages/aiohttp/streams.py\", line 312, in _wait\n    await waiter\naiohttp.client_exceptions.ClientPayloadError: Response payload is not completed: <TransferEncodingError: 400, message='Not enough data for satisfy transfer length header.'>\n", "Traceback (most recent call last):\n  File \"/usr/local/lib/python3.10/dist-packages/aiohttp/client_proto.py\", line 94, in connection_lost\n    uncompleted = self._parser.feed_eof()\n  File \"aiohttp/_http_parser.pyx\", line 513, in aiohttp._http_parser.HttpParser.feed_eof\naiohttp.http_exceptions.TransferEncodingError: 400, message:\n  Not enough data for satisfy transfer length header.\n\nThe above exception was the direct cause of the following exception:\n\nTraceback (most recent call last):\n  File \"/vllm-workspace/backend_request_func.py\", line 261, in async_request_openai_completions\n    async for chunk_bytes in response.content:\n  File \"/usr/local/lib/python3.10/dist-packages/aiohttp/streams.py\", line 50, in __anext__\n    rv = await self.read_func()\n  File \"/usr/local/lib/python3.10/dist-packages/aiohttp/streams.py\", line 317, in readline\n    return await self.readuntil()\n  File \"/usr/local/lib/python3.10/dist-packages/aiohttp/streams.py\", line 351, in readuntil\n    await self._wait(\"readuntil\")\n  File \"/usr/local/lib/python3.10/dist-packages/aiohttp/streams.py\", line 312, in _wait\n    await waiter\naiohttp.client_exceptions.ClientPayloadError: Response payload is not completed: <TransferEncodingError: 400, message='Not enough data for satisfy transfer length header.'>\n", "Traceback (most recent call last):\n  File \"/usr/local/lib/python3.10/dist-packages/aiohttp/client_proto.py\", line 94, in connection_lost\n    uncompleted = self._parser.feed_eof()\n  File \"aiohttp/_http_parser.pyx\", line 513, in aiohttp._http_parser.HttpParser.feed_eof\naiohttp.http_exceptions.TransferEncodingError: 400, message:\n  Not enough data for satisfy transfer length header.\n\nThe above exception was the direct cause of the following exception:\n\nTraceback (most recent call last):\n  File \"/vllm-workspace/backend_request_func.py\", line 261, in async_request_openai_completions\n    async for chunk_bytes in response.content:\n  File \"/usr/local/lib/python3.10/dist-packages/aiohttp/streams.py\", line 50, in __anext__\n    rv = await self.read_func()\n  File \"/usr/local/lib/python3.10/dist-packages/aiohttp/streams.py\", line 317, in readline\n    return await self.readuntil()\n  File \"/usr/local/lib/python3.10/dist-packages/aiohttp/streams.py\", line 351, in readuntil\n    await self._wait(\"readuntil\")\n  File \"/usr/local/lib/python3.10/dist-packages/aiohttp/streams.py\", line 312, in _wait\n    await waiter\naiohttp.client_exceptions.ClientPayloadError: Response payload is not completed: <TransferEncodingError: 400, message='Not enough data for satisfy transfer length header.'>\n", "Traceback (most recent call last):\n  File \"/usr/local/lib/python3.10/dist-packages/aiohttp/client_proto.py\", line 94, in connection_lost\n    uncompleted = self._parser.feed_eof()\n  File \"aiohttp/_http_parser.pyx\", line 513, in aiohttp._http_parser.HttpParser.feed_eof\naiohttp.http_exceptions.TransferEncodingError: 400, message:\n  Not enough data for satisfy transfer length header.\n\nThe above exception was the direct cause of the following exception:\n\nTraceback (most recent call last):\n  File \"/vllm-workspace/backend_request_func.py\", line 261, in async_request_openai_completions\n    async for chunk_bytes in response.content:\n  File \"/usr/local/lib/python3.10/dist-packages/aiohttp/streams.py\", line 50, in __anext__\n    rv = await self.read_func()\n  File \"/usr/local/lib/python3.10/dist-packages/aiohttp/streams.py\", line 317, in readline\n    return await self.readuntil()\n  File \"/usr/local/lib/python3.10/dist-packages/aiohttp/streams.py\", line 351, in readuntil\n    await self._wait(\"readuntil\")\n  File \"/usr/local/lib/python3.10/dist-packages/aiohttp/streams.py\", line 312, in _wait\n    await waiter\naiohttp.client_exceptions.ClientPayloadError: Response payload is not completed: <TransferEncodingError: 400, message='Not enough data for satisfy transfer length header.'>\n", "Traceback (most recent call last):\n  File \"/usr/local/lib/python3.10/dist-packages/aiohttp/client_proto.py\", line 94, in connection_lost\n    uncompleted = self._parser.feed_eof()\n  File \"aiohttp/_http_parser.pyx\", line 513, in aiohttp._http_parser.HttpParser.feed_eof\naiohttp.http_exceptions.TransferEncodingError: 400, message:\n  Not enough data for satisfy transfer length header.\n\nThe above exception was the direct cause of the following exception:\n\nTraceback (most recent call last):\n  File \"/vllm-workspace/backend_request_func.py\", line 261, in async_request_openai_completions\n    async for chunk_bytes in response.content:\n  File \"/usr/local/lib/python3.10/dist-packages/aiohttp/streams.py\", line 50, in __anext__\n    rv = await self.read_func()\n  File \"/usr/local/lib/python3.10/dist-packages/aiohttp/streams.py\", line 317, in readline\n    return await self.readuntil()\n  File \"/usr/local/lib/python3.10/dist-packages/aiohttp/streams.py\", line 351, in readuntil\n    await self._wait(\"readuntil\")\n  File \"/usr/local/lib/python3.10/dist-packages/aiohttp/streams.py\", line 312, in _wait\n    await waiter\naiohttp.client_exceptions.ClientPayloadError: Response payload is not completed: <TransferEncodingError: 400, message='Not enough data for satisfy transfer length header.'>\n", "Traceback (most recent call last):\n  File \"/usr/local/lib/python3.10/dist-packages/aiohttp/client_proto.py\", line 94, in connection_lost\n    uncompleted = self._parser.feed_eof()\n  File \"aiohttp/_http_parser.pyx\", line 513, in aiohttp._http_parser.HttpParser.feed_eof\naiohttp.http_exceptions.TransferEncodingError: 400, message:\n  Not enough data for satisfy transfer length header.\n\nThe above exception was the direct cause of the following exception:\n\nTraceback (most recent call last):\n  File \"/vllm-workspace/backend_request_func.py\", line 261, in async_request_openai_completions\n    async for chunk_bytes in response.content:\n  File \"/usr/local/lib/python3.10/dist-packages/aiohttp/streams.py\", line 50, in __anext__\n    rv = await self.read_func()\n  File \"/usr/local/lib/python3.10/dist-packages/aiohttp/streams.py\", line 317, in readline\n    return await self.readuntil()\n  File \"/usr/local/lib/python3.10/dist-packages/aiohttp/streams.py\", line 351, in readuntil\n    await self._wait(\"readuntil\")\n  File \"/usr/local/lib/python3.10/dist-packages/aiohttp/streams.py\", line 312, in _wait\n    await waiter\naiohttp.client_exceptions.ClientPayloadError: Response payload is not completed: <TransferEncodingError: 400, message='Not enough data for satisfy transfer length header.'>\n", "Traceback (most recent call last):\n  File \"/usr/local/lib/python3.10/dist-packages/aiohttp/client_proto.py\", line 94, in connection_lost\n    uncompleted = self._parser.feed_eof()\n  File \"aiohttp/_http_parser.pyx\", line 513, in aiohttp._http_parser.HttpParser.feed_eof\naiohttp.http_exceptions.TransferEncodingError: 400, message:\n  Not enough data for satisfy transfer length header.\n\nThe above exception was the direct cause of the following exception:\n\nTraceback (most recent call last):\n  File \"/vllm-workspace/backend_request_func.py\", line 261, in async_request_openai_completions\n    async for chunk_bytes in response.content:\n  File \"/usr/local/lib/python3.10/dist-packages/aiohttp/streams.py\", line 50, in __anext__\n    rv = await self.read_func()\n  File \"/usr/local/lib/python3.10/dist-packages/aiohttp/streams.py\", line 317, in readline\n    return await self.readuntil()\n  File \"/usr/local/lib/python3.10/dist-packages/aiohttp/streams.py\", line 351, in readuntil\n    await self._wait(\"readuntil\")\n  File \"/usr/local/lib/python3.10/dist-packages/aiohttp/streams.py\", line 312, in _wait\n    await waiter\naiohttp.client_exceptions.ClientPayloadError: Response payload is not completed: <TransferEncodingError: 400, message='Not enough data for satisfy transfer length header.'>\n", "Traceback (most recent call last):\n  File \"/usr/local/lib/python3.10/dist-packages/aiohttp/client_proto.py\", line 94, in connection_lost\n    uncompleted = self._parser.feed_eof()\n  File \"aiohttp/_http_parser.pyx\", line 513, in aiohttp._http_parser.HttpParser.feed_eof\naiohttp.http_exceptions.TransferEncodingError: 400, message:\n  Not enough data for satisfy transfer length header.\n\nThe above exception was the direct cause of the following exception:\n\nTraceback (most recent call last):\n  File \"/vllm-workspace/backend_request_func.py\", line 261, in async_request_openai_completions\n    async for chunk_bytes in response.content:\n  File \"/usr/local/lib/python3.10/dist-packages/aiohttp/streams.py\", line 50, in __anext__\n    rv = await self.read_func()\n  File \"/usr/local/lib/python3.10/dist-packages/aiohttp/streams.py\", line 317, in readline\n    return await self.readuntil()\n  File \"/usr/local/lib/python3.10/dist-packages/aiohttp/streams.py\", line 351, in readuntil\n    await self._wait(\"readuntil\")\n  File \"/usr/local/lib/python3.10/dist-packages/aiohttp/streams.py\", line 312, in _wait\n    await waiter\naiohttp.client_exceptions.ClientPayloadError: Response payload is not completed: <TransferEncodingError: 400, message='Not enough data for satisfy transfer length header.'>\n", "Traceback (most recent call last):\n  File \"/usr/local/lib/python3.10/dist-packages/aiohttp/client_proto.py\", line 94, in connection_lost\n    uncompleted = self._parser.feed_eof()\n  File \"aiohttp/_http_parser.pyx\", line 513, in aiohttp._http_parser.HttpParser.feed_eof\naiohttp.http_exceptions.TransferEncodingError: 400, message:\n  Not enough data for satisfy transfer length header.\n\nThe above exception was the direct cause of the following exception:\n\nTraceback (most recent call last):\n  File \"/vllm-workspace/backend_request_func.py\", line 261, in async_request_openai_completions\n    async for chunk_bytes in response.content:\n  File \"/usr/local/lib/python3.10/dist-packages/aiohttp/streams.py\", line 50, in __anext__\n    rv = await self.read_func()\n  File \"/usr/local/lib/python3.10/dist-packages/aiohttp/streams.py\", line 317, in readline\n    return await self.readuntil()\n  File \"/usr/local/lib/python3.10/dist-packages/aiohttp/streams.py\", line 351, in readuntil\n    await self._wait(\"readuntil\")\n  File \"/usr/local/lib/python3.10/dist-packages/aiohttp/streams.py\", line 312, in _wait\n    await waiter\naiohttp.client_exceptions.ClientPayloadError: Response payload is not completed: <TransferEncodingError: 400, message='Not enough data for satisfy transfer length header.'>\n", "Traceback (most recent call last):\n  File \"/usr/local/lib/python3.10/dist-packages/aiohttp/client_proto.py\", line 94, in connection_lost\n    uncompleted = self._parser.feed_eof()\n  File \"aiohttp/_http_parser.pyx\", line 513, in aiohttp._http_parser.HttpParser.feed_eof\naiohttp.http_exceptions.TransferEncodingError: 400, message:\n  Not enough data for satisfy transfer length header.\n\nThe above exception was the direct cause of the following exception:\n\nTraceback (most recent call last):\n  File \"/vllm-workspace/backend_request_func.py\", line 261, in async_request_openai_completions\n    async for chunk_bytes in response.content:\n  File \"/usr/local/lib/python3.10/dist-packages/aiohttp/streams.py\", line 50, in __anext__\n    rv = await self.read_func()\n  File \"/usr/local/lib/python3.10/dist-packages/aiohttp/streams.py\", line 317, in readline\n    return await self.readuntil()\n  File \"/usr/local/lib/python3.10/dist-packages/aiohttp/streams.py\", line 351, in readuntil\n    await self._wait(\"readuntil\")\n  File \"/usr/local/lib/python3.10/dist-packages/aiohttp/streams.py\", line 312, in _wait\n    await waiter\naiohttp.client_exceptions.ClientPayloadError: Response payload is not completed: <TransferEncodingError: 400, message='Not enough data for satisfy transfer length header.'>\n", "Traceback (most recent call last):\n  File \"/usr/local/lib/python3.10/dist-packages/aiohttp/client_proto.py\", line 94, in connection_lost\n    uncompleted = self._parser.feed_eof()\n  File \"aiohttp/_http_parser.pyx\", line 513, in aiohttp._http_parser.HttpParser.feed_eof\naiohttp.http_exceptions.TransferEncodingError: 400, message:\n  Not enough data for satisfy transfer length header.\n\nThe above exception was the direct cause of the following exception:\n\nTraceback (most recent call last):\n  File \"/vllm-workspace/backend_request_func.py\", line 261, in async_request_openai_completions\n    async for chunk_bytes in response.content:\n  File \"/usr/local/lib/python3.10/dist-packages/aiohttp/streams.py\", line 50, in __anext__\n    rv = await self.read_func()\n  File \"/usr/local/lib/python3.10/dist-packages/aiohttp/streams.py\", line 317, in readline\n    return await self.readuntil()\n  File \"/usr/local/lib/python3.10/dist-packages/aiohttp/streams.py\", line 351, in readuntil\n    await self._wait(\"readuntil\")\n  File \"/usr/local/lib/python3.10/dist-packages/aiohttp/streams.py\", line 312, in _wait\n    await waiter\naiohttp.client_exceptions.ClientPayloadError: Response payload is not completed: <TransferEncodingError: 400, message='Not enough data for satisfy transfer length header.'>\n", "Traceback (most recent call last):\n  File \"/usr/local/lib/python3.10/dist-packages/aiohttp/client_proto.py\", line 94, in connection_lost\n    uncompleted = self._parser.feed_eof()\n  File \"aiohttp/_http_parser.pyx\", line 513, in aiohttp._http_parser.HttpParser.feed_eof\naiohttp.http_exceptions.TransferEncodingError: 400, message:\n  Not enough data for satisfy transfer length header.\n\nThe above exception was the direct cause of the following exception:\n\nTraceback (most recent call last):\n  File \"/vllm-workspace/backend_request_func.py\", line 261, in async_request_openai_completions\n    async for chunk_bytes in response.content:\n  File \"/usr/local/lib/python3.10/dist-packages/aiohttp/streams.py\", line 50, in __anext__\n    rv = await self.read_func()\n  File \"/usr/local/lib/python3.10/dist-packages/aiohttp/streams.py\", line 317, in readline\n    return await self.readuntil()\n  File \"/usr/local/lib/python3.10/dist-packages/aiohttp/streams.py\", line 351, in readuntil\n    await self._wait(\"readuntil\")\n  File \"/usr/local/lib/python3.10/dist-packages/aiohttp/streams.py\", line 312, in _wait\n    await waiter\naiohttp.client_exceptions.ClientPayloadError: Response payload is not completed: <TransferEncodingError: 400, message='Not enough data for satisfy transfer length header.'>\n", "Traceback (most recent call last):\n  File \"/usr/local/lib/python3.10/dist-packages/aiohttp/client_proto.py\", line 94, in connection_lost\n    uncompleted = self._parser.feed_eof()\n  File \"aiohttp/_http_parser.pyx\", line 513, in aiohttp._http_parser.HttpParser.feed_eof\naiohttp.http_exceptions.TransferEncodingError: 400, message:\n  Not enough data for satisfy transfer length header.\n\nThe above exception was the direct cause of the following exception:\n\nTraceback (most recent call last):\n  File \"/vllm-workspace/backend_request_func.py\", line 261, in async_request_openai_completions\n    async for chunk_bytes in response.content:\n  File \"/usr/local/lib/python3.10/dist-packages/aiohttp/streams.py\", line 50, in __anext__\n    rv = await self.read_func()\n  File \"/usr/local/lib/python3.10/dist-packages/aiohttp/streams.py\", line 317, in readline\n    return await self.readuntil()\n  File \"/usr/local/lib/python3.10/dist-packages/aiohttp/streams.py\", line 351, in readuntil\n    await self._wait(\"readuntil\")\n  File \"/usr/local/lib/python3.10/dist-packages/aiohttp/streams.py\", line 312, in _wait\n    await waiter\naiohttp.client_exceptions.ClientPayloadError: Response payload is not completed: <TransferEncodingError: 400, message='Not enough data for satisfy transfer length header.'>\n", "Traceback (most recent call last):\n  File \"/usr/local/lib/python3.10/dist-packages/aiohttp/client_proto.py\", line 94, in connection_lost\n    uncompleted = self._parser.feed_eof()\n  File \"aiohttp/_http_parser.pyx\", line 513, in aiohttp._http_parser.HttpParser.feed_eof\naiohttp.http_exceptions.TransferEncodingError: 400, message:\n  Not enough data for satisfy transfer length header.\n\nThe above exception was the direct cause of the following exception:\n\nTraceback (most recent call last):\n  File \"/vllm-workspace/backend_request_func.py\", line 261, in async_request_openai_completions\n    async for chunk_bytes in response.content:\n  File \"/usr/local/lib/python3.10/dist-packages/aiohttp/streams.py\", line 50, in __anext__\n    rv = await self.read_func()\n  File \"/usr/local/lib/python3.10/dist-packages/aiohttp/streams.py\", line 317, in readline\n    return await self.readuntil()\n  File \"/usr/local/lib/python3.10/dist-packages/aiohttp/streams.py\", line 351, in readuntil\n    await self._wait(\"readuntil\")\n  File \"/usr/local/lib/python3.10/dist-packages/aiohttp/streams.py\", line 312, in _wait\n    await waiter\naiohttp.client_exceptions.ClientPayloadError: Response payload is not completed: <TransferEncodingError: 400, message='Not enough data for satisfy transfer length header.'>\n", "Traceback (most recent call last):\n  File \"/usr/local/lib/python3.10/dist-packages/aiohttp/client_proto.py\", line 94, in connection_lost\n    uncompleted = self._parser.feed_eof()\n  File \"aiohttp/_http_parser.pyx\", line 513, in aiohttp._http_parser.HttpParser.feed_eof\naiohttp.http_exceptions.TransferEncodingError: 400, message:\n  Not enough data for satisfy transfer length header.\n\nThe above exception was the direct cause of the following exception:\n\nTraceback (most recent call last):\n  File \"/vllm-workspace/backend_request_func.py\", line 261, in async_request_openai_completions\n    async for chunk_bytes in response.content:\n  File \"/usr/local/lib/python3.10/dist-packages/aiohttp/streams.py\", line 50, in __anext__\n    rv = await self.read_func()\n  File \"/usr/local/lib/python3.10/dist-packages/aiohttp/streams.py\", line 317, in readline\n    return await self.readuntil()\n  File \"/usr/local/lib/python3.10/dist-packages/aiohttp/streams.py\", line 351, in readuntil\n    await self._wait(\"readuntil\")\n  File \"/usr/local/lib/python3.10/dist-packages/aiohttp/streams.py\", line 312, in _wait\n    await waiter\naiohttp.client_exceptions.ClientPayloadError: Response payload is not completed: <TransferEncodingError: 400, message='Not enough data for satisfy transfer length header.'>\n", "Traceback (most recent call last):\n  File \"/usr/local/lib/python3.10/dist-packages/aiohttp/client_proto.py\", line 94, in connection_lost\n    uncompleted = self._parser.feed_eof()\n  File \"aiohttp/_http_parser.pyx\", line 513, in aiohttp._http_parser.HttpParser.feed_eof\naiohttp.http_exceptions.TransferEncodingError: 400, message:\n  Not enough data for satisfy transfer length header.\n\nThe above exception was the direct cause of the following exception:\n\nTraceback (most recent call last):\n  File \"/vllm-workspace/backend_request_func.py\", line 261, in async_request_openai_completions\n    async for chunk_bytes in response.content:\n  File \"/usr/local/lib/python3.10/dist-packages/aiohttp/streams.py\", line 50, in __anext__\n    rv = await self.read_func()\n  File \"/usr/local/lib/python3.10/dist-packages/aiohttp/streams.py\", line 317, in readline\n    return await self.readuntil()\n  File \"/usr/local/lib/python3.10/dist-packages/aiohttp/streams.py\", line 351, in readuntil\n    await self._wait(\"readuntil\")\n  File \"/usr/local/lib/python3.10/dist-packages/aiohttp/streams.py\", line 312, in _wait\n    await waiter\naiohttp.client_exceptions.ClientPayloadError: Response payload is not completed: <TransferEncodingError: 400, message='Not enough data for satisfy transfer length header.'>\n", "Traceback (most recent call last):\n  File \"/usr/local/lib/python3.10/dist-packages/aiohttp/client_proto.py\", line 94, in connection_lost\n    uncompleted = self._parser.feed_eof()\n  File \"aiohttp/_http_parser.pyx\", line 513, in aiohttp._http_parser.HttpParser.feed_eof\naiohttp.http_exceptions.TransferEncodingError: 400, message:\n  Not enough data for satisfy transfer length header.\n\nThe above exception was the direct cause of the following exception:\n\nTraceback (most recent call last):\n  File \"/vllm-workspace/backend_request_func.py\", line 261, in async_request_openai_completions\n    async for chunk_bytes in response.content:\n  File \"/usr/local/lib/python3.10/dist-packages/aiohttp/streams.py\", line 50, in __anext__\n    rv = await self.read_func()\n  File \"/usr/local/lib/python3.10/dist-packages/aiohttp/streams.py\", line 317, in readline\n    return await self.readuntil()\n  File \"/usr/local/lib/python3.10/dist-packages/aiohttp/streams.py\", line 351, in readuntil\n    await self._wait(\"readuntil\")\n  File \"/usr/local/lib/python3.10/dist-packages/aiohttp/streams.py\", line 312, in _wait\n    await waiter\naiohttp.client_exceptions.ClientPayloadError: Response payload is not completed: <TransferEncodingError: 400, message='Not enough data for satisfy transfer length header.'>\n", "Traceback (most recent call last):\n  File \"/usr/local/lib/python3.10/dist-packages/aiohttp/client_proto.py\", line 94, in connection_lost\n    uncompleted = self._parser.feed_eof()\n  File \"aiohttp/_http_parser.pyx\", line 513, in aiohttp._http_parser.HttpParser.feed_eof\naiohttp.http_exceptions.TransferEncodingError: 400, message:\n  Not enough data for satisfy transfer length header.\n\nThe above exception was the direct cause of the following exception:\n\nTraceback (most recent call last):\n  File \"/vllm-workspace/backend_request_func.py\", line 261, in async_request_openai_completions\n    async for chunk_bytes in response.content:\n  File \"/usr/local/lib/python3.10/dist-packages/aiohttp/streams.py\", line 50, in __anext__\n    rv = await self.read_func()\n  File \"/usr/local/lib/python3.10/dist-packages/aiohttp/streams.py\", line 317, in readline\n    return await self.readuntil()\n  File \"/usr/local/lib/python3.10/dist-packages/aiohttp/streams.py\", line 351, in readuntil\n    await self._wait(\"readuntil\")\n  File \"/usr/local/lib/python3.10/dist-packages/aiohttp/streams.py\", line 312, in _wait\n    await waiter\naiohttp.client_exceptions.ClientPayloadError: Response payload is not completed: <TransferEncodingError: 400, message='Not enough data for satisfy transfer length header.'>\n", "Traceback (most recent call last):\n  File \"/usr/local/lib/python3.10/dist-packages/aiohttp/client_proto.py\", line 94, in connection_lost\n    uncompleted = self._parser.feed_eof()\n  File \"aiohttp/_http_parser.pyx\", line 513, in aiohttp._http_parser.HttpParser.feed_eof\naiohttp.http_exceptions.TransferEncodingError: 400, message:\n  Not enough data for satisfy transfer length header.\n\nThe above exception was the direct cause of the following exception:\n\nTraceback (most recent call last):\n  File \"/vllm-workspace/backend_request_func.py\", line 261, in async_request_openai_completions\n    async for chunk_bytes in response.content:\n  File \"/usr/local/lib/python3.10/dist-packages/aiohttp/streams.py\", line 50, in __anext__\n    rv = await self.read_func()\n  File \"/usr/local/lib/python3.10/dist-packages/aiohttp/streams.py\", line 317, in readline\n    return await self.readuntil()\n  File \"/usr/local/lib/python3.10/dist-packages/aiohttp/streams.py\", line 351, in readuntil\n    await self._wait(\"readuntil\")\n  File \"/usr/local/lib/python3.10/dist-packages/aiohttp/streams.py\", line 312, in _wait\n    await waiter\naiohttp.client_exceptions.ClientPayloadError: Response payload is not completed: <TransferEncodingError: 400, message='Not enough data for satisfy transfer length header.'>\n", "Traceback (most recent call last):\n  File \"/usr/local/lib/python3.10/dist-packages/aiohttp/client_proto.py\", line 94, in connection_lost\n    uncompleted = self._parser.feed_eof()\n  File \"aiohttp/_http_parser.pyx\", line 513, in aiohttp._http_parser.HttpParser.feed_eof\naiohttp.http_exceptions.TransferEncodingError: 400, message:\n  Not enough data for satisfy transfer length header.\n\nThe above exception was the direct cause of the following exception:\n\nTraceback (most recent call last):\n  File \"/vllm-workspace/backend_request_func.py\", line 261, in async_request_openai_completions\n    async for chunk_bytes in response.content:\n  File \"/usr/local/lib/python3.10/dist-packages/aiohttp/streams.py\", line 50, in __anext__\n    rv = await self.read_func()\n  File \"/usr/local/lib/python3.10/dist-packages/aiohttp/streams.py\", line 317, in readline\n    return await self.readuntil()\n  File \"/usr/local/lib/python3.10/dist-packages/aiohttp/streams.py\", line 351, in readuntil\n    await self._wait(\"readuntil\")\n  File \"/usr/local/lib/python3.10/dist-packages/aiohttp/streams.py\", line 312, in _wait\n    await waiter\naiohttp.client_exceptions.ClientPayloadError: Response payload is not completed: <TransferEncodingError: 400, message='Not enough data for satisfy transfer length header.'>\n", "Traceback (most recent call last):\n  File \"/usr/local/lib/python3.10/dist-packages/aiohttp/client_proto.py\", line 94, in connection_lost\n    uncompleted = self._parser.feed_eof()\n  File \"aiohttp/_http_parser.pyx\", line 513, in aiohttp._http_parser.HttpParser.feed_eof\naiohttp.http_exceptions.TransferEncodingError: 400, message:\n  Not enough data for satisfy transfer length header.\n\nThe above exception was the direct cause of the following exception:\n\nTraceback (most recent call last):\n  File \"/vllm-workspace/backend_request_func.py\", line 261, in async_request_openai_completions\n    async for chunk_bytes in response.content:\n  File \"/usr/local/lib/python3.10/dist-packages/aiohttp/streams.py\", line 50, in __anext__\n    rv = await self.read_func()\n  File \"/usr/local/lib/python3.10/dist-packages/aiohttp/streams.py\", line 317, in readline\n    return await self.readuntil()\n  File \"/usr/local/lib/python3.10/dist-packages/aiohttp/streams.py\", line 351, in readuntil\n    await self._wait(\"readuntil\")\n  File \"/usr/local/lib/python3.10/dist-packages/aiohttp/streams.py\", line 312, in _wait\n    await waiter\naiohttp.client_exceptions.ClientPayloadError: Response payload is not completed: <TransferEncodingError: 400, message='Not enough data for satisfy transfer length header.'>\n", "Traceback (most recent call last):\n  File \"/usr/local/lib/python3.10/dist-packages/aiohttp/client_proto.py\", line 94, in connection_lost\n    uncompleted = self._parser.feed_eof()\n  File \"aiohttp/_http_parser.pyx\", line 513, in aiohttp._http_parser.HttpParser.feed_eof\naiohttp.http_exceptions.TransferEncodingError: 400, message:\n  Not enough data for satisfy transfer length header.\n\nThe above exception was the direct cause of the following exception:\n\nTraceback (most recent call last):\n  File \"/vllm-workspace/backend_request_func.py\", line 261, in async_request_openai_completions\n    async for chunk_bytes in response.content:\n  File \"/usr/local/lib/python3.10/dist-packages/aiohttp/streams.py\", line 50, in __anext__\n    rv = await self.read_func()\n  File \"/usr/local/lib/python3.10/dist-packages/aiohttp/streams.py\", line 317, in readline\n    return await self.readuntil()\n  File \"/usr/local/lib/python3.10/dist-packages/aiohttp/streams.py\", line 351, in readuntil\n    await self._wait(\"readuntil\")\n  File \"/usr/local/lib/python3.10/dist-packages/aiohttp/streams.py\", line 312, in _wait\n    await waiter\naiohttp.client_exceptions.ClientPayloadError: Response payload is not completed: <TransferEncodingError: 400, message='Not enough data for satisfy transfer length header.'>\n", "Traceback (most recent call last):\n  File \"/usr/local/lib/python3.10/dist-packages/aiohttp/client_proto.py\", line 94, in connection_lost\n    uncompleted = self._parser.feed_eof()\n  File \"aiohttp/_http_parser.pyx\", line 513, in aiohttp._http_parser.HttpParser.feed_eof\naiohttp.http_exceptions.TransferEncodingError: 400, message:\n  Not enough data for satisfy transfer length header.\n\nThe above exception was the direct cause of the following exception:\n\nTraceback (most recent call last):\n  File \"/vllm-workspace/backend_request_func.py\", line 261, in async_request_openai_completions\n    async for chunk_bytes in response.content:\n  File \"/usr/local/lib/python3.10/dist-packages/aiohttp/streams.py\", line 50, in __anext__\n    rv = await self.read_func()\n  File \"/usr/local/lib/python3.10/dist-packages/aiohttp/streams.py\", line 317, in readline\n    return await self.readuntil()\n  File \"/usr/local/lib/python3.10/dist-packages/aiohttp/streams.py\", line 351, in readuntil\n    await self._wait(\"readuntil\")\n  File \"/usr/local/lib/python3.10/dist-packages/aiohttp/streams.py\", line 312, in _wait\n    await waiter\naiohttp.client_exceptions.ClientPayloadError: Response payload is not completed: <TransferEncodingError: 400, message='Not enough data for satisfy transfer length header.'>\n", "Traceback (most recent call last):\n  File \"/usr/local/lib/python3.10/dist-packages/aiohttp/client_proto.py\", line 94, in connection_lost\n    uncompleted = self._parser.feed_eof()\n  File \"aiohttp/_http_parser.pyx\", line 513, in aiohttp._http_parser.HttpParser.feed_eof\naiohttp.http_exceptions.TransferEncodingError: 400, message:\n  Not enough data for satisfy transfer length header.\n\nThe above exception was the direct cause of the following exception:\n\nTraceback (most recent call last):\n  File \"/vllm-workspace/backend_request_func.py\", line 261, in async_request_openai_completions\n    async for chunk_bytes in response.content:\n  File \"/usr/local/lib/python3.10/dist-packages/aiohttp/streams.py\", line 50, in __anext__\n    rv = await self.read_func()\n  File \"/usr/local/lib/python3.10/dist-packages/aiohttp/streams.py\", line 317, in readline\n    return await self.readuntil()\n  File \"/usr/local/lib/python3.10/dist-packages/aiohttp/streams.py\", line 351, in readuntil\n    await self._wait(\"readuntil\")\n  File \"/usr/local/lib/python3.10/dist-packages/aiohttp/streams.py\", line 312, in _wait\n    await waiter\naiohttp.client_exceptions.ClientPayloadError: Response payload is not completed: <TransferEncodingError: 400, message='Not enough data for satisfy transfer length header.'>\n", "Traceback (most recent call last):\n  File \"/usr/local/lib/python3.10/dist-packages/aiohttp/client_proto.py\", line 94, in connection_lost\n    uncompleted = self._parser.feed_eof()\n  File \"aiohttp/_http_parser.pyx\", line 513, in aiohttp._http_parser.HttpParser.feed_eof\naiohttp.http_exceptions.TransferEncodingError: 400, message:\n  Not enough data for satisfy transfer length header.\n\nThe above exception was the direct cause of the following exception:\n\nTraceback (most recent call last):\n  File \"/vllm-workspace/backend_request_func.py\", line 261, in async_request_openai_completions\n    async for chunk_bytes in response.content:\n  File \"/usr/local/lib/python3.10/dist-packages/aiohttp/streams.py\", line 50, in __anext__\n    rv = await self.read_func()\n  File \"/usr/local/lib/python3.10/dist-packages/aiohttp/streams.py\", line 317, in readline\n    return await self.readuntil()\n  File \"/usr/local/lib/python3.10/dist-packages/aiohttp/streams.py\", line 351, in readuntil\n    await self._wait(\"readuntil\")\n  File \"/usr/local/lib/python3.10/dist-packages/aiohttp/streams.py\", line 312, in _wait\n    await waiter\naiohttp.client_exceptions.ClientPayloadError: Response payload is not completed: <TransferEncodingError: 400, message='Not enough data for satisfy transfer length header.'>\n", "Traceback (most recent call last):\n  File \"/usr/local/lib/python3.10/dist-packages/aiohttp/client_proto.py\", line 94, in connection_lost\n    uncompleted = self._parser.feed_eof()\n  File \"aiohttp/_http_parser.pyx\", line 513, in aiohttp._http_parser.HttpParser.feed_eof\naiohttp.http_exceptions.TransferEncodingError: 400, message:\n  Not enough data for satisfy transfer length header.\n\nThe above exception was the direct cause of the following exception:\n\nTraceback (most recent call last):\n  File \"/vllm-workspace/backend_request_func.py\", line 261, in async_request_openai_completions\n    async for chunk_bytes in response.content:\n  File \"/usr/local/lib/python3.10/dist-packages/aiohttp/streams.py\", line 50, in __anext__\n    rv = await self.read_func()\n  File \"/usr/local/lib/python3.10/dist-packages/aiohttp/streams.py\", line 317, in readline\n    return await self.readuntil()\n  File \"/usr/local/lib/python3.10/dist-packages/aiohttp/streams.py\", line 351, in readuntil\n    await self._wait(\"readuntil\")\n  File \"/usr/local/lib/python3.10/dist-packages/aiohttp/streams.py\", line 312, in _wait\n    await waiter\naiohttp.client_exceptions.ClientPayloadError: Response payload is not completed: <TransferEncodingError: 400, message='Not enough data for satisfy transfer length header.'>\n", "Traceback (most recent call last):\n  File \"/usr/local/lib/python3.10/dist-packages/aiohttp/client_proto.py\", line 94, in connection_lost\n    uncompleted = self._parser.feed_eof()\n  File \"aiohttp/_http_parser.pyx\", line 513, in aiohttp._http_parser.HttpParser.feed_eof\naiohttp.http_exceptions.TransferEncodingError: 400, message:\n  Not enough data for satisfy transfer length header.\n\nThe above exception was the direct cause of the following exception:\n\nTraceback (most recent call last):\n  File \"/vllm-workspace/backend_request_func.py\", line 261, in async_request_openai_completions\n    async for chunk_bytes in response.content:\n  File \"/usr/local/lib/python3.10/dist-packages/aiohttp/streams.py\", line 50, in __anext__\n    rv = await self.read_func()\n  File \"/usr/local/lib/python3.10/dist-packages/aiohttp/streams.py\", line 317, in readline\n    return await self.readuntil()\n  File \"/usr/local/lib/python3.10/dist-packages/aiohttp/streams.py\", line 351, in readuntil\n    await self._wait(\"readuntil\")\n  File \"/usr/local/lib/python3.10/dist-packages/aiohttp/streams.py\", line 312, in _wait\n    await waiter\naiohttp.client_exceptions.ClientPayloadError: Response payload is not completed: <TransferEncodingError: 400, message='Not enough data for satisfy transfer length header.'>\n", "Traceback (most recent call last):\n  File \"/usr/local/lib/python3.10/dist-packages/aiohttp/client_proto.py\", line 94, in connection_lost\n    uncompleted = self._parser.feed_eof()\n  File \"aiohttp/_http_parser.pyx\", line 513, in aiohttp._http_parser.HttpParser.feed_eof\naiohttp.http_exceptions.TransferEncodingError: 400, message:\n  Not enough data for satisfy transfer length header.\n\nThe above exception was the direct cause of the following exception:\n\nTraceback (most recent call last):\n  File \"/vllm-workspace/backend_request_func.py\", line 261, in async_request_openai_completions\n    async for chunk_bytes in response.content:\n  File \"/usr/local/lib/python3.10/dist-packages/aiohttp/streams.py\", line 50, in __anext__\n    rv = await self.read_func()\n  File \"/usr/local/lib/python3.10/dist-packages/aiohttp/streams.py\", line 317, in readline\n    return await self.readuntil()\n  File \"/usr/local/lib/python3.10/dist-packages/aiohttp/streams.py\", line 351, in readuntil\n    await self._wait(\"readuntil\")\n  File \"/usr/local/lib/python3.10/dist-packages/aiohttp/streams.py\", line 312, in _wait\n    await waiter\naiohttp.client_exceptions.ClientPayloadError: Response payload is not completed: <TransferEncodingError: 400, message='Not enough data for satisfy transfer length header.'>\n", "Traceback (most recent call last):\n  File \"/usr/local/lib/python3.10/dist-packages/aiohttp/client_proto.py\", line 94, in connection_lost\n    uncompleted = self._parser.feed_eof()\n  File \"aiohttp/_http_parser.pyx\", line 513, in aiohttp._http_parser.HttpParser.feed_eof\naiohttp.http_exceptions.TransferEncodingError: 400, message:\n  Not enough data for satisfy transfer length header.\n\nThe above exception was the direct cause of the following exception:\n\nTraceback (most recent call last):\n  File \"/vllm-workspace/backend_request_func.py\", line 261, in async_request_openai_completions\n    async for chunk_bytes in response.content:\n  File \"/usr/local/lib/python3.10/dist-packages/aiohttp/streams.py\", line 50, in __anext__\n    rv = await self.read_func()\n  File \"/usr/local/lib/python3.10/dist-packages/aiohttp/streams.py\", line 317, in readline\n    return await self.readuntil()\n  File \"/usr/local/lib/python3.10/dist-packages/aiohttp/streams.py\", line 351, in readuntil\n    await self._wait(\"readuntil\")\n  File \"/usr/local/lib/python3.10/dist-packages/aiohttp/streams.py\", line 312, in _wait\n    await waiter\naiohttp.client_exceptions.ClientPayloadError: Response payload is not completed: <TransferEncodingError: 400, message='Not enough data for satisfy transfer length header.'>\n", "", "", "", "", "", "", "Traceback (most recent call last):\n  File \"/usr/local/lib/python3.10/dist-packages/aiohttp/client_proto.py\", line 94, in connection_lost\n    uncompleted = self._parser.feed_eof()\n  File \"aiohttp/_http_parser.pyx\", line 513, in aiohttp._http_parser.HttpParser.feed_eof\naiohttp.http_exceptions.TransferEncodingError: 400, message:\n  Not enough data for satisfy transfer length header.\n\nThe above exception was the direct cause of the following exception:\n\nTraceback (most recent call last):\n  File \"/vllm-workspace/backend_request_func.py\", line 261, in async_request_openai_completions\n    async for chunk_bytes in response.content:\n  File \"/usr/local/lib/python3.10/dist-packages/aiohttp/streams.py\", line 50, in __anext__\n    rv = await self.read_func()\n  File \"/usr/local/lib/python3.10/dist-packages/aiohttp/streams.py\", line 317, in readline\n    return await self.readuntil()\n  File \"/usr/local/lib/python3.10/dist-packages/aiohttp/streams.py\", line 351, in readuntil\n    await self._wait(\"readuntil\")\n  File \"/usr/local/lib/python3.10/dist-packages/aiohttp/streams.py\", line 312, in _wait\n    await waiter\naiohttp.client_exceptions.ClientPayloadError: Response payload is not completed: <TransferEncodingError: 400, message='Not enough data for satisfy transfer length header.'>\n", "Traceback (most recent call last):\n  File \"/usr/local/lib/python3.10/dist-packages/aiohttp/client_proto.py\", line 94, in connection_lost\n    uncompleted = self._parser.feed_eof()\n  File \"aiohttp/_http_parser.pyx\", line 513, in aiohttp._http_parser.HttpParser.feed_eof\naiohttp.http_exceptions.TransferEncodingError: 400, message:\n  Not enough data for satisfy transfer length header.\n\nThe above exception was the direct cause of the following exception:\n\nTraceback (most recent call last):\n  File \"/vllm-workspace/backend_request_func.py\", line 261, in async_request_openai_completions\n    async for chunk_bytes in response.content:\n  File \"/usr/local/lib/python3.10/dist-packages/aiohttp/streams.py\", line 50, in __anext__\n    rv = await self.read_func()\n  File \"/usr/local/lib/python3.10/dist-packages/aiohttp/streams.py\", line 317, in readline\n    return await self.readuntil()\n  File \"/usr/local/lib/python3.10/dist-packages/aiohttp/streams.py\", line 351, in readuntil\n    await self._wait(\"readuntil\")\n  File \"/usr/local/lib/python3.10/dist-packages/aiohttp/streams.py\", line 312, in _wait\n    await waiter\naiohttp.client_exceptions.ClientPayloadError: Response payload is not completed: <TransferEncodingError: 400, message='Not enough data for satisfy transfer length header.'>\n", "Traceback (most recent call last):\n  File \"/usr/local/lib/python3.10/dist-packages/aiohttp/client_proto.py\", line 94, in connection_lost\n    uncompleted = self._parser.feed_eof()\n  File \"aiohttp/_http_parser.pyx\", line 513, in aiohttp._http_parser.HttpParser.feed_eof\naiohttp.http_exceptions.TransferEncodingError: 400, message:\n  Not enough data for satisfy transfer length header.\n\nThe above exception was the direct cause of the following exception:\n\nTraceback (most recent call last):\n  File \"/vllm-workspace/backend_request_func.py\", line 261, in async_request_openai_completions\n    async for chunk_bytes in response.content:\n  File \"/usr/local/lib/python3.10/dist-packages/aiohttp/streams.py\", line 50, in __anext__\n    rv = await self.read_func()\n  File \"/usr/local/lib/python3.10/dist-packages/aiohttp/streams.py\", line 317, in readline\n    return await self.readuntil()\n  File \"/usr/local/lib/python3.10/dist-packages/aiohttp/streams.py\", line 351, in readuntil\n    await self._wait(\"readuntil\")\n  File \"/usr/local/lib/python3.10/dist-packages/aiohttp/streams.py\", line 312, in _wait\n    await waiter\naiohttp.client_exceptions.ClientPayloadError: Response payload is not completed: <TransferEncodingError: 400, message='Not enough data for satisfy transfer length header.'>\n", "Traceback (most recent call last):\n  File \"/usr/local/lib/python3.10/dist-packages/aiohttp/client_proto.py\", line 94, in connection_lost\n    uncompleted = self._parser.feed_eof()\n  File \"aiohttp/_http_parser.pyx\", line 513, in aiohttp._http_parser.HttpParser.feed_eof\naiohttp.http_exceptions.TransferEncodingError: 400, message:\n  Not enough data for satisfy transfer length header.\n\nThe above exception was the direct cause of the following exception:\n\nTraceback (most recent call last):\n  File \"/vllm-workspace/backend_request_func.py\", line 261, in async_request_openai_completions\n    async for chunk_bytes in response.content:\n  File \"/usr/local/lib/python3.10/dist-packages/aiohttp/streams.py\", line 50, in __anext__\n    rv = await self.read_func()\n  File \"/usr/local/lib/python3.10/dist-packages/aiohttp/streams.py\", line 317, in readline\n    return await self.readuntil()\n  File \"/usr/local/lib/python3.10/dist-packages/aiohttp/streams.py\", line 351, in readuntil\n    await self._wait(\"readuntil\")\n  File \"/usr/local/lib/python3.10/dist-packages/aiohttp/streams.py\", line 312, in _wait\n    await waiter\naiohttp.client_exceptions.ClientPayloadError: Response payload is not completed: <TransferEncodingError: 400, message='Not enough data for satisfy transfer length header.'>\n", "Traceback (most recent call last):\n  File \"/usr/local/lib/python3.10/dist-packages/aiohttp/client_proto.py\", line 94, in connection_lost\n    uncompleted = self._parser.feed_eof()\n  File \"aiohttp/_http_parser.pyx\", line 513, in aiohttp._http_parser.HttpParser.feed_eof\naiohttp.http_exceptions.TransferEncodingError: 400, message:\n  Not enough data for satisfy transfer length header.\n\nThe above exception was the direct cause of the following exception:\n\nTraceback (most recent call last):\n  File \"/vllm-workspace/backend_request_func.py\", line 261, in async_request_openai_completions\n    async for chunk_bytes in response.content:\n  File \"/usr/local/lib/python3.10/dist-packages/aiohttp/streams.py\", line 50, in __anext__\n    rv = await self.read_func()\n  File \"/usr/local/lib/python3.10/dist-packages/aiohttp/streams.py\", line 317, in readline\n    return await self.readuntil()\n  File \"/usr/local/lib/python3.10/dist-packages/aiohttp/streams.py\", line 351, in readuntil\n    await self._wait(\"readuntil\")\n  File \"/usr/local/lib/python3.10/dist-packages/aiohttp/streams.py\", line 312, in _wait\n    await waiter\naiohttp.client_exceptions.ClientPayloadError: Response payload is not completed: <TransferEncodingError: 400, message='Not enough data for satisfy transfer length header.'>\n", "", "Traceback (most recent call last):\n  File \"/usr/local/lib/python3.10/dist-packages/aiohttp/client_proto.py\", line 94, in connection_lost\n    uncompleted = self._parser.feed_eof()\n  File \"aiohttp/_http_parser.pyx\", line 513, in aiohttp._http_parser.HttpParser.feed_eof\naiohttp.http_exceptions.TransferEncodingError: 400, message:\n  Not enough data for satisfy transfer length header.\n\nThe above exception was the direct cause of the following exception:\n\nTraceback (most recent call last):\n  File \"/vllm-workspace/backend_request_func.py\", line 261, in async_request_openai_completions\n    async for chunk_bytes in response.content:\n  File \"/usr/local/lib/python3.10/dist-packages/aiohttp/streams.py\", line 50, in __anext__\n    rv = await self.read_func()\n  File \"/usr/local/lib/python3.10/dist-packages/aiohttp/streams.py\", line 317, in readline\n    return await self.readuntil()\n  File \"/usr/local/lib/python3.10/dist-packages/aiohttp/streams.py\", line 351, in readuntil\n    await self._wait(\"readuntil\")\n  File \"/usr/local/lib/python3.10/dist-packages/aiohttp/streams.py\", line 312, in _wait\n    await waiter\naiohttp.client_exceptions.ClientPayloadError: Response payload is not completed: <TransferEncodingError: 400, message='Not enough data for satisfy transfer length header.'>\n", "", "", "Traceback (most recent call last):\n  File \"/usr/local/lib/python3.10/dist-packages/aiohttp/client_proto.py\", line 94, in connection_lost\n    uncompleted = self._parser.feed_eof()\n  File \"aiohttp/_http_parser.pyx\", line 513, in aiohttp._http_parser.HttpParser.feed_eof\naiohttp.http_exceptions.TransferEncodingError: 400, message:\n  Not enough data for satisfy transfer length header.\n\nThe above exception was the direct cause of the following exception:\n\nTraceback (most recent call last):\n  File \"/vllm-workspace/backend_request_func.py\", line 261, in async_request_openai_completions\n    async for chunk_bytes in response.content:\n  File \"/usr/local/lib/python3.10/dist-packages/aiohttp/streams.py\", line 50, in __anext__\n    rv = await self.read_func()\n  File \"/usr/local/lib/python3.10/dist-packages/aiohttp/streams.py\", line 317, in readline\n    return await self.readuntil()\n  File \"/usr/local/lib/python3.10/dist-packages/aiohttp/streams.py\", line 351, in readuntil\n    await self._wait(\"readuntil\")\n  File \"/usr/local/lib/python3.10/dist-packages/aiohttp/streams.py\", line 312, in _wait\n    await waiter\naiohttp.client_exceptions.ClientPayloadError: Response payload is not completed: <TransferEncodingError: 400, message='Not enough data for satisfy transfer length header.'>\n", "Traceback (most recent call last):\n  File \"/usr/local/lib/python3.10/dist-packages/aiohttp/client_proto.py\", line 94, in connection_lost\n    uncompleted = self._parser.feed_eof()\n  File \"aiohttp/_http_parser.pyx\", line 513, in aiohttp._http_parser.HttpParser.feed_eof\naiohttp.http_exceptions.TransferEncodingError: 400, message:\n  Not enough data for satisfy transfer length header.\n\nThe above exception was the direct cause of the following exception:\n\nTraceback (most recent call last):\n  File \"/vllm-workspace/backend_request_func.py\", line 261, in async_request_openai_completions\n    async for chunk_bytes in response.content:\n  File \"/usr/local/lib/python3.10/dist-packages/aiohttp/streams.py\", line 50, in __anext__\n    rv = await self.read_func()\n  File \"/usr/local/lib/python3.10/dist-packages/aiohttp/streams.py\", line 317, in readline\n    return await self.readuntil()\n  File \"/usr/local/lib/python3.10/dist-packages/aiohttp/streams.py\", line 351, in readuntil\n    await self._wait(\"readuntil\")\n  File \"/usr/local/lib/python3.10/dist-packages/aiohttp/streams.py\", line 312, in _wait\n    await waiter\naiohttp.client_exceptions.ClientPayloadError: Response payload is not completed: <TransferEncodingError: 400, message='Not enough data for satisfy transfer length header.'>\n", "Traceback (most recent call last):\n  File \"/usr/local/lib/python3.10/dist-packages/aiohttp/client_proto.py\", line 94, in connection_lost\n    uncompleted = self._parser.feed_eof()\n  File \"aiohttp/_http_parser.pyx\", line 513, in aiohttp._http_parser.HttpParser.feed_eof\naiohttp.http_exceptions.TransferEncodingError: 400, message:\n  Not enough data for satisfy transfer length header.\n\nThe above exception was the direct cause of the following exception:\n\nTraceback (most recent call last):\n  File \"/vllm-workspace/backend_request_func.py\", line 261, in async_request_openai_completions\n    async for chunk_bytes in response.content:\n  File \"/usr/local/lib/python3.10/dist-packages/aiohttp/streams.py\", line 50, in __anext__\n    rv = await self.read_func()\n  File \"/usr/local/lib/python3.10/dist-packages/aiohttp/streams.py\", line 317, in readline\n    return await self.readuntil()\n  File \"/usr/local/lib/python3.10/dist-packages/aiohttp/streams.py\", line 351, in readuntil\n    await self._wait(\"readuntil\")\n  File \"/usr/local/lib/python3.10/dist-packages/aiohttp/streams.py\", line 312, in _wait\n    await waiter\naiohttp.client_exceptions.ClientPayloadError: Response payload is not completed: <TransferEncodingError: 400, message='Not enough data for satisfy transfer length header.'>\n", "", "Traceback (most recent call last):\n  File \"/usr/local/lib/python3.10/dist-packages/aiohttp/client_proto.py\", line 94, in connection_lost\n    uncompleted = self._parser.feed_eof()\n  File \"aiohttp/_http_parser.pyx\", line 513, in aiohttp._http_parser.HttpParser.feed_eof\naiohttp.http_exceptions.TransferEncodingError: 400, message:\n  Not enough data for satisfy transfer length header.\n\nThe above exception was the direct cause of the following exception:\n\nTraceback (most recent call last):\n  File \"/vllm-workspace/backend_request_func.py\", line 261, in async_request_openai_completions\n    async for chunk_bytes in response.content:\n  File \"/usr/local/lib/python3.10/dist-packages/aiohttp/streams.py\", line 50, in __anext__\n    rv = await self.read_func()\n  File \"/usr/local/lib/python3.10/dist-packages/aiohttp/streams.py\", line 317, in readline\n    return await self.readuntil()\n  File \"/usr/local/lib/python3.10/dist-packages/aiohttp/streams.py\", line 351, in readuntil\n    await self._wait(\"readuntil\")\n  File \"/usr/local/lib/python3.10/dist-packages/aiohttp/streams.py\", line 312, in _wait\n    await waiter\naiohttp.client_exceptions.ClientPayloadError: Response payload is not completed: <TransferEncodingError: 400, message='Not enough data for satisfy transfer length header.'>\n", "Traceback (most recent call last):\n  File \"/usr/local/lib/python3.10/dist-packages/aiohttp/client_proto.py\", line 94, in connection_lost\n    uncompleted = self._parser.feed_eof()\n  File \"aiohttp/_http_parser.pyx\", line 513, in aiohttp._http_parser.HttpParser.feed_eof\naiohttp.http_exceptions.TransferEncodingError: 400, message:\n  Not enough data for satisfy transfer length header.\n\nThe above exception was the direct cause of the following exception:\n\nTraceback (most recent call last):\n  File \"/vllm-workspace/backend_request_func.py\", line 261, in async_request_openai_completions\n    async for chunk_bytes in response.content:\n  File \"/usr/local/lib/python3.10/dist-packages/aiohttp/streams.py\", line 50, in __anext__\n    rv = await self.read_func()\n  File \"/usr/local/lib/python3.10/dist-packages/aiohttp/streams.py\", line 317, in readline\n    return await self.readuntil()\n  File \"/usr/local/lib/python3.10/dist-packages/aiohttp/streams.py\", line 351, in readuntil\n    await self._wait(\"readuntil\")\n  File \"/usr/local/lib/python3.10/dist-packages/aiohttp/streams.py\", line 312, in _wait\n    await waiter\naiohttp.client_exceptions.ClientPayloadError: Response payload is not completed: <TransferEncodingError: 400, message='Not enough data for satisfy transfer length header.'>\n", "Traceback (most recent call last):\n  File \"/usr/local/lib/python3.10/dist-packages/aiohttp/client_proto.py\", line 94, in connection_lost\n    uncompleted = self._parser.feed_eof()\n  File \"aiohttp/_http_parser.pyx\", line 513, in aiohttp._http_parser.HttpParser.feed_eof\naiohttp.http_exceptions.TransferEncodingError: 400, message:\n  Not enough data for satisfy transfer length header.\n\nThe above exception was the direct cause of the following exception:\n\nTraceback (most recent call last):\n  File \"/vllm-workspace/backend_request_func.py\", line 261, in async_request_openai_completions\n    async for chunk_bytes in response.content:\n  File \"/usr/local/lib/python3.10/dist-packages/aiohttp/streams.py\", line 50, in __anext__\n    rv = await self.read_func()\n  File \"/usr/local/lib/python3.10/dist-packages/aiohttp/streams.py\", line 317, in readline\n    return await self.readuntil()\n  File \"/usr/local/lib/python3.10/dist-packages/aiohttp/streams.py\", line 351, in readuntil\n    await self._wait(\"readuntil\")\n  File \"/usr/local/lib/python3.10/dist-packages/aiohttp/streams.py\", line 312, in _wait\n    await waiter\naiohttp.client_exceptions.ClientPayloadError: Response payload is not completed: <TransferEncodingError: 400, message='Not enough data for satisfy transfer length header.'>\n", "", "Traceback (most recent call last):\n  File \"/usr/local/lib/python3.10/dist-packages/aiohttp/client_proto.py\", line 94, in connection_lost\n    uncompleted = self._parser.feed_eof()\n  File \"aiohttp/_http_parser.pyx\", line 513, in aiohttp._http_parser.HttpParser.feed_eof\naiohttp.http_exceptions.TransferEncodingError: 400, message:\n  Not enough data for satisfy transfer length header.\n\nThe above exception was the direct cause of the following exception:\n\nTraceback (most recent call last):\n  File \"/vllm-workspace/backend_request_func.py\", line 261, in async_request_openai_completions\n    async for chunk_bytes in response.content:\n  File \"/usr/local/lib/python3.10/dist-packages/aiohttp/streams.py\", line 50, in __anext__\n    rv = await self.read_func()\n  File \"/usr/local/lib/python3.10/dist-packages/aiohttp/streams.py\", line 317, in readline\n    return await self.readuntil()\n  File \"/usr/local/lib/python3.10/dist-packages/aiohttp/streams.py\", line 351, in readuntil\n    await self._wait(\"readuntil\")\n  File \"/usr/local/lib/python3.10/dist-packages/aiohttp/streams.py\", line 312, in _wait\n    await waiter\naiohttp.client_exceptions.ClientPayloadError: Response payload is not completed: <TransferEncodingError: 400, message='Not enough data for satisfy transfer length header.'>\n", "Traceback (most recent call last):\n  File \"/usr/local/lib/python3.10/dist-packages/aiohttp/client_proto.py\", line 94, in connection_lost\n    uncompleted = self._parser.feed_eof()\n  File \"aiohttp/_http_parser.pyx\", line 513, in aiohttp._http_parser.HttpParser.feed_eof\naiohttp.http_exceptions.TransferEncodingError: 400, message:\n  Not enough data for satisfy transfer length header.\n\nThe above exception was the direct cause of the following exception:\n\nTraceback (most recent call last):\n  File \"/vllm-workspace/backend_request_func.py\", line 261, in async_request_openai_completions\n    async for chunk_bytes in response.content:\n  File \"/usr/local/lib/python3.10/dist-packages/aiohttp/streams.py\", line 50, in __anext__\n    rv = await self.read_func()\n  File \"/usr/local/lib/python3.10/dist-packages/aiohttp/streams.py\", line 317, in readline\n    return await self.readuntil()\n  File \"/usr/local/lib/python3.10/dist-packages/aiohttp/streams.py\", line 351, in readuntil\n    await self._wait(\"readuntil\")\n  File \"/usr/local/lib/python3.10/dist-packages/aiohttp/streams.py\", line 312, in _wait\n    await waiter\naiohttp.client_exceptions.ClientPayloadError: Response payload is not completed: <TransferEncodingError: 400, message='Not enough data for satisfy transfer length header.'>\n", "", "", "", "", "Traceback (most recent call last):\n  File \"/usr/local/lib/python3.10/dist-packages/aiohttp/client_proto.py\", line 94, in connection_lost\n    uncompleted = self._parser.feed_eof()\n  File \"aiohttp/_http_parser.pyx\", line 513, in aiohttp._http_parser.HttpParser.feed_eof\naiohttp.http_exceptions.TransferEncodingError: 400, message:\n  Not enough data for satisfy transfer length header.\n\nThe above exception was the direct cause of the following exception:\n\nTraceback (most recent call last):\n  File \"/vllm-workspace/backend_request_func.py\", line 261, in async_request_openai_completions\n    async for chunk_bytes in response.content:\n  File \"/usr/local/lib/python3.10/dist-packages/aiohttp/streams.py\", line 50, in __anext__\n    rv = await self.read_func()\n  File \"/usr/local/lib/python3.10/dist-packages/aiohttp/streams.py\", line 317, in readline\n    return await self.readuntil()\n  File \"/usr/local/lib/python3.10/dist-packages/aiohttp/streams.py\", line 351, in readuntil\n    await self._wait(\"readuntil\")\n  File \"/usr/local/lib/python3.10/dist-packages/aiohttp/streams.py\", line 312, in _wait\n    await waiter\naiohttp.client_exceptions.ClientPayloadError: Response payload is not completed: <TransferEncodingError: 400, message='Not enough data for satisfy transfer length header.'>\n", "Traceback (most recent call last):\n  File \"/usr/local/lib/python3.10/dist-packages/aiohttp/client_proto.py\", line 94, in connection_lost\n    uncompleted = self._parser.feed_eof()\n  File \"aiohttp/_http_parser.pyx\", line 513, in aiohttp._http_parser.HttpParser.feed_eof\naiohttp.http_exceptions.TransferEncodingError: 400, message:\n  Not enough data for satisfy transfer length header.\n\nThe above exception was the direct cause of the following exception:\n\nTraceback (most recent call last):\n  File \"/vllm-workspace/backend_request_func.py\", line 261, in async_request_openai_completions\n    async for chunk_bytes in response.content:\n  File \"/usr/local/lib/python3.10/dist-packages/aiohttp/streams.py\", line 50, in __anext__\n    rv = await self.read_func()\n  File \"/usr/local/lib/python3.10/dist-packages/aiohttp/streams.py\", line 317, in readline\n    return await self.readuntil()\n  File \"/usr/local/lib/python3.10/dist-packages/aiohttp/streams.py\", line 351, in readuntil\n    await self._wait(\"readuntil\")\n  File \"/usr/local/lib/python3.10/dist-packages/aiohttp/streams.py\", line 312, in _wait\n    await waiter\naiohttp.client_exceptions.ClientPayloadError: Response payload is not completed: <TransferEncodingError: 400, message='Not enough data for satisfy transfer length header.'>\n", "", "", "", "Traceback (most recent call last):\n  File \"/usr/local/lib/python3.10/dist-packages/aiohttp/client_proto.py\", line 94, in connection_lost\n    uncompleted = self._parser.feed_eof()\n  File \"aiohttp/_http_parser.pyx\", line 513, in aiohttp._http_parser.HttpParser.feed_eof\naiohttp.http_exceptions.TransferEncodingError: 400, message:\n  Not enough data for satisfy transfer length header.\n\nThe above exception was the direct cause of the following exception:\n\nTraceback (most recent call last):\n  File \"/vllm-workspace/backend_request_func.py\", line 261, in async_request_openai_completions\n    async for chunk_bytes in response.content:\n  File \"/usr/local/lib/python3.10/dist-packages/aiohttp/streams.py\", line 50, in __anext__\n    rv = await self.read_func()\n  File \"/usr/local/lib/python3.10/dist-packages/aiohttp/streams.py\", line 317, in readline\n    return await self.readuntil()\n  File \"/usr/local/lib/python3.10/dist-packages/aiohttp/streams.py\", line 351, in readuntil\n    await self._wait(\"readuntil\")\n  File \"/usr/local/lib/python3.10/dist-packages/aiohttp/streams.py\", line 312, in _wait\n    await waiter\naiohttp.client_exceptions.ClientPayloadError: Response payload is not completed: <TransferEncodingError: 400, message='Not enough data for satisfy transfer length header.'>\n", "", "", "Traceback (most recent call last):\n  File \"/usr/local/lib/python3.10/dist-packages/aiohttp/client_proto.py\", line 94, in connection_lost\n    uncompleted = self._parser.feed_eof()\n  File \"aiohttp/_http_parser.pyx\", line 513, in aiohttp._http_parser.HttpParser.feed_eof\naiohttp.http_exceptions.TransferEncodingError: 400, message:\n  Not enough data for satisfy transfer length header.\n\nThe above exception was the direct cause of the following exception:\n\nTraceback (most recent call last):\n  File \"/vllm-workspace/backend_request_func.py\", line 261, in async_request_openai_completions\n    async for chunk_bytes in response.content:\n  File \"/usr/local/lib/python3.10/dist-packages/aiohttp/streams.py\", line 50, in __anext__\n    rv = await self.read_func()\n  File \"/usr/local/lib/python3.10/dist-packages/aiohttp/streams.py\", line 317, in readline\n    return await self.readuntil()\n  File \"/usr/local/lib/python3.10/dist-packages/aiohttp/streams.py\", line 351, in readuntil\n    await self._wait(\"readuntil\")\n  File \"/usr/local/lib/python3.10/dist-packages/aiohttp/streams.py\", line 312, in _wait\n    await waiter\naiohttp.client_exceptions.ClientPayloadError: Response payload is not completed: <TransferEncodingError: 400, message='Not enough data for satisfy transfer length header.'>\n", "Traceback (most recent call last):\n  File \"/usr/local/lib/python3.10/dist-packages/aiohttp/client_proto.py\", line 94, in connection_lost\n    uncompleted = self._parser.feed_eof()\n  File \"aiohttp/_http_parser.pyx\", line 513, in aiohttp._http_parser.HttpParser.feed_eof\naiohttp.http_exceptions.TransferEncodingError: 400, message:\n  Not enough data for satisfy transfer length header.\n\nThe above exception was the direct cause of the following exception:\n\nTraceback (most recent call last):\n  File \"/vllm-workspace/backend_request_func.py\", line 261, in async_request_openai_completions\n    async for chunk_bytes in response.content:\n  File \"/usr/local/lib/python3.10/dist-packages/aiohttp/streams.py\", line 50, in __anext__\n    rv = await self.read_func()\n  File \"/usr/local/lib/python3.10/dist-packages/aiohttp/streams.py\", line 317, in readline\n    return await self.readuntil()\n  File \"/usr/local/lib/python3.10/dist-packages/aiohttp/streams.py\", line 351, in readuntil\n    await self._wait(\"readuntil\")\n  File \"/usr/local/lib/python3.10/dist-packages/aiohttp/streams.py\", line 312, in _wait\n    await waiter\naiohttp.client_exceptions.ClientPayloadError: Response payload is not completed: <TransferEncodingError: 400, message='Not enough data for satisfy transfer length header.'>\n", "", "Traceback (most recent call last):\n  File \"/usr/local/lib/python3.10/dist-packages/aiohttp/client_proto.py\", line 94, in connection_lost\n    uncompleted = self._parser.feed_eof()\n  File \"aiohttp/_http_parser.pyx\", line 513, in aiohttp._http_parser.HttpParser.feed_eof\naiohttp.http_exceptions.TransferEncodingError: 400, message:\n  Not enough data for satisfy transfer length header.\n\nThe above exception was the direct cause of the following exception:\n\nTraceback (most recent call last):\n  File \"/vllm-workspace/backend_request_func.py\", line 261, in async_request_openai_completions\n    async for chunk_bytes in response.content:\n  File \"/usr/local/lib/python3.10/dist-packages/aiohttp/streams.py\", line 50, in __anext__\n    rv = await self.read_func()\n  File \"/usr/local/lib/python3.10/dist-packages/aiohttp/streams.py\", line 317, in readline\n    return await self.readuntil()\n  File \"/usr/local/lib/python3.10/dist-packages/aiohttp/streams.py\", line 351, in readuntil\n    await self._wait(\"readuntil\")\n  File \"/usr/local/lib/python3.10/dist-packages/aiohttp/streams.py\", line 312, in _wait\n    await waiter\naiohttp.client_exceptions.ClientPayloadError: Response payload is not completed: <TransferEncodingError: 400, message='Not enough data for satisfy transfer length header.'>\n", "", "", "Traceback (most recent call last):\n  File \"/usr/local/lib/python3.10/dist-packages/aiohttp/client_proto.py\", line 94, in connection_lost\n    uncompleted = self._parser.feed_eof()\n  File \"aiohttp/_http_parser.pyx\", line 513, in aiohttp._http_parser.HttpParser.feed_eof\naiohttp.http_exceptions.TransferEncodingError: 400, message:\n  Not enough data for satisfy transfer length header.\n\nThe above exception was the direct cause of the following exception:\n\nTraceback (most recent call last):\n  File \"/vllm-workspace/backend_request_func.py\", line 261, in async_request_openai_completions\n    async for chunk_bytes in response.content:\n  File \"/usr/local/lib/python3.10/dist-packages/aiohttp/streams.py\", line 50, in __anext__\n    rv = await self.read_func()\n  File \"/usr/local/lib/python3.10/dist-packages/aiohttp/streams.py\", line 317, in readline\n    return await self.readuntil()\n  File \"/usr/local/lib/python3.10/dist-packages/aiohttp/streams.py\", line 351, in readuntil\n    await self._wait(\"readuntil\")\n  File \"/usr/local/lib/python3.10/dist-packages/aiohttp/streams.py\", line 312, in _wait\n    await waiter\naiohttp.client_exceptions.ClientPayloadError: Response payload is not completed: <TransferEncodingError: 400, message='Not enough data for satisfy transfer length header.'>\n", "", "Traceback (most recent call last):\n  File \"/usr/local/lib/python3.10/dist-packages/aiohttp/client_proto.py\", line 94, in connection_lost\n    uncompleted = self._parser.feed_eof()\n  File \"aiohttp/_http_parser.pyx\", line 513, in aiohttp._http_parser.HttpParser.feed_eof\naiohttp.http_exceptions.TransferEncodingError: 400, message:\n  Not enough data for satisfy transfer length header.\n\nThe above exception was the direct cause of the following exception:\n\nTraceback (most recent call last):\n  File \"/vllm-workspace/backend_request_func.py\", line 261, in async_request_openai_completions\n    async for chunk_bytes in response.content:\n  File \"/usr/local/lib/python3.10/dist-packages/aiohttp/streams.py\", line 50, in __anext__\n    rv = await self.read_func()\n  File \"/usr/local/lib/python3.10/dist-packages/aiohttp/streams.py\", line 317, in readline\n    return await self.readuntil()\n  File \"/usr/local/lib/python3.10/dist-packages/aiohttp/streams.py\", line 351, in readuntil\n    await self._wait(\"readuntil\")\n  File \"/usr/local/lib/python3.10/dist-packages/aiohttp/streams.py\", line 312, in _wait\n    await waiter\naiohttp.client_exceptions.ClientPayloadError: Response payload is not completed: <TransferEncodingError: 400, message='Not enough data for satisfy transfer length header.'>\n", "Traceback (most recent call last):\n  File \"/usr/local/lib/python3.10/dist-packages/aiohttp/client_proto.py\", line 94, in connection_lost\n    uncompleted = self._parser.feed_eof()\n  File \"aiohttp/_http_parser.pyx\", line 513, in aiohttp._http_parser.HttpParser.feed_eof\naiohttp.http_exceptions.TransferEncodingError: 400, message:\n  Not enough data for satisfy transfer length header.\n\nThe above exception was the direct cause of the following exception:\n\nTraceback (most recent call last):\n  File \"/vllm-workspace/backend_request_func.py\", line 261, in async_request_openai_completions\n    async for chunk_bytes in response.content:\n  File \"/usr/local/lib/python3.10/dist-packages/aiohttp/streams.py\", line 50, in __anext__\n    rv = await self.read_func()\n  File \"/usr/local/lib/python3.10/dist-packages/aiohttp/streams.py\", line 317, in readline\n    return await self.readuntil()\n  File \"/usr/local/lib/python3.10/dist-packages/aiohttp/streams.py\", line 351, in readuntil\n    await self._wait(\"readuntil\")\n  File \"/usr/local/lib/python3.10/dist-packages/aiohttp/streams.py\", line 312, in _wait\n    await waiter\naiohttp.client_exceptions.ClientPayloadError: Response payload is not completed: <TransferEncodingError: 400, message='Not enough data for satisfy transfer length header.'>\n", "Traceback (most recent call last):\n  File \"/usr/local/lib/python3.10/dist-packages/aiohttp/client_proto.py\", line 94, in connection_lost\n    uncompleted = self._parser.feed_eof()\n  File \"aiohttp/_http_parser.pyx\", line 513, in aiohttp._http_parser.HttpParser.feed_eof\naiohttp.http_exceptions.TransferEncodingError: 400, message:\n  Not enough data for satisfy transfer length header.\n\nThe above exception was the direct cause of the following exception:\n\nTraceback (most recent call last):\n  File \"/vllm-workspace/backend_request_func.py\", line 261, in async_request_openai_completions\n    async for chunk_bytes in response.content:\n  File \"/usr/local/lib/python3.10/dist-packages/aiohttp/streams.py\", line 50, in __anext__\n    rv = await self.read_func()\n  File \"/usr/local/lib/python3.10/dist-packages/aiohttp/streams.py\", line 317, in readline\n    return await self.readuntil()\n  File \"/usr/local/lib/python3.10/dist-packages/aiohttp/streams.py\", line 351, in readuntil\n    await self._wait(\"readuntil\")\n  File \"/usr/local/lib/python3.10/dist-packages/aiohttp/streams.py\", line 312, in _wait\n    await waiter\naiohttp.client_exceptions.ClientPayloadError: Response payload is not completed: <TransferEncodingError: 400, message='Not enough data for satisfy transfer length header.'>\n", "Traceback (most recent call last):\n  File \"/usr/local/lib/python3.10/dist-packages/aiohttp/client_proto.py\", line 94, in connection_lost\n    uncompleted = self._parser.feed_eof()\n  File \"aiohttp/_http_parser.pyx\", line 513, in aiohttp._http_parser.HttpParser.feed_eof\naiohttp.http_exceptions.TransferEncodingError: 400, message:\n  Not enough data for satisfy transfer length header.\n\nThe above exception was the direct cause of the following exception:\n\nTraceback (most recent call last):\n  File \"/vllm-workspace/backend_request_func.py\", line 261, in async_request_openai_completions\n    async for chunk_bytes in response.content:\n  File \"/usr/local/lib/python3.10/dist-packages/aiohttp/streams.py\", line 50, in __anext__\n    rv = await self.read_func()\n  File \"/usr/local/lib/python3.10/dist-packages/aiohttp/streams.py\", line 317, in readline\n    return await self.readuntil()\n  File \"/usr/local/lib/python3.10/dist-packages/aiohttp/streams.py\", line 351, in readuntil\n    await self._wait(\"readuntil\")\n  File \"/usr/local/lib/python3.10/dist-packages/aiohttp/streams.py\", line 312, in _wait\n    await waiter\naiohttp.client_exceptions.ClientPayloadError: Response payload is not completed: <TransferEncodingError: 400, message='Not enough data for satisfy transfer length header.'>\n", "Traceback (most recent call last):\n  File \"/usr/local/lib/python3.10/dist-packages/aiohttp/client_proto.py\", line 94, in connection_lost\n    uncompleted = self._parser.feed_eof()\n  File \"aiohttp/_http_parser.pyx\", line 513, in aiohttp._http_parser.HttpParser.feed_eof\naiohttp.http_exceptions.TransferEncodingError: 400, message:\n  Not enough data for satisfy transfer length header.\n\nThe above exception was the direct cause of the following exception:\n\nTraceback (most recent call last):\n  File \"/vllm-workspace/backend_request_func.py\", line 261, in async_request_openai_completions\n    async for chunk_bytes in response.content:\n  File \"/usr/local/lib/python3.10/dist-packages/aiohttp/streams.py\", line 50, in __anext__\n    rv = await self.read_func()\n  File \"/usr/local/lib/python3.10/dist-packages/aiohttp/streams.py\", line 317, in readline\n    return await self.readuntil()\n  File \"/usr/local/lib/python3.10/dist-packages/aiohttp/streams.py\", line 351, in readuntil\n    await self._wait(\"readuntil\")\n  File \"/usr/local/lib/python3.10/dist-packages/aiohttp/streams.py\", line 312, in _wait\n    await waiter\naiohttp.client_exceptions.ClientPayloadError: Response payload is not completed: <TransferEncodingError: 400, message='Not enough data for satisfy transfer length header.'>\n", "Traceback (most recent call last):\n  File \"/usr/local/lib/python3.10/dist-packages/aiohttp/client_proto.py\", line 94, in connection_lost\n    uncompleted = self._parser.feed_eof()\n  File \"aiohttp/_http_parser.pyx\", line 513, in aiohttp._http_parser.HttpParser.feed_eof\naiohttp.http_exceptions.TransferEncodingError: 400, message:\n  Not enough data for satisfy transfer length header.\n\nThe above exception was the direct cause of the following exception:\n\nTraceback (most recent call last):\n  File \"/vllm-workspace/backend_request_func.py\", line 261, in async_request_openai_completions\n    async for chunk_bytes in response.content:\n  File \"/usr/local/lib/python3.10/dist-packages/aiohttp/streams.py\", line 50, in __anext__\n    rv = await self.read_func()\n  File \"/usr/local/lib/python3.10/dist-packages/aiohttp/streams.py\", line 317, in readline\n    return await self.readuntil()\n  File \"/usr/local/lib/python3.10/dist-packages/aiohttp/streams.py\", line 351, in readuntil\n    await self._wait(\"readuntil\")\n  File \"/usr/local/lib/python3.10/dist-packages/aiohttp/streams.py\", line 312, in _wait\n    await waiter\naiohttp.client_exceptions.ClientPayloadError: Response payload is not completed: <TransferEncodingError: 400, message='Not enough data for satisfy transfer length header.'>\n", "Traceback (most recent call last):\n  File \"/usr/local/lib/python3.10/dist-packages/aiohttp/client_proto.py\", line 94, in connection_lost\n    uncompleted = self._parser.feed_eof()\n  File \"aiohttp/_http_parser.pyx\", line 513, in aiohttp._http_parser.HttpParser.feed_eof\naiohttp.http_exceptions.TransferEncodingError: 400, message:\n  Not enough data for satisfy transfer length header.\n\nThe above exception was the direct cause of the following exception:\n\nTraceback (most recent call last):\n  File \"/vllm-workspace/backend_request_func.py\", line 261, in async_request_openai_completions\n    async for chunk_bytes in response.content:\n  File \"/usr/local/lib/python3.10/dist-packages/aiohttp/streams.py\", line 50, in __anext__\n    rv = await self.read_func()\n  File \"/usr/local/lib/python3.10/dist-packages/aiohttp/streams.py\", line 317, in readline\n    return await self.readuntil()\n  File \"/usr/local/lib/python3.10/dist-packages/aiohttp/streams.py\", line 351, in readuntil\n    await self._wait(\"readuntil\")\n  File \"/usr/local/lib/python3.10/dist-packages/aiohttp/streams.py\", line 312, in _wait\n    await waiter\naiohttp.client_exceptions.ClientPayloadError: Response payload is not completed: <TransferEncodingError: 400, message='Not enough data for satisfy transfer length header.'>\n", "Traceback (most recent call last):\n  File \"/usr/local/lib/python3.10/dist-packages/aiohttp/client_proto.py\", line 94, in connection_lost\n    uncompleted = self._parser.feed_eof()\n  File \"aiohttp/_http_parser.pyx\", line 513, in aiohttp._http_parser.HttpParser.feed_eof\naiohttp.http_exceptions.TransferEncodingError: 400, message:\n  Not enough data for satisfy transfer length header.\n\nThe above exception was the direct cause of the following exception:\n\nTraceback (most recent call last):\n  File \"/vllm-workspace/backend_request_func.py\", line 261, in async_request_openai_completions\n    async for chunk_bytes in response.content:\n  File \"/usr/local/lib/python3.10/dist-packages/aiohttp/streams.py\", line 50, in __anext__\n    rv = await self.read_func()\n  File \"/usr/local/lib/python3.10/dist-packages/aiohttp/streams.py\", line 317, in readline\n    return await self.readuntil()\n  File \"/usr/local/lib/python3.10/dist-packages/aiohttp/streams.py\", line 351, in readuntil\n    await self._wait(\"readuntil\")\n  File \"/usr/local/lib/python3.10/dist-packages/aiohttp/streams.py\", line 312, in _wait\n    await waiter\naiohttp.client_exceptions.ClientPayloadError: Response payload is not completed: <TransferEncodingError: 400, message='Not enough data for satisfy transfer length header.'>\n", "Traceback (most recent call last):\n  File \"/usr/local/lib/python3.10/dist-packages/aiohttp/client_proto.py\", line 94, in connection_lost\n    uncompleted = self._parser.feed_eof()\n  File \"aiohttp/_http_parser.pyx\", line 513, in aiohttp._http_parser.HttpParser.feed_eof\naiohttp.http_exceptions.TransferEncodingError: 400, message:\n  Not enough data for satisfy transfer length header.\n\nThe above exception was the direct cause of the following exception:\n\nTraceback (most recent call last):\n  File \"/vllm-workspace/backend_request_func.py\", line 261, in async_request_openai_completions\n    async for chunk_bytes in response.content:\n  File \"/usr/local/lib/python3.10/dist-packages/aiohttp/streams.py\", line 50, in __anext__\n    rv = await self.read_func()\n  File \"/usr/local/lib/python3.10/dist-packages/aiohttp/streams.py\", line 317, in readline\n    return await self.readuntil()\n  File \"/usr/local/lib/python3.10/dist-packages/aiohttp/streams.py\", line 351, in readuntil\n    await self._wait(\"readuntil\")\n  File \"/usr/local/lib/python3.10/dist-packages/aiohttp/streams.py\", line 312, in _wait\n    await waiter\naiohttp.client_exceptions.ClientPayloadError: Response payload is not completed: <TransferEncodingError: 400, message='Not enough data for satisfy transfer length header.'>\n", "Traceback (most recent call last):\n  File \"/usr/local/lib/python3.10/dist-packages/aiohttp/client_proto.py\", line 94, in connection_lost\n    uncompleted = self._parser.feed_eof()\n  File \"aiohttp/_http_parser.pyx\", line 513, in aiohttp._http_parser.HttpParser.feed_eof\naiohttp.http_exceptions.TransferEncodingError: 400, message:\n  Not enough data for satisfy transfer length header.\n\nThe above exception was the direct cause of the following exception:\n\nTraceback (most recent call last):\n  File \"/vllm-workspace/backend_request_func.py\", line 261, in async_request_openai_completions\n    async for chunk_bytes in response.content:\n  File \"/usr/local/lib/python3.10/dist-packages/aiohttp/streams.py\", line 50, in __anext__\n    rv = await self.read_func()\n  File \"/usr/local/lib/python3.10/dist-packages/aiohttp/streams.py\", line 317, in readline\n    return await self.readuntil()\n  File \"/usr/local/lib/python3.10/dist-packages/aiohttp/streams.py\", line 351, in readuntil\n    await self._wait(\"readuntil\")\n  File \"/usr/local/lib/python3.10/dist-packages/aiohttp/streams.py\", line 312, in _wait\n    await waiter\naiohttp.client_exceptions.ClientPayloadError: Response payload is not completed: <TransferEncodingError: 400, message='Not enough data for satisfy transfer length header.'>\n", "Traceback (most recent call last):\n  File \"/usr/local/lib/python3.10/dist-packages/aiohttp/client_proto.py\", line 94, in connection_lost\n    uncompleted = self._parser.feed_eof()\n  File \"aiohttp/_http_parser.pyx\", line 513, in aiohttp._http_parser.HttpParser.feed_eof\naiohttp.http_exceptions.TransferEncodingError: 400, message:\n  Not enough data for satisfy transfer length header.\n\nThe above exception was the direct cause of the following exception:\n\nTraceback (most recent call last):\n  File \"/vllm-workspace/backend_request_func.py\", line 261, in async_request_openai_completions\n    async for chunk_bytes in response.content:\n  File \"/usr/local/lib/python3.10/dist-packages/aiohttp/streams.py\", line 50, in __anext__\n    rv = await self.read_func()\n  File \"/usr/local/lib/python3.10/dist-packages/aiohttp/streams.py\", line 317, in readline\n    return await self.readuntil()\n  File \"/usr/local/lib/python3.10/dist-packages/aiohttp/streams.py\", line 351, in readuntil\n    await self._wait(\"readuntil\")\n  File \"/usr/local/lib/python3.10/dist-packages/aiohttp/streams.py\", line 312, in _wait\n    await waiter\naiohttp.client_exceptions.ClientPayloadError: Response payload is not completed: <TransferEncodingError: 400, message='Not enough data for satisfy transfer length header.'>\n", "Traceback (most recent call last):\n  File \"/usr/local/lib/python3.10/dist-packages/aiohttp/client_proto.py\", line 94, in connection_lost\n    uncompleted = self._parser.feed_eof()\n  File \"aiohttp/_http_parser.pyx\", line 513, in aiohttp._http_parser.HttpParser.feed_eof\naiohttp.http_exceptions.TransferEncodingError: 400, message:\n  Not enough data for satisfy transfer length header.\n\nThe above exception was the direct cause of the following exception:\n\nTraceback (most recent call last):\n  File \"/vllm-workspace/backend_request_func.py\", line 261, in async_request_openai_completions\n    async for chunk_bytes in response.content:\n  File \"/usr/local/lib/python3.10/dist-packages/aiohttp/streams.py\", line 50, in __anext__\n    rv = await self.read_func()\n  File \"/usr/local/lib/python3.10/dist-packages/aiohttp/streams.py\", line 317, in readline\n    return await self.readuntil()\n  File \"/usr/local/lib/python3.10/dist-packages/aiohttp/streams.py\", line 351, in readuntil\n    await self._wait(\"readuntil\")\n  File \"/usr/local/lib/python3.10/dist-packages/aiohttp/streams.py\", line 312, in _wait\n    await waiter\naiohttp.client_exceptions.ClientPayloadError: Response payload is not completed: <TransferEncodingError: 400, message='Not enough data for satisfy transfer length header.'>\n"]}