{"date": "20240907-085759", "backend": "vllm", "model_id": "neuralmagic/Meta-Llama-3.1-70B-Instruct-FP8", "tokenizer_id": "neuralmagic/Meta-Llama-3.1-70B-Instruct-FP8", "best_of": 1, "use_beam_search": false, "num_prompts": 40, "request_rate": "inf", "duration": 6.831055171787739, "completed": 5, "total_input_tokens": 2035, "total_output_tokens": 0, "request_throughput": 0.731951341961049, "input_throughput": 297.90419617814695, "output_throughput": 0.0, "mean_ttft_ms": 0.0, "median_ttft_ms": 0.0, "std_ttft_ms": 0.0, "p99_ttft_ms": 0.0, "mean_tpot_ms": 0.0, "median_tpot_ms": 0.0, "std_tpot_ms": 0.0, "p99_tpot_ms": 0.0, "mean_itl_ms": 0.0, "median_itl_ms": 0.0, "std_itl_ms": 0.0, "p99_itl_ms": 0.0, "mean_latency_ms": 569.3316580727696, "median_latency_ms": 0.0, "std_latency_ms": 1603.0367338993833, "p99_latency_ms": 6438.300065360962, "input_lens": [13, 25, 27, 10, 329, 29, 399, 328, 4, 205, 16, 372, 403, 9, 12, 770, 227, 8, 14, 390, 659, 59, 76, 744, 619, 279, 344, 9, 10, 45, 11, 4, 80, 768, 317, 40, 619, 8, 298, 16], "output_lens": [0, 0, 0, 0, 0, 0, 0, 0, 0, 0, 0, 0, 0, 0, 0, 0, 0, 0, 0, 0, 0, 0, 0, 0, 0, 0, 0, 0, 0, 0, 0, 0, 0, 0, 0, 0, 0, 0, 0, 0], "ttfts": [2.9566610157489777, 2.956314269453287, 2.9561025202274323, 2.955994840711355, 2.955873515456915, 2.9556127935647964, 0.0, 0.0, 2.954059913754463, 2.9539928138256073, 2.953485731035471, 0.0, 2.9532489106059074, 4.1647608652710915, 4.164673022925854, 4.16464314982295, 4.163901697844267, 4.163788463920355, 4.163887187838554, 4.163463592529297, 5.9333592019975185, 5.933223161846399, 5.9331973269581795, 6.7596163004636765, 0.0, 6.7595097199082375, 5.932444725185633, 6.762071695178747, 6.759039711207151, 6.758502766489983, 6.758340425789356, 6.758482553064823, 6.7608299516141415, 6.758194372057915, 0.0, 6.757876809686422, 6.759721104055643, 6.7595653384923935, 0.0, 6.759382795542479], "itls": [[], [], [], [], [], [], [], [], [], [], [], [], [], [], [], [], [], [], [], [], [], [], [], [], [], [], [], [], [], [], [], [], [], [], [], [], [], [], [], []], "generated_texts": ["", "", "", "", "", "", "", "", "", "", "", "", "", "", "", "", "", "", "", "", "", "", "", "", "", "", "", "", "", "", "", "", "", "", "", "", "", "", "", ""], "errors": ["Traceback (most recent call last):\n  File \"/usr/local/lib/python3.10/dist-packages/aiohttp/client_proto.py\", line 94, in connection_lost\n    uncompleted = self._parser.feed_eof()\n  File \"aiohttp/_http_parser.pyx\", line 513, in aiohttp._http_parser.HttpParser.feed_eof\naiohttp.http_exceptions.TransferEncodingError: 400, message:\n  Not enough data for satisfy transfer length header.\n\nThe above exception was the direct cause of the following exception:\n\nTraceback (most recent call last):\n  File \"/vllm-workspace/backend_request_func.py\", line 261, in async_request_openai_completions\n    async for chunk_bytes in response.content:\n  File \"/usr/local/lib/python3.10/dist-packages/aiohttp/streams.py\", line 50, in __anext__\n    rv = await self.read_func()\n  File \"/usr/local/lib/python3.10/dist-packages/aiohttp/streams.py\", line 317, in readline\n    return await self.readuntil()\n  File \"/usr/local/lib/python3.10/dist-packages/aiohttp/streams.py\", line 351, in readuntil\n    await self._wait(\"readuntil\")\n  File \"/usr/local/lib/python3.10/dist-packages/aiohttp/streams.py\", line 312, in _wait\n    await waiter\naiohttp.client_exceptions.ClientPayloadError: Response payload is not completed: <TransferEncodingError: 400, message='Not enough data for satisfy transfer length header.'>\n", "Traceback (most recent call last):\n  File \"/usr/local/lib/python3.10/dist-packages/aiohttp/client_proto.py\", line 94, in connection_lost\n    uncompleted = self._parser.feed_eof()\n  File \"aiohttp/_http_parser.pyx\", line 513, in aiohttp._http_parser.HttpParser.feed_eof\naiohttp.http_exceptions.TransferEncodingError: 400, message:\n  Not enough data for satisfy transfer length header.\n\nThe above exception was the direct cause of the following exception:\n\nTraceback (most recent call last):\n  File \"/vllm-workspace/backend_request_func.py\", line 261, in async_request_openai_completions\n    async for chunk_bytes in response.content:\n  File \"/usr/local/lib/python3.10/dist-packages/aiohttp/streams.py\", line 50, in __anext__\n    rv = await self.read_func()\n  File \"/usr/local/lib/python3.10/dist-packages/aiohttp/streams.py\", line 317, in readline\n    return await self.readuntil()\n  File \"/usr/local/lib/python3.10/dist-packages/aiohttp/streams.py\", line 351, in readuntil\n    await self._wait(\"readuntil\")\n  File \"/usr/local/lib/python3.10/dist-packages/aiohttp/streams.py\", line 312, in _wait\n    await waiter\naiohttp.client_exceptions.ClientPayloadError: Response payload is not completed: <TransferEncodingError: 400, message='Not enough data for satisfy transfer length header.'>\n", "Traceback (most recent call last):\n  File \"/usr/local/lib/python3.10/dist-packages/aiohttp/client_proto.py\", line 94, in connection_lost\n    uncompleted = self._parser.feed_eof()\n  File \"aiohttp/_http_parser.pyx\", line 513, in aiohttp._http_parser.HttpParser.feed_eof\naiohttp.http_exceptions.TransferEncodingError: 400, message:\n  Not enough data for satisfy transfer length header.\n\nThe above exception was the direct cause of the following exception:\n\nTraceback (most recent call last):\n  File \"/vllm-workspace/backend_request_func.py\", line 261, in async_request_openai_completions\n    async for chunk_bytes in response.content:\n  File \"/usr/local/lib/python3.10/dist-packages/aiohttp/streams.py\", line 50, in __anext__\n    rv = await self.read_func()\n  File \"/usr/local/lib/python3.10/dist-packages/aiohttp/streams.py\", line 317, in readline\n    return await self.readuntil()\n  File \"/usr/local/lib/python3.10/dist-packages/aiohttp/streams.py\", line 351, in readuntil\n    await self._wait(\"readuntil\")\n  File \"/usr/local/lib/python3.10/dist-packages/aiohttp/streams.py\", line 312, in _wait\n    await waiter\naiohttp.client_exceptions.ClientPayloadError: Response payload is not completed: <TransferEncodingError: 400, message='Not enough data for satisfy transfer length header.'>\n", "Traceback (most recent call last):\n  File \"/usr/local/lib/python3.10/dist-packages/aiohttp/client_proto.py\", line 94, in connection_lost\n    uncompleted = self._parser.feed_eof()\n  File \"aiohttp/_http_parser.pyx\", line 513, in aiohttp._http_parser.HttpParser.feed_eof\naiohttp.http_exceptions.TransferEncodingError: 400, message:\n  Not enough data for satisfy transfer length header.\n\nThe above exception was the direct cause of the following exception:\n\nTraceback (most recent call last):\n  File \"/vllm-workspace/backend_request_func.py\", line 261, in async_request_openai_completions\n    async for chunk_bytes in response.content:\n  File \"/usr/local/lib/python3.10/dist-packages/aiohttp/streams.py\", line 50, in __anext__\n    rv = await self.read_func()\n  File \"/usr/local/lib/python3.10/dist-packages/aiohttp/streams.py\", line 317, in readline\n    return await self.readuntil()\n  File \"/usr/local/lib/python3.10/dist-packages/aiohttp/streams.py\", line 351, in readuntil\n    await self._wait(\"readuntil\")\n  File \"/usr/local/lib/python3.10/dist-packages/aiohttp/streams.py\", line 312, in _wait\n    await waiter\naiohttp.client_exceptions.ClientPayloadError: Response payload is not completed: <TransferEncodingError: 400, message='Not enough data for satisfy transfer length header.'>\n", "Traceback (most recent call last):\n  File \"/usr/local/lib/python3.10/dist-packages/aiohttp/client_proto.py\", line 94, in connection_lost\n    uncompleted = self._parser.feed_eof()\n  File \"aiohttp/_http_parser.pyx\", line 513, in aiohttp._http_parser.HttpParser.feed_eof\naiohttp.http_exceptions.TransferEncodingError: 400, message:\n  Not enough data for satisfy transfer length header.\n\nThe above exception was the direct cause of the following exception:\n\nTraceback (most recent call last):\n  File \"/vllm-workspace/backend_request_func.py\", line 261, in async_request_openai_completions\n    async for chunk_bytes in response.content:\n  File \"/usr/local/lib/python3.10/dist-packages/aiohttp/streams.py\", line 50, in __anext__\n    rv = await self.read_func()\n  File \"/usr/local/lib/python3.10/dist-packages/aiohttp/streams.py\", line 317, in readline\n    return await self.readuntil()\n  File \"/usr/local/lib/python3.10/dist-packages/aiohttp/streams.py\", line 351, in readuntil\n    await self._wait(\"readuntil\")\n  File \"/usr/local/lib/python3.10/dist-packages/aiohttp/streams.py\", line 312, in _wait\n    await waiter\naiohttp.client_exceptions.ClientPayloadError: Response payload is not completed: <TransferEncodingError: 400, message='Not enough data for satisfy transfer length header.'>\n", "Traceback (most recent call last):\n  File \"/usr/local/lib/python3.10/dist-packages/aiohttp/client_proto.py\", line 94, in connection_lost\n    uncompleted = self._parser.feed_eof()\n  File \"aiohttp/_http_parser.pyx\", line 513, in aiohttp._http_parser.HttpParser.feed_eof\naiohttp.http_exceptions.TransferEncodingError: 400, message:\n  Not enough data for satisfy transfer length header.\n\nThe above exception was the direct cause of the following exception:\n\nTraceback (most recent call last):\n  File \"/vllm-workspace/backend_request_func.py\", line 261, in async_request_openai_completions\n    async for chunk_bytes in response.content:\n  File \"/usr/local/lib/python3.10/dist-packages/aiohttp/streams.py\", line 50, in __anext__\n    rv = await self.read_func()\n  File \"/usr/local/lib/python3.10/dist-packages/aiohttp/streams.py\", line 317, in readline\n    return await self.readuntil()\n  File \"/usr/local/lib/python3.10/dist-packages/aiohttp/streams.py\", line 351, in readuntil\n    await self._wait(\"readuntil\")\n  File \"/usr/local/lib/python3.10/dist-packages/aiohttp/streams.py\", line 312, in _wait\n    await waiter\naiohttp.client_exceptions.ClientPayloadError: Response payload is not completed: <TransferEncodingError: 400, message='Not enough data for satisfy transfer length header.'>\n", "", "", "Traceback (most recent call last):\n  File \"/usr/local/lib/python3.10/dist-packages/aiohttp/client_proto.py\", line 94, in connection_lost\n    uncompleted = self._parser.feed_eof()\n  File \"aiohttp/_http_parser.pyx\", line 513, in aiohttp._http_parser.HttpParser.feed_eof\naiohttp.http_exceptions.TransferEncodingError: 400, message:\n  Not enough data for satisfy transfer length header.\n\nThe above exception was the direct cause of the following exception:\n\nTraceback (most recent call last):\n  File \"/vllm-workspace/backend_request_func.py\", line 261, in async_request_openai_completions\n    async for chunk_bytes in response.content:\n  File \"/usr/local/lib/python3.10/dist-packages/aiohttp/streams.py\", line 50, in __anext__\n    rv = await self.read_func()\n  File \"/usr/local/lib/python3.10/dist-packages/aiohttp/streams.py\", line 317, in readline\n    return await self.readuntil()\n  File \"/usr/local/lib/python3.10/dist-packages/aiohttp/streams.py\", line 351, in readuntil\n    await self._wait(\"readuntil\")\n  File \"/usr/local/lib/python3.10/dist-packages/aiohttp/streams.py\", line 312, in _wait\n    await waiter\naiohttp.client_exceptions.ClientPayloadError: Response payload is not completed: <TransferEncodingError: 400, message='Not enough data for satisfy transfer length header.'>\n", "Traceback (most recent call last):\n  File \"/usr/local/lib/python3.10/dist-packages/aiohttp/client_proto.py\", line 94, in connection_lost\n    uncompleted = self._parser.feed_eof()\n  File \"aiohttp/_http_parser.pyx\", line 513, in aiohttp._http_parser.HttpParser.feed_eof\naiohttp.http_exceptions.TransferEncodingError: 400, message:\n  Not enough data for satisfy transfer length header.\n\nThe above exception was the direct cause of the following exception:\n\nTraceback (most recent call last):\n  File \"/vllm-workspace/backend_request_func.py\", line 261, in async_request_openai_completions\n    async for chunk_bytes in response.content:\n  File \"/usr/local/lib/python3.10/dist-packages/aiohttp/streams.py\", line 50, in __anext__\n    rv = await self.read_func()\n  File \"/usr/local/lib/python3.10/dist-packages/aiohttp/streams.py\", line 317, in readline\n    return await self.readuntil()\n  File \"/usr/local/lib/python3.10/dist-packages/aiohttp/streams.py\", line 351, in readuntil\n    await self._wait(\"readuntil\")\n  File \"/usr/local/lib/python3.10/dist-packages/aiohttp/streams.py\", line 312, in _wait\n    await waiter\naiohttp.client_exceptions.ClientPayloadError: Response payload is not completed: <TransferEncodingError: 400, message='Not enough data for satisfy transfer length header.'>\n", "Traceback (most recent call last):\n  File \"/usr/local/lib/python3.10/dist-packages/aiohttp/client_proto.py\", line 94, in connection_lost\n    uncompleted = self._parser.feed_eof()\n  File \"aiohttp/_http_parser.pyx\", line 513, in aiohttp._http_parser.HttpParser.feed_eof\naiohttp.http_exceptions.TransferEncodingError: 400, message:\n  Not enough data for satisfy transfer length header.\n\nThe above exception was the direct cause of the following exception:\n\nTraceback (most recent call last):\n  File \"/vllm-workspace/backend_request_func.py\", line 261, in async_request_openai_completions\n    async for chunk_bytes in response.content:\n  File \"/usr/local/lib/python3.10/dist-packages/aiohttp/streams.py\", line 50, in __anext__\n    rv = await self.read_func()\n  File \"/usr/local/lib/python3.10/dist-packages/aiohttp/streams.py\", line 317, in readline\n    return await self.readuntil()\n  File \"/usr/local/lib/python3.10/dist-packages/aiohttp/streams.py\", line 351, in readuntil\n    await self._wait(\"readuntil\")\n  File \"/usr/local/lib/python3.10/dist-packages/aiohttp/streams.py\", line 312, in _wait\n    await waiter\naiohttp.client_exceptions.ClientPayloadError: Response payload is not completed: <TransferEncodingError: 400, message='Not enough data for satisfy transfer length header.'>\n", "", "Traceback (most recent call last):\n  File \"/usr/local/lib/python3.10/dist-packages/aiohttp/client_proto.py\", line 94, in connection_lost\n    uncompleted = self._parser.feed_eof()\n  File \"aiohttp/_http_parser.pyx\", line 513, in aiohttp._http_parser.HttpParser.feed_eof\naiohttp.http_exceptions.TransferEncodingError: 400, message:\n  Not enough data for satisfy transfer length header.\n\nThe above exception was the direct cause of the following exception:\n\nTraceback (most recent call last):\n  File \"/vllm-workspace/backend_request_func.py\", line 261, in async_request_openai_completions\n    async for chunk_bytes in response.content:\n  File \"/usr/local/lib/python3.10/dist-packages/aiohttp/streams.py\", line 50, in __anext__\n    rv = await self.read_func()\n  File \"/usr/local/lib/python3.10/dist-packages/aiohttp/streams.py\", line 317, in readline\n    return await self.readuntil()\n  File \"/usr/local/lib/python3.10/dist-packages/aiohttp/streams.py\", line 351, in readuntil\n    await self._wait(\"readuntil\")\n  File \"/usr/local/lib/python3.10/dist-packages/aiohttp/streams.py\", line 312, in _wait\n    await waiter\naiohttp.client_exceptions.ClientPayloadError: Response payload is not completed: <TransferEncodingError: 400, message='Not enough data for satisfy transfer length header.'>\n", "Traceback (most recent call last):\n  File \"/usr/local/lib/python3.10/dist-packages/aiohttp/client_proto.py\", line 94, in connection_lost\n    uncompleted = self._parser.feed_eof()\n  File \"aiohttp/_http_parser.pyx\", line 513, in aiohttp._http_parser.HttpParser.feed_eof\naiohttp.http_exceptions.TransferEncodingError: 400, message:\n  Not enough data for satisfy transfer length header.\n\nThe above exception was the direct cause of the following exception:\n\nTraceback (most recent call last):\n  File \"/vllm-workspace/backend_request_func.py\", line 261, in async_request_openai_completions\n    async for chunk_bytes in response.content:\n  File \"/usr/local/lib/python3.10/dist-packages/aiohttp/streams.py\", line 50, in __anext__\n    rv = await self.read_func()\n  File \"/usr/local/lib/python3.10/dist-packages/aiohttp/streams.py\", line 317, in readline\n    return await self.readuntil()\n  File \"/usr/local/lib/python3.10/dist-packages/aiohttp/streams.py\", line 351, in readuntil\n    await self._wait(\"readuntil\")\n  File \"/usr/local/lib/python3.10/dist-packages/aiohttp/streams.py\", line 312, in _wait\n    await waiter\naiohttp.client_exceptions.ClientPayloadError: Response payload is not completed: <TransferEncodingError: 400, message='Not enough data for satisfy transfer length header.'>\n", "Traceback (most recent call last):\n  File \"/usr/local/lib/python3.10/dist-packages/aiohttp/client_proto.py\", line 94, in connection_lost\n    uncompleted = self._parser.feed_eof()\n  File \"aiohttp/_http_parser.pyx\", line 513, in aiohttp._http_parser.HttpParser.feed_eof\naiohttp.http_exceptions.TransferEncodingError: 400, message:\n  Not enough data for satisfy transfer length header.\n\nThe above exception was the direct cause of the following exception:\n\nTraceback (most recent call last):\n  File \"/vllm-workspace/backend_request_func.py\", line 261, in async_request_openai_completions\n    async for chunk_bytes in response.content:\n  File \"/usr/local/lib/python3.10/dist-packages/aiohttp/streams.py\", line 50, in __anext__\n    rv = await self.read_func()\n  File \"/usr/local/lib/python3.10/dist-packages/aiohttp/streams.py\", line 317, in readline\n    return await self.readuntil()\n  File \"/usr/local/lib/python3.10/dist-packages/aiohttp/streams.py\", line 351, in readuntil\n    await self._wait(\"readuntil\")\n  File \"/usr/local/lib/python3.10/dist-packages/aiohttp/streams.py\", line 312, in _wait\n    await waiter\naiohttp.client_exceptions.ClientPayloadError: Response payload is not completed: <TransferEncodingError: 400, message='Not enough data for satisfy transfer length header.'>\n", "Traceback (most recent call last):\n  File \"/usr/local/lib/python3.10/dist-packages/aiohttp/client_proto.py\", line 94, in connection_lost\n    uncompleted = self._parser.feed_eof()\n  File \"aiohttp/_http_parser.pyx\", line 513, in aiohttp._http_parser.HttpParser.feed_eof\naiohttp.http_exceptions.TransferEncodingError: 400, message:\n  Not enough data for satisfy transfer length header.\n\nThe above exception was the direct cause of the following exception:\n\nTraceback (most recent call last):\n  File \"/vllm-workspace/backend_request_func.py\", line 261, in async_request_openai_completions\n    async for chunk_bytes in response.content:\n  File \"/usr/local/lib/python3.10/dist-packages/aiohttp/streams.py\", line 50, in __anext__\n    rv = await self.read_func()\n  File \"/usr/local/lib/python3.10/dist-packages/aiohttp/streams.py\", line 317, in readline\n    return await self.readuntil()\n  File \"/usr/local/lib/python3.10/dist-packages/aiohttp/streams.py\", line 351, in readuntil\n    await self._wait(\"readuntil\")\n  File \"/usr/local/lib/python3.10/dist-packages/aiohttp/streams.py\", line 312, in _wait\n    await waiter\naiohttp.client_exceptions.ClientPayloadError: Response payload is not completed: <TransferEncodingError: 400, message='Not enough data for satisfy transfer length header.'>\n", "Traceback (most recent call last):\n  File \"/usr/local/lib/python3.10/dist-packages/aiohttp/client_proto.py\", line 94, in connection_lost\n    uncompleted = self._parser.feed_eof()\n  File \"aiohttp/_http_parser.pyx\", line 513, in aiohttp._http_parser.HttpParser.feed_eof\naiohttp.http_exceptions.TransferEncodingError: 400, message:\n  Not enough data for satisfy transfer length header.\n\nThe above exception was the direct cause of the following exception:\n\nTraceback (most recent call last):\n  File \"/vllm-workspace/backend_request_func.py\", line 261, in async_request_openai_completions\n    async for chunk_bytes in response.content:\n  File \"/usr/local/lib/python3.10/dist-packages/aiohttp/streams.py\", line 50, in __anext__\n    rv = await self.read_func()\n  File \"/usr/local/lib/python3.10/dist-packages/aiohttp/streams.py\", line 317, in readline\n    return await self.readuntil()\n  File \"/usr/local/lib/python3.10/dist-packages/aiohttp/streams.py\", line 351, in readuntil\n    await self._wait(\"readuntil\")\n  File \"/usr/local/lib/python3.10/dist-packages/aiohttp/streams.py\", line 312, in _wait\n    await waiter\naiohttp.client_exceptions.ClientPayloadError: Response payload is not completed: <TransferEncodingError: 400, message='Not enough data for satisfy transfer length header.'>\n", "Traceback (most recent call last):\n  File \"/usr/local/lib/python3.10/dist-packages/aiohttp/client_proto.py\", line 94, in connection_lost\n    uncompleted = self._parser.feed_eof()\n  File \"aiohttp/_http_parser.pyx\", line 513, in aiohttp._http_parser.HttpParser.feed_eof\naiohttp.http_exceptions.TransferEncodingError: 400, message:\n  Not enough data for satisfy transfer length header.\n\nThe above exception was the direct cause of the following exception:\n\nTraceback (most recent call last):\n  File \"/vllm-workspace/backend_request_func.py\", line 261, in async_request_openai_completions\n    async for chunk_bytes in response.content:\n  File \"/usr/local/lib/python3.10/dist-packages/aiohttp/streams.py\", line 50, in __anext__\n    rv = await self.read_func()\n  File \"/usr/local/lib/python3.10/dist-packages/aiohttp/streams.py\", line 317, in readline\n    return await self.readuntil()\n  File \"/usr/local/lib/python3.10/dist-packages/aiohttp/streams.py\", line 351, in readuntil\n    await self._wait(\"readuntil\")\n  File \"/usr/local/lib/python3.10/dist-packages/aiohttp/streams.py\", line 312, in _wait\n    await waiter\naiohttp.client_exceptions.ClientPayloadError: Response payload is not completed: <TransferEncodingError: 400, message='Not enough data for satisfy transfer length header.'>\n", "Traceback (most recent call last):\n  File \"/usr/local/lib/python3.10/dist-packages/aiohttp/client_proto.py\", line 94, in connection_lost\n    uncompleted = self._parser.feed_eof()\n  File \"aiohttp/_http_parser.pyx\", line 513, in aiohttp._http_parser.HttpParser.feed_eof\naiohttp.http_exceptions.TransferEncodingError: 400, message:\n  Not enough data for satisfy transfer length header.\n\nThe above exception was the direct cause of the following exception:\n\nTraceback (most recent call last):\n  File \"/vllm-workspace/backend_request_func.py\", line 261, in async_request_openai_completions\n    async for chunk_bytes in response.content:\n  File \"/usr/local/lib/python3.10/dist-packages/aiohttp/streams.py\", line 50, in __anext__\n    rv = await self.read_func()\n  File \"/usr/local/lib/python3.10/dist-packages/aiohttp/streams.py\", line 317, in readline\n    return await self.readuntil()\n  File \"/usr/local/lib/python3.10/dist-packages/aiohttp/streams.py\", line 351, in readuntil\n    await self._wait(\"readuntil\")\n  File \"/usr/local/lib/python3.10/dist-packages/aiohttp/streams.py\", line 312, in _wait\n    await waiter\naiohttp.client_exceptions.ClientPayloadError: Response payload is not completed: <TransferEncodingError: 400, message='Not enough data for satisfy transfer length header.'>\n", "Traceback (most recent call last):\n  File \"/usr/local/lib/python3.10/dist-packages/aiohttp/client_proto.py\", line 94, in connection_lost\n    uncompleted = self._parser.feed_eof()\n  File \"aiohttp/_http_parser.pyx\", line 513, in aiohttp._http_parser.HttpParser.feed_eof\naiohttp.http_exceptions.TransferEncodingError: 400, message:\n  Not enough data for satisfy transfer length header.\n\nThe above exception was the direct cause of the following exception:\n\nTraceback (most recent call last):\n  File \"/vllm-workspace/backend_request_func.py\", line 261, in async_request_openai_completions\n    async for chunk_bytes in response.content:\n  File \"/usr/local/lib/python3.10/dist-packages/aiohttp/streams.py\", line 50, in __anext__\n    rv = await self.read_func()\n  File \"/usr/local/lib/python3.10/dist-packages/aiohttp/streams.py\", line 317, in readline\n    return await self.readuntil()\n  File \"/usr/local/lib/python3.10/dist-packages/aiohttp/streams.py\", line 351, in readuntil\n    await self._wait(\"readuntil\")\n  File \"/usr/local/lib/python3.10/dist-packages/aiohttp/streams.py\", line 312, in _wait\n    await waiter\naiohttp.client_exceptions.ClientPayloadError: Response payload is not completed: <TransferEncodingError: 400, message='Not enough data for satisfy transfer length header.'>\n", "Traceback (most recent call last):\n  File \"/usr/local/lib/python3.10/dist-packages/aiohttp/client_proto.py\", line 94, in connection_lost\n    uncompleted = self._parser.feed_eof()\n  File \"aiohttp/_http_parser.pyx\", line 513, in aiohttp._http_parser.HttpParser.feed_eof\naiohttp.http_exceptions.TransferEncodingError: 400, message:\n  Not enough data for satisfy transfer length header.\n\nThe above exception was the direct cause of the following exception:\n\nTraceback (most recent call last):\n  File \"/vllm-workspace/backend_request_func.py\", line 261, in async_request_openai_completions\n    async for chunk_bytes in response.content:\n  File \"/usr/local/lib/python3.10/dist-packages/aiohttp/streams.py\", line 50, in __anext__\n    rv = await self.read_func()\n  File \"/usr/local/lib/python3.10/dist-packages/aiohttp/streams.py\", line 317, in readline\n    return await self.readuntil()\n  File \"/usr/local/lib/python3.10/dist-packages/aiohttp/streams.py\", line 351, in readuntil\n    await self._wait(\"readuntil\")\n  File \"/usr/local/lib/python3.10/dist-packages/aiohttp/streams.py\", line 312, in _wait\n    await waiter\naiohttp.client_exceptions.ClientPayloadError: Response payload is not completed: <TransferEncodingError: 400, message='Not enough data for satisfy transfer length header.'>\n", "Traceback (most recent call last):\n  File \"/usr/local/lib/python3.10/dist-packages/aiohttp/client_proto.py\", line 94, in connection_lost\n    uncompleted = self._parser.feed_eof()\n  File \"aiohttp/_http_parser.pyx\", line 513, in aiohttp._http_parser.HttpParser.feed_eof\naiohttp.http_exceptions.TransferEncodingError: 400, message:\n  Not enough data for satisfy transfer length header.\n\nThe above exception was the direct cause of the following exception:\n\nTraceback (most recent call last):\n  File \"/vllm-workspace/backend_request_func.py\", line 261, in async_request_openai_completions\n    async for chunk_bytes in response.content:\n  File \"/usr/local/lib/python3.10/dist-packages/aiohttp/streams.py\", line 50, in __anext__\n    rv = await self.read_func()\n  File \"/usr/local/lib/python3.10/dist-packages/aiohttp/streams.py\", line 317, in readline\n    return await self.readuntil()\n  File \"/usr/local/lib/python3.10/dist-packages/aiohttp/streams.py\", line 351, in readuntil\n    await self._wait(\"readuntil\")\n  File \"/usr/local/lib/python3.10/dist-packages/aiohttp/streams.py\", line 312, in _wait\n    await waiter\naiohttp.client_exceptions.ClientPayloadError: Response payload is not completed: <TransferEncodingError: 400, message='Not enough data for satisfy transfer length header.'>\n", "Traceback (most recent call last):\n  File \"/usr/local/lib/python3.10/dist-packages/aiohttp/client_proto.py\", line 94, in connection_lost\n    uncompleted = self._parser.feed_eof()\n  File \"aiohttp/_http_parser.pyx\", line 513, in aiohttp._http_parser.HttpParser.feed_eof\naiohttp.http_exceptions.TransferEncodingError: 400, message:\n  Not enough data for satisfy transfer length header.\n\nThe above exception was the direct cause of the following exception:\n\nTraceback (most recent call last):\n  File \"/vllm-workspace/backend_request_func.py\", line 261, in async_request_openai_completions\n    async for chunk_bytes in response.content:\n  File \"/usr/local/lib/python3.10/dist-packages/aiohttp/streams.py\", line 50, in __anext__\n    rv = await self.read_func()\n  File \"/usr/local/lib/python3.10/dist-packages/aiohttp/streams.py\", line 317, in readline\n    return await self.readuntil()\n  File \"/usr/local/lib/python3.10/dist-packages/aiohttp/streams.py\", line 351, in readuntil\n    await self._wait(\"readuntil\")\n  File \"/usr/local/lib/python3.10/dist-packages/aiohttp/streams.py\", line 312, in _wait\n    await waiter\naiohttp.client_exceptions.ClientPayloadError: Response payload is not completed: <TransferEncodingError: 400, message='Not enough data for satisfy transfer length header.'>\n", "Traceback (most recent call last):\n  File \"/usr/local/lib/python3.10/dist-packages/aiohttp/client_proto.py\", line 94, in connection_lost\n    uncompleted = self._parser.feed_eof()\n  File \"aiohttp/_http_parser.pyx\", line 513, in aiohttp._http_parser.HttpParser.feed_eof\naiohttp.http_exceptions.TransferEncodingError: 400, message:\n  Not enough data for satisfy transfer length header.\n\nThe above exception was the direct cause of the following exception:\n\nTraceback (most recent call last):\n  File \"/vllm-workspace/backend_request_func.py\", line 261, in async_request_openai_completions\n    async for chunk_bytes in response.content:\n  File \"/usr/local/lib/python3.10/dist-packages/aiohttp/streams.py\", line 50, in __anext__\n    rv = await self.read_func()\n  File \"/usr/local/lib/python3.10/dist-packages/aiohttp/streams.py\", line 317, in readline\n    return await self.readuntil()\n  File \"/usr/local/lib/python3.10/dist-packages/aiohttp/streams.py\", line 351, in readuntil\n    await self._wait(\"readuntil\")\n  File \"/usr/local/lib/python3.10/dist-packages/aiohttp/streams.py\", line 312, in _wait\n    await waiter\naiohttp.client_exceptions.ClientPayloadError: Response payload is not completed: <TransferEncodingError: 400, message='Not enough data for satisfy transfer length header.'>\n", "", "Traceback (most recent call last):\n  File \"/usr/local/lib/python3.10/dist-packages/aiohttp/client_proto.py\", line 94, in connection_lost\n    uncompleted = self._parser.feed_eof()\n  File \"aiohttp/_http_parser.pyx\", line 513, in aiohttp._http_parser.HttpParser.feed_eof\naiohttp.http_exceptions.TransferEncodingError: 400, message:\n  Not enough data for satisfy transfer length header.\n\nThe above exception was the direct cause of the following exception:\n\nTraceback (most recent call last):\n  File \"/vllm-workspace/backend_request_func.py\", line 261, in async_request_openai_completions\n    async for chunk_bytes in response.content:\n  File \"/usr/local/lib/python3.10/dist-packages/aiohttp/streams.py\", line 50, in __anext__\n    rv = await self.read_func()\n  File \"/usr/local/lib/python3.10/dist-packages/aiohttp/streams.py\", line 317, in readline\n    return await self.readuntil()\n  File \"/usr/local/lib/python3.10/dist-packages/aiohttp/streams.py\", line 351, in readuntil\n    await self._wait(\"readuntil\")\n  File \"/usr/local/lib/python3.10/dist-packages/aiohttp/streams.py\", line 312, in _wait\n    await waiter\naiohttp.client_exceptions.ClientPayloadError: Response payload is not completed: <TransferEncodingError: 400, message='Not enough data for satisfy transfer length header.'>\n", "Traceback (most recent call last):\n  File \"/usr/local/lib/python3.10/dist-packages/aiohttp/client_proto.py\", line 94, in connection_lost\n    uncompleted = self._parser.feed_eof()\n  File \"aiohttp/_http_parser.pyx\", line 513, in aiohttp._http_parser.HttpParser.feed_eof\naiohttp.http_exceptions.TransferEncodingError: 400, message:\n  Not enough data for satisfy transfer length header.\n\nThe above exception was the direct cause of the following exception:\n\nTraceback (most recent call last):\n  File \"/vllm-workspace/backend_request_func.py\", line 261, in async_request_openai_completions\n    async for chunk_bytes in response.content:\n  File \"/usr/local/lib/python3.10/dist-packages/aiohttp/streams.py\", line 50, in __anext__\n    rv = await self.read_func()\n  File \"/usr/local/lib/python3.10/dist-packages/aiohttp/streams.py\", line 317, in readline\n    return await self.readuntil()\n  File \"/usr/local/lib/python3.10/dist-packages/aiohttp/streams.py\", line 351, in readuntil\n    await self._wait(\"readuntil\")\n  File \"/usr/local/lib/python3.10/dist-packages/aiohttp/streams.py\", line 312, in _wait\n    await waiter\naiohttp.client_exceptions.ClientPayloadError: Response payload is not completed: <TransferEncodingError: 400, message='Not enough data for satisfy transfer length header.'>\n", "Traceback (most recent call last):\n  File \"/usr/local/lib/python3.10/dist-packages/aiohttp/client_proto.py\", line 94, in connection_lost\n    uncompleted = self._parser.feed_eof()\n  File \"aiohttp/_http_parser.pyx\", line 513, in aiohttp._http_parser.HttpParser.feed_eof\naiohttp.http_exceptions.TransferEncodingError: 400, message:\n  Not enough data for satisfy transfer length header.\n\nThe above exception was the direct cause of the following exception:\n\nTraceback (most recent call last):\n  File \"/vllm-workspace/backend_request_func.py\", line 261, in async_request_openai_completions\n    async for chunk_bytes in response.content:\n  File \"/usr/local/lib/python3.10/dist-packages/aiohttp/streams.py\", line 50, in __anext__\n    rv = await self.read_func()\n  File \"/usr/local/lib/python3.10/dist-packages/aiohttp/streams.py\", line 317, in readline\n    return await self.readuntil()\n  File \"/usr/local/lib/python3.10/dist-packages/aiohttp/streams.py\", line 351, in readuntil\n    await self._wait(\"readuntil\")\n  File \"/usr/local/lib/python3.10/dist-packages/aiohttp/streams.py\", line 312, in _wait\n    await waiter\naiohttp.client_exceptions.ClientPayloadError: Response payload is not completed: <TransferEncodingError: 400, message='Not enough data for satisfy transfer length header.'>\n", "Traceback (most recent call last):\n  File \"/usr/local/lib/python3.10/dist-packages/aiohttp/client_proto.py\", line 94, in connection_lost\n    uncompleted = self._parser.feed_eof()\n  File \"aiohttp/_http_parser.pyx\", line 513, in aiohttp._http_parser.HttpParser.feed_eof\naiohttp.http_exceptions.TransferEncodingError: 400, message:\n  Not enough data for satisfy transfer length header.\n\nThe above exception was the direct cause of the following exception:\n\nTraceback (most recent call last):\n  File \"/vllm-workspace/backend_request_func.py\", line 261, in async_request_openai_completions\n    async for chunk_bytes in response.content:\n  File \"/usr/local/lib/python3.10/dist-packages/aiohttp/streams.py\", line 50, in __anext__\n    rv = await self.read_func()\n  File \"/usr/local/lib/python3.10/dist-packages/aiohttp/streams.py\", line 317, in readline\n    return await self.readuntil()\n  File \"/usr/local/lib/python3.10/dist-packages/aiohttp/streams.py\", line 351, in readuntil\n    await self._wait(\"readuntil\")\n  File \"/usr/local/lib/python3.10/dist-packages/aiohttp/streams.py\", line 312, in _wait\n    await waiter\naiohttp.client_exceptions.ClientPayloadError: Response payload is not completed: <TransferEncodingError: 400, message='Not enough data for satisfy transfer length header.'>\n", "Traceback (most recent call last):\n  File \"/usr/local/lib/python3.10/dist-packages/aiohttp/client_proto.py\", line 94, in connection_lost\n    uncompleted = self._parser.feed_eof()\n  File \"aiohttp/_http_parser.pyx\", line 513, in aiohttp._http_parser.HttpParser.feed_eof\naiohttp.http_exceptions.TransferEncodingError: 400, message:\n  Not enough data for satisfy transfer length header.\n\nThe above exception was the direct cause of the following exception:\n\nTraceback (most recent call last):\n  File \"/vllm-workspace/backend_request_func.py\", line 261, in async_request_openai_completions\n    async for chunk_bytes in response.content:\n  File \"/usr/local/lib/python3.10/dist-packages/aiohttp/streams.py\", line 50, in __anext__\n    rv = await self.read_func()\n  File \"/usr/local/lib/python3.10/dist-packages/aiohttp/streams.py\", line 317, in readline\n    return await self.readuntil()\n  File \"/usr/local/lib/python3.10/dist-packages/aiohttp/streams.py\", line 351, in readuntil\n    await self._wait(\"readuntil\")\n  File \"/usr/local/lib/python3.10/dist-packages/aiohttp/streams.py\", line 312, in _wait\n    await waiter\naiohttp.client_exceptions.ClientPayloadError: Response payload is not completed: <TransferEncodingError: 400, message='Not enough data for satisfy transfer length header.'>\n", "Traceback (most recent call last):\n  File \"/usr/local/lib/python3.10/dist-packages/aiohttp/client_proto.py\", line 94, in connection_lost\n    uncompleted = self._parser.feed_eof()\n  File \"aiohttp/_http_parser.pyx\", line 513, in aiohttp._http_parser.HttpParser.feed_eof\naiohttp.http_exceptions.TransferEncodingError: 400, message:\n  Not enough data for satisfy transfer length header.\n\nThe above exception was the direct cause of the following exception:\n\nTraceback (most recent call last):\n  File \"/vllm-workspace/backend_request_func.py\", line 261, in async_request_openai_completions\n    async for chunk_bytes in response.content:\n  File \"/usr/local/lib/python3.10/dist-packages/aiohttp/streams.py\", line 50, in __anext__\n    rv = await self.read_func()\n  File \"/usr/local/lib/python3.10/dist-packages/aiohttp/streams.py\", line 317, in readline\n    return await self.readuntil()\n  File \"/usr/local/lib/python3.10/dist-packages/aiohttp/streams.py\", line 351, in readuntil\n    await self._wait(\"readuntil\")\n  File \"/usr/local/lib/python3.10/dist-packages/aiohttp/streams.py\", line 312, in _wait\n    await waiter\naiohttp.client_exceptions.ClientPayloadError: Response payload is not completed: <TransferEncodingError: 400, message='Not enough data for satisfy transfer length header.'>\n", "Traceback (most recent call last):\n  File \"/usr/local/lib/python3.10/dist-packages/aiohttp/client_proto.py\", line 94, in connection_lost\n    uncompleted = self._parser.feed_eof()\n  File \"aiohttp/_http_parser.pyx\", line 513, in aiohttp._http_parser.HttpParser.feed_eof\naiohttp.http_exceptions.TransferEncodingError: 400, message:\n  Not enough data for satisfy transfer length header.\n\nThe above exception was the direct cause of the following exception:\n\nTraceback (most recent call last):\n  File \"/vllm-workspace/backend_request_func.py\", line 261, in async_request_openai_completions\n    async for chunk_bytes in response.content:\n  File \"/usr/local/lib/python3.10/dist-packages/aiohttp/streams.py\", line 50, in __anext__\n    rv = await self.read_func()\n  File \"/usr/local/lib/python3.10/dist-packages/aiohttp/streams.py\", line 317, in readline\n    return await self.readuntil()\n  File \"/usr/local/lib/python3.10/dist-packages/aiohttp/streams.py\", line 351, in readuntil\n    await self._wait(\"readuntil\")\n  File \"/usr/local/lib/python3.10/dist-packages/aiohttp/streams.py\", line 312, in _wait\n    await waiter\naiohttp.client_exceptions.ClientPayloadError: Response payload is not completed: <TransferEncodingError: 400, message='Not enough data for satisfy transfer length header.'>\n", "Traceback (most recent call last):\n  File \"/usr/local/lib/python3.10/dist-packages/aiohttp/client_proto.py\", line 94, in connection_lost\n    uncompleted = self._parser.feed_eof()\n  File \"aiohttp/_http_parser.pyx\", line 513, in aiohttp._http_parser.HttpParser.feed_eof\naiohttp.http_exceptions.TransferEncodingError: 400, message:\n  Not enough data for satisfy transfer length header.\n\nThe above exception was the direct cause of the following exception:\n\nTraceback (most recent call last):\n  File \"/vllm-workspace/backend_request_func.py\", line 261, in async_request_openai_completions\n    async for chunk_bytes in response.content:\n  File \"/usr/local/lib/python3.10/dist-packages/aiohttp/streams.py\", line 50, in __anext__\n    rv = await self.read_func()\n  File \"/usr/local/lib/python3.10/dist-packages/aiohttp/streams.py\", line 317, in readline\n    return await self.readuntil()\n  File \"/usr/local/lib/python3.10/dist-packages/aiohttp/streams.py\", line 351, in readuntil\n    await self._wait(\"readuntil\")\n  File \"/usr/local/lib/python3.10/dist-packages/aiohttp/streams.py\", line 312, in _wait\n    await waiter\naiohttp.client_exceptions.ClientPayloadError: Response payload is not completed: <TransferEncodingError: 400, message='Not enough data for satisfy transfer length header.'>\n", "Traceback (most recent call last):\n  File \"/usr/local/lib/python3.10/dist-packages/aiohttp/client_proto.py\", line 94, in connection_lost\n    uncompleted = self._parser.feed_eof()\n  File \"aiohttp/_http_parser.pyx\", line 513, in aiohttp._http_parser.HttpParser.feed_eof\naiohttp.http_exceptions.TransferEncodingError: 400, message:\n  Not enough data for satisfy transfer length header.\n\nThe above exception was the direct cause of the following exception:\n\nTraceback (most recent call last):\n  File \"/vllm-workspace/backend_request_func.py\", line 261, in async_request_openai_completions\n    async for chunk_bytes in response.content:\n  File \"/usr/local/lib/python3.10/dist-packages/aiohttp/streams.py\", line 50, in __anext__\n    rv = await self.read_func()\n  File \"/usr/local/lib/python3.10/dist-packages/aiohttp/streams.py\", line 317, in readline\n    return await self.readuntil()\n  File \"/usr/local/lib/python3.10/dist-packages/aiohttp/streams.py\", line 351, in readuntil\n    await self._wait(\"readuntil\")\n  File \"/usr/local/lib/python3.10/dist-packages/aiohttp/streams.py\", line 312, in _wait\n    await waiter\naiohttp.client_exceptions.ClientPayloadError: Response payload is not completed: <TransferEncodingError: 400, message='Not enough data for satisfy transfer length header.'>\n", "", "Traceback (most recent call last):\n  File \"/usr/local/lib/python3.10/dist-packages/aiohttp/client_proto.py\", line 94, in connection_lost\n    uncompleted = self._parser.feed_eof()\n  File \"aiohttp/_http_parser.pyx\", line 513, in aiohttp._http_parser.HttpParser.feed_eof\naiohttp.http_exceptions.TransferEncodingError: 400, message:\n  Not enough data for satisfy transfer length header.\n\nThe above exception was the direct cause of the following exception:\n\nTraceback (most recent call last):\n  File \"/vllm-workspace/backend_request_func.py\", line 261, in async_request_openai_completions\n    async for chunk_bytes in response.content:\n  File \"/usr/local/lib/python3.10/dist-packages/aiohttp/streams.py\", line 50, in __anext__\n    rv = await self.read_func()\n  File \"/usr/local/lib/python3.10/dist-packages/aiohttp/streams.py\", line 317, in readline\n    return await self.readuntil()\n  File \"/usr/local/lib/python3.10/dist-packages/aiohttp/streams.py\", line 351, in readuntil\n    await self._wait(\"readuntil\")\n  File \"/usr/local/lib/python3.10/dist-packages/aiohttp/streams.py\", line 312, in _wait\n    await waiter\naiohttp.client_exceptions.ClientPayloadError: Response payload is not completed: <TransferEncodingError: 400, message='Not enough data for satisfy transfer length header.'>\n", "Traceback (most recent call last):\n  File \"/usr/local/lib/python3.10/dist-packages/aiohttp/client_proto.py\", line 94, in connection_lost\n    uncompleted = self._parser.feed_eof()\n  File \"aiohttp/_http_parser.pyx\", line 513, in aiohttp._http_parser.HttpParser.feed_eof\naiohttp.http_exceptions.TransferEncodingError: 400, message:\n  Not enough data for satisfy transfer length header.\n\nThe above exception was the direct cause of the following exception:\n\nTraceback (most recent call last):\n  File \"/vllm-workspace/backend_request_func.py\", line 261, in async_request_openai_completions\n    async for chunk_bytes in response.content:\n  File \"/usr/local/lib/python3.10/dist-packages/aiohttp/streams.py\", line 50, in __anext__\n    rv = await self.read_func()\n  File \"/usr/local/lib/python3.10/dist-packages/aiohttp/streams.py\", line 317, in readline\n    return await self.readuntil()\n  File \"/usr/local/lib/python3.10/dist-packages/aiohttp/streams.py\", line 351, in readuntil\n    await self._wait(\"readuntil\")\n  File \"/usr/local/lib/python3.10/dist-packages/aiohttp/streams.py\", line 312, in _wait\n    await waiter\naiohttp.client_exceptions.ClientPayloadError: Response payload is not completed: <TransferEncodingError: 400, message='Not enough data for satisfy transfer length header.'>\n", "Traceback (most recent call last):\n  File \"/usr/local/lib/python3.10/dist-packages/aiohttp/client_proto.py\", line 94, in connection_lost\n    uncompleted = self._parser.feed_eof()\n  File \"aiohttp/_http_parser.pyx\", line 513, in aiohttp._http_parser.HttpParser.feed_eof\naiohttp.http_exceptions.TransferEncodingError: 400, message:\n  Not enough data for satisfy transfer length header.\n\nThe above exception was the direct cause of the following exception:\n\nTraceback (most recent call last):\n  File \"/vllm-workspace/backend_request_func.py\", line 261, in async_request_openai_completions\n    async for chunk_bytes in response.content:\n  File \"/usr/local/lib/python3.10/dist-packages/aiohttp/streams.py\", line 50, in __anext__\n    rv = await self.read_func()\n  File \"/usr/local/lib/python3.10/dist-packages/aiohttp/streams.py\", line 317, in readline\n    return await self.readuntil()\n  File \"/usr/local/lib/python3.10/dist-packages/aiohttp/streams.py\", line 351, in readuntil\n    await self._wait(\"readuntil\")\n  File \"/usr/local/lib/python3.10/dist-packages/aiohttp/streams.py\", line 312, in _wait\n    await waiter\naiohttp.client_exceptions.ClientPayloadError: Response payload is not completed: <TransferEncodingError: 400, message='Not enough data for satisfy transfer length header.'>\n", "Traceback (most recent call last):\n  File \"/usr/local/lib/python3.10/dist-packages/aiohttp/client_proto.py\", line 94, in connection_lost\n    uncompleted = self._parser.feed_eof()\n  File \"aiohttp/_http_parser.pyx\", line 513, in aiohttp._http_parser.HttpParser.feed_eof\naiohttp.http_exceptions.TransferEncodingError: 400, message:\n  Not enough data for satisfy transfer length header.\n\nThe above exception was the direct cause of the following exception:\n\nTraceback (most recent call last):\n  File \"/vllm-workspace/backend_request_func.py\", line 261, in async_request_openai_completions\n    async for chunk_bytes in response.content:\n  File \"/usr/local/lib/python3.10/dist-packages/aiohttp/streams.py\", line 50, in __anext__\n    rv = await self.read_func()\n  File \"/usr/local/lib/python3.10/dist-packages/aiohttp/streams.py\", line 317, in readline\n    return await self.readuntil()\n  File \"/usr/local/lib/python3.10/dist-packages/aiohttp/streams.py\", line 351, in readuntil\n    await self._wait(\"readuntil\")\n  File \"/usr/local/lib/python3.10/dist-packages/aiohttp/streams.py\", line 312, in _wait\n    await waiter\naiohttp.client_exceptions.ClientPayloadError: Response payload is not completed: <TransferEncodingError: 400, message='Not enough data for satisfy transfer length header.'>\n", "Traceback (most recent call last):\n  File \"/usr/local/lib/python3.10/dist-packages/aiohttp/client_proto.py\", line 94, in connection_lost\n    uncompleted = self._parser.feed_eof()\n  File \"aiohttp/_http_parser.pyx\", line 513, in aiohttp._http_parser.HttpParser.feed_eof\naiohttp.http_exceptions.TransferEncodingError: 400, message:\n  Not enough data for satisfy transfer length header.\n\nThe above exception was the direct cause of the following exception:\n\nTraceback (most recent call last):\n  File \"/vllm-workspace/backend_request_func.py\", line 261, in async_request_openai_completions\n    async for chunk_bytes in response.content:\n  File \"/usr/local/lib/python3.10/dist-packages/aiohttp/streams.py\", line 50, in __anext__\n    rv = await self.read_func()\n  File \"/usr/local/lib/python3.10/dist-packages/aiohttp/streams.py\", line 317, in readline\n    return await self.readuntil()\n  File \"/usr/local/lib/python3.10/dist-packages/aiohttp/streams.py\", line 351, in readuntil\n    await self._wait(\"readuntil\")\n  File \"/usr/local/lib/python3.10/dist-packages/aiohttp/streams.py\", line 312, in _wait\n    await waiter\naiohttp.client_exceptions.ClientPayloadError: Response payload is not completed: <TransferEncodingError: 400, message='Not enough data for satisfy transfer length header.'>\n"]}